Workbook
Name Annee_Reporting: "Paramètres!$B$7"
Name Bilan_Total: "Paramètres!$B$10"
Name Borne_Basse: "Incertitudes!$B$41"
Name Borne_Haute: "Incertitudes!$B$42"
Name CA_Total: "Paramètres!$B$9"
Name CapEx_Total: "Paramètres!$B$14"
Name ESRS_DataPoints_Auto: "ESRS_E1!$B$36"
Name ESRS_DataPoints_Completes: "ESRS_E1!$B$37"
Name ETP_Total: "Paramètres!$B$11"
Name GES_Grand_Total: "Synthese_GES!$C$47"
Name Incertitude_Totale_Abs: "Incertitudes!$B$39"
Name Incertitude_Totale_Pct: "Incertitudes!$E$35"
Name Intensite_CA: "Synthese_GES!$C$50"
Name Intensite_ETP: "Synthese_GES!$C$51"
Name Intensite_m2: "Synthese_GES!$C$52"
Name Methode_Consolidation: "Paramètres!$B$17"
Name Nb_Sites: "Paramètres!$B$13"
Name OpEx_Eligible_Taxo: "Paramètres!$B$15"
Name Part_ETS: "Paramètres!$B$22"
Name Part_Scope1: "Synthese_GES!$C$53"
Name Part_Scope2: "Synthese_GES!$C$54"
Name Part_Scope3: "Synthese_GES!$C$55"
Name Perimetre_Geo: "Paramètres!$B$18"
Name Periode_Reporting: "Paramètres!$B$8"
Name PT_CapEx_Decarb: "Plan_Transition!$C$42"
Name PT_Pct_CapEx_Aligne: "Plan_Transition!$C$44"
Name PT_Prix_Carbone: "Plan_Transition!$C$20"
Name PT_Total_Invest: "Plan_Transition!$D$16"
Name PT_Total_Reduction: "Plan_Transition!$F$16"
Name QC_Error_Count: "_Controles_Qualite!$F$5"
Name QC_OK_Count: "_Controles_Qualite!$B$5"
Name QC_Warn_Count: "_Controles_Qualite!$D$5"
Name Raison_Sociale: "Paramètres!$B$4"
Name SBTi_Annee_Baseline: "Trajectoire_SBTi!$B$4"
Name SBTi_Baseline_S12: "Trajectoire_SBTi!$B$5"
Name SBTi_Baseline_S3: "Trajectoire_SBTi!$B$6"
Name SBTi_Horizon: "Trajectoire_SBTi!$B$10"
Name SBTi_Taux_S12: "Trajectoire_SBTi!$B$8"
Name SBTi_Taux_S3: "Trajectoire_SBTi!$B$9"
Name Scope1_1A: "Synthese_GES!$C$6"
Name Scope1_1B: "Synthese_GES!$C$7"
Name Scope1_1C: "Synthese_GES!$C$8"
Name Scope1_1D: "Synthese_GES!$C$9"
Name Scope1_Total: "Synthese_GES!$C$10"
Name Scope12_LB_Total: "Synthese_GES!$C$37"
Name Scope2_LB_Chaleur: "Synthese_GES!$C$14"
Name Scope2_LB_Elec: "Synthese_GES!$C$13"
Name Scope2_LB_Total: "Synthese_GES!$C$15"
Name Scope2_MB_Total: "Synthese_GES!$C$17"
Name Scope3_Cat1: "Synthese_GES!$C$20"
Name Scope3_Cat10: "Synthese_GES!$C$29"
Name Scope3_Cat11: "Synthese_GES!$C$30"
Name Scope3_Cat12: "Synthese_GES!$C$31"
Name Scope3_Cat13: "Synthese_GES!$C$32"
Name Scope3_Cat14: "Synthese_GES!$C$33"
Name Scope3_Cat15: "Synthese_GES!$C$34"
Name Scope3_Cat2: "Synthese_GES!$C$21"
Name Scope3_Cat3: "Synthese_GES!$C$22"
Name Scope3_Cat4: "Synthese_GES!$C$23"
Name Scope3_Cat5: "Synthese_GES!$C$24"

Sheet Couverture
B4: 🌍 CarbonCo
B5: Plateforme de Calcul Carbone & Reporting ESG
B6: BILAN D'ÉMISSIONS DE GAZ À EFFET DE SERRE
B7: Conforme GHG Protocol Corporate Standard | ISO 14064-1:2018 | ESRS E1 (CSRD)
B11: INFORMATIONS DE L'ENTREPRISE
B12: Raison sociale | C12: =IF(Paramètres!B4="","À compléter",Paramètres!B4)
B13: SIREN / SIRET | C13: =IF(Paramètres!B5="","À compléter",Paramètres!B5)
B14: Secteur d'activité | C14: =IF(Paramètres!B6="","À compléter",Paramètres!B6)
B15: Exercice de reporting | C15: =Paramètres!B8
B16: Année de reporting | C16: =Paramètres!B7
B17: Chiffre d'affaires (M€) | C17: =IF(Paramètres!B9=0,"À compléter",TEXT(Paramètres!B9/1000000,"#,##0.0"))
B18: Effectifs (ETP) | C18: =IF(Paramètres!B11=0,"À compléter",Paramètres!B11)
B19: Version du fichier | C19: =Paramètres!B74
B20: Date de génération | C20: =TODAY()
B21: Responsable BEGES | C21: À compléter
B22: Validé par | C22: À compléter
B26: ✅ GHG Protocol Corporate Standard (WRI/WBCSD 2004)
B27: ✅ ISO 14064-1:2018 — Quantification et déclaration des émissions de GES
B28: ✅ ESRS E1 (CSRD) — Delegated Regulation (EU) 2023/2772
B32: 📋 ACCÉDER AU SOMMAIRE →
B36: 🔒 Document confidentiel — Usage interne uniquement
B37: ="CarbonCo — BEGES v2.0 — Exercice "&Paramètres!B7&" — Mise à jour "&DAY(TODAY())&"/"&MONTH(TODAY())&"/"&YEAR(TODAY())

Sheet Sommaire
B4: SOMMAIRE — BILAN D'ÉMISSIONS DE GAZ À EFFET DE SERRE
B5: CarbonCo — Outil de calcul carbone | Cliquez sur le nom d'un onglet pour y accéder directement
C7: Onglet | D7: Description | E7: Catégorie | F7: Statut
B8: NAVIGATION & CONFIGURATION
B9: 🏠 | C9: Couverture | D9: Page de garde — Informations entreprise & conformité | E9: Navigation | F9: ⬜ À remplir
B10: 📋 | C10: Guide | D10: Mode d'emploi, ordre de remplissage, légende, références | E10: Navigation | F10: ⬜ À remplir
B11: 📖 | C11: Notes_Methodologiques | D11: Sources données, hypothèses, exclusions, changements méthodo | E11: Documentation | F11: À compléter
B12: ⚙️ | C12: Paramètres | D12: Configuration entreprise, périmètre, méthodologie, versioning | E12: Configuration | F12: ⬜ À remplir
B14: COLLECTE DES DONNÉES
B15: 📘 | C15: Facteurs_Emission | D15: Base de facteurs d'émission ADEME Base Carbone v23.1 | E15: Référentiel | F15: ⬜ À remplir
B16: 🔥 | C16: Scope_1 | D16: Émissions directes : combustion fixe, mobile, process, fugitives | E16: Émissions | F16: ⬜ À remplir
B17: ⚡ | C17: Scope_2 | D17: Électricité, chaleur, vapeur (location-based & market-based) | E17: Émissions | F17: ⬜ À remplir
B18: 🌍 | C18: Scope_3 | D18: Chaîne de valeur — 15 catégories GHG Protocol | E18: Émissions | F18: ⬜ À remplir
B19: 💡 | C19: Energie | D19: Mix énergétique annuel — conformité ESRS E1-5 | E19: Collecte | F19: ⬜ À remplir
B20: 🚗 | C20: Transport | D20: Déplacements professionnels & domicile-travail | E20: Collecte | F20: ⬜ À remplir
B21: 📦 | C21: Matieres_Premieres | D21: Achats de matières premières et intrants — Scope 3 Cat.1 | E21: Collecte | F21: ⬜ À remplir
B22: ♻️ | C22: Dechets | D22: Production de déchets par filière et mode de traitement | E22: Collecte | F22: ⬜ À remplir
B23: 💧 | C23: Eau | D23: Consommations d'eau et rejets | E23: Collecte | F23: ⬜ À remplir
B25: RÉSULTATS & ANALYSE
B26: 📊 | C26: Synthese_GES | D26: Bilan consolidé BEGES — Scope 1+2+3 — Conformité Art. L229-25 | E26: Résultats | F26: ⬜ À remplir
B27: 📈 | C27: Intensite_Carbone | D27: Ratios d'intensité carbone — benchmarking ESRS E1 | E27: Résultats | F27: ⬜ À remplir
B28: 🎯 | C28: Trajectoire_SBTi | D28: Trajectoire de réduction SBTi 1.5°C — Scope 1+2 et Scope 3 | E28: Résultats | F28: ⬜ À remplir
B30: CONFORMITÉ RÉGLEMENTAIRE
B31: 🌐 | C31: CBAM | D31: Mécanisme d'ajustement carbone aux frontières (UE) 2023/956 | E31: Conformité | F31: ⬜ À remplir
B32: 🌿 | C32: Taxonomie | D32: Alignement Taxonomie verte UE — KPIs CA/CapEx/OpEx | E32: Conformité | F32: ⬜ À remplir
B33: 📝 | C33: ESRS_E1 | D33: Data points ESRS E1 — Delegated Reg. (EU) 2023/2772 | E33: Conformité | F33: ⬜ À remplir
B34: 📐 | C34: Incertitudes | D34: Propagation d'incertitude ISO 14064-1 §9.2 — Audit raisonnable | E34: Conformité | F34: ⬜ À remplir
B35: 🗺️ | C35: Plan_Transition | D35: Plan de transition ESRS E1-1 — Leviers, budget, risques TCFD | E35: Conformité | F35: ⬜ À remplir
B36: 📅 | C36: Historique_5ans | D36: Comparabilité 5 ans — ESRS E1-6 §48 — Rebasement | E36: Conformité | F36: ⬜ À remplir
B37: 🔍 | C37: _Controles_Qualite | D37: 30 contrôles automatiques — Audit readiness CSRD | E37: Conformité | F37: =_Controles_Qualite!B5&"✓ "&_Controles_Qualite!D5&"⚠ "&_Controles_Qualite!F5&"✗"
B39: DASHBOARD
B40: 🖥️ | C40: Dashboard | D40: Tableau de bord synthétique — KPIs, graphiques | E40: Dashboard | F40: ⬜ À remplir
B43: ="Dernière mise à jour : "&DAY(TODAY())&"/"&MONTH(TODAY())&"/"&YEAR(TODAY())&" | Exercice "&Paramètres!B7

Sheet Guide
A1: GUIDE D'UTILISATION — OUTIL DE CALCUL CARBONE CarbonCo v2.0 | N1: 🏠 Sommaire | O1: 📄 Couverture
A3: PRÉSENTATION DE L'OUTIL
A4: Cet outil permet de réaliser le bilan d'émissions de gaz à effet de serre (BEGES) d'une entreprise conformément au GHG Protocol Corporate Standard, à la norme ISO 14064-1:2018, et aux exigences de reporting ESRS E1 dans le cadre de la directive CSRD. Il couvre les Scopes 1, 2 et 3, la trajectoire SBTi, le mécanisme CBAM et l'alignement à la Taxonomie verte européenne.
A5: ⚠️ AVERTISSEMENT : Les facteurs d'émission sont issus de la Base Carbone ADEME v23.1 et du GIEC AR6. Ils sont fournis à titre indicatif. Pour un bilan officiel (BEGES réglementaire, rapport CSRD audité), l'utilisateur doit vérifier l'applicabilité des FE à sa situation spécifique. Dernière mise à jour des FE : mars 2026.
A9: ORDRE DE REMPLISSAGE RECOMMANDÉ
A10: Étape | B10: Onglet | C10: Action | D10: Prérequis
A11: 1 | B11: Paramètres | C11: Configurer l'entreprise : raison sociale, effectifs, CA, bilan, périmètre | D11: Aucun
A12: 2 | B12: Scope_1 | C12: Saisir les émissions directes : combustion fixe, mobile, process, fugitives | D12: Paramètres rempli
A13: 3 | B13: Scope_2 | C13: Saisir la consommation d'électricité, chaleur, vapeur par site et pays | D13: Paramètres rempli
A14: 4 | B14: Energie | C14: Détailler le mix énergétique annuel (ventilation ESRS E1-5) | D14: Scope 1 et 2
A15: 5 | B15: Transport | C15: Détailler les déplacements pro et domicile-travail | D15: Paramètres
A16: 6 | B16: Matieres_Premieres | C16: Saisir les achats de matériaux et intrants | D16: Paramètres
A17: 7 | B17: Dechets | C17: Saisir la production de déchets par filière | D17: Aucun
A18: 8 | B18: Eau | C18: Saisir les consommations d'eau et rejets | D18: Aucun
A19: 9 | B19: Scope_3 | C19: Consolider les 15 catégories (certaines auto-alimentées) | D19: Étapes 2-8
A20: 10 | B20: Synthese_GES | C20: Vérifier le bilan consolidé (automatique) | D20: Étapes 2-9
A21: 11 | B21: Trajectoire_SBTi | C21: Paramétrer et suivre la trajectoire de réduction | D21: Synthèse
A22: 12 | B22: CBAM / Taxonomie / ESRS_E1 | C22: Compléter selon obligations | D22: Synthèse
A24: LÉGENDE DES COULEURS
B25: Cellule sur fond gris clair | C25: Cellule de SAISIE utilisateur
B26: Texte en bleu italique | C26: Valeur CALCULÉE automatiquement (ne pas modifier)
B27: Fond vert clair | C27: Ligne de TOTAL ou sous-total
B28: Fond orange | C28: En-tête de SECTION
B29: Fond rouge clair | C29: Alerte ou valeur hors norme
A32: NIVEAUX DE QUALITÉ DES DONNÉES D'ACTIVITÉ (ISO 14064-1:2018 §9.2)
A33: Niveau | B33: Source de données | C33: Incertitude typique | D33: Exemple
A34: 1 | B34: Mesure directe (compteur dédié) | C34: ±2 à 5% | D34: Compteur gaz, sous-compteur électrique
A35: 2 | B35: Factures fournisseurs | C35: ±5 à 10% | D35: Facture électricité, relevé fioul
A36: 3 | B36: Estimation activité × FE moyen | C36: ±10 à 30% | D36: km estimés × FE/km
A37: 4 | B37: Données monétaires × FE/€ | C37: ±30 à 80% | D37: k€ achats × kgCO2e/k€ sectoriel
A38: 5 | B38: Extrapolation / benchmark sectoriel | C38: ±50 à 100% | D38: Moyenne nationale du secteur
A41: NOTE MÉTHODOLOGIQUE : SCOPE 1 vs ÉMISSIONS AMONT
A42: Conformément au GHG Protocol Corporate Standard (Chapter 4), le Scope 1 ne comptabilise QUE les émissions de COMBUSTION (émissions directes). Les émissions liées à l'EXTRACTION, au RAFFINAGE et au TRANSPORT du combustible jusqu'au site sont des émissions AMONT et relèvent du Scope 3, Catégorie 3.
A43: Exemple : Gaz naturel — FE total = 0,227 kgCO2e/kWh = Combustion (0,205) + Amont (0,022). Seul 0,205 est comptabilisé en Scope 1. Le 0,022 est automatiquement affecté au Scope 3 Cat. 3.
A50: RÉFÉRENCES RÉGLEMENTAIRES ET MÉTHODOLOGIQUES
B51: GHG Protocol Corporate Accounting and Reporting Standard | C51: WRI/WBCSD, 2004 (rev. 2015) | D51: ghgprotocol.org
B52: GHG Protocol Scope 2 Guidance | C52: WRI/WBCSD, 2015 | D52: Méthode LB + MB
B53: GHG Protocol Corporate Value Chain (Scope 3) Standard | C53: WRI/WBCSD, 2011 | D53: 15 catégories
B54: ISO 14064-1:2018 | C54: Spécification avec lignes directrices | D54: Quantification GES
B55: IPCC AR6 WG1, Chapter 7, Table 7.15 | C55: GIEC, 2021 | D55: PRG 100 ans
...

Sheet Notes_Methodologiques
A1: NOTES MÉTHODOLOGIQUES — ESRS 2 BP-2 / ISO 14064-1:2018 §5 | K1: 🏠 Sommaire
A2: Documentation méthodologique obligatoire (ESRS 2 BP-2 §27-33 + ISO 14064-1:2018 §5.2). À compléter et à annexer au rapport CSRD ou BEGES.
A4: SECTION 1 — PÉRIMÈTRE ORGANISATIONNEL
A5: 1a. Entités incluses dans le périmètre de consolidation
A6: # | B6: Raison sociale / Entité | C6: SIREN | D6: Forme juridique | E6: % Capital | F6: % Contrôle opérationnel | G6: Méthode consolidation | H6: Incluse (O/N) | I6: Motif exclusion | J6: Note
A7: 1 | B7: =Paramètres!B4 | G7: =Paramètres!B17 | H7: Oui
A8: 2
A9: 3
A10: 4
A11: 5
A13: 1b. Évolution du périmètre vs exercice précédent
A14: Description des acquisitions, cessions, ou changements de périmètre affectant la comparabilité :
A15: (Saisir ici le récit des changements de périmètre — ex. 'Acquisition de filiale XYZ en mars 2025 : +120 ETP, +15% émissions S3 Cat.1')
A19: SECTION 2 — SOURCES DE DONNÉES PAR SCOPE
A20: Scope/Cat. | B20: Donnée d'activité | C20: Source du document | D20: Système / Outil | E20: Responsable | F20: Fréquence collecte | G20: Niveau qualité (1-5) | H20: Incertitude DA (%) | I20: Incertitude FE (%) | J20: Commentaire
A21: Scope 1 1A Combustion | B21: Consommation gaz naturel (kWh) | C21: Factures fournisseur gaz | D21: Compteur client / ERP | F21: Annuelle | G21: 2 | H21: 0.05 | I21: 0.08
A22: Scope 1 1B Mobile | B22: Carburant véhicules (L) | C22: Relevés cartes carburant | D22: Fleet management / ERP | F22: Mensuelle | G22: 2 | H22: 0.05 | I22: 0.05
A23: Scope 1 1D Fugitives | B23: Recharges fluides frigorigènes (kg) | C23: Bons d'intervention clim. | D23: GMAO / papier | F23: Annuelle | G23: 3 | H23: 0.2 | I23: 0.1
A24: Scope 2 LB | B24: Consommation électricité (kWh) | C24: Factures fournisseur élec. | D24: Smart meter / ERP | F24: Mensuelle | G24: 2 | H24: 0.03 | I24: 0.1 | J24: FE RTE réseau 2023
A25: Scope 2 MB | B25: Garanties d'Origine (GO) | C25: Certificats GO fournisseur | D25: Contrat PPA / GO | F25: Annuelle | G25: 2 | H25: 0.03 | I25: 0.05 | J25: Si pas de GO : mix résiduel AIB
A26: Scope 3 Cat.1 | B26: Montant achats par catégorie (€) | C26: Export ERP Achats | D26: SAP / Sage / ERP | F26: Annuelle | G26: 4 | H26: 0.2 | I26: 0.3 | J26: Méthode spend-based par défaut
A27: Scope 3 Cat.6 | B27: Km aériens + distance terres (km) | C27: Outil note de frais | D27: Concur / Notilus | F27: Annuelle | G27: 2 | H27: 0.05 | I27: 0.05 | J27: RF aviation ×1.9 inclus
A28: Scope 3 Cat.7 | B28: Mode + distance dom.-travail (km) | C28: Enquête mobilité interne | D28: Excel / SurveyMonkey | F28: Bi-annuelle | G28: 3 | H28: 0.15 | I28: 0.05 | J28: Hypothèse : 220 j/an
A30: SECTION 3 — HYPOTHÈSES CLÉS ET CONVENTIONS DE CALCUL
A31: Hypothèse / Convention | B31: Valeur retenue | C31: Source / Justification | D31: Impact si variation | E31: Validée par
A32: Jours ouvrés annuels | B32: 218 j/an | C32: Convention légale France (RTT inclus) | D32: ±5% sur Cat.7
A33: Distance dom.-travail moyenne | B33: 15 km (A/R = 30 km) | C33: Enquête mobilité ou valeur nationale ADEME | D33: ±15% sur Cat.7
A34: Taux télétravail | B34: 0 | C34: Saisir le taux réel ou l'hypothèse retenue | D34: Impact Cat.7 direct
A35: Taux de remplissage véhicule | B35: 1.2 passagers/véhicule | C35: ADEME / enquête interne | D35: ±10% Cat.7
A36: Multiplicateur forçage radiatif aviation | B36: ×1.9 (RF factor) | C36: ADEME/DGAC, Lee et al. 2021 | D36: Quasi-doublement GES avion
A37: CO2 biogénique | B37: Non inclus dans le bilan | C37: ISO 14064-1 §5.2.4 — comptabilisé séparément | D37: Hors total tCO2e
A38: FE électricité réseau FR | B38: 0.0599 kgCO2e/kWh (2023) | C38: ADEME Base Carbone v23.1 — code FE21 | D38: Variation annuelle ≈ ±5%
A39: FE gaz naturel (combustion) | B39: 0.205 kgCO2e/kWh PCS | C39: ADEME Base Carbone v23.1 — code FE45 | D39: Stable — FE fossile
A40: Mix résiduel AIB France | B40: 79 gCO2/kWh (2023) | C40: AIB European Residual Mix 2023 — publié juil. 2024 | D40: Pour Scope 2 Market-based
A41: Année de référence PRG | B41: GIEC AR6 2021 — PRG 100 ans | C41: Requis ESRS E1 §46 / GHG Protocol | D41: CH4 = 29.8 (vs 28 AR5)
A43: SECTION 4 — CHANGEMENTS MÉTHODOLOGIQUES ET CORRECTIONS
A44: Exercice | B44: Nature du changement | C44: Description narrative | D44: Impact quantitatif (tCO2e) | E44: Impact relatif (%) | F44: Rebasement effectué ? | G44: Validé par
A51: SECTION 5 — LIMITES, EXCLUSIONS ET ÉMISSIONS NON CALCULÉES
A52: Catégorie exclue | B52: Motif d'exclusion | C52: Estimation poids relatif (%) | D52: Plan d'intégration futur | E52: Réf. réglementaire
A53: Scope 3 Cat.15 (Investissements) | B53: Entreprise non-investisseur institutionnel | C53: < 1% | D53: N/A | E53: GHG Protocol S3 p.141
...

Sheet Paramètres
A1: PARAMÈTRES DE CONFIGURATION — BILAN CARBONE | N1: 🏠 Sommaire | O1: 📄 Couverture
A3: INFORMATIONS ENTREPRISE
A4: Raison sociale
A5: SIREN / SIRET
A6: Secteur d'activité
A7: Année de reporting
A8: Période
A9: Chiffre d'affaires net (€)
A10: Total du bilan (€)
A11: Effectifs (ETP)
A12: Surface occupée (m²)
A13: Nombre de sites
A14: CapEx total entreprise (€)
A15: OpEx éligible Taxonomie (€) | C15: (R&D + rénovation bâtiments + leases CT + maintenance)
A17: PÉRIMÈTRE ORGANISATIONNEL
A18: Méthode de consolidation | B18: Contrôle opérationnel
A19: Périmètre géographique | B19: France
A20: Scope 1 inclus | B20: Oui
A21: Scope 2 inclus | B21: Oui
A22: Scope 3 inclus | B22: Oui
A23: Part Scope 1 sous EU ETS (%) | B23: 0 | C23: Quotas gratuits (tCO2e) | D23: 0
A25: MÉTHODOLOGIE & RÉFÉRENCES
A26: Référentiel principal | B26: GHG Protocol Corporate Standard
A27: Norme ISO | B27: ISO 14064-1:2018
A28: Base de facteurs d'émission | B28: ADEME Base Carbone v23.1
A29: PRG utilisé | B29: GIEC AR6 (2021) — PRG 100 ans
A30: Gaz pris en compte | B30: CO2, CH4, N2O, HFC, PFC, SF6, NF3
A31: Unité de reporting | B31: tCO2e (tonnes CO2 équivalent)
A32: Méthode Scope 2 | B32: Location-based + Market-based
A33: Mix résiduel utilisé (MB) | B33: AIB European Residual Mix 2023
A35: POUVOIRS DE RÉCHAUFFEMENT GLOBAL (PRG 100 ans)
A36: Gaz | B36: Formule | C36: PRG 100 ans (AR6) | D36: PRG 100 ans (AR5)
A37: Dioxyde de carbone | B37: CO2 | C37: 1 | D37: 1
A38: Méthane (fossile) | B38: CH4 | C38: 29.8 | D38: 28
A39: Méthane (biogénique) | B39: CH4 bio | C39: 27 | D39: 28
A40: Protoxyde d'azote | B40: N2O | C40: 273 | D40: 265
A41: Hexafluorure de soufre | B41: SF6 | C41: 25200 | D41: 23500
A42: R-410A | B42: HFC | C42: 2088 | D42: 2088
A43: R-134a | B43: HFC-134a | C43: 1530 | D43: 1430
A45: SEUILS RÉGLEMENTAIRES
...

Sheet Facteurs_Emission
A1: BASE DE FACTEURS D'ÉMISSION — ADEME Base Carbone v23.1 / GIEC AR6 / AIB 2023 | N1: 🏠 Sommaire | O1: 🏠 Sommaire
A2: Les colonnes E (Combustion) et F (Amont) permettent de séparer correctement Scope 1 et Scope 3 Cat.3. La colonne G = E+F (total). La colonne H fournit le FE residual mix pour le Scope 2 market-based.
A3: ID | B3: Catégorie | C3: Poste d'émission | D3: Unité source | E3: FE Combustion (kgCO2e/u) [Scope 1] | F3: FE Amont (kgCO2e/u) [Scope 3 Cat.3] | G3: FE Total (kgCO2e/u) [E+F] | H3: FE Résiduel / Market-based | I3: Incertitude (%) | J3: Source | K3: Notes / Périmètre
A4: FE001 | B4: Combustibles | C4: Gaz naturel (PCI) | D4: kWh | E4: 0.205 | F4: 0.022 | G4: =E4+F4 | I4: 5 | J4: ADEME 2024 | K4: Combustion seule en Scope 1 ; amont en Scope 3 Cat.3
A5: FE002 | B5: Combustibles | C5: Gaz naturel (PCS) | D5: kWh | E5: 0.185 | F5: 0.02 | G5: =E5+F5 | I5: 5 | J5: ADEME 2024 | K5: PCS = PCI × 1.11
A6: FE003 | B6: Combustibles | C6: Fioul domestique | D6: litre | E6: 2.68 | F6: 0.57 | G6: =E6+F6 | I6: 5 | J6: ADEME 2024 | K6: 2,68 combustion + 0,57 amont
A7: FE004 | B7: Combustibles | C7: Fioul lourd | D7: tonne | E7: 3160 | F7: 365 | G7: =E7+F7 | I7: 5 | J7: ADEME 2024
A8: FE005 | B8: Combustibles | C8: Charbon (houille) | D8: tonne | E8: 2684 | F8: 276 | G8: =E8+F8 | I8: 10 | J8: ADEME 2024
A9: FE006 | B9: Combustibles | C9: GPL | D9: litre | E9: 1.49 | F9: 0.18 | G9: =E9+F9 | I9: 5 | J9: ADEME 2024
A10: FE007 | B10: Combustibles | C10: Propane | D10: kg | E10: 2.94 | F10: 0.5 | G10: =E10+F10 | I10: 5 | J10: ADEME 2024
A11: FE008 | B11: Combustibles | C11: Bois bûches | D11: kWh | E11: 0 | F11: 0.03 | G11: =E11+F11 | I11: 30 | J11: ADEME 2024 | K11: CO2 biogénique neutre (combustion=0). Amont seul
A12: FE010 | B12: Carburants | C12: Essence SP95/SP98 | D12: litre | E12: 2.28 | F12: 0.52 | G12: =E12+F12 | I12: 5 | J12: ADEME 2024 | K12: 2,28 combustion + 0,52 amont
A13: FE011 | B13: Carburants | C13: Diesel / Gazole | D13: litre | E13: 2.49 | F13: 0.68 | G13: =E13+F13 | I13: 5 | J13: ADEME 2024 | K13: 2,49 combustion + 0,68 amont
A14: FE012 | B14: Carburants | C14: E85 (Superéthanol) | D14: litre | E14: 1.11 | F14: 0.5 | G14: =E14+F14 | I14: 15 | J14: ADEME 2024 | K14: Part biogénique : CO2 combustion bio exclu
A15: FE013 | B15: Carburants | C15: B100 (Biodiesel pur) | D15: litre | E15: 0.22 | F15: 0.96 | G15: =E15+F15 | I15: 20 | J15: ADEME 2024 | K15: Combustion bio quasi nulle
A16: FE014 | B16: Carburants | C16: GNV (Gaz Naturel Véhicule) | D16: kg | E16: 2.63 | F16: 0.64 | G16: =E16+F16 | I16: 10 | J16: ADEME 2024
A17: FE015 | B17: Carburants | C17: Kérosène (aviation) | D17: litre | E17: 2.52 | F17: 0.63 | G17: =E17+F17 | I17: 5 | J17: ADEME 2024 | K17: Combustion seule
A18: FE016 | B18: Carburants | C18: Hydrogène gris (vaporeformage) | D18: kg | E18: 0 | F18: 11.5 | G18: =E18+F18 | I18: 15 | J18: ADEME 2024 | K18: Pas de combustion : tout en amont
A19: FE017 | B19: Carburants | C19: Hydrogène vert (électrolyse ENR) | D19: kg | E19: 0 | F19: 1 | G19: =E19+F19 | I19: 30 | J19: ADEME 2024
A20: FE020 | B20: Électricité | C20: Électricité France (location-based) | D20: kWh | G20: 0.0569 | H20: 0.06 | I20: 10 | J20: ADEME 2024 + AIB 2023 | K20: LB = mix moyen annuel FR 2023. MB résiduel = AIB
A21: FE021 | B21: Électricité | C21: Électricité France (amont T&D) | D21: kWh | H21: 0.0119 | I21: 10 | J21: ADEME 2024 | K21: Émissions amont production+T&D → Scope 3 Cat.3
A22: FE022 | B22: Électricité | C22: Électricité Allemagne | D22: kWh | G22: 0.385 | H22: 0.576 | I22: 10 | J22: AIE 2023 + AIB 2023 | K22: Mix résiduel DE supérieur au mix moyen
A23: FE023 | B23: Électricité | C23: Électricité Europe (UE27) | D23: kWh | G23: 0.267 | H23: 0.396 | I23: 15 | J23: AIE 2023 + AIB 2023 | K23: Moyenne UE27
A24: FE024 | B24: Électricité | C24: Électricité USA | D24: kWh | G24: 0.39 | H24: 0.39 | I24: 10 | J24: EPA eGRID 2023 | K24: Pas de residual mix officiel USA
A25: FE025 | B25: Électricité | C25: Électricité Chine | D25: kWh | G25: 0.555 | H25: 0.555 | I25: 10 | J25: AIE 2023
A26: FE026 | B26: Électricité | C26: Renouvelable certifiée (GO/PPA) | D26: kWh | G26: 0.006 | H26: 0.006 | I26: 50 | J26: ADEME 2024 | K26: Market-based avec GO ou PPA
A27: FE027 | B27: Électricité | C27: Réseau chaleur urbain (France moy.) | D27: kWh | G27: 0.112 | I27: 20 | J27: ADEME 2024
A28: FE028 | B28: Électricité | C28: Réseau de froid urbain | D28: kWh | G28: 0.032 | I28: 25 | J28: ADEME 2024
A29: FE029 | B29: Électricité | C29: Pertes T&D électricité France (%) | D29: % | G29: 0.075 | I29: 10 | J29: RTE 2023 | K29: Taux de pertes réseau T&D = 7,5%
A30: FE030 | B30: Transp. pers. | C30: Voiture thermique moy. FR (1 pass.) | D30: km | E30: 0.193 | F30: 0.025 | G30: =E30+F30 | I30: 15 | J30: ADEME 2024 | K30: Moyenne parc FR
A31: FE031 | B31: Transp. pers. | C31: Voiture diesel (1 passager) | D31: km | E31: 0.17 | F31: 0.023 | G31: =E31+F31 | I31: 10 | J31: ADEME 2024
A32: FE032 | B32: Transp. pers. | C32: Voiture essence (1 passager) | D32: km | E32: 0.199 | F32: 0.026 | G32: =E32+F32 | I32: 10 | J32: ADEME 2024
A33: FE033 | B33: Transp. pers. | C33: Voiture électrique (usage, France) | D33: km | E33: 0.02 | F33: 0.003 | G33: =E33+F33 | I33: 20 | J33: ADEME 2024 | K33: Usage uniquement (électricité)
A34: FE033b | B34: Transp. pers. | C34: Voiture électrique (fabrication amortie) | D34: km | E34: 0.035 | F34: 0.02 | G34: =E34+F34 | I34: 30 | J34: ADEME + IVL 2019 | K34: Fabrication amortie 200 000 km
A35: FE034 | B35: Transp. pers. | C35: Voiture hybride rechargeable | D35: km | E35: 0.09 | F35: 0.02 | G35: =E35+F35 | I35: 20 | J35: ADEME 2024 | K35: Usage mixte 50/50
A36: FE035 | B36: Transp. pers. | C36: TGV / Intercités | D36: km.passager | E36: 0.00174 | F36: 0 | G36: =E36+F36 | I36: 20 | J36: ADEME 2024 | K36: Électrique France
A37: FE036 | B37: Transp. pers. | C37: TER | D37: km.passager | E37: 0.0298 | F37: 0 | G37: =E37+F37 | I37: 20 | J37: ADEME 2024 | K37: Mix diesel+électrique
A38: FE037 | B38: Transp. pers. | C38: Métro / Tramway | D38: km.passager | E38: 0.00394 | F38: 0 | G38: =E38+F38 | I38: 20 | J38: ADEME 2024
A39: FE038 | B39: Transp. pers. | C39: Bus urbain (diesel) | D39: km.passager | E39: 0.113 | F39: 0 | G39: =E39+F39 | I39: 15 | J39: ADEME 2024
A40: FE039 | B40: Transp. pers. | C40: Avion court-courrier (<1000 km, éco) | D40: km.passager | E40: 0.141 | F40: 0 | G40: =E40+F40 | I40: 15 | J40: ADEME 2024 | K40: CO2 seul = 0.141
...

Sheet Scope_1
A1: SCOPE 1 — ÉMISSIONS DIRECTES | N1: 🏠 Sommaire | O1: 🏠 Sommaire
A2: Conformément au GHG Protocol, seules les émissions de COMBUSTION sont comptabilisées en Scope 1. Les émissions AMONT sont en Scope 3 Cat. 3 et calculées automatiquement dans les colonnes J-K.
A4: 1A — COMBUSTION FIXE (chauffage, production de chaleur, cogénération)
A5: Ligne | B5: Source / Équipement / Site | C5: Combustible | D5: Quantité consommée | E5: Unité | F5: ID FE | G5: FE Combustion (kgCO2e/u) | H5: Émissions Scope 1 (kgCO2e) | I5: Émissions Scope 1 (tCO2e) | J5: FE Amont (kgCO2e/u) | K5: Émissions amont → Scope 3 Cat.3 (kgCO2e)
A6: 1 | D6: 0 | E6: =IF(C6="","",IF(OR(C6="Gaz naturel (PCI)",C6="Gaz naturel (PCS)"),"kWh",IF(OR(C6="Fioul domestique",C6="GPL"),"litre",IF(OR(C6="Fioul lourd",C6="Charbon (houille)"),"tonne",IF(C6="Propane","kg",IF(C6="Bois bûches","kWh","")))))) | F6: =IF(C6="","",IF(C6="Gaz naturel (PCI)","FE001",IF(C6="Gaz naturel (PCS)","FE002",IF(C6="Fioul domestique","FE003",IF(C6="Fioul lourd","FE004",IF(C6="Charbon (houille)","FE005",IF(C6="GPL","FE006",IF(C6="Propane","FE007",IF(C6="Bois bûches","FE008",""))))))))) | G6: =IF(F6="","",VLOOKUP(F6,Facteurs_Emission!$A$4:$E$108,5,FALSE())) | H6: =IF(OR(D6=0,G6=""),0,D6*G6) | I6: =H6/1000 | J6: =IF(F6="","",VLOOKUP(F6,Facteurs_Emission!$A$4:$F$108,6,FALSE())) | K6: =IF(OR(D6=0,J6=""),0,D6*J6)
A7: 2 | D7: 0 | E7: =IF(C7="","",IF(OR(C7="Gaz naturel (PCI)",C7="Gaz naturel (PCS)"),"kWh",IF(OR(C7="Fioul domestique",C7="GPL"),"litre",IF(OR(C7="Fioul lourd",C7="Charbon (houille)"),"tonne",IF(C7="Propane","kg",IF(C7="Bois bûches","kWh","")))))) | F7: =IF(C7="","",IF(C7="Gaz naturel (PCI)","FE001",IF(C7="Gaz naturel (PCS)","FE002",IF(C7="Fioul domestique","FE003",IF(C7="Fioul lourd","FE004",IF(C7="Charbon (houille)","FE005",IF(C7="GPL","FE006",IF(C7="Propane","FE007",IF(C7="Bois bûches","FE008",""))))))))) | G7: =IF(F7="","",VLOOKUP(F7,Facteurs_Emission!$A$4:$E$108,5,FALSE())) | H7: =IF(OR(D7=0,G7=""),0,D7*G7) | I7: =H7/1000 | J7: =IF(F7="","",VLOOKUP(F7,Facteurs_Emission!$A$4:$F$108,6,FALSE())) | K7: =IF(OR(D7=0,J7=""),0,D7*J7)
A8: 3 | D8: 0 | E8: =IF(C8="","",IF(OR(C8="Gaz naturel (PCI)",C8="Gaz naturel (PCS)"),"kWh",IF(OR(C8="Fioul domestique",C8="GPL"),"litre",IF(OR(C8="Fioul lourd",C8="Charbon (houille)"),"tonne",IF(C8="Propane","kg",IF(C8="Bois bûches","kWh","")))))) | F8: =IF(C8="","",IF(C8="Gaz naturel (PCI)","FE001",IF(C8="Gaz naturel (PCS)","FE002",IF(C8="Fioul domestique","FE003",IF(C8="Fioul lourd","FE004",IF(C8="Charbon (houille)","FE005",IF(C8="GPL","FE006",IF(C8="Propane","FE007",IF(C8="Bois bûches","FE008",""))))))))) | G8: =IF(F8="","",VLOOKUP(F8,Facteurs_Emission!$A$4:$E$108,5,FALSE())) | H8: =IF(OR(D8=0,G8=""),0,D8*G8) | I8: =H8/1000 | J8: =IF(F8="","",VLOOKUP(F8,Facteurs_Emission!$A$4:$F$108,6,FALSE())) | K8: =IF(OR(D8=0,J8=""),0,D8*J8)
A9: 4 | D9: 0 | E9: =IF(C9="","",IF(OR(C9="Gaz naturel (PCI)",C9="Gaz naturel (PCS)"),"kWh",IF(OR(C9="Fioul domestique",C9="GPL"),"litre",IF(OR(C9="Fioul lourd",C9="Charbon (houille)"),"tonne",IF(C9="Propane","kg",IF(C9="Bois bûches","kWh","")))))) | F9: =IF(C9="","",IF(C9="Gaz naturel (PCI)","FE001",IF(C9="Gaz naturel (PCS)","FE002",IF(C9="Fioul domestique","FE003",IF(C9="Fioul lourd","FE004",IF(C9="Charbon (houille)","FE005",IF(C9="GPL","FE006",IF(C9="Propane","FE007",IF(C9="Bois bûches","FE008",""))))))))) | G9: =IF(F9="","",VLOOKUP(F9,Facteurs_Emission!$A$4:$E$108,5,FALSE())) | H9: =IF(OR(D9=0,G9=""),0,D9*G9) | I9: =H9/1000 | J9: =IF(F9="","",VLOOKUP(F9,Facteurs_Emission!$A$4:$F$108,6,FALSE())) | K9: =IF(OR(D9=0,J9=""),0,D9*J9)
A10: 5 | D10: 0 | E10: =IF(C10="","",IF(OR(C10="Gaz naturel (PCI)",C10="Gaz naturel (PCS)"),"kWh",IF(OR(C10="Fioul domestique",C10="GPL"),"litre",IF(OR(C10="Fioul lourd",C10="Charbon (houille)"),"tonne",IF(C10="Propane","kg",IF(C10="Bois bûches","kWh","")))))) | F10: =IF(C10="","",IF(C10="Gaz naturel (PCI)","FE001",IF(C10="Gaz naturel (PCS)","FE002",IF(C10="Fioul domestique","FE003",IF(C10="Fioul lourd","FE004",IF(C10="Charbon (houille)","FE005",IF(C10="GPL","FE006",IF(C10="Propane","FE007",IF(C10="Bois bûches","FE008",""))))))))) | G10: =IF(F10="","",VLOOKUP(F10,Facteurs_Emission!$A$4:$E$108,5,FALSE())) | H10: =IF(OR(D10=0,G10=""),0,D10*G10) | I10: =H10/1000 | J10: =IF(F10="","",VLOOKUP(F10,Facteurs_Emission!$A$4:$F$108,6,FALSE())) | K10: =IF(OR(D10=0,J10=""),0,D10*J10)
A11: 6 | D11: 0 | E11: =IF(C11="","",IF(OR(C11="Gaz naturel (PCI)",C11="Gaz naturel (PCS)"),"kWh",IF(OR(C11="Fioul domestique",C11="GPL"),"litre",IF(OR(C11="Fioul lourd",C11="Charbon (houille)"),"tonne",IF(C11="Propane","kg",IF(C11="Bois bûches","kWh","")))))) | F11: =IF(C11="","",IF(C11="Gaz naturel (PCI)","FE001",IF(C11="Gaz naturel (PCS)","FE002",IF(C11="Fioul domestique","FE003",IF(C11="Fioul lourd","FE004",IF(C11="Charbon (houille)","FE005",IF(C11="GPL","FE006",IF(C11="Propane","FE007",IF(C11="Bois bûches","FE008",""))))))))) | G11: =IF(F11="","",VLOOKUP(F11,Facteurs_Emission!$A$4:$E$108,5,FALSE())) | H11: =IF(OR(D11=0,G11=""),0,D11*G11) | I11: =H11/1000 | J11: =IF(F11="","",VLOOKUP(F11,Facteurs_Emission!$A$4:$F$108,6,FALSE())) | K11: =IF(OR(D11=0,J11=""),0,D11*J11)
A12: 7 | D12: 0 | E12: =IF(C12="","",IF(OR(C12="Gaz naturel (PCI)",C12="Gaz naturel (PCS)"),"kWh",IF(OR(C12="Fioul domestique",C12="GPL"),"litre",IF(OR(C12="Fioul lourd",C12="Charbon (houille)"),"tonne",IF(C12="Propane","kg",IF(C12="Bois bûches","kWh","")))))) | F12: =IF(C12="","",IF(C12="Gaz naturel (PCI)","FE001",IF(C12="Gaz naturel (PCS)","FE002",IF(C12="Fioul domestique","FE003",IF(C12="Fioul lourd","FE004",IF(C12="Charbon (houille)","FE005",IF(C12="GPL","FE006",IF(C12="Propane","FE007",IF(C12="Bois bûches","FE008",""))))))))) | G12: =IF(F12="","",VLOOKUP(F12,Facteurs_Emission!$A$4:$E$108,5,FALSE())) | H12: =IF(OR(D12=0,G12=""),0,D12*G12) | I12: =H12/1000 | J12: =IF(F12="","",VLOOKUP(F12,Facteurs_Emission!$A$4:$F$108,6,FALSE())) | K12: =IF(OR(D12=0,J12=""),0,D12*J12)
A13: 8 | D13: 0 | E13: =IF(C13="","",IF(OR(C13="Gaz naturel (PCI)",C13="Gaz naturel (PCS)"),"kWh",IF(OR(C13="Fioul domestique",C13="GPL"),"litre",IF(OR(C13="Fioul lourd",C13="Charbon (houille)"),"tonne",IF(C13="Propane","kg",IF(C13="Bois bûches","kWh","")))))) | F13: =IF(C13="","",IF(C13="Gaz naturel (PCI)","FE001",IF(C13="Gaz naturel (PCS)","FE002",IF(C13="Fioul domestique","FE003",IF(C13="Fioul lourd","FE004",IF(C13="Charbon (houille)","FE005",IF(C13="GPL","FE006",IF(C13="Propane","FE007",IF(C13="Bois bûches","FE008",""))))))))) | G13: =IF(F13="","",VLOOKUP(F13,Facteurs_Emission!$A$4:$E$108,5,FALSE())) | H13: =IF(OR(D13=0,G13=""),0,D13*G13) | I13: =H13/1000 | J13: =IF(F13="","",VLOOKUP(F13,Facteurs_Emission!$A$4:$F$108,6,FALSE())) | K13: =IF(OR(D13=0,J13=""),0,D13*J13)
A14: 9 | D14: 0 | E14: =IF(C14="","",IF(OR(C14="Gaz naturel (PCI)",C14="Gaz naturel (PCS)"),"kWh",IF(OR(C14="Fioul domestique",C14="GPL"),"litre",IF(OR(C14="Fioul lourd",C14="Charbon (houille)"),"tonne",IF(C14="Propane","kg",IF(C14="Bois bûches","kWh","")))))) | F14: =IF(C14="","",IF(C14="Gaz naturel (PCI)","FE001",IF(C14="Gaz naturel (PCS)","FE002",IF(C14="Fioul domestique","FE003",IF(C14="Fioul lourd","FE004",IF(C14="Charbon (houille)","FE005",IF(C14="GPL","FE006",IF(C14="Propane","FE007",IF(C14="Bois bûches","FE008",""))))))))) | G14: =IF(F14="","",VLOOKUP(F14,Facteurs_Emission!$A$4:$E$108,5,FALSE())) | H14: =IF(OR(D14=0,G14=""),0,D14*G14) | I14: =H14/1000 | J14: =IF(F14="","",VLOOKUP(F14,Facteurs_Emission!$A$4:$F$108,6,FALSE())) | K14: =IF(OR(D14=0,J14=""),0,D14*J14)
A15: 10 | D15: 0 | E15: =IF(C15="","",IF(OR(C15="Gaz naturel (PCI)",C15="Gaz naturel (PCS)"),"kWh",IF(OR(C15="Fioul domestique",C15="GPL"),"litre",IF(OR(C15="Fioul lourd",C15="Charbon (houille)"),"tonne",IF(C15="Propane","kg",IF(C15="Bois bûches","kWh","")))))) | F15: =IF(C15="","",IF(C15="Gaz naturel (PCI)","FE001",IF(C15="Gaz naturel (PCS)","FE002",IF(C15="Fioul domestique","FE003",IF(C15="Fioul lourd","FE004",IF(C15="Charbon (houille)","FE005",IF(C15="GPL","FE006",IF(C15="Propane","FE007",IF(C15="Bois bûches","FE008",""))))))))) | G15: =IF(F15="","",VLOOKUP(F15,Facteurs_Emission!$A$4:$E$108,5,FALSE())) | H15: =IF(OR(D15=0,G15=""),0,D15*G15) | I15: =H15/1000 | J15: =IF(F15="","",VLOOKUP(F15,Facteurs_Emission!$A$4:$F$108,6,FALSE())) | K15: =IF(OR(D15=0,J15=""),0,D15*J15)
B16: SOUS-TOTAL COMBUSTION FIXE | H16: =SUM(H6:H15) | I16: =SUM(I6:I15) | K16: =SUM(K6:K15)
A18: 1B — COMBUSTION MOBILE (véhicules détenus ou contrôlés par l'entreprise)
A19: Ligne | B19: Source / Équipement / Site | C19: Combustible | D19: Quantité consommée | E19: Unité | F19: ID FE | G19: FE Combustion (kgCO2e/u) | H19: Émissions Scope 1 (kgCO2e) | I19: Émissions Scope 1 (tCO2e) | J19: FE Amont (kgCO2e/u) | K19: Émissions amont → Scope 3 Cat.3 (kgCO2e)
A20: 1 | D20: 0 | E20: =IF(C20="","",IF(C20="GNV","kg","litre")) | F20: =IF(C20="","",IF(C20="Essence SP95/SP98","FE010",IF(C20="Diesel / Gazole","FE011",IF(C20="E85 (Superéthanol)","FE012",IF(C20="B100 (Biodiesel pur)","FE013",IF(C20="GNV","FE014","")))))) | G20: =IF(F20="","",VLOOKUP(F20,Facteurs_Emission!$A$4:$E$108,5,FALSE())) | H20: =IF(OR(D20=0,G20=""),0,D20*G20) | I20: =H20/1000 | J20: =IF(F20="","",VLOOKUP(F20,Facteurs_Emission!$A$4:$F$108,6,FALSE())) | K20: =IF(OR(D20=0,J20=""),0,D20*J20)
A21: 2 | D21: 0 | E21: =IF(C21="","",IF(C21="GNV","kg","litre")) | F21: =IF(C21="","",IF(C21="Essence SP95/SP98","FE010",IF(C21="Diesel / Gazole","FE011",IF(C21="E85 (Superéthanol)","FE012",IF(C21="B100 (Biodiesel pur)","FE013",IF(C21="GNV","FE014","")))))) | G21: =IF(F21="","",VLOOKUP(F21,Facteurs_Emission!$A$4:$E$108,5,FALSE())) | H21: =IF(OR(D21=0,G21=""),0,D21*G21) | I21: =H21/1000 | J21: =IF(F21="","",VLOOKUP(F21,Facteurs_Emission!$A$4:$F$108,6,FALSE())) | K21: =IF(OR(D21=0,J21=""),0,D21*J21)
A22: 3 | D22: 0 | E22: =IF(C22="","",IF(C22="GNV","kg","litre")) | F22: =IF(C22="","",IF(C22="Essence SP95/SP98","FE010",IF(C22="Diesel / Gazole","FE011",IF(C22="E85 (Superéthanol)","FE012",IF(C22="B100 (Biodiesel pur)","FE013",IF(C22="GNV","FE014","")))))) | G22: =IF(F22="","",VLOOKUP(F22,Facteurs_Emission!$A$4:$E$108,5,FALSE())) | H22: =IF(OR(D22=0,G22=""),0,D22*G22) | I22: =H22/1000 | J22: =IF(F22="","",VLOOKUP(F22,Facteurs_Emission!$A$4:$F$108,6,FALSE())) | K22: =IF(OR(D22=0,J22=""),0,D22*J22)
A23: 4 | D23: 0 | E23: =IF(C23="","",IF(C23="GNV","kg","litre")) | F23: =IF(C23="","",IF(C23="Essence SP95/SP98","FE010",IF(C23="Diesel / Gazole","FE011",IF(C23="E85 (Superéthanol)","FE012",IF(C23="B100 (Biodiesel pur)","FE013",IF(C23="GNV","FE014","")))))) | G23: =IF(F23="","",VLOOKUP(F23,Facteurs_Emission!$A$4:$E$108,5,FALSE())) | H23: =IF(OR(D23=0,G23=""),0,D23*G23) | I23: =H23/1000 | J23: =IF(F23="","",VLOOKUP(F23,Facteurs_Emission!$A$4:$F$108,6,FALSE())) | K23: =IF(OR(D23=0,J23=""),0,D23*J23)
A24: 5 | D24: 0 | E24: =IF(C24="","",IF(C24="GNV","kg","litre")) | F24: =IF(C24="","",IF(C24="Essence SP95/SP98","FE010",IF(C24="Diesel / Gazole","FE011",IF(C24="E85 (Superéthanol)","FE012",IF(C24="B100 (Biodiesel pur)","FE013",IF(C24="GNV","FE014","")))))) | G24: =IF(F24="","",VLOOKUP(F24,Facteurs_Emission!$A$4:$E$108,5,FALSE())) | H24: =IF(OR(D24=0,G24=""),0,D24*G24) | I24: =H24/1000 | J24: =IF(F24="","",VLOOKUP(F24,Facteurs_Emission!$A$4:$F$108,6,FALSE())) | K24: =IF(OR(D24=0,J24=""),0,D24*J24)
A25: 6 | D25: 0 | E25: =IF(C25="","",IF(C25="GNV","kg","litre")) | F25: =IF(C25="","",IF(C25="Essence SP95/SP98","FE010",IF(C25="Diesel / Gazole","FE011",IF(C25="E85 (Superéthanol)","FE012",IF(C25="B100 (Biodiesel pur)","FE013",IF(C25="GNV","FE014","")))))) | G25: =IF(F25="","",VLOOKUP(F25,Facteurs_Emission!$A$4:$E$108,5,FALSE())) | H25: =IF(OR(D25=0,G25=""),0,D25*G25) | I25: =H25/1000 | J25: =IF(F25="","",VLOOKUP(F25,Facteurs_Emission!$A$4:$F$108,6,FALSE())) | K25: =IF(OR(D25=0,J25=""),0,D25*J25)
A26: 7 | D26: 0 | E26: =IF(C26="","",IF(C26="GNV","kg","litre")) | F26: =IF(C26="","",IF(C26="Essence SP95/SP98","FE010",IF(C26="Diesel / Gazole","FE011",IF(C26="E85 (Superéthanol)","FE012",IF(C26="B100 (Biodiesel pur)","FE013",IF(C26="GNV","FE014","")))))) | G26: =IF(F26="","",VLOOKUP(F26,Facteurs_Emission!$A$4:$E$108,5,FALSE())) | H26: =IF(OR(D26=0,G26=""),0,D26*G26) | I26: =H26/1000 | J26: =IF(F26="","",VLOOKUP(F26,Facteurs_Emission!$A$4:$F$108,6,FALSE())) | K26: =IF(OR(D26=0,J26=""),0,D26*J26)
A27: 8 | D27: 0 | E27: =IF(C27="","",IF(C27="GNV","kg","litre")) | F27: =IF(C27="","",IF(C27="Essence SP95/SP98","FE010",IF(C27="Diesel / Gazole","FE011",IF(C27="E85 (Superéthanol)","FE012",IF(C27="B100 (Biodiesel pur)","FE013",IF(C27="GNV","FE014","")))))) | G27: =IF(F27="","",VLOOKUP(F27,Facteurs_Emission!$A$4:$E$108,5,FALSE())) | H27: =IF(OR(D27=0,G27=""),0,D27*G27) | I27: =H27/1000 | J27: =IF(F27="","",VLOOKUP(F27,Facteurs_Emission!$A$4:$F$108,6,FALSE())) | K27: =IF(OR(D27=0,J27=""),0,D27*J27)
A28: 9 | D28: 0 | E28: =IF(C28="","",IF(C28="GNV","kg","litre")) | F28: =IF(C28="","",IF(C28="Essence SP95/SP98","FE010",IF(C28="Diesel / Gazole","FE011",IF(C28="E85 (Superéthanol)","FE012",IF(C28="B100 (Biodiesel pur)","FE013",IF(C28="GNV","FE014","")))))) | G28: =IF(F28="","",VLOOKUP(F28,Facteurs_Emission!$A$4:$E$108,5,FALSE())) | H28: =IF(OR(D28=0,G28=""),0,D28*G28) | I28: =H28/1000 | J28: =IF(F28="","",VLOOKUP(F28,Facteurs_Emission!$A$4:$F$108,6,FALSE())) | K28: =IF(OR(D28=0,J28=""),0,D28*J28)
A29: 10 | D29: 0 | E29: =IF(C29="","",IF(C29="GNV","kg","litre")) | F29: =IF(C29="","",IF(C29="Essence SP95/SP98","FE010",IF(C29="Diesel / Gazole","FE011",IF(C29="E85 (Superéthanol)","FE012",IF(C29="B100 (Biodiesel pur)","FE013",IF(C29="GNV","FE014","")))))) | G29: =IF(F29="","",VLOOKUP(F29,Facteurs_Emission!$A$4:$E$108,5,FALSE())) | H29: =IF(OR(D29=0,G29=""),0,D29*G29) | I29: =H29/1000 | J29: =IF(F29="","",VLOOKUP(F29,Facteurs_Emission!$A$4:$F$108,6,FALSE())) | K29: =IF(OR(D29=0,J29=""),0,D29*J29)
B30: SOUS-TOTAL COMBUSTION MOBILE | H30: =SUM(H20:H29) | I30: =SUM(I20:I29) | K30: =SUM(K20:K29)
A32: 1C — ÉMISSIONS DE PROCESS (réactions chimiques, procédés industriels)
A33: Ligne | B33: Process / Source | C33: Gaz émis | D33: Quantité émise (kg) | E33: Unité | F33: PRG | H33: Émissions (kgCO2e) | I33: Émissions (tCO2e)
A34: 1 | D34: 0 | E34: kg | F34: =IF(C34="","",IF(C34="CO2",1,IF(C34="CH4 (fossile)",29.8,IF(C34="N2O",273,IF(C34="HFC (R-410A)",2088,IF(C34="SF6",25200,0)))))) | H34: =IF(OR(D34=0,F34=""),0,D34*F34) | I34: =IF(H34=0,0,H34/1000)
A35: 2 | D35: 0 | E35: kg | F35: =IF(C35="","",IF(C35="CO2",1,IF(C35="CH4 (fossile)",29.8,IF(C35="N2O",273,IF(C35="HFC (R-410A)",2088,IF(C35="SF6",25200,0)))))) | H35: =IF(OR(D35=0,F35=""),0,D35*F35) | I35: =IF(H35=0,0,H35/1000)
A36: 3 | D36: 0 | E36: kg | F36: =IF(C36="","",IF(C36="CO2",1,IF(C36="CH4 (fossile)",29.8,IF(C36="N2O",273,IF(C36="HFC (R-410A)",2088,IF(C36="SF6",25200,0)))))) | H36: =IF(OR(D36=0,F36=""),0,D36*F36) | I36: =IF(H36=0,0,H36/1000)
A37: 4 | D37: 0 | E37: kg | F37: =IF(C37="","",IF(C37="CO2",1,IF(C37="CH4 (fossile)",29.8,IF(C37="N2O",273,IF(C37="HFC (R-410A)",2088,IF(C37="SF6",25200,0)))))) | H37: =IF(OR(D37=0,F37=""),0,D37*F37) | I37: =IF(H37=0,0,H37/1000)
A38: 5 | D38: 0 | E38: kg | F38: =IF(C38="","",IF(C38="CO2",1,IF(C38="CH4 (fossile)",29.8,IF(C38="N2O",273,IF(C38="HFC (R-410A)",2088,IF(C38="SF6",25200,0)))))) | H38: =IF(OR(D38=0,F38=""),0,D38*F38) | I38: =IF(H38=0,0,H38/1000)
A39: 6 | D39: 0 | E39: kg | F39: =IF(C39="","",IF(C39="CO2",1,IF(C39="CH4 (fossile)",29.8,IF(C39="N2O",273,IF(C39="HFC (R-410A)",2088,IF(C39="SF6",25200,0)))))) | H39: =IF(OR(D39=0,F39=""),0,D39*F39) | I39: =IF(H39=0,0,H39/1000)
A40: 7 | D40: 0 | E40: kg | F40: =IF(C40="","",IF(C40="CO2",1,IF(C40="CH4 (fossile)",29.8,IF(C40="N2O",273,IF(C40="HFC (R-410A)",2088,IF(C40="SF6",25200,0)))))) | H40: =IF(OR(D40=0,F40=""),0,D40*F40) | I40: =IF(H40=0,0,H40/1000)
A41: 8 | D41: 0 | E41: kg | F41: =IF(C41="","",IF(C41="CO2",1,IF(C41="CH4 (fossile)",29.8,IF(C41="N2O",273,IF(C41="HFC (R-410A)",2088,IF(C41="SF6",25200,0)))))) | H41: =IF(OR(D41=0,F41=""),0,D41*F41) | I41: =IF(H41=0,0,H41/1000)
B42: SOUS-TOTAL PROCESS | H42: =SUM(H34:H41) | I42: =SUM(I34:I41)
A44: 1D — ÉMISSIONS FUGITIVES (fuites de fluides frigorigènes, fuites de gaz)
...

Sheet Scope_2
A1: SCOPE 2 — ÉMISSIONS INDIRECTES LIÉES À L'ÉNERGIE | N1: 🏠 Sommaire | O1: 🏠 Sommaire
A2: Double reporting obligatoire : Location-based (LB) ET Market-based (MB). En l'absence de GO/PPA, le MB utilise le mix résiduel (AIB 2023).
A4: 2A — ÉLECTRICITÉ ACHETÉE ET CONSOMMÉE
A5: Ligne | B5: Site / Usage | C5: Pays / Source | D5: Consommation (kWh) | E5: GO/PPA? (O/N) | F5: FE LB (kgCO2e/kWh) | G5: Émissions LB (kgCO2e) | H5: Émissions LB (tCO2e) | I5: FE MB (kgCO2e/kWh) | J5: Émissions MB (kgCO2e) | K5: Émissions MB (tCO2e)
A6: 1 | D6: 0 | F6: =IF(C6="","",IF(C6="France",Facteurs_Emission!G20,IF(C6="Allemagne",Facteurs_Emission!G22,IF(C6="Europe (UE27)",Facteurs_Emission!G23,IF(C6="USA",Facteurs_Emission!G24,IF(C6="Chine",Facteurs_Emission!G25,0)))))) | G6: =IF(OR(D6=0,F6=""),0,D6*F6) | H6: =IF(G6=0,0,G6/1000) | I6: =IF(C6="","",IF(E6="O",Facteurs_Emission!G26,IF(C6="France",Facteurs_Emission!H20,IF(C6="Allemagne",Facteurs_Emission!H22,IF(C6="Europe (UE27)",Facteurs_Emission!H23,IF(C6="USA",Facteurs_Emission!H24,IF(C6="Chine",Facteurs_Emission!H25,0))))))) | J6: =IF(OR(D6=0,I6=""),0,D6*I6) | K6: =IF(J6=0,0,J6/1000)
A7: 2 | D7: 0 | F7: =IF(C7="","",IF(C7="France",Facteurs_Emission!G20,IF(C7="Allemagne",Facteurs_Emission!G22,IF(C7="Europe (UE27)",Facteurs_Emission!G23,IF(C7="USA",Facteurs_Emission!G24,IF(C7="Chine",Facteurs_Emission!G25,0)))))) | G7: =IF(OR(D7=0,F7=""),0,D7*F7) | H7: =IF(G7=0,0,G7/1000) | I7: =IF(C7="","",IF(E7="O",Facteurs_Emission!G26,IF(C7="France",Facteurs_Emission!H20,IF(C7="Allemagne",Facteurs_Emission!H22,IF(C7="Europe (UE27)",Facteurs_Emission!H23,IF(C7="USA",Facteurs_Emission!H24,IF(C7="Chine",Facteurs_Emission!H25,0))))))) | J7: =IF(OR(D7=0,I7=""),0,D7*I7) | K7: =IF(J7=0,0,J7/1000)
A8: 3 | D8: 0 | F8: =IF(C8="","",IF(C8="France",Facteurs_Emission!G20,IF(C8="Allemagne",Facteurs_Emission!G22,IF(C8="Europe (UE27)",Facteurs_Emission!G23,IF(C8="USA",Facteurs_Emission!G24,IF(C8="Chine",Facteurs_Emission!G25,0)))))) | G8: =IF(OR(D8=0,F8=""),0,D8*F8) | H8: =IF(G8=0,0,G8/1000) | I8: =IF(C8="","",IF(E8="O",Facteurs_Emission!G26,IF(C8="France",Facteurs_Emission!H20,IF(C8="Allemagne",Facteurs_Emission!H22,IF(C8="Europe (UE27)",Facteurs_Emission!H23,IF(C8="USA",Facteurs_Emission!H24,IF(C8="Chine",Facteurs_Emission!H25,0))))))) | J8: =IF(OR(D8=0,I8=""),0,D8*I8) | K8: =IF(J8=0,0,J8/1000)
A9: 4 | D9: 0 | F9: =IF(C9="","",IF(C9="France",Facteurs_Emission!G20,IF(C9="Allemagne",Facteurs_Emission!G22,IF(C9="Europe (UE27)",Facteurs_Emission!G23,IF(C9="USA",Facteurs_Emission!G24,IF(C9="Chine",Facteurs_Emission!G25,0)))))) | G9: =IF(OR(D9=0,F9=""),0,D9*F9) | H9: =IF(G9=0,0,G9/1000) | I9: =IF(C9="","",IF(E9="O",Facteurs_Emission!G26,IF(C9="France",Facteurs_Emission!H20,IF(C9="Allemagne",Facteurs_Emission!H22,IF(C9="Europe (UE27)",Facteurs_Emission!H23,IF(C9="USA",Facteurs_Emission!H24,IF(C9="Chine",Facteurs_Emission!H25,0))))))) | J9: =IF(OR(D9=0,I9=""),0,D9*I9) | K9: =IF(J9=0,0,J9/1000)
A10: 5 | D10: 0 | F10: =IF(C10="","",IF(C10="France",Facteurs_Emission!G20,IF(C10="Allemagne",Facteurs_Emission!G22,IF(C10="Europe (UE27)",Facteurs_Emission!G23,IF(C10="USA",Facteurs_Emission!G24,IF(C10="Chine",Facteurs_Emission!G25,0)))))) | G10: =IF(OR(D10=0,F10=""),0,D10*F10) | H10: =IF(G10=0,0,G10/1000) | I10: =IF(C10="","",IF(E10="O",Facteurs_Emission!G26,IF(C10="France",Facteurs_Emission!H20,IF(C10="Allemagne",Facteurs_Emission!H22,IF(C10="Europe (UE27)",Facteurs_Emission!H23,IF(C10="USA",Facteurs_Emission!H24,IF(C10="Chine",Facteurs_Emission!H25,0))))))) | J10: =IF(OR(D10=0,I10=""),0,D10*I10) | K10: =IF(J10=0,0,J10/1000)
A11: 6 | D11: 0 | F11: =IF(C11="","",IF(C11="France",Facteurs_Emission!G20,IF(C11="Allemagne",Facteurs_Emission!G22,IF(C11="Europe (UE27)",Facteurs_Emission!G23,IF(C11="USA",Facteurs_Emission!G24,IF(C11="Chine",Facteurs_Emission!G25,0)))))) | G11: =IF(OR(D11=0,F11=""),0,D11*F11) | H11: =IF(G11=0,0,G11/1000) | I11: =IF(C11="","",IF(E11="O",Facteurs_Emission!G26,IF(C11="France",Facteurs_Emission!H20,IF(C11="Allemagne",Facteurs_Emission!H22,IF(C11="Europe (UE27)",Facteurs_Emission!H23,IF(C11="USA",Facteurs_Emission!H24,IF(C11="Chine",Facteurs_Emission!H25,0))))))) | J11: =IF(OR(D11=0,I11=""),0,D11*I11) | K11: =IF(J11=0,0,J11/1000)
A12: 7 | D12: 0 | F12: =IF(C12="","",IF(C12="France",Facteurs_Emission!G20,IF(C12="Allemagne",Facteurs_Emission!G22,IF(C12="Europe (UE27)",Facteurs_Emission!G23,IF(C12="USA",Facteurs_Emission!G24,IF(C12="Chine",Facteurs_Emission!G25,0)))))) | G12: =IF(OR(D12=0,F12=""),0,D12*F12) | H12: =IF(G12=0,0,G12/1000) | I12: =IF(C12="","",IF(E12="O",Facteurs_Emission!G26,IF(C12="France",Facteurs_Emission!H20,IF(C12="Allemagne",Facteurs_Emission!H22,IF(C12="Europe (UE27)",Facteurs_Emission!H23,IF(C12="USA",Facteurs_Emission!H24,IF(C12="Chine",Facteurs_Emission!H25,0))))))) | J12: =IF(OR(D12=0,I12=""),0,D12*I12) | K12: =IF(J12=0,0,J12/1000)
A13: 8 | D13: 0 | F13: =IF(C13="","",IF(C13="France",Facteurs_Emission!G20,IF(C13="Allemagne",Facteurs_Emission!G22,IF(C13="Europe (UE27)",Facteurs_Emission!G23,IF(C13="USA",Facteurs_Emission!G24,IF(C13="Chine",Facteurs_Emission!G25,0)))))) | G13: =IF(OR(D13=0,F13=""),0,D13*F13) | H13: =IF(G13=0,0,G13/1000) | I13: =IF(C13="","",IF(E13="O",Facteurs_Emission!G26,IF(C13="France",Facteurs_Emission!H20,IF(C13="Allemagne",Facteurs_Emission!H22,IF(C13="Europe (UE27)",Facteurs_Emission!H23,IF(C13="USA",Facteurs_Emission!H24,IF(C13="Chine",Facteurs_Emission!H25,0))))))) | J13: =IF(OR(D13=0,I13=""),0,D13*I13) | K13: =IF(J13=0,0,J13/1000)
A14: 9 | D14: 0 | F14: =IF(C14="","",IF(C14="France",Facteurs_Emission!G20,IF(C14="Allemagne",Facteurs_Emission!G22,IF(C14="Europe (UE27)",Facteurs_Emission!G23,IF(C14="USA",Facteurs_Emission!G24,IF(C14="Chine",Facteurs_Emission!G25,0)))))) | G14: =IF(OR(D14=0,F14=""),0,D14*F14) | H14: =IF(G14=0,0,G14/1000) | I14: =IF(C14="","",IF(E14="O",Facteurs_Emission!G26,IF(C14="France",Facteurs_Emission!H20,IF(C14="Allemagne",Facteurs_Emission!H22,IF(C14="Europe (UE27)",Facteurs_Emission!H23,IF(C14="USA",Facteurs_Emission!H24,IF(C14="Chine",Facteurs_Emission!H25,0))))))) | J14: =IF(OR(D14=0,I14=""),0,D14*I14) | K14: =IF(J14=0,0,J14/1000)
A15: 10 | D15: 0 | F15: =IF(C15="","",IF(C15="France",Facteurs_Emission!G20,IF(C15="Allemagne",Facteurs_Emission!G22,IF(C15="Europe (UE27)",Facteurs_Emission!G23,IF(C15="USA",Facteurs_Emission!G24,IF(C15="Chine",Facteurs_Emission!G25,0)))))) | G15: =IF(OR(D15=0,F15=""),0,D15*F15) | H15: =IF(G15=0,0,G15/1000) | I15: =IF(C15="","",IF(E15="O",Facteurs_Emission!G26,IF(C15="France",Facteurs_Emission!H20,IF(C15="Allemagne",Facteurs_Emission!H22,IF(C15="Europe (UE27)",Facteurs_Emission!H23,IF(C15="USA",Facteurs_Emission!H24,IF(C15="Chine",Facteurs_Emission!H25,0))))))) | J15: =IF(OR(D15=0,I15=""),0,D15*I15) | K15: =IF(J15=0,0,J15/1000)
B16: SOUS-TOTAL ÉLECTRICITÉ | D16: =SUM(D6:D15) | G16: =SUM(G6:G15) | H16: =SUM(H6:H15) | J16: =SUM(J6:J15) | K16: =SUM(K6:K15)
B17: → Émissions amont électricité (→ Scope 3 Cat.3) | D17: =D16 | G17: =D16*Facteurs_Emission!H21 | H17: =G17/1000
B18: → Pertes transport & distribution (→ Scope 3 Cat.3) | D18: =D16*Facteurs_Emission!G29 | G18: =IF(D18=0,0,D18*Facteurs_Emission!G20) | H18: =G18/1000
A20: 2B — CHALEUR, VAPEUR, FROID ACHETÉS
A21: Ligne | B21: Site / Source | C21: Type | D21: Consommation (kWh) | E21: ID FE | F21: FE (kgCO2e/kWh) | G21: Émissions (kgCO2e) | H21: Émissions (tCO2e)
A22: 1 | D22: 0 | E22: =IF(C22="","",IF(C22="Réseau de chaleur urbain","FE027",IF(C22="Réseau de froid urbain","FE028","FE027"))) | F22: =IF(E22="","",VLOOKUP(E22,Facteurs_Emission!$A$4:$G$108,7,FALSE())) | G22: =IF(OR(D22=0,F22=""),0,D22*F22) | H22: =IF(G22=0,0,G22/1000)
A23: 2 | D23: 0 | E23: =IF(C23="","",IF(C23="Réseau de chaleur urbain","FE027",IF(C23="Réseau de froid urbain","FE028","FE027"))) | F23: =IF(E23="","",VLOOKUP(E23,Facteurs_Emission!$A$4:$G$108,7,FALSE())) | G23: =IF(OR(D23=0,F23=""),0,D23*F23) | H23: =IF(G23=0,0,G23/1000)
A24: 3 | D24: 0 | E24: =IF(C24="","",IF(C24="Réseau de chaleur urbain","FE027",IF(C24="Réseau de froid urbain","FE028","FE027"))) | F24: =IF(E24="","",VLOOKUP(E24,Facteurs_Emission!$A$4:$G$108,7,FALSE())) | G24: =IF(OR(D24=0,F24=""),0,D24*F24) | H24: =IF(G24=0,0,G24/1000)
A25: 4 | D25: 0 | E25: =IF(C25="","",IF(C25="Réseau de chaleur urbain","FE027",IF(C25="Réseau de froid urbain","FE028","FE027"))) | F25: =IF(E25="","",VLOOKUP(E25,Facteurs_Emission!$A$4:$G$108,7,FALSE())) | G25: =IF(OR(D25=0,F25=""),0,D25*F25) | H25: =IF(G25=0,0,G25/1000)
A26: 5 | D26: 0 | E26: =IF(C26="","",IF(C26="Réseau de chaleur urbain","FE027",IF(C26="Réseau de froid urbain","FE028","FE027"))) | F26: =IF(E26="","",VLOOKUP(E26,Facteurs_Emission!$A$4:$G$108,7,FALSE())) | G26: =IF(OR(D26=0,F26=""),0,D26*F26) | H26: =IF(G26=0,0,G26/1000)
A27: 6 | D27: 0 | E27: =IF(C27="","",IF(C27="Réseau de chaleur urbain","FE027",IF(C27="Réseau de froid urbain","FE028","FE027"))) | F27: =IF(E27="","",VLOOKUP(E27,Facteurs_Emission!$A$4:$G$108,7,FALSE())) | G27: =IF(OR(D27=0,F27=""),0,D27*F27) | H27: =IF(G27=0,0,G27/1000)
A28: 7 | D28: 0 | E28: =IF(C28="","",IF(C28="Réseau de chaleur urbain","FE027",IF(C28="Réseau de froid urbain","FE028","FE027"))) | F28: =IF(E28="","",VLOOKUP(E28,Facteurs_Emission!$A$4:$G$108,7,FALSE())) | G28: =IF(OR(D28=0,F28=""),0,D28*F28) | H28: =IF(G28=0,0,G28/1000)
B29: SOUS-TOTAL CHALEUR/VAPEUR/FROID | G29: =SUM(G22:G28) | H29: =SUM(H22:H28)
A31: TOTAL SCOPE 2 — LOCATION-BASED | G31: =G16+G29 | H31: =H16+H29
A32: TOTAL SCOPE 2 — MARKET-BASED | J32: =J16 | K32: =K16
B34: Émissions amont associées → Scope 3 Cat.3 | G34: =G17+G18 | H34: =H17+H18

Sheet Scope_3
A1: SCOPE 3 — ÉMISSIONS INDIRECTES DE LA CHAÎNE DE VALEUR | N1: 🏠 Sommaire | O1: 🏠 Sommaire
A2: 15 catégories selon le GHG Protocol Corporate Value Chain (Scope 3) Standard (2011).
A4: Catégorie 1 — Achats de biens et services (amont)
A5: Méthode recommandée : données physiques (quantité × FE matériau) OU fallback monétaire (k€ × FE/k€)
A6: Ligne | B6: Description | C6: Matériau/Service | D6: Quantité | E6: Unité | F6: ID FE | G6: FE (kgCO2e/u) | H6: Émissions (kgCO2e) | I6: Émissions (tCO2e) | J6: Qualité | K6: Méthode | L6: Incertitude (%)
A7: 1 | D7: 0 | H7: =IF(OR(D7=0,G7=""),0,D7*G7) | I7: =H7/1000
A8: 2 | D8: 0 | H8: =IF(OR(D8=0,G8=""),0,D8*G8) | I8: =H8/1000
A9: 3 | D9: 0 | H9: =IF(OR(D9=0,G9=""),0,D9*G9) | I9: =H9/1000
A10: 4 | D10: 0 | H10: =IF(OR(D10=0,G10=""),0,D10*G10) | I10: =H10/1000
A11: 5 | D11: 0 | H11: =IF(OR(D11=0,G11=""),0,D11*G11) | I11: =H11/1000
A12: 6 | D12: 0 | H12: =IF(OR(D12=0,G12=""),0,D12*G12) | I12: =H12/1000
A13: 7 | D13: 0 | H13: =IF(OR(D13=0,G13=""),0,D13*G13) | I13: =H13/1000
A14: 8 | D14: 0 | H14: =IF(OR(D14=0,G14=""),0,D14*G14) | I14: =H14/1000
A15: 9 | D15: 0 | H15: =IF(OR(D15=0,G15=""),0,D15*G15) | I15: =H15/1000
A16: 10 | D16: 0 | H16: =IF(OR(D16=0,G16=""),0,D16*G16) | I16: =H16/1000
A17: 11 | D17: 0 | H17: =IF(OR(D17=0,G17=""),0,D17*G17) | I17: =H17/1000
A18: 12 | D18: 0 | H18: =IF(OR(D18=0,G18=""),0,D18*G18) | I18: =H18/1000
B19: SOUS-TOTAL Cat. 1 | H19: =SUM(H7:H18) | I19: =SUM(I7:I18)
A21: Catégorie 2 — Biens d'équipement (amont)
A22: Immobilisations : ordinateurs, mobilier, véhicules, machines, bâtiments. Amortir sur durée de vie.
A23: Ligne | B23: Description | C23: Matériau/Service | D23: Quantité | E23: Unité | F23: ID FE | G23: FE (kgCO2e/u) | H23: Émissions (kgCO2e) | I23: Émissions (tCO2e) | J23: Qualité | K23: Méthode | L23: Incertitude (%)
A24: 1 | D24: 0 | H24: =IF(OR(D24=0,G24=""),0,D24*G24) | I24: =H24/1000
A25: 2 | D25: 0 | H25: =IF(OR(D25=0,G25=""),0,D25*G25) | I25: =H25/1000
A26: 3 | D26: 0 | H26: =IF(OR(D26=0,G26=""),0,D26*G26) | I26: =H26/1000
A27: 4 | D27: 0 | H27: =IF(OR(D27=0,G27=""),0,D27*G27) | I27: =H27/1000
A28: 5 | D28: 0 | H28: =IF(OR(D28=0,G28=""),0,D28*G28) | I28: =H28/1000
A29: 6 | D29: 0 | H29: =IF(OR(D29=0,G29=""),0,D29*G29) | I29: =H29/1000
B30: SOUS-TOTAL Cat. 2 | H30: =SUM(H24:H29) | I30: =SUM(I24:I29)
A32: Catégorie 3 — Activités liées aux combustibles et à l'énergie (amont)
A33: CALCULÉE AUTOMATIQUEMENT à partir des données Scope 1 et Scope 2.
A34: Ligne | B34: Description | C34: Matériau/Service | D34: Quantité | E34: Unité | F34: ID FE | G34: FE (kgCO2e/u) | H34: Émissions (kgCO2e) | I34: Émissions (tCO2e) | J34: Qualité | K34: Méthode | L34: Incertitude (%)
B35: Émissions amont des combustibles (Scope 1) | H35: =Scope_1!K57 | I35: =H35/1000 | J35: 2 | K35: Données primaires
B36: Émissions amont production et T&D électricité | H36: =Scope_2!G17 | I36: =H36/1000 | J36: 2 | K36: Données primaires
B37: Pertes transport & distribution | H37: =Scope_2!G18 | I37: =H37/1000 | J37: 2 | K37: Données primaires
B38: SOUS-TOTAL Cat. 3 | H38: =SUM(H35:H37) | I38: =SUM(I35:I37)
A40: Catégorie 4 — Transport et distribution amont
A41: Transport marchandises achetées. Formule : tonnes × km × FE (kgCO2e/t.km)
A42: Ligne | B42: Description | C42: Matériau/Service | D42: Quantité | E42: Unité | F42: ID FE | G42: FE (kgCO2e/u) | H42: Émissions (kgCO2e) | I42: Émissions (tCO2e) | J42: Qualité | K42: Méthode | L42: Incertitude (%)
A43: 1 | D43: 0 | H43: =IF(OR(D43=0,G43=""),0,D43*G43) | I43: =H43/1000
A44: 2 | D44: 0 | H44: =IF(OR(D44=0,G44=""),0,D44*G44) | I44: =H44/1000
...

Sheet Energie
A1: SUIVI ÉNERGÉTIQUE — VENTILATION ESRS E1-5 §37-38 | N1: 🏠 Sommaire | O1: 🏠 Sommaire
A3: A — CONSOMMATION D'ÉNERGIE NON-RENOUVELABLE
A4: Poste | B4: Quantité | C4: Unité d'origine | D4: Conversion MWh | E4: MWh
A5: (i) Charbon et dérivés | B5: 0 | C5: tonnes | D5: =B5*7.22 | E5: =D5
A6: (ii) Pétrole brut et dérivés | B6: 0 | C6: litres | D6: =B6*0.01008 | E6: =D6
A7: (iii) Gaz naturel | B7: 0 | C7: kWh | D7: =B7/1000 | E7: =D7
A8: (iv) Autres non-renouvelables | B8: 0 | C8: MWh | D8: =B8 | E8: =D8
A9: (v) Électricité achetée non-ENR | B9: 0 | C9: kWh | D9: =B9/1000 | E9: =D9
A10: TOTAL A — Non-renouvelable | E10: =SUM(E5:E9) -> 0
A12: B — CONSOMMATION D'ÉNERGIE RENOUVELABLE
A13: (i) Combustibles renouvelables (biomasse) | B13: 0 | C13: kWh | D13: =B13/1000 | E13: =D13
A14: (ii) Électricité achetée ENR (GO/PPA) | B14: 0 | C14: kWh | D14: =B14/1000 | E14: =D14
A15: (iii) Autoprod. renouvelable (PV, éolien) | B15: 0 | C15: MWh | D15: =B15 | E15: =D15
A16: TOTAL B — Renouvelable | E16: =SUM(E13:E15) -> 0
A18: C — TOTAUX ET INDICATEURS
A19: Total consommation énergie (MWh) | E19: =E10+E16 -> 0
A20: Part énergie renouvelable (%) | E20: =IF(E19=0,0,ROUND(E16/E19*100,1)) -> 0
A21: Intensité énergétique (MWh/M€ CA) | E21: =IF(Paramètres!B9=0,0,E19/(Paramètres!B9/1000000))
A23: D — SUIVI MENSUEL DÉTAILLÉ
A24: Mois | B24: Électricité (kWh) | C24: Gaz naturel (kWh) | D24: Fioul (litres) | E24: Chaleur réseau (kWh) | F24: ENR autoprod. (kWh) | G24: Total énergie (kWh) | H24: Coût total (€)
A25: Janvier | B25: 0 | C25: 0 | D25: 0 | E25: 0 | F25: 0 | G25: =B25+C25+(D25*10.08)+E25+F25 | H25: 0
A26: Février | B26: 0 | C26: 0 | D26: 0 | E26: 0 | F26: 0 | G26: =B26+C26+(D26*10.08)+E26+F26 | H26: 0
A27: Mars | B27: 0 | C27: 0 | D27: 0 | E27: 0 | F27: 0 | G27: =B27+C27+(D27*10.08)+E27+F27 | H27: 0
A28: Avril | B28: 0 | C28: 0 | D28: 0 | E28: 0 | F28: 0 | G28: =B28+C28+(D28*10.08)+E28+F28 | H28: 0
A29: Mai | B29: 0 | C29: 0 | D29: 0 | E29: 0 | F29: 0 | G29: =B29+C29+(D29*10.08)+E29+F29 | H29: 0
A30: Juin | B30: 0 | C30: 0 | D30: 0 | E30: 0 | F30: 0 | G30: =B30+C30+(D30*10.08)+E30+F30 | H30: 0
A31: Juillet | B31: 0 | C31: 0 | D31: 0 | E31: 0 | F31: 0 | G31: =B31+C31+(D31*10.08)+E31+F31 | H31: 0
A32: Août | B32: 0 | C32: 0 | D32: 0 | E32: 0 | F32: 0 | G32: =B32+C32+(D32*10.08)+E32+F32 | H32: 0
A33: Septembre | B33: 0 | C33: 0 | D33: 0 | E33: 0 | F33: 0 | G33: =B33+C33+(D33*10.08)+E33+F33 | H33: 0
A34: Octobre | B34: 0 | C34: 0 | D34: 0 | E34: 0 | F34: 0 | G34: =B34+C34+(D34*10.08)+E34+F34 | H34: 0
A35: Novembre | B35: 0 | C35: 0 | D35: 0 | E35: 0 | F35: 0 | G35: =B35+C35+(D35*10.08)+E35+F35 | H35: 0
A36: Décembre | B36: 0 | C36: 0 | D36: 0 | E36: 0 | F36: 0 | G36: =B36+C36+(D36*10.08)+E36+F36 | H36: 0
A37: TOTAL ANNUEL | B37: =SUM(B25:B36) | C37: =SUM(C25:C36) | D37: =SUM(D25:D36) | E37: =SUM(E25:E36) | F37: =SUM(F25:F36) | G37: =SUM(G25:G36) | H37: =SUM(H25:H36)

Sheet Transport
A1: TRANSPORT — DÉPLACEMENTS PROFESSIONNELS ET DOMICILE-TRAVAIL | N1: 🏠 Sommaire | O1: 🏠 Sommaire
A3: A — DÉPLACEMENTS PROFESSIONNELS (Scope 3 Cat. 6)
A4: Ligne | B4: Description du trajet | C4: Mode de transport | D4: Distance (km) | E4: Nb voyages | F4: Total km.passager | G4: ID FE | H4: FE (kgCO2e/km) | I4: Émissions (kgCO2e) | J4: tCO2e
A5: 1 | D5: 0 | E5: 0 | F5: =D5*E5 | G5: =IF(C5="","",IF(C5="Voiture thermique","FE030",IF(C5="Voiture diesel","FE031",IF(C5="Voiture essence","FE032",IF(C5="Voiture électrique","FE033",IF(C5="TGV","FE035",IF(C5="TER","FE036",IF(C5="Métro/Tramway","FE037",IF(C5="Bus urbain","FE038",IF(C5="Avion CC éco (avec RF)","FE039_RF",IF(C5="Avion MC éco (avec RF)","FE040_RF",IF(C5="Avion LC éco (avec RF)","FE041_RF",IF(C5="Avion LC business (avec RF)","FE042",""))))))))))))) | H5: =IF(G5="","",VLOOKUP(G5,Facteurs_Emission!$A$4:$E$108,5,FALSE())) | I5: =IF(OR(F5=0,H5=""),0,F5*H5) | J5: =I5/1000
A6: 2 | D6: 0 | E6: 0 | F6: =D6*E6 | G6: =IF(C6="","",IF(C6="Voiture thermique","FE030",IF(C6="Voiture diesel","FE031",IF(C6="Voiture essence","FE032",IF(C6="Voiture électrique","FE033",IF(C6="TGV","FE035",IF(C6="TER","FE036",IF(C6="Métro/Tramway","FE037",IF(C6="Bus urbain","FE038",IF(C6="Avion CC éco (avec RF)","FE039_RF",IF(C6="Avion MC éco (avec RF)","FE040_RF",IF(C6="Avion LC éco (avec RF)","FE041_RF",IF(C6="Avion LC business (avec RF)","FE042",""))))))))))))) | H6: =IF(G6="","",VLOOKUP(G6,Facteurs_Emission!$A$4:$E$108,5,FALSE())) | I6: =IF(OR(F6=0,H6=""),0,F6*H6) | J6: =I6/1000
A7: 3 | D7: 0 | E7: 0 | F7: =D7*E7 | G7: =IF(C7="","",IF(C7="Voiture thermique","FE030",IF(C7="Voiture diesel","FE031",IF(C7="Voiture essence","FE032",IF(C7="Voiture électrique","FE033",IF(C7="TGV","FE035",IF(C7="TER","FE036",IF(C7="Métro/Tramway","FE037",IF(C7="Bus urbain","FE038",IF(C7="Avion CC éco (avec RF)","FE039_RF",IF(C7="Avion MC éco (avec RF)","FE040_RF",IF(C7="Avion LC éco (avec RF)","FE041_RF",IF(C7="Avion LC business (avec RF)","FE042",""))))))))))))) | H7: =IF(G7="","",VLOOKUP(G7,Facteurs_Emission!$A$4:$E$108,5,FALSE())) | I7: =IF(OR(F7=0,H7=""),0,F7*H7) | J7: =I7/1000
A8: 4 | D8: 0 | E8: 0 | F8: =D8*E8 | G8: =IF(C8="","",IF(C8="Voiture thermique","FE030",IF(C8="Voiture diesel","FE031",IF(C8="Voiture essence","FE032",IF(C8="Voiture électrique","FE033",IF(C8="TGV","FE035",IF(C8="TER","FE036",IF(C8="Métro/Tramway","FE037",IF(C8="Bus urbain","FE038",IF(C8="Avion CC éco (avec RF)","FE039_RF",IF(C8="Avion MC éco (avec RF)","FE040_RF",IF(C8="Avion LC éco (avec RF)","FE041_RF",IF(C8="Avion LC business (avec RF)","FE042",""))))))))))))) | H8: =IF(G8="","",VLOOKUP(G8,Facteurs_Emission!$A$4:$E$108,5,FALSE())) | I8: =IF(OR(F8=0,H8=""),0,F8*H8) | J8: =I8/1000
