Workbook
Name CC_VSME_BP1_Raison_Sociale: 'VSME_Reporting'!$E$7
Name CC_VSME_BP2_Secteur_NAF: 'VSME_Reporting'!$E$8
Name CC_VSME_BP3_ETP: 'VSME_Reporting'!$E$9
Name CC_VSME_BP4_CA_Net: 'VSME_Reporting'!$E$10
Name CC_VSME_BP5_Annee: 'VSME_Reporting'!$E$11
Name CC_VSME_BP6_Pays: 'VSME_Reporting'!$E$12
Name CC_VSME_BP7_Perimetre: 'VSME_Reporting'!$E$13
Name CC_VSME_E1_Scope1: 'VSME_Reporting'!$E$17
Name CC_VSME_E2_Scope2_LB: 'VSME_Reporting'!$E$18
Name CC_VSME_E3_Scope2_MB: 'VSME_Reporting'!$E$19
Name CC_VSME_E4_Scope3: 'VSME_Reporting'!$E$20
Name CC_VSME_E5_Total_GES: 'VSME_Reporting'!$E$21
Name CC_VSME_E6_Intensite_CA: 'VSME_Reporting'!$E$22
Name CC_VSME_E7_Energie_MWh: 'VSME_Reporting'!$E$23
Name CC_VSME_E8_Part_ENR: 'VSME_Reporting'!$E$24
Name CC_VSME_E9_Eau_m3: 'VSME_Reporting'!$E$25
Name CC_VSME_E10_Dechets_t: 'VSME_Reporting'!$E$26
Name CC_VSME_E11_Valorisation_Pct: 'VSME_Reporting'!$E$27
Name CC_VSME_E12_Plan_GES: 'VSME_Reporting'!$E$28
Name CC_VSME_S1_Effectif: 'VSME_Reporting'!$E$32
Name CC_VSME_S2_Pct_CDI: 'VSME_Reporting'!$E$33
Name CC_VSME_S3_Rotation_Pct: 'VSME_Reporting'!$E$34
Name CC_VSME_S4_LTIR: 'VSME_Reporting'!$E$35
Name CC_VSME_S5_Formation_h_ETP: 'VSME_Reporting'!$E$36
Name CC_VSME_S6_Ecart_Salaire_HF: 'VSME_Reporting'!$E$37
Name CC_VSME_S7_Pct_Femmes_Mgmt: 'VSME_Reporting'!$E$38
Name CC_VSME_S8_Diversite: 'VSME_Reporting'!$E$39
Name CC_VSME_S9_Dialogue_Social: 'VSME_Reporting'!$E$40
Name CC_VSME_S10_Litiges: 'VSME_Reporting'!$E$41
Name CC_VSME_G1_Anti_Corruption: 'VSME_Reporting'!$E$45
Name CC_VSME_G2_Formation_Ethique: 'VSME_Reporting'!$E$46
Name CC_VSME_G3_Whistleblowing: 'VSME_Reporting'!$E$47
Name CC_VSME_G4_Pct_CA_Independants: 'VSME_Reporting'!$E$48
Name CC_VSME_G5_Protection_Donnees: 'VSME_Reporting'!$E$49
Name CC_MAT_E1_Score_Impact: 'Materialite'!$F$10
Name CC_MAT_E2_Score_Impact: 'Materialite'!$F$11
Name CC_MAT_E3_Score_Impact: 'Materialite'!$F$12
Name CC_MAT_E4_Score_Impact: 'Materialite'!$F$13
Name CC_MAT_E5_Score_Impact: 'Materialite'!$F$14
Name CC_MAT_S1_Score_Impact: 'Materialite'!$F$15
Name CC_MAT_S2_Score_Impact: 'Materialite'!$F$16
Name CC_MAT_S3_Score_Impact: 'Materialite'!$F$17
Name CC_MAT_S4_Score_Impact: 'Materialite'!$F$18
Name CC_MAT_G1_Score_Impact: 'Materialite'!$F$19
Name CC_ESG_Score_Global: 'Synthese_ESG'!$D$10
Name CC_ESG_Score_E: 'Synthese_ESG'!$D$6
Name CC_ESG_Score_S: 'Synthese_ESG'!$D$7
Name CC_ESG_Score_G: 'Synthese_ESG'!$D$8
Name CC_ESG_Enjeux_Materiels: 'Synthese_ESG'!$D$16

Sheet Couverture
B1: 🌍 CarbonCo
B4: Fichier ESG Social & Gouvernance
B6: REPORTING ESG — VOLETS SOCIAL, GOUVERNANCE & VSME
B7: Conforme ESRS S1-S4 / G1 (CSRD) | Norme VSME (EFRAG 2025) | Double Matérialité
B9: INFORMATIONS DE L'ENTREPRISE
B10: Raison sociale | C10: À compléter
B11: SIREN / SIRET | C11: À compléter
B12: Secteur d'activité | C12: À compléter
B13: Exercice de reporting | C13: 01/01/2025 — 31/12/2025
B14: Année de reporting | C14: 2025
B15: Effectifs (ETP) | C15: À compléter
B16: Chiffre d'affaires (M€) | C16: À compléter
B17: Responsable ESG | C17: À compléter
B18: Version du fichier | C18: v1.0
B19: Date de génération | C19: 46124
B22: ✅ Conforme ESRS S1-S4 / G1 — Delegated Regulation (EU) 2023/2772
B23: ✅ Norme VSME volontaire — EFRAG / Commission européenne (juil. 2025)
B24: ✅ Double Matérialité — ESRS 1 §3 / EFRAG IG 1
B26: 📋 ACCÉDER AU SOMMAIRE →
B27: 🔒 Document confidentiel — Usage interne uniquement
B29: CarbonCo — ESG Social v1.0 — Exercice 2025 — Mise à jour 12/4/2026

Sheet Sommaire
A1: SOMMAIRE — FICHIER ESG SOCIAL & GOUVERNANCE CarbonCo
A2: Cliquez sur le nom d'un onglet pour y accéder directement
C4: Onglet | D4: Description | E4: Catégorie | F4: Statut
B5: NAVIGATION & CONFIGURATION
B6: 🏠 | C6: Couverture | D6: Page de garde — Informations entreprise & conformité | E6: Navigation | F6: —
B7: 📋 | C7: Liaison_Donnees | D7: Import des données clés depuis le fichier Calcul Carbone v2 | E7: Configuration | F7: ⬜ À remplir
B8: REPORTING VSME & MATÉRIALITÉ
B9: 📗 | C9: VSME_Reporting | D9: Reporting volontaire VSME conforme EFRAG — PME/ETI | E9: VSME | F9: ⬜ À remplir
B10: 🎯 | C10: Materialite | D10: Analyse de double matérialité — ESRS 1 §3 | E10: Conformité | F10: ⬜ À remplir
B11: ESRS SOCIAL & GOUVERNANCE
B12: 👥 | C12: ESRS_S1 | D12: Effectifs propres — conditions de travail, égalité, santé | E12: Social | F12: ⬜ À remplir
B13: 🔗 | C13: ESRS_S2 | D13: Travailleurs chaîne de valeur — fournisseurs | E13: Social | F13: ⬜ À remplir
B14: 🏘️ | C14: ESRS_S3 | D14: Communautés affectées — impacts locaux | E14: Social | F14: ⬜ À remplir
B15: 🛒 | C15: ESRS_S4 | D15: Consommateurs et utilisateurs finaux | E15: Social | F15: ⬜ À remplir
B16: ⚖️ | C16: ESRS_G1 | D16: Conduite des affaires — éthique, gouvernance | E16: Gouvernance | F16: ⬜ À remplir
B17: ESRS SIMPLIFIÉ (POST-OMNIBUS)
B18: 📐 | C18: ESRS_Simplifie | D18: Mode ~300 data points — Acte délégué 2026 | E18: Conformité | F18: ⬜ À remplir
B19: RÉSULTATS & SYNTHÈSE
B20: 📊 | C20: Synthese_ESG | D20: Score ESG consolidé E/S/G + radar + KPIs | E20: Résultats | F20: Auto
B21: 🔍 | C21: Controles_QC_ESG | D21: Contrôles qualité automatiques — 15 vérifications | E21: Audit | F21: Auto
B23: Dernière mise à jour : 12/4/2026 | Exercice 2025

Sheet Liaison_Donnees
J1: 🏠 Sommaire | K1: 📄 Couverture
A2: LIAISON DONNÉES — Import depuis CarbonCo_Calcul_Carbone_v2.xlsx
A3: Saisir ici les valeurs clés de votre fichier Calcul Carbone. Ces cellules alimentent automatiquement tous les onglets de ce fichier.
B5: Donnée | C5: Valeur | D5: Unité | E5: Source (onglet Calcul Carbone v2)
B6: DONNÉES ENTREPRISE
B7: Raison sociale | D7: Texte | E7: Paramètres!B4
B8: Année de reporting | C8: 2025 | D8: Année | E8: Paramètres!B7
B9: Chiffre d'affaires net (€) | C9: 0 | D9: € | E9: Paramètres!B9
B10: Effectifs (ETP) | C10: 0 | D10: ETP | E10: Paramètres!B11
B11: Secteur d'activité / Code NAF | D11: Texte / Code | E11: Paramètres!B6 / C6
B12: Surface occupée (m²) | C12: 0 | D12: m² | E12: Paramètres!B12
B13: CapEx total (€) | C13: 0 | D13: € | E13: Paramètres!B14
B14: DONNÉES CARBONE (depuis Synthese_GES)
B15: Scope 1 total (tCO2e) | C15: 0 | D15: tCO2e | E15: Synthese_GES!C10
B16: Scope 2 Location-based (tCO2e) | C16: 0 | D16: tCO2e | E16: Synthese_GES!C15
B17: Scope 2 Market-based (tCO2e) | C17: 0 | D17: tCO2e | E17: Synthese_GES!C17
B18: Scope 3 total (tCO2e) | C18: 0 | D18: tCO2e | E18: Synthese_GES!C35
B19: Total S1+S2(LB)+S3 (tCO2e) | C19: =C15+C16+C18 | D19: tCO2e | E19: calcul auto
B20: Intensité / CA (tCO2e/M€) | C20: =IF(C9>0,C19/(C9/1000000),0) | D20: tCO2e/M€ | E20: calcul auto
B21: DONNÉES ÉNERGIE
B22: Part énergie renouvelable (%) | C22: 0 | D22: % | E22: Energie!E20
B23: Conso totale énergie (MWh) | C23: 0 | D23: MWh | E23: Energie!E19
B24: DONNÉES TAXONOMIE / CBAM
B25: % CA aligné Taxonomie | C25: 0 | D25: % | E25: Taxonomie!E27
B26: Coût CBAM estimé (€) | C26: 0 | D26: € | E26: CBAM!M24
B27: TRAJECTOIRE SBTi
B28: Objectif réduction S1+2 (%/an) | C28: 4.2 | D28: % | E28: Trajectoire_SBTi!B8
B29: Objectif réduction S3 (%/an) | C29: 2.5 | D29: % | E29: Trajectoire_SBTi!B9
B31: ⚠️ Saisir les valeurs depuis votre fichier Calcul Carbone v2. Les cellules jaunes (bleu) sont des saisies utilisateur. Les cellules grises sont calculées automatiquement.

Sheet VSME_Reporting
J1: 🏠 Sommaire | K1: 📄 Couverture
A2: REPORTING VSME VOLONTAIRE — Conforme EFRAG / Commission européenne (juil. 2025)
A3: Norme volontaire pour les entreprises <1 000 salariés exclues de la CSRD (Omnibus déc. 2025). Ce rapport structure votre réponse aux demandes ESG de vos donneurs d'ordre.
A5: A — PROFIL ENTREPRISE
B6: # | C6: Indicateur VSME | D6: Valeur | E6: Unité | F6: Statut | G6: Source
C7: BP-1 | D7: Raison sociale | E7: =Liaison_Donnees!C7 | F7: Texte | G7: =IF(E7<>"","✓ OK","⬜ À remplir") | H7: Liaison
C8: BP-2 | D8: Secteur d'activité / NAF | E8: =Liaison_Donnees!C11 | F8: Code NAF | G8: =IF(E8<>"","✓ OK","⬜ À remplir") | H8: Liaison
C9: BP-3 | D9: Effectifs (ETP) | E9: =Liaison_Donnees!C10 | F9: ETP | G9: =IF(E9<>"","✓ OK","⬜ À remplir") | H9: Liaison
C10: BP-4 | D10: Chiffre d'affaires net (€) | E10: =Liaison_Donnees!C9 | F10: € | G10: =IF(E10<>"","✓ OK","⬜ À remplir") | H10: Liaison
C11: BP-5 | D11: Exercice de reporting | E11: =Liaison_Donnees!C8 | F11: Année | G11: =IF(E11<>"","✓ OK","⬜ À remplir") | H11: Liaison
C12: BP-6 | D12: Pays principal d'activité | F12: Texte | G12: =IF(E12<>"","✓ OK","⬜ À remplir") | H12: Saisie
C13: BP-7 | D13: Périmètre (sites inclus) | F13: Texte | G13: =IF(E13<>"","✓ OK","⬜ À remplir") | H13: Saisie
A15: B — ENVIRONNEMENT (E)
B16: # | C16: Indicateur VSME | D16: Valeur | E16: Unité | F16: Statut | G16: Source
C17: E-1 | D17: Émissions GES Scope 1 (tCO2e) | E17: =Liaison_Donnees!C15 | F17: tCO2e | G17: =IF(E17<>"","✓ OK","⬜ À remplir")
C18: E-2 | D18: Émissions GES Scope 2 LB (tCO2e) | E18: =Liaison_Donnees!C16 | F18: tCO2e | G18: =IF(E18<>"","✓ OK","⬜ À remplir")
C19: E-3 | D19: Émissions GES Scope 2 MB (tCO2e) | E19: =Liaison_Donnees!C17 | F19: tCO2e | G19: =IF(E19<>"","✓ OK","⬜ À remplir")
C20: E-4 | D20: Émissions GES Scope 3 (tCO2e) | E20: =Liaison_Donnees!C18 | F20: tCO2e | G20: =IF(E20<>"","✓ OK","⬜ À remplir")
C21: E-5 | D21: Total GES (tCO2e) | E21: =Liaison_Donnees!C19 | F21: tCO2e | G21: =IF(E21<>"","✓ OK","⬜ À remplir")
C22: E-6 | D22: Intensité GES / CA (tCO2e/M€) | E22: =Liaison_Donnees!C20 | F22: tCO2e/M€ | G22: =IF(E22<>"","✓ OK","⬜ À remplir")
C23: E-7 | D23: Consommation totale énergie (MWh) | E23: =Liaison_Donnees!C23 | F23: MWh | G23: =IF(E23<>"","✓ OK","⬜ À remplir")
C24: E-8 | D24: Part énergie renouvelable (%) | E24: =Liaison_Donnees!C22 | F24: % | G24: =IF(E24<>"","✓ OK","⬜ À remplir")
C25: E-9 | D25: Consommation eau totale (m³) | F25: m³ | G25: =IF(E25<>"","✓ OK","⬜ À remplir")
C26: E-10 | D26: Production de déchets (tonnes) | F26: t | G26: =IF(E26<>"","✓ OK","⬜ À remplir")
C27: E-11 | D27: Taux valorisation déchets (%) | F27: % | G27: =IF(E27<>"","✓ OK","⬜ À remplir")
C28: E-12 | D28: Plan de réduction GES adopté (O/N) | F28: O/N | G28: =IF(E28<>"","✓ OK","⬜ À remplir")
A30: C — SOCIAL (S)
B31: # | C31: Indicateur VSME | D31: Valeur | E31: Unité | F31: Statut | G31: Source
C32: S-1 | D32: Effectif total au 31/12 | G32: =IF(E32<>"","✓ OK","⬜ À remplir")
C33: S-2 | D33: % CDI / Total | G33: =IF(E33<>"","✓ OK","⬜ À remplir")
C34: S-3 | D34: Taux de rotation du personnel (%) | G34: =IF(E34<>"","✓ OK","⬜ À remplir")
C35: S-4 | D35: Taux d'accidents du travail (LTIR) | G35: =IF(E35<>"","✓ OK","⬜ À remplir")
C36: S-5 | D36: Heures de formation / ETP | G36: =IF(E36<>"","✓ OK","⬜ À remplir")
C37: S-6 | D37: Écart de rémunération H/F (%) | G37: =IF(E37<>"","✓ OK","⬜ À remplir")
C38: S-7 | D38: % femmes dans l'encadrement | G38: =IF(E38<>"","✓ OK","⬜ À remplir")
C39: S-8 | D39: Politique diversité & inclusion (O/N) | G39: =IF(E39<>"","✓ OK","⬜ À remplir")
C40: S-9 | D40: Mécanisme de dialogue social (O/N) | G40: =IF(E40<>"","✓ OK","⬜ À remplir")
C41: S-10 | D41: Nb de litiges sociaux en cours | G41: =IF(E41<>"","✓ OK","⬜ À remplir")
A43: D — GOUVERNANCE (G)
B44: # | C44: Indicateur VSME | D44: Valeur | E44: Unité | F44: Statut | G44: Source
...

Sheet Materialite
J1: 🏠 Sommaire | K1: 📄 Couverture
A2: ANALYSE DE DOUBLE MATÉRIALITÉ — ESRS 1 §3 / EFRAG IG 1
A3: Évaluez chaque enjeu ESG sur deux dimensions : Impact (effets sur l'environnement/société) et Financier (risques/opportunités pour l'entreprise). Score 1 à 5. Matériel si ≥3 sur au moins un axe.
B5: ÉCHELLE DE NOTATION
B6: 1 = Négligeable
B7: 2 = Faible
B8: 3 = Modéré
B9: 4 = Significatif
B10: 5 = Majeur
B12: # | C12: Enjeu ESG | D12: Catégorie | E12: Norme ESRS | F12: Sévérité (1-5) | G12: Probabilité (1-5) | H12: Score Impact | I12: Risque fin. (1-5) | J12: Opport. fin. (1-5) | K12: Score Financier | L12: Score Fin. | M12: Matériel ?
C13: E1 | D13: Changement climatique | E13: Environnement | F13: ESRS E1 | I13: =IF(AND(G13<>"",H13<>""),G13*0.6+H13*0.4,"") | L13: =IF(AND(J13<>"",K13<>""),J13*0.5+K13*0.5,"") | M13: =IF(OR(I13<>"",L13<>""),IF(OR(I13>=3,L13>=3),"OUI","NON"),"")
C14: E2 | D14: Pollution | E14: Environnement | F14: ESRS E2 | I14: =IF(AND(G14<>"",H14<>""),G14*0.6+H14*0.4,"") | L14: =IF(AND(J14<>"",K14<>""),J14*0.5+K14*0.5,"") | M14: =IF(OR(I14<>"",L14<>""),IF(OR(I14>=3,L14>=3),"OUI","NON"),"")
C15: E3 | D15: Eau et ressources marines | E15: Environnement | F15: ESRS E3 | I15: =IF(AND(G15<>"",H15<>""),G15*0.6+H15*0.4,"") | L15: =IF(AND(J15<>"",K15<>""),J15*0.5+K15*0.5,"") | M15: =IF(OR(I15<>"",L15<>""),IF(OR(I15>=3,L15>=3),"OUI","NON"),"")
C16: E4 | D16: Biodiversité et écosystèmes | E16: Environnement | F16: ESRS E4 | I16: =IF(AND(G16<>"",H16<>""),G16*0.6+H16*0.4,"") | L16: =IF(AND(J16<>"",K16<>""),J16*0.5+K16*0.5,"") | M16: =IF(OR(I16<>"",L16<>""),IF(OR(I16>=3,L16>=3),"OUI","NON"),"")
C17: E5 | D17: Économie circulaire | E17: Environnement | F17: ESRS E5 | I17: =IF(AND(G17<>"",H17<>""),G17*0.6+H17*0.4,"") | L17: =IF(AND(J17<>"",K17<>""),J17*0.5+K17*0.5,"") | M17: =IF(OR(I17<>"",L17<>""),IF(OR(I17>=3,L17>=3),"OUI","NON"),"")
C18: S1 | D18: Effectifs propres | E18: Social | F18: ESRS S1 | I18: =IF(AND(G18<>"",H18<>""),G18*0.6+H18*0.4,"") | L18: =IF(AND(J18<>"",K18<>""),J18*0.5+K18*0.5,"") | M18: =IF(OR(I18<>"",L18<>""),IF(OR(I18>=3,L18>=3),"OUI","NON"),"")
C19: S2 | D19: Travailleurs chaîne de valeur | E19: Social | F19: ESRS S2 | I19: =IF(AND(G19<>"",H19<>""),G19*0.6+H19*0.4,"") | L19: =IF(AND(J19<>"",K19<>""),J19*0.5+K19*0.5,"") | M19: =IF(OR(I19<>"",L19<>""),IF(OR(I19>=3,L19>=3),"OUI","NON"),"")
C20: S3 | D20: Communautés affectées | E20: Social | F20: ESRS S3 | I20: =IF(AND(G20<>"",H20<>""),G20*0.6+H20*0.4,"") | L20: =IF(AND(J20<>"",K20<>""),J20*0.5+K20*0.5,"") | M20: =IF(OR(I20<>"",L20<>""),IF(OR(I20>=3,L20>=3),"OUI","NON"),"")
C21: S4 | D21: Consommateurs / utilisateurs | E21: Social | F21: ESRS S4 | I21: =IF(AND(G21<>"",H21<>""),G21*0.6+H21*0.4,"") | L21: =IF(AND(J21<>"",K21<>""),J21*0.5+K21*0.5,"") | M21: =IF(OR(I21<>"",L21<>""),IF(OR(I21>=3,L21>=3),"OUI","NON"),"")
C22: G1 | D22: Conduite des affaires | E22: Gouvernance | F22: ESRS G1 | I22: =IF(AND(G22<>"",H22<>""),G22*0.6+H22*0.4,"") | L22: =IF(AND(J22<>"",K22<>""),J22*0.5+K22*0.5,"") | M22: =IF(OR(I22<>"",L22<>""),IF(OR(I22>=3,L22>=3),"OUI","NON"),"")
B25: SYNTHÈSE MATÉRIALITÉ
B26: Enjeux évalués | E26: =COUNTA(M13:M22)-COUNTBLANK(M13:M22)
B27: Enjeux matériels | E27: =COUNTIF(M13:M22,"OUI")
B28: Enjeux non matériels | E28: =COUNTIF(M13:M22,"NON")
B29: Enjeux matériels E | E29: =COUNTIFS(E13:E22,"Environnement",M13:M22,"OUI")
B30: Enjeux matériels S | E30: =COUNTIFS(E13:E22,"Social",M13:M22,"OUI")
B31: Enjeux matériels G | E31: =COUNTIFS(E13:E22,"Gouvernance",M13:M22,"OUI")
B33: ⚠️ Seuls les enjeux marqués OUI déclenchent l'obligation de reporter selon la norme ESRS correspondante. Documentez la justification pour chaque enjeu non matériel.

Sheet Synthese_ESG
J1: 🏠 Sommaire | K1: 📄 Couverture
A2: SYNTHÈSE ESG — Score consolidé Environnement / Social / Gouvernance
A3: Agrégation automatique des scores de complétude par pilier ESG. Pondération : E 40% / S 35% / G 25%.
B5: Pilier ESG | C5: Score complétude (%) | D5: Nb data points | E5: Nb complétés | F5: Pondération
C6: 🌍 Environnement (E) | D6: =IF(F6>0,E6/F6*100,0) | E6: 12 | F6: =COUNTIF(VSME_Reporting!G17:G28,"✓ OK") | G6: 40%
C7: 👥 Social (S) | D7: =IF(F7>0,E7/F7*100,0) | E7: 74 | F7: =COUNTIF(ESRS_S1!G8:G55,"✓ OK")+COUNTIF(ESRS_S2!G8:G19,"✓ OK")+COUNTIF(ESRS_S3!G8:G17,"✓ OK")+COUNTIF(ESRS_S4!G8:G20,"✓ OK") | G7: 35%
C8: ⚖️ Gouvernance (G) | D8: =IF(F8>0,E8/F8*100,0) | E8: 20 | F8: =COUNTIF(ESRS_G1!G8:G30,"✓ OK") | G8: 25%
C10: SCORE ESG GLOBAL | D10: =D6*0.4+D7*0.35+D8*0.25 | E10: =F6+F7+F8 | F10: =E6+E7+E8
C12: Statut ESG | D12: =IF(D10>=75,"✅ Maturité ESG élevée",IF(D10>=50,"⚠️ En progression","❌ Insuffisant — à compléter"))
C14: Équilibre E/S/G | D14: =IF(AND(D6>=40,D7>=40,D8>=40),"✅ Équilibré",IF(OR(D6<20,D7<20,D8<20),"❌ Déséquilibre majeur","⚠️ Déséquilibre à corriger"))
C16: Enjeux matériels identifiés | D16: =Materialite!E27
C17: dont Environnement | D17: =Materialite!E29
C18: dont Social | D18: =Materialite!E30
C19: dont Gouvernance | D19: =Materialite!E31
A21: KPIs CARBONE (depuis fichier Calcul Carbone)
B22: Indicateur | C22: Score ESRS Simplifié (%) | D22: =ESRS_Simplifie!E42
C23: Total GES (tCO2e) | D23: =Liaison_Donnees!C19 | E23: tCO2e
C24: Intensité / CA (tCO2e/M€) | D24: =Liaison_Donnees!C20 | E24: tCO2e/M€
C25: Part ENR (%) | D25: =Liaison_Donnees!C22 | E25: %
C26: % CA aligné Taxonomie | D26: =Liaison_Donnees!C25 | E26: %
C27: Objectif SBTi S1+2 (%/an) | D27: =Liaison_Donnees!C27 | E27: %

Sheet Controles_QC_ESG
J1: 🏠 Sommaire | K1: 📄 Couverture
A2: CONTRÔLES QUALITÉ AUTOMATIQUES — AUDIT READINESS ESG
A3: 15 contrôles automatiques pour préparer l'assurance limitée / raisonnable CSRD. ✓ = OK | ✗ = Erreur | ⚠ = Avertissement
B5: SYNTHÈSE | C5: =COUNTIF(F9:F23,"✓ OK") | D5: ✓ OK | E5: =COUNTIF(F9:F23,"⚠ Alerte") | F5: ⚠ Alerte
C6: =COUNTIF(F9:F23,"✗ ERREUR") | D6: ✗ ERREUR
B8: ID | C8: Nom du contrôle | D8: Description / Règle | E8: Criticité | F8: Statut | G8: Action recommandée
C9: C-E01 | D9: Liaison données renseignée | E9: Au moins CA et ETP saisis dans Liaison_Donnees | F9: Bloquant | G9: =IF(AND(Liaison_Donnees!C9>0,Liaison_Donnees!C10>0),"✓ OK","✗ ERREUR") | H9: Compléter Liaison_Donnees : CA et ETP
C10: C-E02 | D10: Score VSME > 50% | E10: Au moins la moitié des indicateurs VSME renseignés | F10: Avertissement | G10: =IF(Synthese_ESG!D10>=50,"✓ OK","⚠ Alerte") | H10: Compléter les indicateurs VSME manquants
C11: C-E03 | D11: Matérialité réalisée | E11: Au moins 5 enjeux évalués dans Materialite | F11: Bloquant | G11: =IF(Materialite!E26>=5,"✓ OK","✗ ERREUR") | H11: Évaluer au moins 5 enjeux dans Materialite
C12: C-E04 | D12: Équilibre E/S/G | E12: Aucun pilier < 20% | F12: Avertissement | G12: =IF(AND(Synthese_ESG!D6>=20,Synthese_ESG!D7>=20,Synthese_ESG!D8>=20),"✓ OK","⚠ Alerte") | H12: Compléter le pilier ESG le plus faible
C13: C-E05 | D13: GES total renseigné | E13: Liaison_Donnees : total S1+S2+S3 > 0 | F13: Bloquant | G13: =IF(Liaison_Donnees!C19>0,"✓ OK","✗ ERREUR") | H13: Saisir les émissions GES dans Liaison_Donnees
C14: C-E06 | D14: Social S1 : effectifs | E14: VSME S-1 (effectif total) renseigné | F14: Avertissement | G14: =IF(VSME_Reporting!E31<>"","✓ OK","⚠ Alerte") | H14: Saisir l'effectif total dans VSME section C
C15: C-E07 | D15: Social S1 : LTIR | E15: Taux d'accidents renseigné si ETP > 250 | F15: Avertissement | G15: =IF(OR(Liaison_Donnees!C10<=250,VSME_Reporting!E34<>""),"✓ OK","⚠ Alerte") | H15: Saisir le LTIR dans VSME section C
C16: C-E08 | D16: Écart salarial H/F | E16: Renseigné si ETP > 250 | F16: Avertissement | G16: =IF(OR(Liaison_Donnees!C10<=250,VSME_Reporting!E36<>""),"✓ OK","⚠ Alerte") | H16: Saisir l'écart H/F dans VSME section C
C17: C-E09 | D17: Gouvernance : anti-corruption | E17: Politique anti-corruption documentée | F17: Avertissement | G17: =IF(VSME_Reporting!E43<>"","✓ OK","⚠ Alerte") | H17: Renseigner G-1 dans VSME section D
C18: C-E10 | D18: Gouvernance : lanceurs d'alerte | E18: Canal de signalement actif | F18: Avertissement | G18: =IF(VSME_Reporting!E45<>"","✓ OK","⚠ Alerte") | H18: Renseigner G-3 dans VSME section D
C19: C-E11 | D19: Part ENR renseignée | E19: Énergie renouvelable documentée | F19: Info | G19: =IF(Liaison_Donnees!C22<>"","✓ OK","⚠ Alerte") | H19: Compléter la part ENR dans Liaison_Donnees
C20: C-E12 | D20: Plan de réduction GES | E20: Plan de réduction adopté (O/N) renseigné | F20: Avertissement | G20: =IF(VSME_Reporting!E28<>"","✓ OK","⚠ Alerte") | H20: Renseigner E-12 dans VSME section B
C21: C-E13 | D21: Score ESG global > 30% | E21: Score minimum pour crédibilité | F21: Bloquant | G21: =IF(Synthese_ESG!D10>=30,"✓ OK","✗ ERREUR") | H21: Le score ESG global est trop bas — compléter tous les piliers
C22: C-E14 | D22: Enjeu E1 climat évalué | E22: Changement climatique doit être évalué | F22: Bloquant | G22: =IF(Materialite!M13<>"","✓ OK","✗ ERREUR") | H22: Évaluer l'enjeu E1 Changement climatique dans Materialite
C23: C-E15 | D23: Cohérence ETP | E23: ETP VSME = ETP Liaison cohérent | F23: Info | G23: =IF(OR(VSME_Reporting!E31="",VSME_Reporting!E31=Liaison_Donnees!C10),"✓ OK","⚠ Alerte") | H23: Vérifier cohérence des effectifs entre VSME et Liaison

Sheet ESRS_S1
H1: 🏠 Sommaire
A2: ESRS S1 — EFFECTIFS PROPRES — Conditions de travail, égalité, santé-sécurité
A3: Delegated Regulation (EU) 2023/2772 — ESRS S1. Reporter si l'enjeu S1 est matériel dans l'analyse de double matérialité.
B4: Matérialité S1 : | D4: =IF(Materialite!M18="OUI","✅ MATÉRIEL — Reporting obligatoire","⚠️ Non matériel — Reporting volontaire")
A6: A — CARACTÉRISTIQUES DES EFFECTIFS (S1-6)
B7: ID | C7: Réf. ESRS | D7: Data point | E7: Valeur | F7: Unité | G7: Statut | H7: Source
B8: S1-6-01 | C8: S1-6 §50(a) | D8: Effectif total au 31/12 (personnes) | F8: Nb | G8: =IF(E8<>"","✓ OK","⬜ À remplir") | H8: saisie
B9: S1-6-02 | C9: S1-6 §50(a) | D9: dont CDI | F9: Nb | G9: =IF(E9<>"","✓ OK","⬜ À remplir") | H9: saisie
B10: S1-6-03 | C10: S1-6 §50(a) | D10: dont CDD | F10: Nb | G10: =IF(E10<>"","✓ OK","⬜ À remplir") | H10: saisie
B11: S1-6-04 | C11: S1-6 §50(a) | D11: dont intérimaires / temporaires | F11: Nb | G11: =IF(E11<>"","✓ OK","⬜ À remplir") | H11: saisie
B12: S1-6-05 | C12: S1-6 §50(b) | D12: Effectif en ETP (équivalent temps plein) | E12: =Liaison_Donnees!C10 | F12: ETP | G12: =IF(E12<>"","✓ OK","⬜ À remplir") | H12: liaison
B13: S1-6-06 | C13: S1-6 §50 | D13: % CDI / effectif total | E13: =IF(E8>0,E9/E8*100,0) | F13: % | G13: =IF(E13<>"","✓ OK","⬜ À remplir") | H13: calc
B14: S1-6-07 | C14: S1-6 §51 | D14: Nb de pays avec effectifs > 50 personnes | F14: Nb | G14: =IF(E14<>"","✓ OK","⬜ À remplir") | H14: saisie
B15: S1-6-08 | C15: S1-6 §52 | D15: % femmes dans l'effectif total | F15: % | G15: =IF(E15<>"","✓ OK","⬜ À remplir") | H15: saisie
B16: S1-6-09 | C16: S1-6 §52 | D16: % femmes dans l'encadrement supérieur | F16: % | G16: =IF(E16<>"","✓ OK","⬜ À remplir") | H16: saisie
B17: S1-6-10 | C17: S1-6 §52 | D17: % femmes au comité de direction | F17: % | G17: =IF(E17<>"","✓ OK","⬜ À remplir") | H17: saisie
A19: B — RÉMUNÉRATION ET AVANTAGES (S1-10)
B20: ID | C20: Réf. ESRS | D20: Data point | E20: Valeur | F20: Unité | G20: Statut | H20: Source
B21: S1-10-01 | C21: S1-10 §68 | D21: Salaire brut médian annuel (€) | F21: € | G21: =IF(E21<>"","✓ OK","⬜ À remplir") | H21: saisie
B22: S1-10-02 | C22: S1-10 §68 | D22: Salaire brut médian hommes (€) | F22: € | G22: =IF(E22<>"","✓ OK","⬜ À remplir") | H22: saisie
B23: S1-10-03 | C23: S1-10 §68 | D23: Salaire brut médian femmes (€) | F23: € | G23: =IF(E23<>"","✓ OK","⬜ À remplir") | H23: saisie
B24: S1-10-04 | C24: S1-10 §69 | D24: Écart de rémunération H/F (%) | E24: =IF(E22>0,(E22-E23)/E22*100,0) | F24: % | G24: =IF(E24<>"","✓ OK","⬜ À remplir") | H24: calc
B25: S1-10-05 | C25: S1-10 §70 | D25: Ratio rémunération PDG / salaire médian | F25: x | G25: =IF(E25<>"","✓ OK","⬜ À remplir") | H25: saisie
B26: S1-10-06 | C26: S1-10 §71 | D26: % salariés couverts par convention collective | F26: % | G26: =IF(E26<>"","✓ OK","⬜ À remplir") | H26: saisie
B27: S1-10-07 | C27: S1-10 | D27: Salaire d'entrée vs SMIC (%) | F27: % | G27: =IF(E27<>"","✓ OK","⬜ À remplir") | H27: saisie
A29: C — SANTÉ ET SÉCURITÉ AU TRAVAIL (S1-14)
B30: ID | C30: Réf. ESRS | D30: Data point | E30: Valeur | F30: Unité | G30: Statut | H30: Source
B31: S1-14-01 | C31: S1-14 §88(a) | D31: Nb d'accidents du travail avec arrêt | F31: Nb | G31: =IF(E31<>"","✓ OK","⬜ À remplir") | H31: saisie
B32: S1-14-02 | C32: S1-14 §88(b) | D32: Nb de jours d'arrêt (accidents) | F32: jours | G32: =IF(E32<>"","✓ OK","⬜ À remplir") | H32: saisie
B33: S1-14-03 | C33: S1-14 §88(c) | D33: Nb total d'heures travaillées | F33: heures | G33: =IF(E33<>"","✓ OK","⬜ À remplir") | H33: saisie
B34: S1-14-04 | C34: S1-14 §88 | D34: Taux de fréquence (LTIR) | E34: =IF(E33>0,E31*1000000/E33,0) | F34: pour 1M h | G34: =IF(E34<>"","✓ OK","⬜ À remplir") | H34: calc
B35: S1-14-05 | C35: S1-14 §88 | D35: Taux de gravité | E35: =IF(E33>0,E32*1000/E33,0) | F35: pour 1000 h | G35: =IF(E35<>"","✓ OK","⬜ À remplir") | H35: calc
B36: S1-14-06 | C36: S1-14 §88(e) | D36: Nb de décès liés au travail | F36: Nb | G36: =IF(E36<>"","✓ OK","⬜ À remplir") | H36: saisie
B37: S1-14-07 | C37: S1-14 §89 | D37: Nb de maladies professionnelles déclarées | F37: Nb | G37: =IF(E37<>"","✓ OK","⬜ À remplir") | H37: saisie
B38: S1-14-08 | C38: S1-14 | D38: Taux d'absentéisme (%) | F38: % | G38: =IF(E38<>"","✓ OK","⬜ À remplir") | H38: saisie
A40: D — FORMATION ET DÉVELOPPEMENT (S1-13)
B41: ID | C41: Réf. ESRS | D41: Data point | E41: Valeur | F41: Unité | G41: Statut | H41: Source
B42: S1-13-01 | C42: S1-13 §83 | D42: Nb total d'heures de formation | F42: heures | G42: =IF(E42<>"","✓ OK","⬜ À remplir") | H42: saisie
B43: S1-13-02 | C43: S1-13 §83 | D43: Heures de formation / ETP | E43: =IF(Liaison_Donnees!C10>0,E42/Liaison_Donnees!C10,0) | F43: h/ETP | G43: =IF(E43<>"","✓ OK","⬜ À remplir") | H43: calc
B44: S1-13-03 | C44: S1-13 §84 | D44: % salariés ayant suivi au moins 1 formation | F44: % | G44: =IF(E44<>"","✓ OK","⬜ À remplir") | H44: saisie
...

Sheet ESRS_S2
H1: 🏠 Sommaire
A2: ESRS S2 — TRAVAILLEURS DE LA CHAÎNE DE VALEUR
B3: Delegated Regulation (EU) 2023/2772 — ESRS S2. Fournisseurs, sous-traitants, prestataires.
B4: Matérialité S2 : | D4: =IF(Materialite!M19="OUI","✅ MATÉRIEL","⚠️ Non matériel")
A6: A — CARTOGRAPHIE FOURNISSEURS (S2-1 / S2-4)
B7: ID | C7: Réf. ESRS | D7: Data point | E7: Valeur | F7: Unité | G7: Statut | H7: Source
B8: S2-1-01 | C8: S2-1 §11 | D8: Nb total de fournisseurs directs (rang 1) | F8: Nb | G8: =IF(E8<>"","✓ OK","⬜ À remplir") | H8: saisie
B9: S2-1-02 | C9: S2-1 §12 | D9: Nb de fournisseurs dans des pays à risque | F9: Nb | G9: =IF(E9<>"","✓ OK","⬜ À remplir") | H9: saisie
B10: S2-1-03 | C10: S2-1 §12 | D10: % fournisseurs ayant signé une charte ESG | F10: % | G10: =IF(E10<>"","✓ OK","⬜ À remplir") | H10: saisie
B11: S2-4-01 | C11: S2-4 §25 | D11: Nb de fournisseurs évalués ESG dans l'année | F11: Nb | G11: =IF(E11<>"","✓ OK","⬜ À remplir") | H11: saisie
B12: S2-4-02 | C12: S2-4 §25 | D12: % fournisseurs évalués / total | E12: =IF(E8>0,E11/E8*100,0) | F12: % | G12: =IF(E12<>"","✓ OK","⬜ À remplir") | H12: calc
B13: S2-4-03 | C13: S2-4 §26 | D13: Nb d'audits sociaux réalisés chez fournisseurs | F13: Nb | G13: =IF(E13<>"","✓ OK","⬜ À remplir") | H13: saisie
B14: S2-4-04 | C14: S2-4 §27 | D14: Nb de non-conformités majeures identifiées | F14: Nb | G14: =IF(E14<>"","✓ OK","⬜ À remplir") | H14: saisie
B15: S2-4-05 | C15: S2-4 §27 | D15: Nb de plans d'action correctifs en cours | F15: Nb | G15: =IF(E15<>"","✓ OK","⬜ À remplir") | H15: saisie
B16: S2-4-06 | C16: S2-4 §28 | D16: Nb de fournisseurs exclus pour non-conformité | F16: Nb | G16: =IF(E16<>"","✓ OK","⬜ À remplir") | H16: saisie
B17: S2-SBT | C17: S2-4 | D17: % fournisseurs engagés SBTi (top 20 achats) | F17: % | G17: =IF(E17<>"","✓ OK","⬜ À remplir") | H17: saisie
B18: S2-DV | C18: S2-5 §30 | D18: Politique de devoir de vigilance adoptée (O/N) | F18: O/N | G18: =IF(E18<>"","✓ OK","⬜ À remplir") | H18: saisie
B19: S2-FORM | C19: S2-4 | D19: Nb de fournisseurs formés aux enjeux ESG | F19: Nb | G19: =IF(E19<>"","✓ OK","⬜ À remplir") | H19: saisie
A21: SCORE DE COMPLÉTUDE S2
C22: Data points renseignés | E22: =COUNTIF(G8:G20,"✓ OK")
C23: Score complétude S2 (%) | E23: =IF(12>0,E22/12*100,0)

Sheet ESRS_S3
H1: 🏠 Sommaire
A2: ESRS S3 — COMMUNAUTÉS AFFECTÉES
B3: Delegated Regulation (EU) 2023/2772 — ESRS S3. Populations locales, peuples autochtones, impacts territoriaux.
B4: Matérialité S3 : | D4: =IF(Materialite!M20="OUI","✅ MATÉRIEL","⚠️ Non matériel")
A6: IMPACTS SUR LES COMMUNAUTÉS (S3-1 à S3-5)
B7: ID | C7: Réf. ESRS | D7: Data point | E7: Valeur | F7: Unité | G7: Statut | H7: Source
B8: S3-1-01 | C8: S3-1 §10 | D8: Nb de sites d'opérations dans/à proximité de communautés | F8: Nb | G8: =IF(E8<>"","✓ OK","⬜ À remplir") | H8: saisie
B9: S3-1-02 | C9: S3-1 §11 | D9: Nb de communautés identifiées comme affectées | F9: Nb | G9: =IF(E9<>"","✓ OK","⬜ À remplir") | H9: saisie
B10: S3-1-03 | C10: S3-1 §12 | D10: Types d'impacts identifiés (environnement, santé, culture) | F10: Texte | G10: =IF(E10<>"","✓ OK","⬜ À remplir") | H10: saisie
B11: S3-3-01 | C11: S3-3 §19 | D11: Processus de consultation des communautés (O/N) | F11: O/N | G11: =IF(E11<>"","✓ OK","⬜ À remplir") | H11: saisie
B12: S3-3-02 | C12: S3-3 §20 | D12: Nb de consultations réalisées dans l'année | F12: Nb | G12: =IF(E12<>"","✓ OK","⬜ À remplir") | H12: saisie
B13: S3-4-01 | C13: S3-4 §23 | D13: Nb de réclamations / plaintes communautaires reçues | F13: Nb | G13: =IF(E13<>"","✓ OK","⬜ À remplir") | H13: saisie
B14: S3-4-02 | C14: S3-4 §24 | D14: Nb de réclamations traitées / résolues | F14: Nb | G14: =IF(E14<>"","✓ OK","⬜ À remplir") | H14: saisie
B15: S3-4-03 | C15: S3-4 | D15: Taux de résolution (%) | E15: =IF(E13>0,E14/E13*100,0) | F15: % | G15: =IF(E15<>"","✓ OK","⬜ À remplir") | H15: calc
B16: S3-5-01 | C16: S3-5 §26 | D16: Nb de litiges en cours avec des communautés | F16: Nb | G16: =IF(E16<>"","✓ OK","⬜ À remplir") | H16: saisie
B17: S3-5-02 | C17: S3-5 §27 | D17: Investissements communautaires dans l'année (€) | F17: € | G17: =IF(E17<>"","✓ OK","⬜ À remplir") | H17: saisie
A19: SCORE DE COMPLÉTUDE S3
C20: Data points renseignés | E20: =COUNTIF(G8:G18,"✓ OK")
C21: Score complétude S3 (%) | E21: =IF(10>0,E20/10*100,0)

Sheet ESRS_S4
H1: 🏠 Sommaire
A2: ESRS S4 — CONSOMMATEURS ET UTILISATEURS FINAUX
B3: Delegated Regulation (EU) 2023/2772 — ESRS S4. Sécurité produit, vie privée, accessibilité, marketing responsable.
B4: Matérialité S4 : | D4: =IF(Materialite!M21="OUI","✅ MATÉRIEL","⚠️ Non matériel")
A6: INDICATEURS CONSOMMATEURS (S4-1 à S4-5)
B7: ID | C7: Réf. ESRS | D7: Data point | E7: Valeur | F7: Unité | G7: Statut | H7: Source
B8: S4-1-01 | C8: S4-1 §10 | D8: Nb de clients / utilisateurs finaux | F8: Nb | G8: =IF(E8<>"","✓ OK","⬜ À remplir") | H8: saisie
B9: S4-1-02 | C9: S4-1 §11 | D9: Marchés géographiques servis | F9: Texte | G9: =IF(E9<>"","✓ OK","⬜ À remplir") | H9: saisie
B10: S4-3-01 | C10: S4-3 §19 | D10: Score satisfaction client (NPS ou CSAT) | F10: Score | G10: =IF(E10<>"","✓ OK","⬜ À remplir") | H10: saisie
B11: S4-3-02 | C11: S4-3 §19 | D11: NPS calculé | F11: Score | G11: =IF(E11<>"","✓ OK","⬜ À remplir") | H11: calc
B12: S4-3-03 | C12: S4-3 §20 | D12: Nb de réclamations produit/service reçues | F12: Nb | G12: =IF(E12<>"","✓ OK","⬜ À remplir") | H12: saisie
B13: S4-3-04 | C13: S4-3 §20 | D13: Nb de réclamations traitées < 30 jours | F13: Nb | G13: =IF(E13<>"","✓ OK","⬜ À remplir") | H13: saisie
B14: S4-3-05 | C14: S4-3 | D14: Taux de résolution rapide (%) | E14: =IF(E12>0,E13/E12*100,0) | F14: % | G14: =IF(E14<>"","✓ OK","⬜ À remplir") | H14: calc
B15: S4-4-01 | C15: S4-4 §24 | D15: Nb d'incidents de sécurité produit | F15: Nb | G15: =IF(E15<>"","✓ OK","⬜ À remplir") | H15: saisie
B16: S4-4-02 | C16: S4-4 §25 | D16: Nb de rappels produit dans l'année | F16: Nb | G16: =IF(E16<>"","✓ OK","⬜ À remplir") | H16: saisie
B17: S4-4-03 | C17: S4-4 §26 | D17: Politique de protection des données (O/N) | F17: O/N | G17: =IF(E17<>"","✓ OK","⬜ À remplir") | H17: saisie
B18: S4-4-04 | C18: S4-4 §27 | D18: Nb de violations de données personnelles | F18: Nb | G18: =IF(E18<>"","✓ OK","⬜ À remplir") | H18: saisie
B19: S4-5-01 | C19: S4-5 §29 | D19: Accessibilité produits/services (score 1-5) | F19: 1-5 | G19: =IF(E19<>"","✓ OK","⬜ À remplir") | H19: saisie
B20: S4-5-02 | C20: S4-5 | D20: Marketing responsable : politique adoptée (O/N) | F20: O/N | G20: =IF(E20<>"","✓ OK","⬜ À remplir") | H20: saisie
A22: SCORE DE COMPLÉTUDE S4
C23: Data points renseignés | E23: =COUNTIF(G8:G21,"✓ OK")
C24: Score complétude S4 (%) | E24: =IF(13>0,E23/13*100,0)

Sheet ESRS_G1
H1: 🏠 Sommaire
A2: ESRS G1 — CONDUITE DES AFFAIRES — Éthique, gouvernance, anti-corruption
A3: Delegated Regulation (EU) 2023/2772 — ESRS G1. Transparence, éthique, lobbying, protection lanceurs d'alerte.
B4: Matérialité G1 : | D4: =IF(Materialite!M22="OUI","✅ MATÉRIEL","⚠️ Non matériel")
A6: A — GOUVERNANCE D'ENTREPRISE (G1-1 à G1-3)
B7: ID | C7: Réf. ESRS | D7: Data point | E7: Valeur | F7: Unité | G7: Statut | H7: Source
B8: G1-1-01 | C8: G1-1 §7 | D8: Rôle des organes de direction dans la durabilité | F8: Texte | G8: =IF(E8<>"","✓ OK","⬜ À remplir") | H8: saisie
B9: G1-1-02 | C9: G1-1 §8 | D9: Nb de membres du conseil d'administration | F9: Nb | G9: =IF(E9<>"","✓ OK","⬜ À remplir") | H9: saisie
B10: G1-1-03 | C10: G1-1 §8 | D10: % de membres indépendants du CA | F10: % | G10: =IF(E10<>"","✓ OK","⬜ À remplir") | H10: saisie
B11: G1-1-04 | C11: G1-1 §9 | D11: % de femmes au CA | F11: % | G11: =IF(E11<>"","✓ OK","⬜ À remplir") | H11: saisie
B12: G1-1-05 | C12: G1-1 §10 | D12: Fréquence de réunion du CA sur la durabilité (/an) | F12: Nb | G12: =IF(E12<>"","✓ OK","⬜ À remplir") | H12: saisie
B13: G1-1-06 | C13: G1-1 | D13: Expertise ESG au sein du CA (O/N) | F13: O/N | G13: =IF(E13<>"","✓ OK","⬜ À remplir") | H13: saisie
A15: B — ÉTHIQUE ET ANTI-CORRUPTION (G1-3 à G1-4)
B16: ID | C16: Réf. ESRS | D16: Data point | E16: Valeur | F16: Unité | G16: Statut | H16: Source
B17: G1-3-01 | C17: G1-3 §15 | D17: Politique anti-corruption adoptée (O/N) | F17: O/N | G17: =IF(E17<>"","✓ OK","⬜ À remplir") | H17: saisie
B18: G1-3-02 | C18: G1-3 §16 | D18: % salariés formés à l'anti-corruption | F18: % | G18: =IF(E18<>"","✓ OK","⬜ À remplir") | H18: saisie
B19: G1-3-03 | C19: G1-3 §17 | D19: Nb d'incidents de corruption confirmés | F19: Nb | G19: =IF(E19<>"","✓ OK","⬜ À remplir") | H19: saisie
B20: G1-3-04 | C20: G1-3 §17 | D20: Nb de procédures judiciaires en cours (corruption) | F20: Nb | G20: =IF(E20<>"","✓ OK","⬜ À remplir") | H20: saisie
B21: G1-4-01 | C21: G1-4 §19 | D21: Canal de signalement lanceurs d'alerte (O/N) | F21: O/N | G21: =IF(E21<>"","✓ OK","⬜ À remplir") | H21: saisie
B22: G1-4-02 | C22: G1-4 §20 | D22: Nb de signalements reçus dans l'année | F22: Nb | G22: =IF(E22<>"","✓ OK","⬜ À remplir") | H22: saisie
B23: G1-4-03 | C23: G1-4 §20 | D23: Nb de signalements traités / clos | F23: Nb | G23: =IF(E23<>"","✓ OK","⬜ À remplir") | H23: saisie
B24: G1-4-04 | C24: G1-4 | D24: Taux de traitement (%) | E24: =IF(E22>0,E23/E22*100,0) | F24: % | G24: =IF(E24<>"","✓ OK","⬜ À remplir") | H24: calc
A26: C — LOBBYING ET CONTRIBUTIONS POLITIQUES (G1-5)
B27: ID | C27: Réf. ESRS | D27: Data point | E27: Valeur | F27: Unité | G27: Statut | H27: Source
B28: G1-5-01 | C28: G1-5 §23 | D28: Dépenses de lobbying dans l'année (€) | F28: € | G28: =IF(E28<>"","✓ OK","⬜ À remplir") | H28: saisie
B29: G1-5-02 | C29: G1-5 §24 | D29: Contributions politiques dans l'année (€) | F29: € | G29: =IF(E29<>"","✓ OK","⬜ À remplir") | H29: saisie
B30: G1-5-03 | C30: G1-5 §25 | D30: Inscription au registre de transparence UE (O/N) | F30: O/N | G30: =IF(E30<>"","✓ OK","⬜ À remplir") | H30: saisie
B31: G1-6-01 | C31: G1-6 §27 | D31: Délai moyen de paiement fournisseurs (jours) | F31: jours | G31: =IF(E31<>"","✓ OK","⬜ À remplir") | H31: saisie
B32: G1-6-02 | C32: G1-6 §28 | D32: % de factures payées à échéance | F32: % | G32: =IF(E32<>"","✓ OK","⬜ À remplir") | H32: saisie
B33: G1-6-03 | C33: G1-6 | D33: Nb de litiges commerciaux en cours | F33: Nb | G33: =IF(E33<>"","✓ OK","⬜ À remplir") | H33: saisie
A35: SCORE DE COMPLÉTUDE G1
C36: Data points renseignés | E36: =COUNTIF(G8:G34,"✓ OK")
C37: Score complétude G1 (%) | E37: =IF(20>0,E36/20*100,0)

Sheet Claude Log
A1: Turn # | B1: Date | C1: User Request | D1: Action Taken | E1: Details | F1: Outcome
A2: 1 | B2: 46124 | C2: Block A governance kickoff | D2: Created Claude Log sheet for ESG Social master workbook | E2: Phase 0 requires homogeneous governance and traceability across the 3 master workbooks. | F2: Claude Log is now available for future structural changes.
A3: 2 | B3: 2026-04-12 | C3: Block A liaison hardening | D3: Corrected misleading source references in Liaison_Donnees for Scope 2 LB, Scope 2 MB, Scope 3, energy KPIs, taxonomie and CBAM. | E3: This change keeps the manual import workflow intact while aligning the workbook with the real source cells in CarbonCo_Calcul_Carbone_v2.xlsx. | F3: ESG Social liaison sheet is now structurally aligned with the Carbon source workbook.

Sheet ESRS_Simplifie
H1: 🏠 Sommaire
A2: ESRS SIMPLIFIÉ — MODE ~300 DATA POINTS (Omnibus / Acte délégué mi-2026)
B3: Ce module filtre les data points obligatoires en mode ESRS Simplifié (~300) vs Complet (~1100). Les valeurs sont auto-alimentées depuis les onglets ESRS détaillés et Liaison_Donnees.
B5: ⚙️ Mode actif : | E5: Simplifié
A7: ESRS E1 — CHANGEMENT CLIMATIQUE (données prioritaires simplifiées)
B8: ID | C8: Réf. ESRS | D8: Data point simplifié | E8: Valeur | F8: Unité | G8: Mode | H8: Statut
B9: E1-6-a | C9: E1-6 §44 | D9: Scope 1 total (tCO2e) | E9: =Liaison_Donnees!C15 | F9: tCO2e | G9: S | H9: =IF(E9<>"","✓ OK","⬜")
B10: E1-6-b | C10: E1-6 §44 | D10: Scope 2 location-based (tCO2e) | E10: =Liaison_Donnees!C16 | F10: tCO2e | G10: S | H10: =IF(E10<>"","✓ OK","⬜")
B11: E1-6-b2 | C11: E1-6 §44 | D11: Scope 2 market-based (tCO2e) | E11: =Liaison_Donnees!C17 | F11: tCO2e | G11: S | H11: =IF(E11<>"","✓ OK","⬜")
B12: E1-6-c | C12: E1-6 §51 | D12: Scope 3 total (tCO2e) | E12: =Liaison_Donnees!C18 | F12: tCO2e | G12: S | H12: =IF(E12<>"","✓ OK","⬜")
B13: E1-6-d | C13: E1-6 §55 | D13: Total GES (S1+S2+S3) | E13: =Liaison_Donnees!C19 | F13: tCO2e | G13: S | H13: =IF(E13<>"","✓ OK","⬜")
B14: E1-6-e | C14: E1-6 §53 | D14: Intensité GES / CA (tCO2e/M€) | E14: =Liaison_Donnees!C20 | F14: tCO2e/M€ | G14: S | H14: =IF(E14<>"","✓ OK","⬜")
B15: E1-5-a | C15: E1-5 §37 | D15: Consommation totale énergie (MWh) | E15: =Liaison_Donnees!C23 | F15: MWh | G15: S | H15: =IF(E15<>"","✓ OK","⬜")
B16: E1-5-b | C16: E1-5 §38 | D16: Part énergie renouvelable (%) | E16: =Liaison_Donnees!C22 | F16: % | G16: S | H16: =IF(E16<>"","✓ OK","⬜")
B17: E1-4 | C17: E1-4 §34 | D17: Objectif réduction S1+2 (%/an) | E17: =Liaison_Donnees!C27 | F17: % | G17: S | H17: =IF(E17<>"","✓ OK","⬜")
B18: E1-1 | C18: E1-1 §14 | D18: Plan de transition climat adopté (O/N) | F18: O/N | G18: S | H18: =IF(E18<>"","✓ OK","⬜")
A20: ESRS S1 — EFFECTIFS (données prioritaires simplifiées)
B21: ID | C21: Réf. ESRS | D21: Data point simplifié | E21: Valeur | F21: Unité | G21: Mode | H21: Statut
B22: S1-6-a | C22: S1-6 §50 | D22: Effectif total | E22: =ESRS_S1!E8 | F22: Nb | G22: S | H22: =IF(E22<>"","✓ OK","⬜")
B23: S1-6-b | C23: S1-6 §52 | D23: % femmes dans l'effectif | E23: =ESRS_S1!E15 | F23: % | G23: S | H23: =IF(E23<>"","✓ OK","⬜")
B24: S1-10 | C24: S1-10 §69 | D24: Écart rémunération H/F (%) | E24: =ESRS_S1!E23 | F24: % | G24: S | H24: =IF(E24<>"","✓ OK","⬜")
B25: S1-14-a | C25: S1-14 §88 | D25: Taux de fréquence accidents (LTIR) | E25: =ESRS_S1!E33 | F25: pour 1M h | G25: S | H25: =IF(E25<>"","✓ OK","⬜")
B26: S1-13 | C26: S1-13 §83 | D26: Heures formation / ETP | E26: =ESRS_S1!E40 | F26: h/ETP | G26: S | H26: =IF(E26<>"","✓ OK","⬜")
B27: S1-7 | C27: S1-7 §55 | D27: Taux de rotation (%) | E27: =ESRS_S1!E49 | F27: % | G27: S | H27: =IF(E27<>"","✓ OK","⬜")
A29: ESRS G1 — GOUVERNANCE (données prioritaires simplifiées)
B30: ID | C30: Réf. ESRS | D30: Data point simplifié | E30: Valeur | F30: Unité | G30: Mode | H30: Statut
B31: G1-1 | C31: G1-1 §8 | D31: % femmes au CA | E31: =ESRS_G1!E11 | F31: % | G31: S | H31: =IF(E31<>"","✓ OK","⬜")
B32: G1-3 | C32: G1-3 §15 | D32: Politique anti-corruption (O/N) | E32: =ESRS_G1!E16 | F32: O/N | G32: S | H32: =IF(E32<>"","✓ OK","⬜")
B33: G1-4 | C33: G1-4 §19 | D33: Canal lanceurs d'alerte (O/N) | E33: =ESRS_G1!E20 | F33: O/N | G33: S | H33: =IF(E33<>"","✓ OK","⬜")
B34: G1-6 | C34: G1-6 §27 | D34: Délai paiement fournisseurs (jours) | E34: =ESRS_G1!E27 | F34: jours | G34: S | H34: =IF(E34<>"","✓ OK","⬜")
A37: SCORE ESRS SIMPLIFIÉ
C38: Data points renseignés (mode simplifié) | E38: =COUNTIF(H9:H36,"✓ OK")
C39: Total data points mode simplifié | E39: 20
C40: Score complétude simplifié (%) | E40: =IF(E39>0,E38/E39*100,0)
C41: Statut | E41: =IF(E40>=80,"✅ Prêt pour reporting simplifié",IF(E40>=50,"⚠️ En cours","❌ Insuffisant"))
B43: ℹ️ Les ESRS simplifiés réduisent les data points de ~1 100 à ~300 (Omnibus déc. 2025). L'acte délégué officiel est attendu mi-2026. Ce module sera mis à jour dès publication.

Sheet _Manifest
A1: CarbonCo_ESG_Social — Manifest
A2: Version | B2: 1.0
A3: Date | B3: 2026-04-12
A4: Onglets obligatoires | B4: Couverture,Sommaire,Liaison_Donnees,VSME_Reporting,Materialite,Synthese_ESG,ESRS_S1,Controles_QC_ESG,Claude Log
A5: Plages CC_* requises | B5: 49
A6: Controles QC | B6: 15
