Workbook

Sheet Claude Log
A1: Turn # | B1: Date | C1: User Request | D1: Action Taken | E1: Details | F1: Outcome
A2: 1 | B2: 46360 | C2: Audit complet du fichier CarbonCo_Finance_DPP_v1_3.xlsx (9 onglets) : formules, liens inter-feuilles, cohérence, formatage visuel. Référence croisée avec fichier ESG Social. | D2: Audit exhaustif → 11 issues détectées, 9 corrections appliquées, formatage visuel professionnel vert/blanc/bleu sur tous les onglets, prix EU ETS mis à jour à 75€. | E2: Corrections: (1) Finance_Climat D17:D26 ref D14→D15 prix carbone, (2) E17:E26 hardcode 0.042→ref Liaison, (3) F/G colonnes ROI/Payback réécrites, (4) Benchmark headers réalignés + INDEX vérifié avec offset _Ref_Secteurs, (5) QC G20 E32→E30 + G18 <>''→>0 + synthèse F→G, (6) SFDR E12 note énergie manquante, (7) SFDR E30 score corrigé (exclut zéros), (8) Couverture date 12/04/2026, (9) Liaison C19 note S2 LB. EU ETS: 70→75€ (source CBAM Q1 2026). Formatage: thème CarbonCo vert (#1B5E20/#2E7D32/#4CAF50), inputs bleu, calcs gris. | F2: Audit terminé. Formules vérifiées post-correction. Prix projections 75→150€ sur 10 ans. QC: 2 OK / 4 ERREUR / 6 Alerte (attendu avec données à zéro). Prêt pour saisie des données Liaison_Donnees.
A3: 2 | B3: 46360 | C3: L'utilisateur a signalé un décalage entre en-têtes et données dans _Ref_Secteurs. Demande de correction en décalant les données vers la gauche. | D3: Déplacé données C5:I20 → B5:H20 pour aligner avec en-têtes B4:H4. Mis à jour toutes les formules INDEX/MATCH dans Benchmark. Corrigé type mismatch MATCH (texte vs nombre) avec D5*1. | E3: Colonnes décalées : B=Code NAF, C=Secteur, D=Intensité médiane, E=Top 25%, F=Intensité/ETP, G=Part S3%, H=Part ENR%. Formules Benchmark E8:E11 et F8:F9 toutes recâblées vers les nouvelles colonnes. MATCH utilise _Ref!B5:B20 avec D5*1 pour conversion texte→nombre. Colonne I orpheline (sans en-tête) effacée. | F3: Alignement en-têtes/données correct. Benchmark vérifié : E8=12 (médiane), F8=6 (top25%), E9=2.1, E10=78, E11=35. Positions et écarts calculés correctement.
A4: 3 | B4: 46360 | C4: Vérification et correction de DPP_Produits, Benchmark et SFDR_Report : erreurs, décalages, mise en forme. | D4: DPP: titre A16 restauré, '1' parasites A18:A24 supprimés, formatage sections B/C unifié, notes saisie ajoutées. Benchmark: D17 MATCH corrigé (C→B), secteur désormais affiché. SFDR: F24:F26 seuil 70 (vs doublon liaison), H24:H26 recalculées en comparant E vs F, notes ajoutées sur 8 champs PAI manuels. | E4: DPP: Béblon A16='B — CALCUL EMPREINTE CARBONE PAR PRODUIT (kgCO2e / unité)'. Benchmark D17=INDEX(C5:C20,MATCH(D5*1,B5:B20)) → 'Services informatiques / ESN'. SFDR F24=F25=F26=70 (seuil SFDR Art.9). Formules H24:H26 lisent E (valeur réelle) et comparent à F (seuil 70). OpEx SFDR E26 = saisie manuelle (champ absent Liaison). | F4: Toutes les formules vérifiées. Benchmark D17='Services informatiques / ESN'. Taxonomie SFDR : 3 lignes '❌ Non classifiable' (attendu, valeurs = 0). Scorecard PAI : 28.6/100, grade D (attendu sans données).
A5: 4 | B5: 46360 | C5: Navigation non fonctionnelle : boutons '🏠 Sommaire' présents sur tous les onglets mais sans hyperlien. Liens du Sommaire vers les onglets également manquants. | D5: Ajouté hyperliens sur J1 de 8 onglets (→ Sommaire!A1). Ajouté hyperliens C4:C10 du Sommaire (→ chaque onglet). Ajouté lien Couverture J1 → Sommaire. Ajouté lien H1 Sommaire → Couverture. | E5: 15 hyperliens configurés : Couverture!J1, Liaison_Donnees!J1, Finance_Climat!J1, DPP_Produits!J1, Benchmark!J1, SFDR_Report!J1, _Ref_Secteurs!J1, Controles_QC!J1 → Sommaire!A1. Sommaire C4:C10 → onglet correspondant. Texte bleu souligné sur Sommaire, blanc sans soulignement sur onglets. | F5: Tous hyperliens vérifiés actifs. Cliquer sur '🏠 Sommaire' sur n'importe quel onglet renvoie bien au Sommaire.
A6: 5 | B6: 46360 | C6: Mise en forme qualitative de Finance_Climat sans modifier l'architecture. Vérification des formules. | D6: En-têtes sections étendus A:H uniformément. Lignes alternantes nettoyées (blanc/gris). Section C ROI : violet supprimé, saisies bleu/calculs gris italic. Formats numériques (#,##0€, 0.0%). Bordures box par section. Largeurs colonnes ajustées. Gel des volets ligne 5. | E6: Formules vérifiées : D10=IF(D8-D9>0,(D8-D9)*D7,0) ok. D12=D10+D11 ok. D27=SUM(F17:F26) ok. D50=IF(D45>0,D48/D45*100,0) ok. D52 statut Paris ok. C41/D41/E41 SUM ok. Aucune erreur détectée. | F6: Rendu visuel vérifié par capture. 4 sections vertes D1-D4 bien délimitées avec bordures box. Saisies bleues, calculs gris italic, totaux vert clair. Statut D52 = '❌ Non aligné' (attendu, pas de données).
A7: 5 | B7: 46360 | C7: Mise en forme qualitative Finance_Climat sans modifier l'architecture. Corrections visuelles ciblées. | D7: Fix B31:B40 alternance restaurée. Row 52 unifiée. Rows 7/45 restaurées. Colonnes B/C élargies. Notes gris 10pt. Formats numériques. Gel ligne 6. | E7: Aucune erreur formule. D10, D27, D52 vérifiées OK. Capture visuelle validée. | F7: Rendu professionnel confirmé. 4 sections vert bien séparées, saisies bleues, calculs gris, totaux vert clair.
A8: 6 | B8: 2026-04-12 | C8: Block A liaison hardening | D8: Corrected misleading source references in Liaison_Donnees and clarified that the aggregated total uses Scope 2 location-based values. | E8: Updated Scope, energy, taxonomie, CBAM and baseline-year source notes to match the real source workbook. | F8: Finance DPP liaison sheet is now structurally aligned with the Carbon source workbook.

Sheet Couverture
J1: 🏠 Sommaire
B3: 🌍 CarbonCo
B4: Fichier Finance Climat, DPP & Investisseurs
B6: FINANCE CLIMAT · DIGITAL PRODUCT PASSPORT · BENCHMARK · SFDR
B7: Green CapEx | PCF ISO 14067 | PAI SFDR | Benchmarking sectoriel ADEME
B9: Raison sociale | C9: À compléter
B10: Exercice | C10: 01/01/2025 — 31/12/2025
B11: Version | C11: v1.0
B12: Date de génération | C12: 46360
B15: ✅ Finance climat conforme ESRS E1-9 / TCFD / Accord de Paris
B16: ✅ Digital Product Passport conforme ESPR (EU) 2024/1781 / ISO 14067
B17: ✅ SFDR PAI — Règlement (UE) 2019/2088 révisé (accord déc. 2025)
B19: 🔒 Confidentiel — Usage interne uniquement

Sheet Sommaire
A1: SOMMAIRE — FINANCE CLIMAT, DPP & INVESTISSEURS | H1: 📄 Couverture
B3: Onglet | D3: Description | E3: Catégorie | F3: Statut
B4: 📄 | C4: Liaison_Donnees | D4: Import données clés depuis Calcul Carbone v2 | E4: Configuration | F4: ⬜ À remplir
B5: 💰 | C5: Finance_Climat | D5: Exposition carbone, projection prix, ROI décarbonation, Green CapEx | E5: Finance | F5: ⬜ À remplir
B6: 📦 | C6: DPP_Produits | D6: Product Carbon Footprint par produit — ESPR / ISO 14067 | E6: DPP | F6: ⬜ À remplir
B7: 📊 | C7: Benchmark | D7: Comparaison sectorielle — ADEME / moyennes marché | E7: Analyse | F7: ⬜ À remplir
B8: 🏦 | C8: SFDR_Report | D8: Indicateurs PAI pour investisseurs — SFDR révisé | E8: Investisseurs | F8: ⬜ À remplir
B9: 📋 | C9: _Ref_Secteurs | D9: Table de référence sectorielle (benchmarks ADEME) | E9: Référentiel | F9: Auto
B10: 🔍 | C10: Controles_QC | D10: Contrôles qualité automatiques — 12 vérifications | E10: Audit | F10: Auto

Sheet Liaison_Donnees
J1: 🏠 Sommaire
A2: LIAISON DONNÉES — Import depuis CarbonCo_Calcul_Carbone_v2.xlsx
A3: Saisir ici les valeurs clés. Ces cellules alimentent automatiquement tous les onglets de ce fichier.
B5: Donnée | C5: Valeur | D5: Unité | E5: Source
B6: ENTREPRISE
B7: Raison sociale | D7: Texte | E7: Paramètres!B4
B8: Année de reporting | C8: 2025 | D8: Année | E8: Paramètres!B7
B9: Chiffre d'affaires net (€) | C9: 0 | D9: € | E9: Paramètres!B9
B10: Effectifs (ETP) | C10: 0 | D10: ETP | E10: Paramètres!B11
B11: Code NAF | D11: Code | E11: Paramètres!C6
B12: CapEx total (€) | C12: 0 | D12: € | E12: Paramètres!B14
B13: OpEx éligible Taxonomie (€) | C13: 0 | D13: € | E13: Paramètres!B15
B14: DONNÉES CARBONE
B15: Scope 1 total (tCO2e) | C15: 0 | D15: tCO2e | E15: Synthese_GES!C10
B16: Scope 2 LB (tCO2e) | C16: 0 | D16: tCO2e | E16: Synthese_GES!C15
B17: Scope 2 MB (tCO2e) | C17: 0 | D17: tCO2e | E17: Synthese_GES!C17
B18: Scope 3 total (tCO2e) | C18: 0 | D18: tCO2e | E18: Synthese_GES!C35
B19: Total S1+S2(LB)+S3 (tCO2e) | C19: =C15+C16+C18 | D19: tCO2e | E19: Calcul auto (LB)
B20: Intensité / CA (tCO2e/M€) | C20: =IF(C9>0,C19/(C9/1000000),0) | D20: tCO2e/M€ | E20: Calcul auto
B21: Part Scope 3 / total (%) | C21: =IF(C19>0,C18/C19*100,0) | D21: % | E21: Calcul auto
B22: ÉNERGIE & TAXONOMIE
B23: Part ENR (%) | C23: 0 | D23: % | E23: Energie!E20
B24: % CA aligné Taxonomie | C24: 0 | D24: % | E24: Taxonomie!E27
B25: % CapEx aligné Taxonomie | C25: 0 | D25: % | E25: Taxonomie!E28
B26: Coût CBAM estimé (€) | C26: 0 | D26: € | E26: CBAM!M24
B27: TRAJECTOIRE
B28: Objectif réduction S1+2 (%/an) | C28: 4.2 | D28: % | E28: Trajectoire_SBTi!B8
B29: Émissions S1+2 baseline (tCO2e) | C29: 0 | D29: tCO2e | E29: Trajectoire_SBTi!B5
B30: Année baseline | C30: 2025 | D30: Année | E30: Trajectoire_SBTi!B4

Sheet Finance_Climat
J1: 🏠 Sommaire
A2: FINANCE CLIMAT — Exposition carbone, projection prix, ROI décarbonation, Green CapEx
A3: Conforme ESRS E1-9 (effets financiers anticipés) / TCFD / Alignement Accord de Paris. Date : 12/04/2026.
A5: A — EXPOSITION AU PRIX CARBONE (EU ETS / CBAM)
A6: Paramètre | C6: Valeur | D6: Unité | E6: Formule / Source | F6: Note
C7: Prix EU ETS actuel | D7: 75 | E7: €/tCO2 | F7: Saisie — source EMBER/ICAP | G7: Prix spot avril 2026
C8: Émissions sous EU ETS (tCO2e) | D8: =Liaison_Donnees!C15 | E8: tCO2e | F8: Scope 1 depuis Liaison | G8: Part soumise au marché ETS
C9: Quotas gratuits EU ETS (tCO2e) | D9: 0 | E9: tCO2e | F9: Saisie | G9: En diminution progressive
C10: Exposition nette EU ETS (€) | D10: =IF(D8-D9>0,(D8-D9)*D7,0) | E10: € | F10: (S1 - quotas) × prix | G10: Coût annuel estimé
C11: Coût CBAM estimé (€) | D11: =Liaison_Donnees!C26 | E11: € | F11: Depuis Liaison_Donnees | G11: Taxe carbone importations
C12: EXPOSITION TOTALE CARBONE (€) | D12: =D10+D11 | E12: € | F12: EU ETS + CBAM | G12: Coût carbone direct annuel
A14: B — PROJECTION PRIX CARBONE 2026-2035
C15: CAGR prix carbone estimé (%/an) | D15: 0.08 | E15: %
B16: Année | C16: Prix projeté (€/tCO2) | D16: Émissions S1 projetées (tCO2e) | E16: Exposition projetée (€) | F16: Réduction cumulée SBTi (%)
C17: 2026 | D17: =D7*(1+$D$15)^0 | E17: =IF(Liaison_Donnees!C29>0,Liaison_Donnees!C29*(1-Liaison_Donnees!$C$28/100*0),Liaison_Donnees!C15*(1-Liaison_Donnees!$C$28/100*0)) | F17: =D17*E17 | G17: =Liaison_Donnees!C28*0
C18: 2027 | D18: =D7*(1+$D$15)^1 | E18: =IF(Liaison_Donnees!C29>0,Liaison_Donnees!C29*(1-Liaison_Donnees!$C$28/100*1),Liaison_Donnees!C15*(1-Liaison_Donnees!$C$28/100*1)) | F18: =D18*E18 | G18: =Liaison_Donnees!C28*1
C19: 2028 | D19: =D7*(1+$D$15)^2 | E19: =IF(Liaison_Donnees!C29>0,Liaison_Donnees!C29*(1-Liaison_Donnees!$C$28/100*2),Liaison_Donnees!C15*(1-Liaison_Donnees!$C$28/100*2)) | F19: =D19*E19 | G19: =Liaison_Donnees!C28*2
C20: 2029 | D20: =D7*(1+$D$15)^3 | E20: =IF(Liaison_Donnees!C29>0,Liaison_Donnees!C29*(1-Liaison_Donnees!$C$28/100*3),Liaison_Donnees!C15*(1-Liaison_Donnees!$C$28/100*3)) | F20: =D20*E20 | G20: =Liaison_Donnees!C28*3
C21: 2030 | D21: =D7*(1+$D$15)^4 | E21: =IF(Liaison_Donnees!C29>0,Liaison_Donnees!C29*(1-Liaison_Donnees!$C$28/100*4),Liaison_Donnees!C15*(1-Liaison_Donnees!$C$28/100*4)) | F21: =D21*E21 | G21: =Liaison_Donnees!C28*4
C22: 2031 | D22: =D7*(1+$D$15)^5 | E22: =IF(Liaison_Donnees!C29>0,Liaison_Donnees!C29*(1-Liaison_Donnees!$C$28/100*5),Liaison_Donnees!C15*(1-Liaison_Donnees!$C$28/100*5)) | F22: =D22*E22 | G22: =Liaison_Donnees!C28*5
C23: 2032 | D23: =D7*(1+$D$15)^6 | E23: =IF(Liaison_Donnees!C29>0,Liaison_Donnees!C29*(1-Liaison_Donnees!$C$28/100*6),Liaison_Donnees!C15*(1-Liaison_Donnees!$C$28/100*6)) | F23: =D23*E23 | G23: =Liaison_Donnees!C28*6
C24: 2033 | D24: =D7*(1+$D$15)^7 | E24: =IF(Liaison_Donnees!C29>0,Liaison_Donnees!C29*(1-Liaison_Donnees!$C$28/100*7),Liaison_Donnees!C15*(1-Liaison_Donnees!$C$28/100*7)) | F24: =D24*E24 | G24: =Liaison_Donnees!C28*7
C25: 2034 | D25: =D7*(1+$D$15)^8 | E25: =IF(Liaison_Donnees!C29>0,Liaison_Donnees!C29*(1-Liaison_Donnees!$C$28/100*8),Liaison_Donnees!C15*(1-Liaison_Donnees!$C$28/100*8)) | F25: =D25*E25 | G25: =Liaison_Donnees!C28*8
C26: 2035 | D26: =D7*(1+$D$15)^9 | E26: =IF(Liaison_Donnees!C29>0,Liaison_Donnees!C29*(1-Liaison_Donnees!$C$28/100*9),Liaison_Donnees!C15*(1-Liaison_Donnees!$C$28/100*9)) | F26: =D26*E26 | G26: =Liaison_Donnees!C28*9
C27: Coût carbone cumulé 2026-2035 (€) | D27: =SUM(F17:F26)
A29: C — ROI DES ACTIONS DE DÉCARBONATION
B30: Action / Levier | C30: Investissement (€) | D30: tCO2e évitées/an | E30: Économie énergie (€/an) | F30: ROI climat (€/tCO2e) | G30: Payback (ans)
C31: Rénovation énergétique bâtiments | D31: 0 | E31: 0 | F31: =IF(AND(C31>0,D31>0),(E31+D31*$D$7)/C31,0) | G31: =IF((E31+D31*$D$7)>0,C31/(E31+D31*$D$7),0)
C32: Verdissement flotte véhicules (VE) | D32: 0 | E32: 0 | F32: =IF(AND(C32>0,D32>0),(E32+D32*$D$7)/C32,0) | G32: =IF((E32+D32*$D$7)>0,C32/(E32+D32*$D$7),0)
C33: PPA énergie renouvelable | D33: 0 | E33: 0 | F33: =IF(AND(C33>0,D33>0),(E33+D33*$D$7)/C33,0) | G33: =IF((E33+D33*$D$7)>0,C33/(E33+D33*$D$7),0)
C34: Panneaux solaires autoconsommation | D34: 0 | E34: 0 | F34: =IF(AND(C34>0,D34>0),(E34+D34*$D$7)/C34,0) | G34: =IF((E34+D34*$D$7)>0,C34/(E34+D34*$D$7),0)
C35: Réduction déplacements pro (visio) | D35: 0 | E35: 0 | F35: =IF(AND(C35>0,D35>0),(E35+D35*$D$7)/C35,0) | G35: =IF((E35+D35*$D$7)>0,C35/(E35+D35*$D$7),0)
C36: Télétravail renforcé | D36: 0 | E36: 0 | F36: =IF(AND(C36>0,D36>0),(E36+D36*$D$7)/C36,0) | G36: =IF((E36+D36*$D$7)>0,C36/(E36+D36*$D$7),0)
C37: Engagement fournisseurs SBTi | D37: 0 | E37: 0 | F37: =IF(AND(C37>0,D37>0),(E37+D37*$D$7)/C37,0) | G37: =IF((E37+D37*$D$7)>0,C37/(E37+D37*$D$7),0)
C38: Éco-conception produits | D38: 0 | E38: 0 | F38: =IF(AND(C38>0,D38>0),(E38+D38*$D$7)/C38,0) | G38: =IF((E38+D38*$D$7)>0,C38/(E38+D38*$D$7),0)
C39: Optimisation logistique | D39: 0 | E39: 0 | F39: =IF(AND(C39>0,D39>0),(E39+D39*$D$7)/C39,0) | G39: =IF((E39+D39*$D$7)>0,C39/(E39+D39*$D$7),0)
C40: Économie circulaire | D40: 0 | E40: 0 | F40: =IF(AND(C40>0,D40>0),(E40+D40*$D$7)/C40,0) | G40: =IF((E40+D40*$D$7)>0,C40/(E40+D40*$D$7),0)
C41: =SUM(C31:C40) | D41: =SUM(D31:D40) | E41: =SUM(E31:E40) | F41: =IF(AND(C41>0,D41>0),(E41+D41*$D$7)/C41,0) | G41: =IF((E41+D41*$D$7)>0,C41/(E41+D41*$D$7),0)
A43: D — GREEN CAPEX & ALIGNEMENT ACCORD DE PARIS
B44: Indicateur | C44: Valeur | D44: Unité | E44: Formule | F44: Seuil | G44: Note
...

Sheet DPP_Produits
J1: 🏠 Sommaire
A2: DIGITAL PRODUCT PASSPORT — Product Carbon Footprint (PCF) par produit
A3: Conforme ESPR (EU) 2024/1781 · ISO 14067:2018 · Registre DPP UE opérationnel juillet 2026. Batteries obligatoires fév. 2027.
A5: A — IDENTIFICATION PRODUIT
B6: # | C6: Produit / Référence | D6: GTIN / Code | E6: Catégorie DPP | F6: Masse unitaire (kg) | G6: Pays fabrication | H6: Durée vie (ans) | I6: Unité fonctionnelle | J6: Nb unités/an
B7: 1
B8: 2
B9: 3
B10: 4
B11: 5
B12: 6
B13: 7
B14: 8
A16: B — CALCUL EMPREINTE CARBONE PAR PRODUIT (kgCO2e / unité)
C17: Phase cycle de vie | D17: Donnée d'activité | E17: Unité | F17: Facteur émission | G17: Unité FE | H17: Émissions (kgCO2e) | I17: % du total | J17: Source FE
C18: Matières premières (extraction) | D18: 0 | E18: kg | F18: 0 | G18: kgCO2e/kg | H18: =D18*F18 | I18: =IF(H24>0,H18/H24*100,0)
C19: Fabrication (process + énergie) | D19: 0 | E19: kWh | F19: 0 | G19: kgCO2e/kWh | H19: =D19*F19 | I19: =IF(H24>0,H19/H24*100,0)
C20: Transport amont (matières → usine) | D20: 0 | E20: t.km | F20: 0 | G20: kgCO2e/t.km | H20: =D20*F20 | I20: =IF(H24>0,H20/H24*100,0)
C21: Distribution (usine → client) | D21: 0 | E21: t.km | F21: 0 | G21: kgCO2e/t.km | H21: =D21*F21 | I21: =IF(H24>0,H21/H24*100,0)
C22: Phase d'usage (énergie consommée) | D22: 0 | E22: kWh | F22: 0 | G22: kgCO2e/kWh | H22: =D22*F22 | I22: =IF(H24>0,H22/H24*100,0)
C23: Fin de vie (traitement déchets) | D23: 0 | E23: kg | F23: 0 | G23: kgCO2e/kg | H23: =D23*F23 | I23: =IF(H24>0,H23/H24*100,0)
C24: TOTAL PCF PRODUIT 1 | H24: =SUM(H18:H23)
A26: C — DONNÉES DPP À DÉCLARER (ESPR Art. 7-10)
C27: Donnée DPP | D27: Valeur | E27: Unité | F27: Obligatoire | G27: Réf. ESPR | H27: Source | I27: Statut
D28: PCF total (kgCO2e/unité) | E28: =H24 | F28: kgCO2e | G28: Oui | H28: Art. 7(2)(c) | I28: Calcul auto | J28: =IF(E28<>"","✓","⬜")
D29: Classe d'empreinte carbone | E29: =IF(H24<5,"A",IF(H24<20,"B",IF(H24<50,"C",IF(H24<100,"D","E")))) | F29: A-E | G29: Oui | H29: Art. 7(2)(c) | I29: Calcul auto | J29: =IF(E29<>"","✓","⬜")
D30: % contenu recyclé | F30: % | G30: Oui | H30: Art. 7(2)(b) | I30: Saisie | J30: =IF(E30<>"","✓","⬜")
D31: Durabilité / durée de vie estimée | F31: ans | G31: Oui | H31: Art. 7(2)(d) | I31: Saisie | J31: =IF(E31<>"","✓","⬜")
D32: Score de réparabilité (1-10) | F32: Score | G32: Si applicable | H32: Art. 7(2)(e) | I32: Saisie | J32: =IF(E32<>"","✓","⬜")
D33: Substances préoccupantes (SVHC) | F33: O/N | G33: Oui | H33: Art. 7(2)(a) | I33: Saisie | J33: =IF(E33<>"","✓","⬜")
D34: Instructions de recyclage | F34: Texte | G34: Oui | H34: Art. 7(2)(f) | I34: Saisie | J34: =IF(E34<>"","✓","⬜")
D35: Pays de fabrication | F35: Pays | G35: Oui | H35: Art. 7(2) | I35: Saisie | J35: =IF(E35<>"","✓","⬜")
D36: Identifiant unique DPP (UUID) | F36: UUID | G36: Oui | H36: Art. 9 | I36: Généré auto | J36: =IF(E36<>"","✓","⬜")
D37: URL data carrier (QR code) | F37: URL | G37: Oui | H37: Art. 10 | I37: Généré auto | J37: =IF(E37<>"","✓","⬜")
B39: ℹ️ Reproduire les sections B et C pour chaque produit. Le registre DPP européen ouvre en juillet 2026. Batteries : obligations DPP dès février 2027.

Sheet Benchmark
J1: 🏠 Sommaire
A2: BENCHMARK SECTORIEL — Positionnement vs médianes ADEME / marché
A3: Comparez vos KPIs carbone et ESG aux médianes et top 25% de votre secteur. Source : ADEME Base Carbone, INSEE, EFRAG 2024.
B5: ⚙️ Votre secteur (Code NAF 2 chiffres) : | D5: 62 | E5: Saisir le code NAF 2 chiffres (ex: 62 = Services IT)
B7: Indicateur | C7: Votre valeur | D7: Votre valeur | E7: Médiane secteur | F7: Top 25% | G7: Écart vs médiane (%) | H7: Position
C8: Intensité carbone / CA (tCO2e/M€) | D8: =Liaison_Donnees!C20 | E8: =IFERROR(INDEX(_Ref_Secteurs!D5:D20,MATCH(D5*1,_Ref_Secteurs!B5:B20,0)),"-") | F8: =IFERROR(INDEX(_Ref_Secteurs!E5:E20,MATCH(D5*1,_Ref_Secteurs!B5:B20,0)),"-") | G8: =IF(AND(ISNUMBER(D8),ISNUMBER(E8),E8>0),(D8-E8)/E8*100,"-") | H8: =IF(AND(ISNUMBER(D8),ISNUMBER(F8)),IF(D8<=F8,"⭐ Leader",IF(D8<=E8,"✅ Bon","⚠️ À améliorer")),IF(ISNUMBER(D8),IF(D8<=E8,"✅ Bon","⚠️"),"-"))
C9: Intensité carbone / ETP (tCO2e/ETP) | D9: =IF(Liaison_Donnees!C10>0,Liaison_Donnees!C19/Liaison_Donnees!C10,0) | E9: =IFERROR(INDEX(_Ref_Secteurs!F5:F20,MATCH(D5*1,_Ref_Secteurs!B5:B20,0)),"-") | F9: =IFERROR(INDEX(_Ref_Secteurs!E5:E20,MATCH(D5*1,_Ref_Secteurs!B5:B20,0)),"-") | G9: =IF(AND(ISNUMBER(D9),ISNUMBER(E9),E9>0),(D9-E9)/E9*100,"-") | H9: =IF(AND(ISNUMBER(D9),ISNUMBER(F9)),IF(D9<=F9,"⭐ Leader",IF(D9<=E9,"✅ Bon","⚠️ À améliorer")),IF(ISNUMBER(D9),IF(D9<=E9,"✅ Bon","⚠️"),"-"))
C10: Part Scope 3 / total (%) | D10: =Liaison_Donnees!C21 | E10: =IFERROR(INDEX(_Ref_Secteurs!G5:G20,MATCH(D5*1,_Ref_Secteurs!B5:B20,0)),"-") | F10: — | G10: =IF(AND(ISNUMBER(D10),ISNUMBER(E10),E10>0),(D10-E10)/E10*100,"-") | H10: =IF(AND(ISNUMBER(D10),ISNUMBER(F10)),IF(D10<=F10,"⭐ Leader",IF(D10<=E10,"✅ Bon","⚠️ À améliorer")),IF(ISNUMBER(D10),IF(D10<=E10,"✅ Bon","⚠️"),"-"))
C11: Part énergie renouvelable (%) | D11: =Liaison_Donnees!C23 | E11: =IFERROR(INDEX(_Ref_Secteurs!H5:H20,MATCH(D5*1,_Ref_Secteurs!B5:B20,0)),"-") | F11: — | G11: =IF(AND(ISNUMBER(D11),ISNUMBER(E11),E11>0),(D11-E11)/E11*100,"-") | H11: =IF(ISNUMBER(D11),IF(D11>=50,"⭐ Leader",IF(D11>=E11,"✅ Bon","⚠️ À améliorer")),"-")
C12: % CA aligné Taxonomie | D12: =Liaison_Donnees!C24 | E12: — | F12: — | G12: — | H12: =IF(ISNUMBER(D12),IF(D12>=30,"✅ Bon","⚠️ À améliorer"),"-")
C13: Green CapEx ratio (%) | D13: =Finance_Climat!D50 | E13: — | F13: — | G13: — | H13: =IF(ISNUMBER(D13),IF(D13>=30,"✅ Bon","⚠️ À améliorer"),"-")
B16: SYNTHÈSE POSITIONNEMENT
B17: Secteur identifié | D17: =IFERROR(INDEX(_Ref_Secteurs!C5:C20,MATCH(D5*1,_Ref_Secteurs!B5:B20,0)),"Secteur non trouvé")
B18: Nb indicateurs en position Leader/Bon | D18: =COUNTIF(H8:H13,"⭐*")+COUNTIF(H8:H13,"✅*")
B19: Nb indicateurs à améliorer | D19: =COUNTIF(H8:H13,"⚠️*")

Sheet SFDR_Report
J1: 🏠 Sommaire
A2: SFDR — PRINCIPAL ADVERSE IMPACTS (PAI) POUR INVESTISSEURS
A3: Règlement (UE) 2019/2088 révisé (accord déc. 2025). 3 catégories de fonds : Transition, ESG de base, Durable. Seuil 70% actifs conformes.
A5: INDICATEURS PAI OBLIGATOIRES — Tableau 1 Annexe I RTS SFDR
B6: PAI # | C6: Indicateur | D6: Valeur | E6: Unité | F6: Cat. fonds | G6: Source / Formule
C7: 1 | D7: Émissions GES totales (S1+S2+S3) | E7: =Liaison_Donnees!C19 | F7: tCO2e | G7: Tous | H7: Synthese_GES
C8: 2 | D8: Empreinte carbone (tCO2e/M€ CA) | E8: =Liaison_Donnees!C20 | F8: tCO2e/M€ | G8: Tous | H8: Calcul auto
C9: 3 | D9: Intensité GES des entreprises bénéficiaires | E9: =IF(Liaison_Donnees!C9>0,Liaison_Donnees!C19/Liaison_Donnees!C9*1000000,0) | F9: tCO2e/M€ | G9: Tous | H9: GES / CA × 1M
C10: 4 | D10: Exposition aux entreprises actives dans les combustibles fossiles | E10: 0 | F10: % | G10: Durable | H10: Saisie — % CA lié fossiles
C11: 5 | D11: Part énergie non renouvelable (production + conso) | E11: =IF(Liaison_Donnees!C23<>"",100-Liaison_Donnees!C23,100) | F11: % | G11: Transition | H11: 100% - Part ENR
C12: 6 | D12: Intensité de consommation énergétique par secteur à fort impact | E12: =0 | F12: MWh/M€ | G12: Transition | H12: Énergie / CA
C13: 7 | D13: Activités avec impact négatif sur zones sensibles biodiversité | F13: O/N | G13: Durable | H13: Saisie
C14: 8 | D14: Rejets dans l'eau | E14: 0 | F14: tonnes | G14: Durable | H14: Saisie
C15: 9 | D15: Ratio déchets dangereux / total déchets | E15: 0 | F15: % | G15: Durable | H15: Saisie
C16: 10 | D16: Violations principes UNGC et OCDE | E16: 0 | F16: Nb | G16: Tous | H16: Saisie — 0 si aucune
C17: 11 | D17: Absence de processus et mécanismes de conformité UNGC/OCDE | F17: O/N | G17: Tous | H17: Saisie
C18: 12 | D18: Écart de rémunération H/F non ajusté | E18: 0 | F18: % | G18: ESG de base | H18: Depuis ESRS_S1 si dispo
C19: 13 | D19: Diversité de genre au sein des organes de gouvernance | E19: 0 | F19: % | G19: ESG de base | H19: Depuis ESRS_G1 si dispo
C20: 14 | D20: Exposition à des armes controversées | F20: O/N | G20: Tous | H20: Saisie — NON si aucune
A22: ALIGNEMENT TAXONOMIE POUR CLASSIFICATION SFDR
A23: KPI Taxonomie | D23: Éligible (%) | E23: Aligné (%) | F23: Seuil fonds Durable | G23: Statut
D24: Chiffre d'affaires | E24: =Liaison_Donnees!C24 | F24: 70 | G24: ≥ 70% | H24: =IF(ISNUMBER(E24),IF(E24>=F24,"✅ Éligible Durable",IF(E24>=30,"⚠️ Transition","❌ Non classifiable")),"-")
D25: CapEx | E25: =Liaison_Donnees!C25 | F25: 70 | G25: ≥ 70% | H25: =IF(ISNUMBER(E25),IF(E25>=F25,"✅ Éligible Durable",IF(E25>=30,"⚠️ Transition","❌ Non classifiable")),"-")
D26: OpEx | E26: 0 | F26: 70 | G26: ≥ 70% | H26: =IF(ISNUMBER(E26),IF(E26>=F26,"✅ Éligible Durable",IF(E26>=30,"⚠️ Transition","❌ Non classifiable")),"-")
A29: SCORECARD ESG INVESTISSEURS
C30: Score ESG consolidé | E30: =(COUNTIF(E7:E20,">0")+COUNTIF(E7:E20,"<0")+COUNTIFS(E7:E20,"<>",E7:E20,"<>0",E7:E20,">=A"))/14*50+IF(Liaison_Donnees!C24>30,25,Liaison_Donnees!C24/30*25)+IF(Liaison_Donnees!C28>=4.2,25,Liaison_Donnees!C28/4.2*25) | F30: / 100
C31: Note | E31: =IF(E30>=80,"A+",IF(E30>=70,"A",IF(E30>=60,"B+",IF(E30>=50,"B",IF(E30>=40,"C","D")))))
C32: Composantes du score | E32: 50% complétude PAI + 25% alignement Taxonomie + 25% trajectoire SBTi

Sheet _Ref_Secteurs
A1: TABLE DE RÉFÉRENCE SECTORIELLE — Benchmarks ADEME / INSEE / Moyennes marché | J1: 🏠 Sommaire
A2: Sources : ADEME Base Carbone 2024, INSEE Stats sectorielles 2024, EFRAG sector benchmarks. Mise à jour : avril 2026.
B4: Code NAF | C4: Secteur | D4: Intensité médiane (tCO2e/M€) | E4: Top 25% (tCO2e/M€) | F4: Intensité / ETP médiane | G4: Part S3 médiane (%) | H4: Part ENR médiane (%)
B5: 62 | C5: Services informatiques / ESN | D5: 12 | E5: 6 | F5: 2.1 | G5: 78 | H5: 35
B6: 64 | C6: Services financiers / Banque | D6: 8 | E6: 4 | F6: 1.5 | G6: 85 | H6: 40
B7: 46 | C7: Commerce de gros | D7: 35 | E7: 18 | F7: 4.5 | G7: 72 | H7: 20
B8: 47 | C8: Commerce de détail | D8: 28 | E8: 15 | F8: 3.2 | G8: 68 | H8: 22
B9: 10 | C9: Industrie alimentaire | D9: 120 | E9: 65 | F9: 8.5 | G9: 82 | H9: 15
B10: 20 | C10: Industrie chimique | D10: 180 | E10: 95 | F10: 15 | G10: 75 | H10: 12
B11: 24 | C11: Métallurgie | D11: 250 | E11: 130 | F11: 22 | G11: 60 | H11: 10
B12: 29 | C12: Industrie automobile | D12: 85 | E12: 45 | F12: 9 | G12: 80 | H12: 18
B13: 35 | C13: Production énergie | D13: 320 | E13: 150 | F13: 35 | G13: 45 | H13: 55
B14: 41 | C14: Construction | D14: 65 | E14: 35 | F14: 7 | G14: 70 | H14: 8
B15: 49 | C15: Transport terrestre | D15: 95 | E15: 50 | F15: 12 | G15: 65 | H15: 5
B16: 51 | C16: Transport aérien | D16: 450 | E16: 250 | F16: 55 | G16: 40 | H16: 2
... B20: 86 | C20: Activités de santé | D20: 25 | E20: 13 | F20: 3.5 | G20: 65 | H20: 20

Sheet Controles_QC
J1: 🏠 Sommaire
A2: CONTRÔLES QUALITÉ AUTOMATIQUES — FINANCE, DPP & INVESTISSEURS
A3: 12 contrôles automatiques. ✓ = OK | ✗ = Erreur | ⚠ = Avertissement
B5: SYNTHÈSE | C5: =COUNTIF(G9:G20,"✓ OK") | D5: ✓ OK | E5: =COUNTIF(G9:G20,"⚠ Alerte") | F5: Alertes ⚠
C6: =COUNTIF(G9:G20,"✗ ERREUR") | D6: ✗ ERREUR
B8: ID | C8: Contrôle | D8: Règle | E8: Criticité | F8: Statut | G8: Action
C9: F-01 | D9: Liaison CA renseigné | E9: CA > 0 dans Liaison_Donnees | F9: Bloquant | G9: =IF(Liaison_Donnees!C9>0,"✓ OK","✗ ERREUR")
C10: F-02 | D10: Liaison GES renseigné | E10: Total S1+S2+S3 > 0 | F10: Bloquant | G10: =IF(Liaison_Donnees!C19>0,"✓ OK","✗ ERREUR")
C11: F-03 | D11: Prix EU ETS défini | E11: Prix carbone > 0 dans Finance_Climat | F11: Avert. | G11: =IF(Finance_Climat!D7>0,"✓ OK","⚠ Alerte")
C12: F-04 | D12: Au moins 1 action climat | E12: Total investissement > 0 | F12: Avert. | G12: =IF(Finance_Climat!D41>0,"✓ OK","⚠ Alerte")
C13: F-05 | D13: Green CapEx ratio > 10% | E13: Minimum pour trajectoire | F13: Avert. | G13: =IF(Finance_Climat!D50>=10,"✓ OK","⚠ Alerte")
C14: F-06 | D14: CapEx total renseigné | E14: Dénominateur Green CapEx | F14: Bloquant | G14: =IF(Liaison_Donnees!C12>0,"✓ OK","✗ ERREUR")
C15: F-07 | D15: Au moins 1 produit DPP | E15: Section A DPP renseignée | F15: Avert. | G15: =IF(DPP_Produits!C7<>"","✓ OK","⚠ Alerte")
C16: F-08 | D16: PCF calculé > 0 | E16: Empreinte produit 1 calculée | F16: Avert. | G16: =IF(DPP_Produits!H24>0,"✓ OK","⚠ Alerte")
C17: F-09 | D17: Secteur benchmark défini | E17: Code NAF saisi dans Benchmark | F17: Avert. | G17: =IF(Benchmark!D5<>"","✓ OK","⚠ Alerte")
C18: F-10 | D18: PAI 1-3 SFDR renseignés | E18: GES totales pour investisseurs | F18: Bloquant | G18: =IF(AND(SFDR_Report!E7>0,SFDR_Report!E8>0,SFDR_Report!E9>0),"✓ OK","✗ ERREUR")
C19: F-11 | D19: PAI 10 UNGC renseigné | E19: Violations principes obligatoire | F19: Avert. | G19: =IF(SFDR_Report!E16<>"","✓ OK","⚠ Alerte")
C20: F-12 | D20: Score ESG > 40/100 | E20: Minimum crédibilité investisseur | F20: Avert. | G20: =IF(SFDR_Report!E30>40,"✓ OK","⚠ Alerte")
