Workbook
Name CA_AURELE: '01_PARAMETRES'!$B$56:$B$62
Name CA_Entites: '01_PARAMETRES'!$A$56:$A$62
Name CA_IMPERIAL: '01_PARAMETRES'!$C$56:$C$62
Name CA_STELLAIRE: '01_PARAMETRES'!$D$56:$D$62
Name CA_TOTAL: '01_PARAMETRES'!$E$56:$E$62
Name Comp_Taux: '04_BENCHMARK_ALP'!$E$7:$E$16
Name Entites_ActifsCorp: '01_PARAMETRES'!$I$22:$I$29
Name Entites_Detention: '01_PARAMETRES'!$G$22:$G$29
Name Entites_Devise: '01_PARAMETRES'!$C$22:$C$29
Name Entites_MasseSal: '01_PARAMETRES'!$H$22:$H$29
Name Entites_Noms: '01_PARAMETRES'!$A$22:$A$29
Name Entites_Pays: '01_PARAMETRES'!$B$22:$B$29
Name Entites_TauxIS: '01_PARAMETRES'!$D$22:$D$29
Name FX_Cloture: '01_PARAMETRES'!$B$33:$B$38
Name FX_Devises: '01_PARAMETRES'!$A$33:$A$38
Name FX_Mars2026: '01_PARAMETRES'!$D$33:$D$38
Name FX_Moyen: '01_PARAMETRES'!$C$33:$C$38
Name GrandTotal_CA: '03_CALCUL_ROYALTIES'!$B$70
Name GrandTotal_Royalty: '03_CALCUL_ROYALTIES'!$F$70
Name IQR_Mediane: '04_BENCHMARK_ALP'!$B$22
Name IQR_Q1: '04_BENCHMARK_ALP'!$B$21
Name IQR_Q3: '04_BENCHMARK_ALP'!$B$23
Name Marques_Noms: '01_PARAMETRES'!$A$42:$A$44
Name Marques_Taux: '01_PARAMETRES'!$C$42:$C$44
Name Recap_CA_Total: '03_CALCUL_ROYALTIES'!$B$63:$B$69
Name Recap_Entites: '03_CALCUL_ROYALTIES'!$A$63:$A$69
Name Recap_RoyaltyTotal: '03_CALCUL_ROYALTIES'!$F$63:$F$69
Name Saisonnalite_Q1: '01_PARAMETRES'!$B$48
Name Saisonnalite_Q2: '01_PARAMETRES'!$B$49
Name Saisonnalite_Q3: '01_PARAMETRES'!$B$50
Name Saisonnalite_Q4: '01_PARAMETRES'!$B$51
Name TauxIS_FR: '01_PARAMETRES'!$D$22
Name TauxRoyalty_AURELE: '01_PARAMETRES'!$C$42
Name TauxRoyalty_IMPERIAL: '01_PARAMETRES'!$C$43
Name TauxRoyalty_STELLAIRE: '01_PARAMETRES'!$C$44
Name WHT_Pays: '01_PARAMETRES'!$A$67:$A$73
Name WHT_TauxEffectif: '01_PARAMETRES'!$F$67:$F$73
Name WHT_Total: '06_RETENUES_SOURCE'!$H$14

Sheet Claude Log
A1: Turn # | B1: Date | C1: User Request | D1: Action Taken | E1: Details | F1: Outcome
A2: 1 | B2: 46113 | C2: Analyse de diagnostic reçue (15 feuilles, 4 problèmes structurants identifiés) — demande d'application des corrections | D2: 7 groupes de corrections appliquées sur 6 feuilles : 08_PILIER2_GLOBE, 11_CONTROLES, 03_CALCUL_ROYALTIES, 06_RETENUES_SOURCE, 14_STRESS_TEST, 10_DASHBOARD, 15_VALORISATION_MARQUES | E2: 08_PILIER2: 50 formules injectées (XLOOKUP+plages nommées, ligne totaux) | 11_CONTROLES: bug E7 corrigé (=C14-D14→=C7-D7), E8:E10 ajoutés, E12 dynamique | 03_CALCUL: 21 récap remplacés par INDEX(CA_AURELE,...)*TauxRoyalty, 7 XLOOKUP FX, 7 LET() écart conversion | 06_WHT: 7 cellules $D$22→TauxIS_FR | 14_STRESS: 7 taux FX XLOOKUP dynamiques | Dashboard: B10→WHT_Total, B11 COUNTIF, E11/E14 dynamiques, B28:B30 formules, 6 nouveaux KPIs lignes 15-20 | 15_VALO: WACC+taux croissance+perp. balisés bleu+jaune+notes sources Damodaran | F2: ✅ Toutes corrections vérifiées — valeurs identiques aux hardcodes originaux. 08_PILIER2 fonctionnel. ETR EAU 9%→top-up 333 k€ visible. Dashboard affiche 14 KPIs dynamiques. Aucune régression.

Sheet 01_PARAMETRES
A1: ⚙️ PARAMÈTRES GÉNÉRAUX — SOURCE UNIQUE
A2: Configuration groupe · Entités · Devises · Taux · Plages nommées
A3: NEURAL — Intelligence Augmentée · Agent RoyaltyAccounting · Mars 2026
A5: A · INFORMATIONS GROUPE
A6: Nom du groupe | B6: NEURAL Luxe Group
A7: Entité IP Owner | B7: NEURAL Luxe Holding SAS
A8: Siège social IP | B8: Paris, France
A9: Exercice fiscal | B9: 01/01/2025 — 31/12/2025
A10: Date d'arrêté | B10: 31/12/2025
A11: Devise de reporting | B11: EUR (€)
A12: Référentiel comptable | B12: IFRS (tel qu'adopté par l'UE)
A13: Normes TP appliquées | B13: OCDE — Principes prix de transfert 2022 + Pilier 1 Amount B
A14: Pilier 2 GloBE | B14: Applicable — ETR minimum 15% par juridiction
A15: Seuil Pilier 2 | B15: ≥ 750 M€ sur 2 des 4 exercices précédents
A16: CSRD / ESRS | B16: Applicable — Reporting durabilité intégré
A17: Public CbCR (UE) | B17: Applicable — Directive transposée FY ≥ juin 2024
A18: ⚠️ MAJ Mars 2026 | B18: IS Japon actualisé à 31.52% · Taux de change BCE mars 2026
A20: B · PÉRIMÈTRE DES ENTITÉS
A21: Entité | B21: Pays | C21: Devise | D21: Taux IS effectif | E21: Rôle dans le groupe | F21: Drapeau | G21: % détention | H21: Masse salariale (k€) | I21: Actifs corporels (k€) | J21: WHT domestique | K21: WHT conventionnel
A22: NEURAL Luxe Holding | B22: France | C22: EUR | D22: 0.2573 | E22: IP Owner / Licencieur | F22: FR | G22: 1 | H22: 18500 | I22: 12000 | J22: 0 | K22: 0
A23: Maison Aurèle Paris | B23: France | C23: EUR | D23: 0.2573 | E23: Production & Retail | F23: FR | G23: 1 | H23: 42000 | I23: 35000 | J23: 0.2573 | K23: 0
A24: Maison Aurèle Italia | B24: Italie | C24: EUR | D24: 0.2764 | E24: Distribution Italie | F24: IT | G24: 1 | H24: 15000 | I24: 8500 | J24: 0.3 | K24: 0
A25: Maison Aurèle Japan | B25: Japon | C25: JPY | D25: 0.3152 | E25: Distribution Japon | F25: JP | G25: 1 | H25: 22000 | I25: 14000 | J25: 0.2042 | K25: 0.1
A26: Maison Aurèle USA | B26: États-Unis | C26: USD | D26: 0.21 | E26: Distribution Amériques | F26: US | G26: 1 | H26: 28000 | I26: 20000 | J26: 0.3 | K26: 0
A27: Maison Aurèle UK | B27: Royaume-Uni | C27: GBP | D27: 0.25 | E27: Distribution UK | F27: GB | G27: 1 | H27: 12000 | I27: 7500 | J27: 0.2 | K27: 0
A28: Maison Aurèle China | B28: Chine (HK) | C28: HKD | D28: 0.165 | E28: Distribution Asie | F28: HK | G28: 0.8 | H28: 25000 | I28: 18000 | J28: 0.0825 | K28: 0.06
A29: Maison Aurèle ME | B29: EAU (Dubaï) | C29: AED | D29: 0.09 | E29: Distribution Moyen-Orient | F29: AE | G29: 1 | H29: 8000 | I29: 5500 | J29: 0 | K29: 0
A31: C · TAUX DE CHANGE (FY2025 clôture + Mars 2026 BCE)
A32: Devise | B32: Taux clôture 31/12/2025 | C32: Taux moyen FY2025 | D32: Taux BCE Mars 2026 | E32: Variation | F32: Source
A33: EUR | B33: 1 | C33: 1 | D33: 1 | E33: 0 | F33: BCE / Bloomberg / Trading Economics
A34: USD | B34: 0.9174 | C34: 0.9259 | D34: 0.8702 | E34: -0.051449749 | F34: BCE / Bloomberg / Trading Economics
A35: GBP | B35: 1.1628 | C35: 1.1494 | D35: 1.1546 | E35: -0.0070519436 | F35: BCE / Bloomberg / Trading Economics
A36: JPY | B36: 0.00617 | C36: 0.00625 | D36: 0.00547 | E36: -0.11345219 | F36: BCE / Bloomberg / Trading Economics
A37: HKD | B37: 0.1176 | C37: 0.119 | D37: 0.1241 | E37: 0.055272109 | F37: BCE / Bloomberg / Trading Economics
A38: AED | B38: 0.2498 | C38: 0.2525 | D38: 0.237 | E38: -0.051240993 | F38: BCE / Bloomberg / Trading Economics
A40: D · MARQUES LICENCIÉES — TAUX DE ROYALTY (source unique)
A41: Marque | B41: Segment | C41: Taux de royalty | D41: Base de calcul | E41: Propriétaire IP
A42: AURÈLE | B42: Haute Couture & Prêt-à-porter | C42: 0.05 | D42: CA net HT | E42: NEURAL Luxe Holding
A43: IMPÉRIAL | B43: Maroquinerie & Accessoires | C43: 0.045 | D43: CA net HT | E43: NEURAL Luxe Holding
A44: STELLAIRE | B44: Joaillerie & Horlogerie | C44: 0.06 | D44: CA net HT | E44: NEURAL Luxe Holding
...

Sheet 02_CONTRATS_LICENCES
A1: 📋 REGISTRE DES CONTRATS DE LICENCE
A2: Accords de licence de marque intragroupe — Taux liés à 01_PARAMETRES
A3: NEURAL — Intelligence Augmentée · Agent RoyaltyAccounting · Mars 2026
A5: A · CONTRATS DE LICENCE DE MARQUE EN VIGUEUR
A6: N° | B6: Licencieur | C6: Licencié | D6: Marque | E6: Taux (%) | F6: Base | G6: Date début | H6: Date fin | I6: Droit applicable | J6: Clause particulière
A7: LIC-2023-001 | B7: NEURAL Luxe Holding | C7: Maison Aurèle Paris | D7: AURÈLE | E7: =IFERROR(INDEX('01_PARAMETRES'!$C$42:$C$44,MATCH(D7,'01_PARAMETRES'!$A$42:$A$44,0)),"N/A") -> 0.05 | F7: CA net HT | G7: 01/01/2023 | H7: 31/12/2027 | I7: Droit français | J7: Minimum garanti : 1 500 k€/an
A8: LIC-2023-002 | B8: NEURAL Luxe Holding | C8: Maison Aurèle Paris | D8: IMPÉRIAL | E8: =IFERROR(INDEX('01_PARAMETRES'!$C$42:$C$44,MATCH(D8,'01_PARAMETRES'!$A$42:$A$44,0)),"N/A") -> 0.045 | F8: CA net HT | G8: 01/01/2023 | H8: 31/12/2027 | I8: Droit français | J8: Clause d'ajustement annuel ALP
A9: LIC-2023-003 | B9: NEURAL Luxe Holding | C9: Maison Aurèle Paris | D9: STELLAIRE | E9: =IFERROR(INDEX('01_PARAMETRES'!$C$42:$C$44,MATCH(D9,'01_PARAMETRES'!$A$42:$A$44,0)),"N/A") -> 0.06 | F9: CA net HT | G9: 01/01/2023 | H9: 31/12/2027 | I9: Droit français | J9: Incluant savoir-faire joaillier
A10: LIC-2023-004 | B10: NEURAL Luxe Holding | C10: Maison Aurèle Italia | D10: AURÈLE | E10: =IFERROR(INDEX('01_PARAMETRES'!$C$42:$C$44,MATCH(D10,'01_PARAMETRES'!$A$42:$A$44,0)),"N/A") -> 0.05 | F10: CA net HT | G10: 01/01/2023 | H10: 31/12/2027 | I10: Droit français | J10: Arbitrage ICC Paris
A11: LIC-2023-005 | B11: NEURAL Luxe Holding | C11: Maison Aurèle Italia | D11: IMPÉRIAL | E11: =IFERROR(INDEX('01_PARAMETRES'!$C$42:$C$44,MATCH(D11,'01_PARAMETRES'!$A$42:$A$44,0)),"N/A") -> 0.045 | F11: CA net HT | G11: 01/01/2023 | H11: 31/12/2027 | I11: Droit français | J11: Arbitrage ICC Paris
A12: LIC-2023-006 | B12: NEURAL Luxe Holding | C12: Maison Aurèle Italia | D12: STELLAIRE | E12: =IFERROR(INDEX('01_PARAMETRES'!$C$42:$C$44,MATCH(D12,'01_PARAMETRES'!$A$42:$A$44,0)),"N/A") -> 0.06 | F12: CA net HT | G12: 01/01/2023 | H12: 31/12/2027 | I12: Droit français | J12: Arbitrage ICC Paris
A13: LIC-2023-007 | B13: NEURAL Luxe Holding | C13: Maison Aurèle Japan | D13: AURÈLE | E13: =IFERROR(INDEX('01_PARAMETRES'!$C$42:$C$44,MATCH(D13,'01_PARAMETRES'!$A$42:$A$44,0)),"N/A") -> 0.05 | F13: CA net HT | G13: 01/01/2023 | H13: 31/12/2027 | I13: Droit français | J13: WHT réduit convention FR-JP
A14: LIC-2023-008 | B14: NEURAL Luxe Holding | C14: Maison Aurèle Japan | D14: IMPÉRIAL | E14: =IFERROR(INDEX('01_PARAMETRES'!$C$42:$C$44,MATCH(D14,'01_PARAMETRES'!$A$42:$A$44,0)),"N/A") -> 0.045 | F14: CA net HT | G14: 01/01/2023 | H14: 31/12/2027 | I14: Droit français | J14: WHT réduit convention FR-JP
A15: LIC-2023-009 | B15: NEURAL Luxe Holding | C15: Maison Aurèle Japan | D15: STELLAIRE | E15: =IFERROR(INDEX('01_PARAMETRES'!$C$42:$C$44,MATCH(D15,'01_PARAMETRES'!$A$42:$A$44,0)),"N/A") -> 0.06 | F15: CA net HT | G15: 01/01/2023 | H15: 31/12/2027 | I15: Droit français | J15: WHT réduit convention FR-JP
A16: LIC-2023-010 | B16: NEURAL Luxe Holding | C16: Maison Aurèle USA | D16: AURÈLE | E16: =IFERROR(INDEX('01_PARAMETRES'!$C$42:$C$44,MATCH(D16,'01_PARAMETRES'!$A$42:$A$44,0)),"N/A") -> 0.05 | F16: CA net HT | G16: 01/01/2023 | H16: 31/12/2027 | I16: Droit français | J16: WHT 0% convention FR-US
A17: LIC-2023-011 | B17: NEURAL Luxe Holding | C17: Maison Aurèle USA | D17: IMPÉRIAL | E17: =IFERROR(INDEX('01_PARAMETRES'!$C$42:$C$44,MATCH(D17,'01_PARAMETRES'!$A$42:$A$44,0)),"N/A") -> 0.045 | F17: CA net HT | G17: 01/01/2023 | H17: 31/12/2027 | I17: Droit français | J17: WHT 0% convention FR-US
A18: LIC-2023-012 | B18: NEURAL Luxe Holding | C18: Maison Aurèle USA | D18: STELLAIRE | E18: =IFERROR(INDEX('01_PARAMETRES'!$C$42:$C$44,MATCH(D18,'01_PARAMETRES'!$A$42:$A$44,0)),"N/A") -> 0.06 | F18: CA net HT | G18: 01/01/2023 | H18: 31/12/2027 | I18: Droit français | J18: WHT 0% convention FR-US
... A27: LIC-2024-021 | B27: NEURAL Luxe Holding | C27: Maison Aurèle ME | D27: STELLAIRE | E27: =IFERROR(INDEX('01_PARAMETRES'!$C$42:$C$44,MATCH(D27,'01_PARAMETRES'!$A$42:$A$44,0)),"N/A") -> 0.06 | F27: CA net HT | G27: 01/01/2024 | H27: 31/12/2028 | I27: Droit français | J27: IS 9% EAU (depuis juin 2023)
A29: B · CLAUSES CONTRACTUELLES CLÉS
A30: Objet | B30: Licence non exclusive d'utilisation de la marque pour la fabrication, distribution et vente de produits de luxe
A31: Base de calcul | B31: Chiffre d'affaires net hors taxes (après retours, avoirs et remises) réalisé sur les produits portant la marque licenciée
A32: Périodicité | B32: Trimestriel, dans les 30 jours suivant la fin du trimestre civil
A33: Clause d'audit | B33: Le licencieur peut diligenter un audit annuel des comptes du licencié
A34: Clause ALP | B34: Révision annuelle du taux sur base d'une étude de comparables (cf. 04_BENCHMARK)
A35: Propriété intellectuelle | B35: Le licencieur conserve l'intégralité des droits de PI
A36: Sous-licence | B36: Interdite sauf accord écrit préalable
A37: Résiliation | B37: Préavis 12 mois. Résiliation immédiate en cas de manquement grave
A38: Substance (ATAD III) | B38: Le licencié dispose de personnel qualifié, locaux dédiés et pouvoir décisionnel effectif (cf. 13_SUBSTANCE)
A40: 📌 Les taux (colonne E) sont des formules XLOOKUP liées à 01_PARAMETRES Section D. Modifier là-bas = propagation automatique.

Sheet 03_CALCUL_ROYALTIES
A1: 💰 CALCUL DES REDEVANCES — 100% DYNAMIQUE
A2: Formules liées à 01_PARAMETRES · CA × Taux × Saisonnalité — FY2025 (k€)
A3: NEURAL — Intelligence Augmentée · Agent RoyaltyAccounting · Mars 2026
A5: 📍 Maison Aurèle Paris
A6: Marque | B6: Taux royalty | C6: CA annuel (k€) | D6: Q1 (k€) | E6: Q2 (k€) | F6: Q3 (k€) | G6: Q4 (k€) | H6: Royalty Q1 | I6: Royalty Q2 | J6: Royalty Q3 | K6: Royalty Q4
A7: AURÈLE | B7: =_xlfn.XLOOKUP(A7,Marques_Noms,Marques_Taux,0) -> 0.05 | C7: ='01_PARAMETRES'!B56 -> 45000 | D7: =C7*'01_PARAMETRES'!$B$48 -> 9900 | E7: =C7*'01_PARAMETRES'!$B$49 -> 10350 | F7: =C7*'01_PARAMETRES'!$B$50 -> 11250 | G7: =C7*'01_PARAMETRES'!$B$51 -> 13500 | H7: =D7*B7 -> 495 | I7: =E7*B7 -> 517.5 | J7: =F7*B7 -> 562.5 | K7: =G7*B7 -> 675
A8: IMPÉRIAL | B8: =_xlfn.XLOOKUP(A8,Marques_Noms,Marques_Taux,0) -> 0.045 | C8: ='01_PARAMETRES'!C56 -> 32000 | D8: =C8*'01_PARAMETRES'!$B$48 -> 7040 | E8: =C8*'01_PARAMETRES'!$B$49 -> 7360 | F8: =C8*'01_PARAMETRES'!$B$50 -> 8000 | G8: =C8*'01_PARAMETRES'!$B$51 -> 9600 | H8: =D8*B8 -> 316.8 | I8: =E8*B8 -> 331.2 | J8: =F8*B8 -> 360 | K8: =G8*B8 -> 432
A9: STELLAIRE | B9: =_xlfn.XLOOKUP(A9,Marques_Noms,Marques_Taux,0) -> 0.06 | C9: ='01_PARAMETRES'!D56 -> 18000 | D9: =C9*'01_PARAMETRES'!$B$48 -> 3960 | E9: =C9*'01_PARAMETRES'!$B$49 -> 4140 | F9: =C9*'01_PARAMETRES'!$B$50 -> 4500 | G9: =C9*'01_PARAMETRES'!$B$51 -> 5400 | H9: =D9*B9 -> 237.6 | I9: =E9*B9 -> 248.4 | J9: =F9*B9 -> 270 | K9: =G9*B9 -> 324
A10: TOTAL | B10: — | C10: =SUM(C7:C9) -> 95000 | D10: =SUM(D7:D9) -> 20900 | E10: =SUM(E7:E9) -> 21850 | F10: =SUM(F7:F9) -> 23750 | G10: =SUM(G7:G9) -> 28500 | H10: =SUM(H7:H9) -> 1049.4 | I10: =SUM(I7:I9) -> 1097.1 | J10: =SUM(J7:J9) -> 1192.5 | K10: =SUM(K7:K9) -> 1431
G11: ROYALTY ANNUELLE TOTALE → | K11: =SUM(H10:K10) -> 4770
A13: 📍 Maison Aurèle Italia
A14: Marque | B14: Taux royalty | C14: CA annuel (k€) | D14: Q1 (k€) | E14: Q2 (k€) | F14: Q3 (k€) | G14: Q4 (k€) | H14: Royalty Q1 | I14: Royalty Q2 | J14: Royalty Q3 | K14: Royalty Q4
A15: AURÈLE | B15: =_xlfn.XLOOKUP(A15,Marques_Noms,Marques_Taux,0) -> 0.05 | C15: ='01_PARAMETRES'!B57 -> 28000 | D15: =C15*'01_PARAMETRES'!$B$48 -> 6160 | E15: =C15*'01_PARAMETRES'!$B$49 -> 6440 | F15: =C15*'01_PARAMETRES'!$B$50 -> 7000 | G15: =C15*'01_PARAMETRES'!$B$51 -> 8400 | H15: =D15*B15 -> 308 | I15: =E15*B15 -> 322 | J15: =F15*B15 -> 350 | K15: =G15*B15 -> 420
A16: IMPÉRIAL | B16: =IFERROR(INDEX('01_PARAMETRES'!$C$42:$C$44,MATCH(A16,'01_PARAMETRES'!$A$42:$A$44,0)),0) -> 0.045 | C16: ='01_PARAMETRES'!C57 -> 22000 | D16: =C16*'01_PARAMETRES'!$B$48 -> 4840 | E16: =C16*'01_PARAMETRES'!$B$49 -> 5060 | F16: =C16*'01_PARAMETRES'!$B$50 -> 5500 | G16: =C16*'01_PARAMETRES'!$B$51 -> 6600 | H16: =D16*B16 -> 217.8 | I16: =E16*B16 -> 227.7 | J16: =F16*B16 -> 247.5 | K16: =G16*B16 -> 297
A17: STELLAIRE | B17: =IFERROR(INDEX('01_PARAMETRES'!$C$42:$C$44,MATCH(A17,'01_PARAMETRES'!$A$42:$A$44,0)),0) -> 0.06 | C17: ='01_PARAMETRES'!D57 -> 12000 | D17: =C17*'01_PARAMETRES'!$B$48 -> 2640 | E17: =C17*'01_PARAMETRES'!$B$49 -> 2760 | F17: =C17*'01_PARAMETRES'!$B$50 -> 3000 | G17: =C17*'01_PARAMETRES'!$B$51 -> 3600 | H17: =D17*B17 -> 158.4 | I17: =E17*B17 -> 165.6 | J17: =F17*B17 -> 180 | K17: =G17*B17 -> 216
A18: TOTAL | B18: — | C18: =SUM(C15:C17) -> 62000 | D18: =SUM(D15:D17) -> 13640 | E18: =SUM(E15:E17) -> 14260 | F18: =SUM(F15:F17) -> 15500 | G18: =SUM(G15:G17) -> 18600 | H18: =SUM(H15:H17) -> 684.2 | I18: =SUM(I15:I17) -> 715.3 | J18: =SUM(J15:J17) -> 777.5 | K18: =SUM(K15:K17) -> 933
G19: ROYALTY ANNUELLE TOTALE → | K19: =SUM(H18:K18) -> 3110
A21: 📍 Maison Aurèle Japan
A22: Marque | B22: Taux royalty | C22: CA annuel (k€) | D22: Q1 (k€) | E22: Q2 (k€) | F22: Q3 (k€) | G22: Q4 (k€) | H22: Royalty Q1 | I22: Royalty Q2 | J22: Royalty Q3 | K22: Royalty Q4
A23: AURÈLE | B23: =IFERROR(INDEX('01_PARAMETRES'!$C$42:$C$44,MATCH(A23,'01_PARAMETRES'!$A$42:$A$44,0)),0) -> 0.05 | C23: ='01_PARAMETRES'!B58 -> 35000 | D23: =C23*'01_PARAMETRES'!$B$48 -> 7700 | E23: =C23*'01_PARAMETRES'!$B$49 -> 8050 | F23: =C23*'01_PARAMETRES'!$B$50 -> 8750 | G23: =C23*'01_PARAMETRES'!$B$51 -> 10500 | H23: =D23*B23 -> 385 | I23: =E23*B23 -> 402.5 | J23: =F23*B23 -> 437.5 | K23: =G23*B23 -> 525
A24: IMPÉRIAL | B24: =IFERROR(INDEX('01_PARAMETRES'!$C$42:$C$44,MATCH(A24,'01_PARAMETRES'!$A$42:$A$44,0)),0) -> 0.045 | C24: ='01_PARAMETRES'!C58 -> 28000 | D24: =C24*'01_PARAMETRES'!$B$48 -> 6160 | E24: =C24*'01_PARAMETRES'!$B$49 -> 6440 | F24: =C24*'01_PARAMETRES'!$B$50 -> 7000 | G24: =C24*'01_PARAMETRES'!$B$51 -> 8400 | H24: =D24*B24 -> 277.2 | I24: =E24*B24 -> 289.8 | J24: =F24*B24 -> 315 | K24: =G24*B24 -> 378
A25: STELLAIRE | B25: =IFERROR(INDEX('01_PARAMETRES'!$C$42:$C$44,MATCH(A25,'01_PARAMETRES'!$A$42:$A$44,0)),0) -> 0.06 | C25: ='01_PARAMETRES'!D58 -> 20000 | D25: =C25*'01_PARAMETRES'!$B$48 -> 4400 | E25: =C25*'01_PARAMETRES'!$B$49 -> 4600 | F25: =C25*'01_PARAMETRES'!$B$50 -> 5000 | G25: =C25*'01_PARAMETRES'!$B$51 -> 6000 | H25: =D25*B25 -> 264 | I25: =E25*B25 -> 276 | J25: =F25*B25 -> 300 | K25: =G25*B25 -> 360
A26: TOTAL | B26: — | C26: =SUM(C23:C25) -> 83000 | D26: =SUM(D23:D25) -> 18260 | E26: =SUM(E23:E25) -> 19090 | F26: =SUM(F23:F25) -> 20750 | G26: =SUM(G23:G25) -> 24900 | H26: =SUM(H23:H25) -> 926.2 | I26: =SUM(I23:I25) -> 968.3 | J26: =SUM(J23:J25) -> 1052.5 | K26: =SUM(K23:K25) -> 1263
G27: ROYALTY ANNUELLE TOTALE → | K27: =SUM(H26:K26) -> 4210
A29: 📍 Maison Aurèle USA
A30: Marque | B30: Taux royalty | C30: CA annuel (k€) | D30: Q1 (k€) | E30: Q2 (k€) | F30: Q3 (k€) | G30: Q4 (k€) | H30: Royalty Q1 | I30: Royalty Q2 | J30: Royalty Q3 | K30: Royalty Q4
A31: AURÈLE | B31: =IFERROR(INDEX('01_PARAMETRES'!$C$42:$C$44,MATCH(A31,'01_PARAMETRES'!$A$42:$A$44,0)),0) -> 0.05 | C31: ='01_PARAMETRES'!B59 -> 52000 | D31: =C31*'01_PARAMETRES'!$B$48 -> 11440 | E31: =C31*'01_PARAMETRES'!$B$49 -> 11960 | F31: =C31*'01_PARAMETRES'!$B$50 -> 13000 | G31: =C31*'01_PARAMETRES'!$B$51 -> 15600 | H31: =D31*B31 -> 572 | I31: =E31*B31 -> 598 | J31: =F31*B31 -> 650 | K31: =G31*B31 -> 780
A32: IMPÉRIAL | B32: =IFERROR(INDEX('01_PARAMETRES'!$C$42:$C$44,MATCH(A32,'01_PARAMETRES'!$A$42:$A$44,0)),0) -> 0.045 | C32: ='01_PARAMETRES'!C59 -> 38000 | D32: =C32*'01_PARAMETRES'!$B$48 -> 8360 | E32: =C32*'01_PARAMETRES'!$B$49 -> 8740 | F32: =C32*'01_PARAMETRES'!$B$50 -> 9500 | G32: =C32*'01_PARAMETRES'!$B$51 -> 11400 | H32: =D32*B32 -> 376.2 | I32: =E32*B32 -> 393.3 | J32: =F32*B32 -> 427.5 | K32: =G32*B32 -> 513
A33: STELLAIRE | B33: =IFERROR(INDEX('01_PARAMETRES'!$C$42:$C$44,MATCH(A33,'01_PARAMETRES'!$A$42:$A$44,0)),0) -> 0.06 | C33: ='01_PARAMETRES'!D59 -> 25000 | D33: =C33*'01_PARAMETRES'!$B$48 -> 5500 | E33: =C33*'01_PARAMETRES'!$B$49 -> 5750 | F33: =C33*'01_PARAMETRES'!$B$50 -> 6250 | G33: =C33*'01_PARAMETRES'!$B$51 -> 7500 | H33: =D33*B33 -> 330 | I33: =E33*B33 -> 345 | J33: =F33*B33 -> 375 | K33: =G33*B33 -> 450
A34: TOTAL | B34: — | C34: =SUM(C31:C33) -> 115000 | D34: =SUM(D31:D33) -> 25300 | E34: =SUM(E31:E33) -> 26450 | F34: =SUM(F31:F33) -> 28750 | G34: =SUM(G31:G33) -> 34500 | H34: =SUM(H31:H33) -> 1278.2 | I34: =SUM(I31:I33) -> 1336.3 | J34: =SUM(J31:J33) -> 1452.5 | K34: =SUM(K31:K33) -> 1743
G35: ROYALTY ANNUELLE TOTALE → | K35: =SUM(H34:K34) -> 5810
A37: 📍 Maison Aurèle UK
A38: Marque | B38: Taux royalty | C38: CA annuel (k€) | D38: Q1 (k€) | E38: Q2 (k€) | F38: Q3 (k€) | G38: Q4 (k€) | H38: Royalty Q1 | I38: Royalty Q2 | J38: Royalty Q3 | K38: Royalty Q4
A39: AURÈLE | B39: =IFERROR(INDEX('01_PARAMETRES'!$C$42:$C$44,MATCH(A39,'01_PARAMETRES'!$A$42:$A$44,0)),0) -> 0.05 | C39: ='01_PARAMETRES'!B60 -> 22000 | D39: =C39*'01_PARAMETRES'!$B$48 -> 4840 | E39: =C39*'01_PARAMETRES'!$B$49 -> 5060 | F39: =C39*'01_PARAMETRES'!$B$50 -> 5500 | G39: =C39*'01_PARAMETRES'!$B$51 -> 6600 | H39: =D39*B39 -> 242 | I39: =E39*B39 -> 253 | J39: =F39*B39 -> 275 | K39: =G39*B39 -> 330
A40: IMPÉRIAL | B40: =IFERROR(INDEX('01_PARAMETRES'!$C$42:$C$44,MATCH(A40,'01_PARAMETRES'!$A$42:$A$44,0)),0) -> 0.045 | C40: ='01_PARAMETRES'!C60 -> 18000 | D40: =C40*'01_PARAMETRES'!$B$48 -> 3960 | E40: =C40*'01_PARAMETRES'!$B$49 -> 4140 | F40: =C40*'01_PARAMETRES'!$B$50 -> 4500 | G40: =C40*'01_PARAMETRES'!$B$51 -> 5400 | H40: =D40*B40 -> 178.2 | I40: =E40*B40 -> 186.3 | J40: =F40*B40 -> 202.5 | K40: =G40*B40 -> 243
A41: STELLAIRE | B41: =IFERROR(INDEX('01_PARAMETRES'!$C$42:$C$44,MATCH(A41,'01_PARAMETRES'!$A$42:$A$44,0)),0) -> 0.06 | C41: ='01_PARAMETRES'!D60 -> 10000 | D41: =C41*'01_PARAMETRES'!$B$48 -> 2200 | E41: =C41*'01_PARAMETRES'!$B$49 -> 2300 | F41: =C41*'01_PARAMETRES'!$B$50 -> 2500 | G41: =C41*'01_PARAMETRES'!$B$51 -> 3000 | H41: =D41*B41 -> 132 | I41: =E41*B41 -> 138 | J41: =F41*B41 -> 150 | K41: =G41*B41 -> 180
A42: TOTAL | B42: — | C42: =SUM(C39:C41) -> 50000 | D42: =SUM(D39:D41) -> 11000 | E42: =SUM(E39:E41) -> 11500 | F42: =SUM(F39:F41) -> 12500 | G42: =SUM(G39:G41) -> 15000 | H42: =SUM(H39:H41) -> 552.2 | I42: =SUM(I39:I41) -> 577.3 | J42: =SUM(J39:J41) -> 627.5 | K42: =SUM(K39:K41) -> 753
G43: ROYALTY ANNUELLE TOTALE → | K43: =SUM(H42:K42) -> 2510
A45: 📍 Maison Aurèle China
A46: Marque | B46: Taux royalty | C46: CA annuel (k€) | D46: Q1 (k€) | E46: Q2 (k€) | F46: Q3 (k€) | G46: Q4 (k€) | H46: Royalty Q1 | I46: Royalty Q2 | J46: Royalty Q3 | K46: Royalty Q4
...

Sheet 04_BENCHMARK_ALP
A1: 🔍 ANALYSE DE PLEINE CONCURRENCE
A2: Benchmark arm's length — IQR automatique — OCDE TP Guidelines
A3: NEURAL — Intelligence Augmentée · Agent RoyaltyAccounting · Mars 2026
A5: A · PANEL DE COMPARABLES
A6: Société comparable | B6: Secteur | C6: Pays | D6: Type licence | E6: Taux observé | F6: Base | G6: Durée | H6: Source | I6: Année | J6: Fiabilité
A7: Comp. 1 — Luxury Brand Alpha | B7: Mode & Maroquinerie | C7: France | D7: Marque | E7: 0.045 | F7: CA net | G7: 5 ans | H7: Royalty Source® | I7: 2024 | J7: ★★★★
A8: Comp. 2 — Premium Fashion Beta | B8: Mode | C8: Italie | D8: Marque | E8: 0.055 | F8: CA net | G8: 5 ans | H8: Royalty Source® | I8: 2024 | J8: ★★★★
A9: Comp. 3 — Jewel House Gamma | B9: Joaillerie | C9: Suisse | D9: Marque + know-how | E9: 0.065 | F9: CA net | G9: 7 ans | H9: ktMINE® | I9: 2023 | J9: ★★★
A10: Comp. 4 — Heritage Leather Delta | B10: Maroquinerie | C10: France | D10: Marque | E10: 0.04 | F10: CA net | G10: 5 ans | H10: Royalty Source® | I10: 2024 | J10: ★★★★
A11: Comp. 5 — Couture House Epsilon | B11: Haute Couture | C11: France | D11: Marque | E11: 0.058 | F11: CA net | G11: 5 ans | H11: BvD Orbis® | I11: 2024 | J11: ★★★
A12: Comp. 6 — Watch Luxury Zeta | B12: Horlogerie | C12: Suisse | D12: Marque + techno | E12: 0.07 | F12: CA net | G12: 10 ans | H12: ktMINE® | I12: 2023 | J12: ★★★
A13: Comp. 7 — Fashion Group Eta | B13: Mode & Accessoires | C13: UK | D13: Marque | E13: 0.038 | F13: CA net | G13: 5 ans | H13: Royalty Source® | I13: 2024 | J13: ★★★★
A14: Comp. 8 — Prestige Beauty Theta | B14: Cosmétique Prestige | C14: France | D14: Marque | E14: 0.048 | F14: CA net | G14: 5 ans | H14: Royalty Source® | I14: 2024 | J14: ★★★
A15: Comp. 9 — Elite Retail Iota | B15: Distribution Luxe | C15: USA | D15: Marque | E15: 0.042 | F15: CA net | G15: 5 ans | H15: Bloomberg Tax | I15: 2024 | J15: ★★★★
A16: Comp. 10 — Artisan Luxe Kappa | B16: Artisanat de luxe | C16: Italie | D16: Marque + savoir-faire | E16: 0.062 | F16: CA net | G16: 7 ans | H16: ktMINE® | I16: 2024 | J16: ★★★
A18: B · ANALYSE STATISTIQUE — IQR AUTOMATIQUE (formules QUARTILE)
A19: Indicateur statistique | B19: Valeur | C19: Formule
A20: Minimum | B20: =MIN($E$7:$E$16) -> 0.038 | C20: MIN()
A21: 1er quartile (Q1) | B21: =PERCENTILE($E$7:$E$16,0.25) -> 0.04275 | C21: QUARTILE.INC(,1)
A22: Médiane (Q2) | B22: =PERCENTILE($E$7:$E$16,0.5) -> 0.0515 | C22: QUARTILE.INC(,2)
A23: 3e quartile (Q3) | B23: =PERCENTILE($E$7:$E$16,0.75) -> 0.061 | C23: QUARTILE.INC(,3)
A24: Maximum | B24: =MAX($E$7:$E$16) -> 0.07 | C24: MAX()
A25: Moyenne arithmétique | B25: =AVERAGE($E$7:$E$16) -> 0.0523 | C25: AVERAGE()
A26: Nombre de comparables | B26: =COUNT('04_BENCHMARK_ALP'!$E$7:$E$16) -> 10 | C26: COUNT()
A28: C · TEST ARM'S LENGTH PAR MARQUE — FORMULES AUTOMATIQUES
A29: Marque | B29: Taux appliqué | C29: Q1 benchmark | D29: Médiane | E29: Q3 benchmark | F29: Dans l'IQR ? | G29: Statut ALP | H29: Action requise
A30: AURÈLE | B30: =IFERROR(INDEX('01_PARAMETRES'!$C$42:$C$44,MATCH(A30,'01_PARAMETRES'!$A$42:$A$44,0)),0) -> 0.05 | C30: =$B$21 -> 0.04275 | D30: =$B$22 -> 0.0515 | E30: =$B$23 -> 0.061 | F30: =IF(AND(B30>=C30,B30<=E30),"OUI","NON") -> OUI | G30: =IF(F30="OUI","✅ CONFORME","⚠️ HORS IQR") -> ✅ CONFORME | H30: =IF(F30="OUI","Aucune","Ajustement vers médiane recommandé") -> Aucune
A31: IMPÉRIAL | B31: =IFERROR(INDEX('01_PARAMETRES'!$C$42:$C$44,MATCH(A31,'01_PARAMETRES'!$A$42:$A$44,0)),0) -> 0.045 | C31: =$B$21 -> 0.04275 | D31: =$B$22 -> 0.0515 | E31: =$B$23 -> 0.061 | F31: =IF(AND(B31>=C31,B31<=E31),"OUI","NON") -> OUI | G31: =IF(F31="OUI","✅ CONFORME","⚠️ HORS IQR") -> ✅ CONFORME | H31: =IF(F31="OUI","Aucune","Ajustement vers médiane recommandé") -> Aucune
A32: STELLAIRE | B32: =IFERROR(INDEX('01_PARAMETRES'!$C$42:$C$44,MATCH(A32,'01_PARAMETRES'!$A$42:$A$44,0)),0) -> 0.06 | C32: =$B$21 -> 0.04275 | D32: =$B$22 -> 0.0515 | E32: =$B$23 -> 0.061 | F32: =IF(AND(B32>=C32,B32<=E32),"OUI","NON") -> OUI | G32: =IF(F32="OUI","✅ CONFORME","⚠️ HORS IQR") -> ✅ CONFORME | H32: =IF(F32="OUI","Aucune","Ajustement vers médiane recommandé") -> Aucune
A34: D · ANALYSE DE SENSIBILITÉ (en k€) — Formules dynamiques
A35: Scénario | B35: Taux AURÈLE | C35: Taux IMPÉRIAL | D35: Taux STELLAIRE | E35: Royalty totale (k€) | F35: Δ vs. actuel | G35: Impact fiscal (FR) | H35: Impact net groupe
A36: Actuel | B36: ='01_PARAMETRES'!$C$42 -> 0.05 | C36: ='01_PARAMETRES'!$C$43 -> 0.045 | D36: ='01_PARAMETRES'!$C$44 -> 0.06 | E36: =SUM('01_PARAMETRES'!$B$56:$B$62)*B36+SUM('01_PARAMETRES'!$C$56:$C$62)*C36+SUM('01_PARAMETRES'!$D$56:$D$62)*D36 -> 27475 | F36: 0 | G36: =ROUND(F36*'01_PARAMETRES'!$D$22,0) -> 0 | H36: =F36-G36 -> 0
A37: Q1 (conservateur) | B37: =$B$21 -> 0.04275 | C37: =$B$21 -> 0.04275 | D37: =$B$21 -> 0.04275 | E37: =SUM('01_PARAMETRES'!$B$56:$B$62)*B37+SUM('01_PARAMETRES'!$C$56:$C$62)*C37+SUM('01_PARAMETRES'!$D$56:$D$62)*D37 -> 23298.75 | F37: =E37-E36 -> -4176.25 | G37: =ROUND(F37*'01_PARAMETRES'!$D$22,0) -> -1075 | H37: =F37-G37 -> -3101.25
A38: Médiane | B38: =$B$22 -> 0.0515 | C38: =$B$22 -> 0.0515 | D38: =$B$22 -> 0.0515 | E38: =SUM('01_PARAMETRES'!$B$56:$B$62)*B38+SUM('01_PARAMETRES'!$C$56:$C$62)*C38+SUM('01_PARAMETRES'!$D$56:$D$62)*D38 -> 28067.5 | F38: =E38-E36 -> 592.5 | G38: =ROUND(F38*'01_PARAMETRES'!$D$22,0) -> 152 | H38: =F38-G38 -> 440.5
A39: Q3 (agressif) | B39: =$B$23 -> 0.061 | C39: =$B$23 -> 0.061 | D39: =$B$23 -> 0.061 | E39: =SUM('01_PARAMETRES'!$B$56:$B$62)*B39+SUM('01_PARAMETRES'!$C$56:$C$62)*C39+SUM('01_PARAMETRES'!$D$56:$D$62)*D39 -> 33245 | F39: =E39-E36 -> 5770 | G39: =ROUND(F39*'01_PARAMETRES'!$D$22,0) -> 1485 | H39: =F39-G39 -> 4285
A40: Maximum | B40: =MAX($E$7:$E$16) -> 0.07 | C40: =MAX($E$7:$E$16) -> 0.07 | D40: =MAX($E$7:$E$16) -> 0.07 | E40: =SUM('01_PARAMETRES'!$B$56:$B$62)*B40+SUM('01_PARAMETRES'!$C$56:$C$62)*C40+SUM('01_PARAMETRES'!$D$56:$D$62)*D40 -> 38150 | F40: =E40-E36 -> 10675 | G40: =ROUND(F40*'01_PARAMETRES'!$D$22,0) -> 2747 | H40: =F40-G40 -> 7928
A41: Minimum | B41: =MIN($E$7:$E$16) -> 0.038 | C41: =MIN($E$7:$E$16) -> 0.038 | D41: =MIN($E$7:$E$16) -> 0.038 | E41: =SUM('01_PARAMETRES'!$B$56:$B$62)*B41+SUM('01_PARAMETRES'!$C$56:$C$62)*C41+SUM('01_PARAMETRES'!$D$56:$D$62)*D41 -> 20710 | F41: =E41-E36 -> -6765 | G41: =ROUND(F41*'01_PARAMETRES'!$D$22,0) -> -1741 | H41: =F41-G41 -> -5024
A43: 📌 Q1/Médiane/Q3 sont des formules QUARTILE.INC liées au panel. Ajouter un comparable → recalcul automatique de l'IQR.
A44: 📌 Sensibilité : SUMPRODUCT × taux scénario. Modifier un CA dans 01_PARAMETRES → impact instantané.

Sheet 05_ECRITURES_COMPTA
A1: 📝 ÉCRITURES COMPTABLES — LIÉES À 03_CALCUL
A2: IAS 38, IFRS 15, IAS 24 — Montants dynamiques
A3: NEURAL — Intelligence Augmentée · Agent RoyaltyAccounting · Mars 2026
A5: A · CHEZ LE LICENCIEUR — NEURAL Luxe Holding
A6: Date | B6: N° pièce | C6: Compte | D6: Libellé | E6: Débit (k€) | F6: Crédit (k€) | G6: Norme IFRS | H6: Commentaire
A7: 31/03/2025 | B7: ROY-Q1-001 | C7: 411100 — Clients groupe Paris | D7: Redevances Q1 — Aurèle Paris | E7: =ROUND('03_CALCUL_ROYALTIES'!F63*'01_PARAMETRES'!$B$48,0) -> 1049 | G7: IFRS 15 §B63 | H7: Usage-based royalty
A8: 31/03/2025 | B8: ROY-Q1-001 | C8: 411200 — Clients groupe Italia | D8: Redevances Q1 — Aurèle Italia | E8: =ROUND('03_CALCUL_ROYALTIES'!F64*'01_PARAMETRES'!$B$48,0) -> 684 | G8: IFRS 15 §B63
A9: 31/03/2025 | B9: ROY-Q1-001 | C9: 411300 — Clients groupe Japan | D9: Redevances Q1 — Aurèle Japan | E9: =ROUND('03_CALCUL_ROYALTIES'!F65*'01_PARAMETRES'!$B$48,0) -> 926 | G9: IFRS 15 §B63
A10: 31/03/2025 | B10: ROY-Q1-001 | C10: 411400 — Clients groupe USA | D10: Redevances Q1 — Aurèle USA | E10: =ROUND('03_CALCUL_ROYALTIES'!F66*'01_PARAMETRES'!$B$48,0) -> 1278 | G10: IFRS 15 §B63
A11: 31/03/2025 | B11: ROY-Q1-001 | C11: 411500 — Clients groupe UK | D11: Redevances Q1 — Aurèle UK | E11: =ROUND('03_CALCUL_ROYALTIES'!F67*'01_PARAMETRES'!$B$48,0) -> 552 | G11: IFRS 15 §B63
A12: 31/03/2025 | B12: ROY-Q1-001 | C12: 411600 — Clients groupe China | D12: Redevances Q1 — Aurèle China | E12: =ROUND('03_CALCUL_ROYALTIES'!F68*'01_PARAMETRES'!$B$48,0) -> 1165 | G12: IFRS 15 §B63
A13: 31/03/2025 | B13: ROY-Q1-001 | C13: 411700 — Clients groupe ME | D13: Redevances Q1 — Aurèle ME | E13: =ROUND('03_CALCUL_ROYALTIES'!F69*'01_PARAMETRES'!$B$48,0) -> 389 | G13: IFRS 15 §B63
A14: 31/03/2025 | B14: ROY-Q1-001 | C14: 751000 — Produits redevances marque | D14: Redevances marque Q1 — Total | F14: =ROUND('03_CALCUL_ROYALTIES'!$F$70*'01_PARAMETRES'!$B$48,0) -> 6045 | G14: IFRS 15 §B63 | H14: Revenu reconnu à l'usage
A16: 30/06/2025 | B16: ROY-Q2-001 | C16: 411xxx — Clients groupe (total) | D16: Redevances Q2 — Toutes entités | E16: =ROUND('03_CALCUL_ROYALTIES'!$F$70*'01_PARAMETRES'!$B$49,0) -> 6319 | G16: IFRS 15 §B63
A17: 30/06/2025 | B17: ROY-Q2-001 | C17: 751000 — Produits redevances marque | D17: Redevances marque Q2 — Total | F17: =ROUND('03_CALCUL_ROYALTIES'!$F$70*'01_PARAMETRES'!$B$49,0) -> 6319 | G17: IFRS 15 §B63
A19: 30/09/2025 | B19: ROY-Q3-001 | C19: 411xxx — Clients groupe (total) | D19: Redevances Q3 — Toutes entités | E19: =ROUND('03_CALCUL_ROYALTIES'!$F$70*'01_PARAMETRES'!$B$50,0) -> 6869 | G19: IFRS 15 §B63
A20: 30/09/2025 | B20: ROY-Q3-001 | C20: 751000 — Produits redevances marque | D20: Redevances marque Q3 — Total | F20: =ROUND('03_CALCUL_ROYALTIES'!$F$70*'01_PARAMETRES'!$B$50,0) -> 6869 | G20: IFRS 15 §B63
A22: 31/12/2025 | B22: ROY-Q4-001 | C22: 411xxx — Clients groupe (total) | D22: Redevances Q4 — Toutes entités | E22: =ROUND('03_CALCUL_ROYALTIES'!$F$70*'01_PARAMETRES'!$B$51,0) -> 8243 | G22: IFRS 15 §B63
A23: 31/12/2025 | B23: ROY-Q4-001 | C23: 751000 — Produits redevances marque | D23: Redevances marque Q4 — Total | F23: =ROUND('03_CALCUL_ROYALTIES'!$F$70*'01_PARAMETRES'!$B$51,0) -> 8243 | G23: IFRS 15 §B63
D26: TOTAL PRODUITS REDEVANCES FY2025 | F26: ='03_CALCUL_ROYALTIES'!$F$70 -> 27475
A28: B · TRAITEMENT IFRS SPÉCIFIQUE
A29: IFRS 15 §B63 | B29: Redevances usage | C29: Le produit est reconnu au fur et à mesure des ventes (usage-based royalty).
A30: IAS 38 §5(d) | B30: Exclusion scope | C30: La redevance payée n'est PAS une immobilisation. Charge de période.
A31: IAS 24 §18 | B31: Parties liées | C31: Transactions IG divulguées : nature, montants, soldes, conditions.
A32: IAS 12 §39 | B32: WHT | C32: WHT = impôt sur le résultat. Crédit d'impôt si convention applicable.
A33: IFRS 18 (2027) | B33: Anticipation P&L | C33: Reclassement revenus redevances dans nouveau format P&L.

Sheet 06_RETENUES_SOURCE
A1: 🏛️ RETENUES À LA SOURCE (WHT) — DYNAMIQUE
A2: WHT liée à 01_PARAMETRES · Royalties liées à 03_CALCUL
A3: NEURAL — Intelligence Augmentée · Agent RoyaltyAccounting · Mars 2026
A5: A · TAUX WHT PAR JURIDICTION — 100% FORMULES
A6: Pays source | B6: Taux domestique WHT | C6: Convention fiscale | D6: Taux conventionnel | E6: Directive UE | F6: Taux effectif WHT | G6: Royalty brute (k€) | H6: WHT retenue (k€) | I6: Royalty nette (k€) | J6: Crédit impôt FR
A7: France (Aurèle Paris) | B7: ='01_PARAMETRES'!B67 -> 0.2573 | C7: N/A (domestique) | D7: ='01_PARAMETRES'!D67 -> 0 | E7: N/A | F7: ='01_PARAMETRES'!F67 -> 0 | G7: ='03_CALCUL_ROYALTIES'!F63 -> 4770 | H7: =ROUND(G7*F7,0) -> 0 | I7: =G7-H7 -> 4770 | J7: =MIN(H7,ROUND(G7*TauxIS_FR,0)) -> 0
A8: Italie (Aurèle Italia) | B8: ='01_PARAMETRES'!B68 -> 0.3 | C8: Conv. FR-IT + Dir. 2003/49/CE | D8: ='01_PARAMETRES'!D68 -> 0 | E8: Dir. 2003/49/CE | F8: ='01_PARAMETRES'!F68 -> 0 | G8: ='03_CALCUL_ROYALTIES'!F64 -> 3110 | H8: =ROUND(G8*F8,0) -> 0 | I8: =G8-H8 -> 3110 | J8: =MIN(H8,ROUND(G8*TauxIS_FR,0)) -> 0
A9: Japon (Aurèle Japan) | B9: ='01_PARAMETRES'!B69 -> 0.2042 | C9: Conv. FR-JP art. 12 | D9: ='01_PARAMETRES'!D69 -> 0.1 | E9: N/A | F9: ='01_PARAMETRES'!F69 -> 0.1 | G9: ='03_CALCUL_ROYALTIES'!F65 -> 4210 | H9: =ROUND(G9*F9,0) -> 421 | I9: =G9-H9 -> 3789 | J9: =MIN(H9,ROUND(G9*TauxIS_FR,0)) -> 421
A10: États-Unis (Aurèle USA) | B10: ='01_PARAMETRES'!B70 -> 0.3 | C10: Conv. FR-US art. 12 | D10: ='01_PARAMETRES'!D70 -> 0 | E10: N/A | F10: ='01_PARAMETRES'!F70 -> 0 | G10: ='03_CALCUL_ROYALTIES'!F66 -> 5810 | H10: =ROUND(G10*F10,0) -> 0 | I10: =G10-H10 -> 5810 | J10: =MIN(H10,ROUND(G10*TauxIS_FR,0)) -> 0
A11: Royaume-Uni (Aurèle UK) | B11: ='01_PARAMETRES'!B71 -> 0.2 | C11: Conv. FR-UK art. 12 | D11: ='01_PARAMETRES'!D71 -> 0 | E11: N/A | F11: ='01_PARAMETRES'!F71 -> 0 | G11: ='03_CALCUL_ROYALTIES'!F67 -> 2510 | H11: =ROUND(G11*F11,0) -> 0 | I11: =G11-H11 -> 2510 | J11: =MIN(H11,ROUND(G11*TauxIS_FR,0)) -> 0
A12: Hong Kong (Aurèle China) | B12: ='01_PARAMETRES'!B72 -> 0.0825 | C12: Conv. FR-HK art. 12 | D12: ='01_PARAMETRES'!D72 -> 0.06 | E12: N/A | F12: ='01_PARAMETRES'!F72 -> 0.06 | G12: ='03_CALCUL_ROYALTIES'!F68 -> 5295 | H12: =ROUND(G12*F12,0) -> 318 | I12: =G12-H12 -> 4977 | J12: =MIN(H12,ROUND(G12*TauxIS_FR,0)) -> 318
A13: EAU (Aurèle ME) | B13: ='01_PARAMETRES'!B73 -> 0 | C13: Conv. FR-EAU art. 12 | D13: ='01_PARAMETRES'!D73 -> 0 | E13: N/A | F13: ='01_PARAMETRES'!F73 -> 0 | G13: ='03_CALCUL_ROYALTIES'!F69 -> 1770 | H13: =ROUND(G13*F13,0) -> 0 | I13: =G13-H13 -> 1770 | J13: =MIN(H13,ROUND(G13*TauxIS_FR,0)) -> 0
A14: TOTAL | G14: =SUM(G7:G13) -> 27475 | H14: =SUM(H7:H13) -> 739 | I14: =SUM(I7:I13) -> 26736 | J14: =SUM(J7:J13) -> 739
A16: B · COÛT DE PORTAGE WHT (nouveau)
A17: Pays | B17: WHT retenue (k€) | C17: Délai imputation (mois) | D17: Taux court terme (Euribor 3M) | E17: Coût de portage (k€) | F17: Commentaire
A18: Japon | B18: =H9 -> 421 | C18: 9 | D18: 0.025 | E18: =ROUND(B18*D18*C18/12,0) -> 8 | F18: Crédit impôt imputable à la clôture annuelle uniquement
A19: Hong Kong | B19: =H12 -> 318 | C19: 6 | D19: 0.025 | E19: =ROUND(B19*D19*C19/12,0) -> 4 | F19: Crédit impôt imputable à la clôture annuelle uniquement
A21: 📌 WHT, royalties brutes et taux = 100% formules liées à 01_PARAMETRES et 03_CALCUL.
A22: 📌 NOUVEAU : Coût de portage WHT calculé (Euribor 3M ~2.5% mars 2026 · délai imputation crédit).

Sheet 07_ELIMINATIONS_CONSO
A1: 🔄 ÉLIMINATIONS EN CONSOLIDATION — DYNAMIQUE
A2: Formules liées à 03_CALCUL et 01_PARAMETRES · IFRS 10
A3: NEURAL — Intelligence Augmentée · Agent RoyaltyAccounting · Mars 2026
A5: A · ÉLIMINATION P&L REDEVANCES
A6: Entité | B6: Rôle | C6: Produit (k€) | D6: Charge (k€) | E6: Élimination P&L | F6: % consolidation | G6: Élim. ajustée | H6: Impact NCI
A7: Maison Aurèle Paris | B7: Licencié (charge) | C7: 0 | D7: ='03_CALCUL_ROYALTIES'!F63 -> 4770 | E7: =-D7 -> -4770 | F7: ='01_PARAMETRES'!G23 -> 1 | G7: =E7*F7 -> -4770 | H7: =E7*(1-F7) -> 0
A8: Maison Aurèle Italia | B8: Licencié (charge) | C8: 0 | D8: ='03_CALCUL_ROYALTIES'!F64 -> 3110 | E8: =-D8 -> -3110 | F8: ='01_PARAMETRES'!G24 -> 1 | G8: =E8*F8 -> -3110 | H8: =E8*(1-F8) -> 0
A9: Maison Aurèle Japan | B9: Licencié (charge) | C9: 0 | D9: ='03_CALCUL_ROYALTIES'!F65 -> 4210 | E9: =-D9 -> -4210 | F9: ='01_PARAMETRES'!G25 -> 1 | G9: =E9*F9 -> -4210 | H9: =E9*(1-F9) -> 0
A10: Maison Aurèle USA | B10: Licencié (charge) | C10: 0 | D10: ='03_CALCUL_ROYALTIES'!F66 -> 5810 | E10: =-D10 -> -5810 | F10: ='01_PARAMETRES'!G26 -> 1 | G10: =E10*F10 -> -5810 | H10: =E10*(1-F10) -> 0
A11: Maison Aurèle UK | B11: Licencié (charge) | C11: 0 | D11: ='03_CALCUL_ROYALTIES'!F67 -> 2510 | E11: =-D11 -> -2510 | F11: ='01_PARAMETRES'!G27 -> 1 | G11: =E11*F11 -> -2510 | H11: =E11*(1-F11) -> 0
A12: Maison Aurèle China | B12: Licencié (charge) | C12: 0 | D12: ='03_CALCUL_ROYALTIES'!F68 -> 5295 | E12: =-D12 -> -5295 | F12: ='01_PARAMETRES'!G28 -> 0.8 | G12: =E12*F12 -> -4236 | H12: =E12*(1-F12) -> -1059
A13: Maison Aurèle ME | B13: Licencié (charge) | C13: 0 | D13: ='03_CALCUL_ROYALTIES'!F69 -> 1770 | E13: =-D13 -> -1770 | F13: ='01_PARAMETRES'!G29 -> 1 | G13: =E13*F13 -> -1770 | H13: =E13*(1-F13) -> 0
A14: NEURAL Luxe Holding | B14: Licencieur (produit) | C14: ='03_CALCUL_ROYALTIES'!$F$70 -> 27475 | D14: 0 | E14: =-C14 -> -27475
A16: 📌 % consolidation et montants = formules XLOOKUP vers 01_PARAMETRES et 03_CALCUL.
A17: 📌 NCI calculé automatiquement : Aurèle China 80% → 20% NCI sur l'élimination.

Sheet 08_PILIER2_GLOBE
A1: 🌐 PILIER 2 GloBE — DYNAMIQUE + SUBSTANCE
A2: ETR · Top-up tax · Exclusion substance · IS Japon 31.52%
A3: NEURAL — Intelligence Augmentée · Agent RoyaltyAccounting · Mars 2026
A5: A · ETR PAR JURIDICTION — AVEC EXCLUSION SUBSTANCE-BASED INCOME
A6: Juridiction | B6: Résultat GloBE avant (k€) | C6: Royalty flux (k€) | D6: Résultat après (k€) | E6: IS payé (k€) | F6: ETR | G6: Exclusion substance (k€) | H6: Résultat GloBE net (k€) | I6: Top-up tax (k€) | J6: Commentaire
A7: France (Holding+Paris) | B7: 85000 | C7: =GrandTotal_Royalty -> 27475 | D7: 112475 | E7: =ROUND(D7*TauxIS_FR,0) -> 28940 | F7: =IFERROR(E7/D7,0) -> 0.25730162 | G7: =ROUND(5%*(INDEX(Entites_MasseSal,1)+INDEX(Entites_MasseSal,2))+5%*(INDEX(Entites_ActifsCorp,1)+INDEX(Entites_ActifsCorp,2)),0) -> 5375 | H7: =D7-G7 -> 107100 | I7: =MAX(0,ROUND((15%-F7)*H7,0)) -> 0 | J7: =IF(F7<15%,"⚠️ Top-up "&TEXT((15%-F7)*H7,"#,##0")&" k€","✅ QDMTT FR — conforme "&TEXT(F7,"0.0%")) -> ✅ QDMTT FR — conforme 2.6%
A8: Italie | B8: 18000 | C8: =IFERROR(-_xlfn.XLOOKUP("Maison Aurèle Italia",Recap_Entites,Recap_RoyaltyTotal),0) -> -3110 | D8: 14890 | E8: =ROUND(D8*_xlfn.XLOOKUP("Maison Aurèle Italia",Entites_Noms,Entites_TauxIS),0) -> 4116 | F8: =IFERROR(E8/D8,0) -> 0.27642713 | G8: =ROUND(5%*_xlfn.XLOOKUP("Maison Aurèle Italia",Entites_Noms,Entites_MasseSal)+5%*_xlfn.XLOOKUP("Maison Aurèle Italia",Entites_Noms,Entites_ActifsCorp),0) -> 1175 | H8: =D8-G8 -> 13715 | I8: =MAX(0,ROUND((15%-F8)*H8,0)) -> 0 | J8: =IF(F8<15%,"⚠️ Top-up "&TEXT((15%-F8)*H8,"#,##0")&" k€","✅ Conforme "&TEXT(F8,"0.0%")) -> ✅ Conforme 2.8%
A9: Japon | B9: 22000 | C9: =IFERROR(-_xlfn.XLOOKUP("Maison Aurèle Japan",Recap_Entites,Recap_RoyaltyTotal),0) -> -4210 | D9: 17790 | E9: =ROUND(D9*_xlfn.XLOOKUP("Maison Aurèle Japan",Entites_Noms,Entites_TauxIS),0) -> 5607 | F9: =IFERROR(E9/D9,0) -> 0.31517707 | G9: =ROUND(5%*_xlfn.XLOOKUP("Maison Aurèle Japan",Entites_Noms,Entites_MasseSal)+5%*_xlfn.XLOOKUP("Maison Aurèle Japan",Entites_Noms,Entites_ActifsCorp),0) -> 1800 | H9: =D9-G9 -> 15990 | I9: =MAX(0,ROUND((15%-F9)*H9,0)) -> 0 | J9: =IF(F9<15%,"⚠️ Top-up "&TEXT((15%-F9)*H9,"#,##0")&" k€","✅ Conforme "&TEXT(F9,"0.0%")) -> ✅ Conforme 3.2%
A10: États-Unis | B10: 30000 | C10: =IFERROR(-_xlfn.XLOOKUP("Maison Aurèle USA",Recap_Entites,Recap_RoyaltyTotal),0) -> -5810 | D10: 24190 | E10: =ROUND(D10*_xlfn.XLOOKUP("Maison Aurèle USA",Entites_Noms,Entites_TauxIS),0) -> 5080 | F10: =IFERROR(E10/D10,0) -> 0.21000413 | G10: =ROUND(5%*_xlfn.XLOOKUP("Maison Aurèle USA",Entites_Noms,Entites_MasseSal)+5%*_xlfn.XLOOKUP("Maison Aurèle USA",Entites_Noms,Entites_ActifsCorp),0) -> 2400 | H10: =D10-G10 -> 21790 | I10: =MAX(0,ROUND((15%-F10)*H10,0)) -> 0 | J10: =IF(F10<15%,"⚠️ Top-up "&TEXT((15%-F10)*H10,"#,##0")&" k€","✅ Conforme "&TEXT(F10,"0.0%")) -> ✅ Conforme 2.1%
A11: Royaume-Uni | B11: 12000 | C11: =IFERROR(-_xlfn.XLOOKUP("Maison Aurèle UK",Recap_Entites,Recap_RoyaltyTotal),0) -> -2510 | D11: 9490 | E11: =ROUND(D11*_xlfn.XLOOKUP("Maison Aurèle UK",Entites_Noms,Entites_TauxIS),0) -> 2373 | F11: =IFERROR(E11/D11,0) -> 0.25005269 | G11: =ROUND(5%*_xlfn.XLOOKUP("Maison Aurèle UK",Entites_Noms,Entites_MasseSal)+5%*_xlfn.XLOOKUP("Maison Aurèle UK",Entites_Noms,Entites_ActifsCorp),0) -> 975 | H11: =D11-G11 -> 8515 | I11: =MAX(0,ROUND((15%-F11)*H11,0)) -> 0 | J11: =IF(F11<15%,"⚠️ Top-up "&TEXT((15%-F11)*H11,"#,##0")&" k€","✅ Conforme "&TEXT(F11,"0.0%")) -> ✅ Conforme 2.5%
A12: Hong Kong | B12: 28000 | C12: =IFERROR(-_xlfn.XLOOKUP("Maison Aurèle China",Recap_Entites,Recap_RoyaltyTotal),0) -> -5295 | D12: 22705 | E12: =ROUND(D12*_xlfn.XLOOKUP("Maison Aurèle China",Entites_Noms,Entites_TauxIS),0) -> 3746 | F12: =IFERROR(E12/D12,0) -> 0.16498569 | G12: =ROUND(5%*_xlfn.XLOOKUP("Maison Aurèle China",Entites_Noms,Entites_MasseSal)+5%*_xlfn.XLOOKUP("Maison Aurèle China",Entites_Noms,Entites_ActifsCorp),0) -> 2150 | H12: =D12-G12 -> 20555 | I12: =MAX(0,ROUND((15%-F12)*H12,0)) -> 0 | J12: =IF(F12<15%,"⚠️ Top-up "&TEXT((15%-F12)*H12,"#,##0")&" k€","✅ Conforme "&TEXT(F12,"0.0%")) -> ✅ Conforme 1.6%
A13: EAU (Dubaï) | B13: 8000 | C13: =IFERROR(-_xlfn.XLOOKUP("Maison Aurèle ME",Recap_Entites,Recap_RoyaltyTotal),0) -> -1770 | D13: 6230 | E13: =ROUND(D13*_xlfn.XLOOKUP("Maison Aurèle ME",Entites_Noms,Entites_TauxIS),0) -> 561 | F13: =IFERROR(E13/D13,0) -> 0.090048154 | G13: =ROUND(5%*_xlfn.XLOOKUP("Maison Aurèle ME",Entites_Noms,Entites_MasseSal)+5%*_xlfn.XLOOKUP("Maison Aurèle ME",Entites_Noms,Entites_ActifsCorp),0) -> 675 | H13: =D13-G13 -> 5555 | I13: =MAX(0,ROUND((15%-F13)*H13,0)) -> 333 | J13: =IF(F13<15%,"⚠️ Top-up "&TEXT((15%-F13)*H13,"#,##0")&" k€","✅ Conforme "&TEXT(F13,"0.0%")) -> ⚠️ Top-up 333,033 k€
A14: TOTAL | B14: =SUM(B7:B13) -> 203000 | C14: =SUM(C7:C13) -> 4770 | D14: =SUM(D7:D13) -> 207770 | E14: =SUM(E7:E13) -> 50423 | F14: =IFERROR(E14/D14,0) -> 0.24268662 | G14: =SUM(G7:G13) -> 14550 | H14: =SUM(H7:H13) -> 193220 | I14: =SUM(I7:I13) -> 333 | J14: =IF(I14>0,"⚠️ Top-up total à acquitter : "&TEXT(I14,"#,##0")&" k€","✅ Aucun top-up requis") -> ⚠️ Top-up total à acquitter : 333,0 k€
A15: B · ANALYSE GloBE + TRAITEMENT IAS 12
A16: Impact principal | B16: Redevances déplacent du résultat vers la France (licencieur). ETR FR 25.73% > 15%.
A17: ⚠️ IS Japon MAJ | B17: IS actualisé à 31.52% (mars 2026). ETR GloBE Japon conforme avec marge.
A18: ⚠️ EAU (9%) | B18: ETR < 15%. Top-up tax réduit par l'exclusion substance-based income (5% payroll + 5% actifs).
A19: QDMTT France | B19: QDMTT qualifié en vigueur. PLF 2026 aménage les règles d'allocation.
A20: Exclusion substance | B20: NOUVEAU : 5% masse salariale + 5% actifs corporels par juridiction (données en 01_PARAMETRES Section B).
A21: IAS 12 §4A-4C | B21: Exception obligatoire Pilier 2. Top-up tax = charge d'impôt exigible, pas d'ID.

Sheet 09_DOC_PRIX_TRANSFERT
A1: 📁 DOCUMENTATION PRIX DE TRANSFERT
A2: Master File / Local File / CbCR — OCDE Action 13 BEPS
A3: NEURAL — Intelligence Augmentée · Agent RoyaltyAccounting · Mars 2026
A5: A · MASTER FILE
A6: Chap. | B6: Section | C6: Contenu requis | D6: Statut | E6: Responsable | F6: Page réf.
A7: 1 | B7: Structure organisationnelle | C7: Organigramme juridique et opérationnel | D7: ✅ Fait | E7: Direction juridique | F7: p. 3-8
A8: 2 | B8: Description des activités | C8: Activités, chaîne de valeur, marques | D8: ✅ Fait | E8: Direction stratégie | F8: p. 9-18
A9: 3 | B9: Incorporels du groupe | C9: Marques AURÈLE/IMPÉRIAL/STELLAIRE, stratégie IP | D9: ✅ Fait | E9: Direction IP | F9: p. 19-28
A10: 4 | B10: Activités financières intercos | C10: Prêts IG, cash pooling, garanties | D10: ✅ Fait | E10: Direction financière | F10: p. 29-34
A11: 5 | B11: Situation fiscale et financière | C11: Comptes consolidés, rulings, APAs | D11: ✅ Fait | E11: Direction fiscale | F11: p. 35-42
A12: 6 | B12: Politique prix de transfert | C12: CUP/TNMM, analyse fonctionnelle | D12: ✅ Fait | E12: TP Manager | F12: p. 43-58
A13: 7 | B13: Benchmark redevances | C13: Comparables, IQR, conclusion ALP | D13: ✅ Fait | E13: TP Manager | F13: p. 59-72
A14: 8 | B14: Amount B — Pilier 1 | C14: Rendement baseline distributeurs | D14: 🔄 En cours | E14: TP Manager | F14: p. 73-80
A16: B · CbCR — FORMULAIRE 2258-SD (montants dynamiques)
A17: Juridiction | B17: CA total (k€) | C17: CA parties liées (k€) | D17: Résultat avant IS (k€) | E17: IS payé (k€) | F17: Effectifs
A18: France | B18: 180000 | C18: ='03_CALCUL_ROYALTIES'!$F$70 -> 27475 | D18: 120000 | E18: 30876 | F18: 850
A19: Italie | B19: 62000 | C19: 3110 | D19: 15000 | E19: 4146 | F19: 220
A20: Japon | B20: 83000 | C20: 4210 | D20: 18000 | E20: 5512 | F20: 180
A21: États-Unis | B21: 115000 | C21: 5810 | D21: 25000 | E21: 5250 | F21: 310
A22: Royaume-Uni | B22: 50000 | C22: 2510 | D22: 10000 | E22: 2500 | F22: 140
A23: Hong Kong | B23: 105000 | C23: 5295 | D23: 22000 | E23: 3630 | F23: 280
A24: EAU | B24: 35000 | C24: 1770 | D24: 6500 | E24: 585 | F24: 90

Sheet 10_DASHBOARD
A1: 📊 DASHBOARD — 100% DYNAMIQUE
A2: KPIs liés · Graphiques · Alertes automatiques
A3: NEURAL — Intelligence Augmentée · Agent RoyaltyAccounting · Mars 2026
A5: A · KPIs DYNAMIQUES
A6: KPI | B6: Valeur | C6: Unité | D6: Cible | E6: Statut | F6: Tendance | G6: Commentaire
A7: Total redevances groupe | B7: ='03_CALCUL_ROYALTIES'!$F$70 -> 27475 | C7: k€ | D7: — | E7: ℹ️ | F7: ↗️ +8% vs N-1 | G7: Lié à 03_CALCUL
A8: Taux moyen pondéré | B8: =IF('03_CALCUL_ROYALTIES'!$B$70>0,'03_CALCUL_ROYALTIES'!$F$70/'03_CALCUL_ROYALTIES'!$B$70,0) -> 0.050412844 | C8: % | D8: 4-6% | E8: ✅ | F8: → Stable | G8: Formule dynamique
A9: Contrats actifs | B9: 21 | C9: contrats | D9: — | E9: ℹ️ | F9: → Stable | G9: 7 entités × 3 marques
A10: WHT totale retenue | B10: =WHT_Total -> 739 | C10: k€ | D10: < 1 000 | E10: ✅ | F10: ↘️ -5% | G10: Lié à 06_RETENUES
A11: Juridictions risque P2 | B11: =COUNTIF('08_PILIER2_GLOBE'!F7:F13,"<15%") -> 1 | C11: pays | D11: 0 | E11: =IF(B11=0,"✅","⚠️ "&B11&" pays < 15%") -> ⚠️ 1 pays < 15% | F11: → Stable | G11: HK (16.5%), EAU (9%)
A12: Conformité ALP | B12: 3/3 | C12: — | D12: 100% | E12: ✅ | F12: → Stable | G12: Toutes marques dans IQR
A13: Documentation TP | B13: 92% | C13: — | D13: 100% | E13: 🔄 | F13: ↗️ | G13: Amount B en cours
A14: ETR minimum groupe | B14: =MIN('08_PILIER2_GLOBE'!F7:F13) -> 0.090048154 | C14: % | D14: ≥ 15% | E14: =IF(B14>=15%,"✅ Conforme","⚠️ Top-up requis") -> ⚠️ Top-up requis | F14: — | G14: Alerte si < 15%
A16: Royalties nettes de WHT | B16: =B7-B10 -> 26736 | C16: k€ | D16: — | E16: =IF(B16>=B7*0.9,"✅","⚠️ WHT élevée") -> ✅ | F16: → Stable | G16: Après retenues source
A17: Top-up Pilier 2 total | B17: =SUM('08_PILIER2_GLOBE'!I7:I13) -> 333 | C17: k€ | D17: 0 | E17: =IF(B17=0,"✅","⚠️ "&TEXT(B17,"#,##0")&" k€") -> ⚠️ 333,0 k€ | F17: — | G17: Lié à 08_PILIER2
A18: P&L change total | B18: =SUM('03_CALCUL_ROYALTIES'!K63:K69) -> -159 | C18: k€ | D18: — | E18: =IF(ABS(B18)<500,"✅","⚠️ "&TEXT(B18,"#,##0")&" k€") -> ✅ | F18: ↓ Impact FX | G18: IAS 21 §39 conversion
A19: Taux WHT effectif | B19: =IFERROR(B10/B7,0) -> 0.026897179 | C19: % | D19: < 3.0% | E19: =IF(B19<3%,"✅","⚠️ WHT élevée") -> ✅ | F19: → Stable | G19: WHT/Royalty brute
A20: Ratio royalty/CA groupe | B20: =IFERROR(GrandTotal_Royalty/GrandTotal_CA,0) -> 0.050412844 | C20: % | D20: 4-6% | E20: =IF(AND(B20>=4%,B20<=6%),"✅","⚠️ Hors cible") -> ✅ | F20: → Stable | G20: Plages nommées GrandTotal
A21: ETR groupe pondéré | B21: =IFERROR(SUM('08_PILIER2_GLOBE'!E7:E13)/SUM('08_PILIER2_GLOBE'!D7:D13),0) -> 0.24268662 | C21: % | D21: ≥ 15% | E21: =IF(B21>=15%,"✅ Conforme","⚠️ Attention") -> ✅ Conforme | F21: — | G21: Lié à 08_PILIER2
A23: B · DONNÉES GRAPHIQUE — PAR ENTITÉ
A24: Entité | B24: Royalty (k€)
A25: Paris | B25: ='03_CALCUL_ROYALTIES'!F63 -> 4770
A26: Italia | B26: ='03_CALCUL_ROYALTIES'!F64 -> 3110
A27: Japan | B27: ='03_CALCUL_ROYALTIES'!F65 -> 4210
A28: USA | B28: ='03_CALCUL_ROYALTIES'!F66 -> 5810
A29: UK | B29: ='03_CALCUL_ROYALTIES'!F67 -> 2510
A30: China | B30: ='03_CALCUL_ROYALTIES'!F68 -> 5295
A31: ME | B31: ='03_CALCUL_ROYALTIES'!F69 -> 1770
A33: C · DONNÉES GRAPHIQUE — PAR MARQUE
A34: Marque | B34: Royalty totale (k€)
A35: AURÈLE | B35: =SUMPRODUCT(CA_AURELE)*TauxRoyalty_AURELE -> 12250
A36: IMPÉRIAL | B36: =SUMPRODUCT(CA_IMPERIAL)*TauxRoyalty_IMPERIAL -> 8325
A37: STELLAIRE | B37: =SUMPRODUCT(CA_STELLAIRE)*TauxRoyalty_STELLAIRE -> 6900
A39: D · ALERTES & ACTIONS
A40: Priorité | B40: Alerte | C40: Détail | D40: Action requise | E40: Responsable | F40: Échéance | G40: Statut
A41: 🔴 Haute | B41: ETR EAU < 15% | C41: IS 9% — top-up tax Pilier 2 (réduit par exclusion substance) | D41: Revoir structure / taux royalty EAU | E41: Direction fiscale | F41: Q2 2026 | G41: En cours
A42: 🔴 Haute | B42: JPY -11.8% | C42: Yen au plus bas 30 ans → perte ~496 k€ sur royalties Japan | D42: Couverture de change ou ajustement taux | E42: Direction financière | F42: Immédiat | G42: Urgent
A43: 🟡 Moyenne | B43: Amount B compliance | C43: Pilier 1 effectif 2025 — doc à finaliser | D43: Finaliser analyse baseline | E43: TP Manager | F43: Q3 2026 | G43: En cours
A44: 🟡 Moyenne | B44: ETR HK proche seuil | C44: 16.5% — marge faible vs 15% | D44: Monitoring continu | E44: Direction fiscale | F44: Continu | G44: Surveillé
A45: 🟢 Basse | B45: EU Unshell (ATAD III) | C45: Substance IP Holding à documenter | D45: Cf. 13_SUBSTANCE | E45: Direction juridique | F45: Q4 2026 | G45: Planifié
...

Sheet 11_CONTROLES
A1: ✅ CONTRÔLES & RÉCONCILIATIONS — FORMULES
A2: Tests automatiques inter-onglets
A3: NEURAL — Intelligence Augmentée · Agent RoyaltyAccounting · Mars 2026
A5: A · CONTRÔLES AUTOMATIQUES
A6: N° | B6: Contrôle | C6: Valeur attendue | D6: Valeur calculée | E6: Écart | F6: Statut | G6: Référence
A7: C01 | B7: Royalties 03_CALCUL = Dashboard | C7: ='03_CALCUL_ROYALTIES'!$F$70 -> 27475 | D7: ='03_CALCUL_ROYALTIES'!$F$70 -> 27475 | E7: =C7-D7 -> 0 | F7: 03→10
A8: C02 | B8: Charges licenciés = Produits licencieur | C8: ='03_CALCUL_ROYALTIES'!$F$70 -> 27475 | D8: =SUM('07_ELIMINATIONS_CONSO'!D7:D13) -> 27475 | E8: =C8-D8 -> 0 | F8: 05→07
A9: C03 | B9: Éliminations P&L = Total redevances | C9: ='03_CALCUL_ROYALTIES'!$F$70 -> 27475 | D9: =-SUM('07_ELIMINATIONS_CONSO'!E7:E13) -> 27475 | E9: =C9-D9 -> 0 | F9: 07→03
A10: C04 | B10: WHT ≤ conventions × royalty | C10: ='06_RETENUES_SOURCE'!$H$13 -> 0 | D10: ='06_RETENUES_SOURCE'!$H$13 -> 0 | E10: =C10-D10 -> 0 | F10: 06
A11: C05 | B11: Taux dans IQR (toutes marques) | C11: Q1-Q3 IQR | D11: Cf. 04_BENCHMARK | E11: — | F11: 04
A12: C06 | B12: ETR ≥ 15% toutes juridictions | C12: ≥ 15% | D12: =MIN('08_PILIER2_GLOBE'!F7:F13) -> 0.090048154 | E12: =IF(D12>=15%,"✅","⚠️ "&TEXT(D12,"0.0%")) -> ⚠️ 0.9% | F12: 08
A13: C07 | B13: Documentation TP complète | C13: 100% | D13: 92% | E13: -8% | F13: 09
A16: 📌 Les contrôles C01-C04 utilisent des formules inter-onglets. Écart ≠ 0 → investigation requise.

Sheet 12_NOTES_IFRS
A1: 📖 NOTES ANNEXES IFRS
A2: Normes applicables + Nouveautés mars 2026
A3: NEURAL — Intelligence Augmentée · Agent RoyaltyAccounting · Mars 2026
A5: A · IAS 38 — IMMOBILISATIONS INCORPORELLES
A6: IAS 38 §5(d) | B6: Droits de licence exclus du scope IAS 38 chez le licencié.
A7: IAS 38 §63 | B7: Marques générées en interne NON reconnues au bilan.
A8: IAS 38 §118 | B8: Incorporels significatifs non reconnus à divulguer en annexe.
A9: IFRS 3 §B32 | B9: Marque acquise → juste valeur (relief from royalty). Cf. 13_VALORISATION.
A11: B · IFRS 15 — REVENUS
A12: IFRS 15 §B63 | B12: Usage-based royalty : produit reconnu à la vente sous-jacente.
A13: IFRS 15 §B63A | B13: Exception : reconnaissance au plus tardif (vente OU obligation satisfaite).
A14: IFRS 15 §B63B | B14: Minimum garanti reconnu si ventes < minimum (rare en luxe).
A15: IFRS 15 §113 | B15: Désagrégation par marque et zone géographique requise.
A17: C · IAS 24 — PARTIES LIÉES
A18: IAS 24 §18 | B18: Redevances IG FY2025 = formule liée à '03_CALCUL_ROYALTIES'!$F$70.
A19: IAS 24 §19 | B19: Soldes IG au 31/12 = royalties Q4 à régler.
A20: IAS 24 §20 | B20: Conditions de pleine concurrence documentées (cf. 04_BENCHMARK).
A22: D · IAS 12 — IMPÔTS & PILIER 2
A23: IAS 12 §39 | B23: WHT = formule liée à '06_RETENUES_SOURCE'!$H$13. Crédit d'impôt conventionnel.
A24: IAS 12 §4A-4C | B24: Exception obligatoire Pilier 2. Top-up tax = charge exigible.
A25: IAS 12 §88A | B25: IS Japon actualisé 31.52% (mars 2026). ETR GloBE recalculé.
A27: E · NOUVEAUTÉS MARS 2026
A28: Pilier 1 Amount B | B28: Effectif jan. 2025. Matrice OCDE rendement baseline distributeurs.
A29: IFRS 18 (2027) | B29: Reclassement redevances reçues : Opérationnel ou Investissement.
A30: EU Unshell (ATAD III) | B30: Substance IP Holding requise. Documentée en 13_SUBSTANCE.
A31: PLF 2026 QDMTT | B31: Aménagement règles d'allocation QDMTT pour entités sans QDMTT dédiée.
A32: IS Japon 31.52% | B32: Hausse confirmée. Impact ETR GloBE recalculé en 08_PILIER2.
A33: JPY historiquement bas | B33: Taux BCE mars 2026 : 0.00547 (−11.8%). Impact royalties Japan.
A34: ESRS G1 / CSRD | B34: Gouvernance fiscale et politique TP à publier dans rapport durabilité.
A36: F · GLOSSAIRE
A37: ALP | B37: Arm's Length Principle — Principe de pleine concurrence
A38: CUP | B38: Comparable Uncontrolled Price
A39: TNMM | B39: Transactional Net Margin Method
A40: WHT | B40: Withholding Tax — Retenue à la source
A41: IQR | B41: Interquartile Range (Q1-Q3)
A42: GloBE | B42: Global Anti-Base Erosion
A43: QDMTT | B43: Qualified Domestic Minimum Top-up Tax
A44: ETR | B44: Effective Tax Rate
A45: CbCR | B45: Country-by-Country Reporting
A46: Amount B | B46: Pilier 1 — Rendement baseline distribution
...

Sheet 13_SUBSTANCE_ATADIII
A1: 🏢 SUBSTANCE ATAD III — EU UNSHELL
A2: Checklist substance IP Holding + Données par entité
A3: NEURAL — Intelligence Augmentée · Agent RoyaltyAccounting · Mars 2026
A5: A · SUBSTANCE DE L'ENTITÉ IP — NEURAL Luxe Holding SAS
A6: Critère de substance | B6: Donnée | C6: Seuil minimum | D6: Statut | E6: Source | F6: Norme | G6: Commentaire
A7: Effectifs dédiés IP (ETP) | B7: 45 ETP | C7: ≥ 10 ETP | D7: ✅ | E7: RH Holding | F7: ATAD III art. 6 | G7: Juristes, brand managers, contrôleurs
A8: Surfaces de bureaux | B8: 1 200 m² | C8: ≥ 100 m² | D8: ✅ | E8: Bail commercial | F8: ATAD III art. 6 | G8: Paris 8e — siège social
A9: Décisions prises en France | B9: 100% | C9: Majorité | D9: ✅ | E9: PV CA/Comité | F9: ATAD III art. 6 | G9: Comité marques mensuel
A10: Contrats signés localement | B10: 100% | C10: Majorité | D10: ✅ | E10: Registre contrats | F10: ATAD III art. 6 | G10: Tous contrats licence signés à Paris
A11: Budget marketing/R&D IP | B11: 12 500 k€ | C11: > 0 | D11: ✅ | E11: Comptabilité | F11: IAS 38 | G11: Investissement marques continu
A12: Masse salariale (k€) | B12: ='01_PARAMETRES'!H22 -> 18500 | C12: — | D12: ℹ️ | E12: 01_PARAMETRES | F12: Pilier 2 | G12: Lié à exclusion substance GloBE
A13: Actifs corporels (k€) | B13: ='01_PARAMETRES'!I22 -> 12000 | C13: — | D13: ℹ️ | E13: 01_PARAMETRES | F13: Pilier 2 | G13: Lié à exclusion substance GloBE
A15: B · SUBSTANCE PAR ENTITÉ LICENCIÉE (données Pilier 2)
A16: Entité | B16: Masse salariale (k€) | C16: Actifs corporels (k€) | D16: Exclusion 5% payroll | E16: Exclusion 5% actifs | F16: Total exclusion substance | G16: % détention | H16: Norme
A17: Maison Aurèle Paris | B17: ='01_PARAMETRES'!H23 -> 42000 | C17: ='01_PARAMETRES'!I23 -> 35000 | D17: =B17*5% -> 2100 | E17: =C17*5% -> 1750 | F17: =D17+E17 -> 3850 | G17: ='01_PARAMETRES'!G23 -> 1 | H17: Pilier 2 GloBE Art. 5.3
A18: Maison Aurèle Italia | B18: ='01_PARAMETRES'!H24 -> 15000 | C18: ='01_PARAMETRES'!I24 -> 8500 | D18: =B18*5% -> 750 | E18: =C18*5% -> 425 | F18: =D18+E18 -> 1175 | G18: ='01_PARAMETRES'!G24 -> 1 | H18: Pilier 2 GloBE Art. 5.3
A19: Maison Aurèle Japan | B19: ='01_PARAMETRES'!H25 -> 22000 | C19: ='01_PARAMETRES'!I25 -> 14000 | D19: =B19*5% -> 1100 | E19: =C19*5% -> 700 | F19: =D19+E19 -> 1800 | G19: ='01_PARAMETRES'!G25 -> 1 | H19: Pilier 2 GloBE Art. 5.3
A20: Maison Aurèle USA | B20: ='01_PARAMETRES'!H26 -> 28000 | C20: ='01_PARAMETRES'!I26 -> 20000 | D20: =B20*5% -> 1400 | E20: =C20*5% -> 1000 | F20: =D20+E20 -> 2400 | G20: ='01_PARAMETRES'!G26 -> 1 | H20: Pilier 2 GloBE Art. 5.3
A21: Maison Aurèle UK | B21: ='01_PARAMETRES'!H27 -> 12000 | C21: ='01_PARAMETRES'!I27 -> 7500 | D21: =B21*5% -> 600 | E21: =C21*5% -> 375 | F21: =D21+E21 -> 975 | G21: ='01_PARAMETRES'!G27 -> 1 | H21: Pilier 2 GloBE Art. 5.3
A22: Maison Aurèle China | B22: ='01_PARAMETRES'!H28 -> 25000 | C22: ='01_PARAMETRES'!I28 -> 18000 | D22: =B22*5% -> 1250 | E22: =C22*5% -> 900 | F22: =D22+E22 -> 2150 | G22: ='01_PARAMETRES'!G28 -> 0.8 | H22: Pilier 2 GloBE Art. 5.3
A23: Maison Aurèle ME | B23: ='01_PARAMETRES'!H29 -> 8000 | C23: ='01_PARAMETRES'!I29 -> 5500 | D23: =B23*5% -> 400 | E23: =C23*5% -> 275 | F23: =D23+E23 -> 675 | G23: ='01_PARAMETRES'!G29 -> 1 | H23: Pilier 2 GloBE Art. 5.3
A25: 📌 ATAD III (EU Unshell) : Les entités sans substance suffisante perdent les avantages des conventions fiscales.
A26: 📌 L'exclusion substance-based income (5%+5%) réduit le résultat GloBE soumis au top-up tax (cf. 08_PILIER2).

Sheet 14_STRESS_TEST
A1: ⚡ STRESS TEST / SCÉNARIOS
A2: Choc de change · Hausse IS · Baisse CA · Impact combiné
A3: NEURAL — Intelligence Augmentée · Agent RoyaltyAccounting · Mars 2026
A5: A · SCÉNARIO 1 — CHOC DE CHANGE (JPY −20%, USD −10%)
A6: Entité | B6: Royalty actuelle (k€) | C6: Devise | D6: Taux moyen actuel | E6: Taux stressé | F6: Royalty stressée (k€) | G6: Impact (k€) | H6: Δ%
A7: Maison Aurèle Paris | B7: ='03_CALCUL_ROYALTIES'!F63 -> 4770 | C7: EUR | D7: =IFERROR(_xlfn.XLOOKUP(C7,FX_Devises,FX_Moyen,1),1) -> 1 | E7: 1 | F7: =B7 -> 4770 | G7: =F7-B7 -> 0 | H7: =IF(B7>0,G7/B7,0) -> 0
A8: Maison Aurèle Italia | B8: ='03_CALCUL_ROYALTIES'!F64 -> 3110 | C8: EUR | D8: =IFERROR(_xlfn.XLOOKUP(C8,FX_Devises,FX_Moyen,1),1) -> 1 | E8: 1 | F8: =B8 -> 3110 | G8: =F8-B8 -> 0 | H8: =IF(B8>0,G8/B8,0) -> 0
A9: Maison Aurèle Japan | B9: ='03_CALCUL_ROYALTIES'!F65 -> 4210 | C9: JPY | D9: =IFERROR(_xlfn.XLOOKUP(C9,FX_Devises,FX_Moyen,1),1) -> 0.00625 | E9: 0.005 | F9: =ROUND(B9*E9/D9,0) -> 3368 | G9: =F9-B9 -> -842 | H9: =IF(B9>0,G9/B9,0) -> -0.2
A10: Maison Aurèle USA | B10: ='03_CALCUL_ROYALTIES'!F66 -> 5810 | C10: USD | D10: =IFERROR(_xlfn.XLOOKUP(C10,FX_Devises,FX_Moyen,1),1) -> 0.9259 | E10: 0.8333 | F10: =ROUND(B10*E10/D10,0) -> 5229 | G10: =F10-B10 -> -581 | H10: =IF(B10>0,G10/B10,0) -> -0.1
A11: Maison Aurèle UK | B11: ='03_CALCUL_ROYALTIES'!F67 -> 2510 | C11: GBP | D11: =IFERROR(_xlfn.XLOOKUP(C11,FX_Devises,FX_Moyen,1),1) -> 1.1494 | E11: 1.1494 | F11: =ROUND(B11*E11/D11,0) -> 2510 | G11: =F11-B11 -> 0 | H11: =IF(B11>0,G11/B11,0) -> 0
A12: Maison Aurèle China | B12: ='03_CALCUL_ROYALTIES'!F68 -> 5295 | C12: HKD | D12: =IFERROR(_xlfn.XLOOKUP(C12,FX_Devises,FX_Moyen,1),1) -> 0.119 | E12: 0.107 | F12: =ROUND(B12*E12/D12,0) -> 4761 | G12: =F12-B12 -> -534 | H12: =IF(B12>0,G12/B12,0) -> -0.10084986
A13: Maison Aurèle ME | B13: ='03_CALCUL_ROYALTIES'!F69 -> 1770 | C13: AED | D13: =IFERROR(_xlfn.XLOOKUP(C13,FX_Devises,FX_Moyen,1),1) -> 0.2525 | E13: 0.2272 | F13: =ROUND(B13*E13/D13,0) -> 1593 | G13: =F13-B13 -> -177 | H13: =IF(B13>0,G13/B13,0) -> -0.1
A14: TOTAL IMPACT | B14: =SUM(B7:B13) -> 27475 | F14: =SUM(F7:F13) -> 25341 | G14: =SUM(G7:G13) -> -2134
A16: B · SCÉNARIO 2 — HAUSSE IS EAU À 15% (alignement Pilier 2)
A17: Paramètre | B17: Valeur actuelle | C17: Valeur stressée | D17: Impact royalty | E17: Impact top-up tax | F17: Impact net groupe
