Workbook
Name LISTE_METIERS: '02_REF_METIERS'!$B$4:$B$100
Name POIDS_SCORING: '01_PARAMETRES'!$D$17:$D$21
Name SEUILS_SCORES: '01_PARAMETRES'!$C$26:$C$30

Sheet Claude Log
A1: Tour # | B1: Date | C1: Demande utilisateur | D1: Action réalisée | E1: Détails | F1: Résultat
A2: 1 | B2: 46113 | C2: Analyser les correctifs proposés (5 erreurs + 4 conflits) et appliquer ceux qui sont pertinents pour le projet NEURAL_LuxeArtisanTalent | D2: Audit complet des 9 points signalés. 3 correctifs appliqués : Dashboard B2 (#VALEUR!), Dashboard B5 (COUNTA→COUNTIF), plage nommée LISTE_METIERS créée. | E2: Erreur #1 (SCORING dim.): Non reproduite - formules 03_COMPETENCES utilisent SUMPRODUCT de moyenne /20, pas de référence C14:C18. Erreur #2 (VIVIER VLOOKUP): Déjà corrigée - E8:E10 utilisent IFERROR(VLOOKUP(),'—'). Erreur #3 (GAP retraite): Correct - colonne I contient ages, '>='&(62-N) est juste. Erreur #4 (SUCCESSION double source): Non reproduite - colonne E contient textes statiques, pas de VLOOKUP. Erreur #5 (DASHBOARD NB.SI): CORRIGÉ - B5 remplacé par COUNTIF('<>'&''). Conflit C1: CORRIGÉ - LISTE_METIERS créée en $B$4:$B$100. Conflit C2 (INDIRECT): Non reproduit. Conflit C3 (doublons): Cosmétique. Conflit C4 (emojis filtres): Style seul. Bonus: CORRIGÉ - B2 Dashboard #VALEUR! via format 'jj/mm/aaaa'. | F2: Dashboard B2 = '📅 Analyse du : 01/04/2026'. B5 = 38 artisans. LISTE_METIERS = '02_REF_METIERS'!$B$4:$B$100 (capacité 97 métiers). Les 4 erreurs non appliquées ne correspondent pas à la structure réelle du fichier.
A3: 2 | B3: 46113 | C3: Implémenter 4 automatisations : AUTO-1 mapping compétences, AUTO-2 alertes vivier enrichies, AUTO-3 GAP dynamique avec params retraite, AUTO-4 score risque succession | D3: 4 automatisations déployées : onglet 03b_MAPPING créé, formules alertes M8:M27 mises à jour (3 niveaux), nouveaux paramètres Section E dans 01_PARAMETRES, formules K/L/M GAP mises à jour, colonnes O/P risque ajoutées à 08_SUCCESSION | E3: AUTO-1: 03b_MAPPING créé (14 lignes, 5 catégories, synthèse par dimension). AUTO-2: Alertes VIVIER → 3 niveaux 🟢/⚠️/🔴 avec nombre de jours + étape actuelle. KPI J3 mis à jour (COUNTIF double). AUTO-3: Params Section E — C45=3 (horizon), C46=55 (vigilance), C47=61 (âge critique auto=C48-C45), C48=64 (âge retraite — C44 bloqué, utilisé C48). GAP K/L/M reformulés sur C48 et C45. AUTO-4: 08_SUCCESSION colonnes O (score 0-1) et P (label 🟢-⚫) — score=(1-readiness)*MAX(0,MIN(1,(C48-âge)/C45)). Formatage couleur appliqué sur O/P et M (vivier). | F3: Scores succession tous 🟢 Faible (0.04-0.22) car readiness actuelle très élevée (85-96%). VIVIER: 3 DORMANTS détectés (Marie D. 45j, Jean P. 48j, Akiko T. 59j). GAP projections N+1 dynamiques sur âge_retraite paramétrable.

Sheet 01_PARAMETRES
B1: ⚙️ NEURAL — LuxeArtisanTalent · Paramètres Généraux
B2: Configuration générale · Identité de la maison · Paramètres de scoring
B4: ▌ SECTION A — IDENTITÉ MAISON
B5: Maison
B6: Secteur d'activité | C6: =IF(C5="","",IF(C5="Hermès","Maroquinerie / Cuir",IF(C5="Chanel","Couture / Parfums",IF(C5="Cartier","Joaillerie / Horlogerie",IF(C5="Boucheron","Joaillerie",IF(C5="Van Cleef & Arpels","Joaillerie",IF(C5="Louis Vuitton","Maroquinerie / Mode",IF(C5="Dior","Couture / Parfums",IF(C5="Berluti","Maroquinerie / Chaussure",IF(C5="Loro Piana","Textile / Cachemire","Multi-métiers"))))))))))
B7: Pays siège
B8: Nombre de sites prod.
B9: Effectif total
B10: Dont artisans
B11: % artisans / effectif | C11: =IF(C9=0,"",C10/C9)
B12: Date d'analyse | C12: =TODAY() -> 46113
B13: Analyste NEURAL
B15: ▌ SECTION B — PARAMÈTRES DE SCORING
B16: Dimension | C16: Poids % | D16: Poids décimal | E16: Validation
B17: Maîtrise technique | C17: 35% | D17: 0.35
B18: Années d'expérience | C18: 20% | D18: 0.2
B19: Rareté du savoir-faire | C19: 20% | D19: 0.2
B20: Potentiel transmission | C20: 15% | D20: 0.15
B21: Adéquation culturelle | C21: 10% | D21: 0.1
B22: TOTAL | C22: =SUM(D17:D21) -> 1 | D22: =SUM(D17:D21) -> 1 | E22: =IF(ABS(D22-1)<0.001,"✅ Pondération valide","❌ Total = "&TEXT(D22,"0%")&" — Doit = 100%") -> ✅ Pondération valide
B24: ▌ SECTION C — SEUILS DE CLASSIFICATION
B25: Niveau | C25: Seuil (%) | D25: Label | E25: Couleur référence
B26: 🟢 Maître d'Art | C26: 0.85 | D26: ≥ 85% | E26: Émeraude
B27: 🔵 Expert | C27: 0.7 | D27: 70–84% | E27: Bleu Nuit
B28: 🟡 Confirmé | C28: 0.55 | D28: 55–69% | E28: Ambre
B29: 🟠 Junior | C29: 0.4 | D29: 40–54% | E29: Orange
B30: 🔴 Apprenti | C30: 0 | D30: < 40% | E30: Rouge
B33: ▌ SECTION D — LISTES DE RÉFÉRENCE (Plages nommées)
B34: Nom Plage | C34: Référence | E34: Description
B35: LISTE_MAISONS | C35: 01_PARAMETRES!$C$5 | E35: Maisons disponibles
B36: LISTE_METIERS | C36: 02_REF_METIERS!$C$3:$C$52 | E36: Catalogue des métiers
B37: LISTE_PAYS | C37: 01_PARAMETRES!$C$7 | E37: Pays référencés
B38: LISTE_NIVEAUX | C38: '01_PARAMETRES'!$B$26:$B$30 | E38: Niveaux de classification
B39: POIDS_SCORING | C39: '01_PARAMETRES'!$D$17:$D$21 | E39: Pondérations (décimales)
B40: SEUILS | C40: '01_PARAMETRES'!$C$26:$C$30 | E40: Seuils de scoring
B41: PARAMS_RETRAITE | C41: 01_PARAMETRES'!$C$44:$C$46 | E41: Âge retraite, horizon, âge vigilance
B42: ▌ SECTION E — PARAMÈTRES DE PROJECTION RETRAITE
B43: Paramètre | C43: 4300 | D43: Unité | E43: Usage
B44: Âge de retraite légal → voir C48
B45: Horizon d'alerte retraite | C45: 3 | D45: ans | E45: Seuil d'alerte : artisans partant dans X ans
...

Sheet 02_REF_METIERS
B1: 📋 NEURAL — REF_METIERS · Catalogue des Métiers d'Art du Luxe
B2: Référentiel exhaustif · ~50 métiers · Classifiés par famille · Filtres actifs
B3: ID | C3: Famille | D3: Métier | E3: Rareté /10 | F3: Délai formation | G3: Risque pénurie | H3: Écoles / Formations référentes | I3: Pays formation | J3: Salaire médian FR (€ brut/an) | K3: Salaire médian CH (CHF/an) | L3: Salaire médian IT (€ brut/an) | M3: Praticiens France (est.) | N3: Tendance effectifs | O3: EPV éligible | P3: MOF existant
B4: M01 | C4: Maroquinerie | D4: Sellier-maroquinier | E4: 9 | F4: 5 ans | G4: =IF(E4>=9,"🔴 Critique",IF(E4>=7,"🟡 Tendu","🟢 OK")) -> 🔴 Critique | H4: ENSAAMA / CFPPA Cuir Paris | I4: France / Italie | J4: 42000 | K4: 68000 | L4: 36000 | M4: 3200 | N4: ↘️ | O4: ✅ | P4: ✅
B5: M02 | C5: Maroquinerie | D5: Coupeur cuir | E5: 7 | F5: 3 ans | G5: =IF(E5>=9,"🔴 Critique",IF(E5>=7,"🟡 Tendu","🟢 OK")) -> 🟡 Tendu | H5: CFPPA Cuir Paris / CFA Mode | I5: France | J5: 34000 | K5: 55000 | L5: 30000 | M5: 4800 | N5: ↘️ | O5: — | P5: —
B6: M03 | C6: Maroquinerie | D6: Piqueur main | E6: 8 | F6: 4 ans | G6: =IF(E6>=9,"🔴 Critique",IF(E6>=7,"🟡 Tendu","🟢 OK")) -> 🟡 Tendu | H6: ENSAAMA / Institut Guillet | I6: France / Espagne | J6: 36000 | K6: 60000 | L6: 32000 | M6: 2100 | N6: ↘️ | O6: ✅ | P6: —
B7: M04 | C7: Maroquinerie | D7: Teinturier cuir | E7: 6 | F7: 2 ans | G7: =IF(E7>=9,"🔴 Critique",IF(E7>=7,"🟡 Tendu","🟢 OK")) -> 🟢 OK | H7: CFPPA Cuir / Hermès interne | I7: France | J7: 31000 | K7: 50000 | L7: 28000 | M7: 1500 | N7: → | O7: — | P7: —
B8: M05 | C8: Joaillerie | D8: Sertisseur | E8: 9 | F8: 5 ans | G8: =IF(E8>=9,"🔴 Critique",IF(E8>=7,"🟡 Tendu","🟢 OK")) -> 🔴 Critique | H8: BJO Paris / École Boulle | I8: France / Belgique | J8: 45000 | K8: 72000 | L8: 38000 | M8: 2800 | N8: ↘️ | O8: ✅ | P8: ✅
B9: M06 | C9: Joaillerie | D9: Polisseur joaillier | E9: 7 | F9: 3 ans | G9: =IF(E9>=9,"🔴 Critique",IF(E9>=7,"🟡 Tendu","🟢 OK")) -> 🟡 Tendu | H9: BJO Paris / AFPIA | I9: France | J9: 32000 | K9: 52000 | L9: 28000 | M9: 3400 | N9: → | O9: — | P9: —
B10: M07 | C10: Joaillerie | D10: Lapidaire | E10: 10 | F10: 7 ans | G10: =IF(E10>=9,"🔴 Critique",IF(E10>=7,"🟡 Tendu","🟢 OK")) -> 🔴 Critique | H10: GIA / IFG Anvers | I10: France / Belgique / Inde | J10: 55000 | K10: 88000 | L10: 45000 | M10: 620 | N10: ↘️ | O10: ✅ | P10: ✅
B11: M08 | C11: Joaillerie | D11: Orfèvre | E11: 8 | F11: 4 ans | G11: =IF(E11>=9,"🔴 Critique",IF(E11>=7,"🟡 Tendu","🟢 OK")) -> 🟡 Tendu | H11: BJOP / École Boulle | I11: France / Italie | J11: 42000 | K11: 68000 | L11: 36000 | M11: 1900 | N11: ↘️ | O11: ✅ | P11: ✅
B12: M09 | C12: Joaillerie | D12: Guillocheur | E12: 10 | F12: 8 ans | G12: =IF(E12>=9,"🔴 Critique",IF(E12>=7,"🟡 Tendu","🟢 OK")) -> 🔴 Critique | H12: Piaget interne / FHH | I12: Suisse / France | J12: 65000 | K12: 95000 | L12: 52000 | M12: 180 | N12: ↘️ | O12: ✅ | P12: ✅
B13: M10 | C13: Horlogerie | D13: Horloger | E13: 8 | F13: 5 ans | G13: =IF(E13>=9,"🔴 Critique",IF(E13>=7,"🟡 Tendu","🟢 OK")) -> 🟡 Tendu | H13: ENSP Cluses / Le Sentier | I13: Suisse / France | J13: 48000 | K13: 85000 | L13: 38000 | M13: 3600 | N13: ↘️ | O13: — | P13: ✅
B14: M11 | C14: Horlogerie | D14: Cadranier | E14: 9 | F14: 6 ans | G14: =IF(E14>=9,"🔴 Critique",IF(E14>=7,"🟡 Tendu","🟢 OK")) -> 🔴 Critique | H14: ENSP / Rolex interne | I14: Suisse | J14: 58000 | K14: 92000 | L14: N/D | M14: 280 | N14: ↘️ | O14: ✅ | P14: ✅
B15: M12 | C15: Horlogerie | D15: Émailleur | E15: 10 | F15: 8 ans | G15: =IF(E15>=9,"🔴 Critique",IF(E15>=7,"🟡 Tendu","🟢 OK")) -> 🔴 Critique | H15: Formation maisons / rare | I15: Suisse / France | J15: 70000 | K15: 110000 | L15: N/D | M15: 95 | N15: ↘️ | O15: ✅ | P15: ✅
B16: M13 | C16: Couture | D16: Première main couture | E16: 9 | F16: 6 ans | G16: =IF(E16>=9,"🔴 Critique",IF(E16>=7,"🟡 Tendu","🟢 OK")) -> 🔴 Critique | H16: ESMOD / Studio Berçot | I16: France | J16: 46000 | K16: N/D | L16: 36000 | M16: 890 | N16: ↘️ | O16: ✅ | P16: ✅
B17: M14 | C17: Couture | D17: Plumassier | E17: 10 | F17: 7 ans | G17: =IF(E17>=9,"🔴 Critique",IF(E17>=7,"🟡 Tendu","🟢 OK")) -> 🔴 Critique | H17: Lemarié interne / ENSAD | I17: France | J17: 52000 | K17: N/D | L17: N/D | M17: 140 | N17: ↘️ | O17: ✅ | P17: ✅
B18: M15 | C18: Couture | D18: Brodeur haute couture | E18: 8 | F18: 4 ans | G18: =IF(E18>=9,"🔴 Critique",IF(E18>=7,"🟡 Tendu","🟢 OK")) -> 🟡 Tendu | H18: ATELIERS LESAGE / École de la Chambre Syndicale | I18: France | J18: 40000 | K18: N/D | L18: 32000 | M18: 650 | N18: ↘️ | O18: ✅ | P18: ✅
B19: M16 | C19: Couture | D19: Modiste | E19: 9 | F19: 5 ans | G19: =IF(E19>=9,"🔴 Critique",IF(E19>=7,"🟡 Tendu","🟢 OK")) -> 🔴 Critique | H19: ESMOD / Maisons interne | I19: France | J19: 44000 | K19: N/D | L19: 34000 | M19: 320 | N19: ↘️ | O19: ✅ | P19: —
B20: M17 | C20: Parfumerie | D20: Nez (parfumeur) | E20: 10 | F20: 10 ans | G20: =IF(E20>=9,"🔴 Critique",IF(E20>=7,"🟡 Tendu","🟢 OK")) -> 🔴 Critique | H20: ISIPCA Versailles / GIVAUDAN | I20: France / Suisse | J20: 95000 | K20: 145000 | L20: 70000 | M20: 420 | N20: → | O20: ✅ | P20: —
B21: M18 | C21: Cristallerie | D21: Souffleur de verre | E21: 8 | F21: 5 ans | G21: =IF(E21>=9,"🔴 Critique",IF(E21>=7,"🟡 Tendu","🟢 OK")) -> 🟡 Tendu | H21: École du Verre / Pôle Verre | I21: France / Italie | J21: 36000 | K21: 58000 | L21: 30000 | M21: 1200 | N21: ↘️ | O21: ✅ | P21: —
B22: M19 | C22: Cristallerie | D22: Tailleur de cristal | E22: 9 | F22: 6 ans | G22: =IF(E22>=9,"🔴 Critique",IF(E22>=7,"🟡 Tendu","🟢 OK")) -> 🔴 Critique | H22: École du Verre Saint-Louis | I22: France | J22: 42000 | K22: 65000 | L22: 34000 | M22: 380 | N22: ↘️ | O22: ✅ | P22: ✅
B23: M20 | C23: Textile | D23: Tisserand soie | E23: 9 | F23: 5 ans | G23: =IF(E23>=9,"🔴 Critique",IF(E23>=7,"🟡 Tendu","🟢 OK")) -> 🔴 Critique | H23: École de tissage de Lyon | I23: France / Italie | J23: 38000 | K23: 60000 | L23: 32000 | M23: 560 | N23: ↘️ | O23: ✅ | P23: ✅
B24: M21 | C24: Textile | D24: Passementier | E24: 8 | F24: 4 ans | G24: =IF(E24>=9,"🔴 Critique",IF(E24>=7,"🟡 Tendu","🟢 OK")) -> 🟡 Tendu | H24: Lycée La Martinière / Passementerie LUREX | I24: France | J24: 35000 | K24: 55000 | L24: 28000 | M24: 340 | N24: ↘️ | O24: ✅ | P24: —
B25: M22 | C25: Textile | D25: Fourreur | E25: 7 | F25: 4 ans | G25: =IF(E25>=9,"🔴 Critique",IF(E25>=7,"🟡 Tendu","🟢 OK")) -> 🟡 Tendu | H25: LCFA / CFPPA Mode | I25: France / Grèce | J25: 32000 | K25: 52000 | L25: 28000 | M25: 480 | N25: ↘️ | O25: — | P25: —
B26: M23 | C26: Maroquinerie | D26: Gainier | E26: 7 | F26: 3 ans | G26: =IF(E26>=9,"🔴 Critique",IF(E26>=7,"🟡 Tendu","🟢 OK")) -> 🟡 Tendu | H26: École Grégoire-Ferrandi | I26: France | J26: 30000 | K26: 48000 | L26: 26000 | M26: 620 | N26: ↘️ | O26: — | P26: —
B27: M24 | C27: Joaillerie | D27: Dessinateur joaillier | E27: 6 | F27: 3 ans | G27: =IF(E27>=9,"🔴 Critique",IF(E27>=7,"🟡 Tendu","🟢 OK")) -> 🟢 OK | H27: BJO / Camondo | I27: France / Italie | J27: 38000 | K27: 58000 | L27: 32000 | M27: 1200 | N27: → | O27: — | P27: —
B28: M25 | C28: Horlogerie | D28: Décorateur cadrans | E28: 8 | F28: 5 ans | G28: =IF(E28>=9,"🔴 Critique",IF(E28>=7,"🟡 Tendu","🟢 OK")) -> 🟡 Tendu | H28: École d'Horlogerie Genève | I28: Suisse / France | J28: 52000 | K28: 82000 | L28: N/D | M28: 210 | N28: ↘️ | O28: ✅ | P28: —
B29: M26 | C29: Couture | D29: Corsetier | E29: 9 | F29: 5 ans | G29: =IF(E29>=9,"🔴 Critique",IF(E29>=7,"🟡 Tendu","🟢 OK")) -> 🔴 Critique | H29: ESMOD / Maisons interne | I29: France | J29: 44000 | K29: N/D | L29: 34000 | M29: 280 | N29: ↘️ | O29: ✅ | P29: —
B30: M27 | C30: Parfumerie | D30: Évaluateur olfactif | E30: 7 | F30: 5 ans | G30: =IF(E30>=9,"🔴 Critique",IF(E30>=7,"🟡 Tendu","🟢 OK")) -> 🟡 Tendu | H30: ISIPCA / Formation interne | I30: France | J30: 48000 | K30: 75000 | L30: 38000 | M30: 850 | N30: → | O30: — | P30: —
B31: M28 | C31: Cristallerie | D31: Graveur sur verre | E31: 9 | F31: 6 ans | G31: =IF(E31>=9,"🔴 Critique",IF(E31>=7,"🟡 Tendu","🟢 OK")) -> 🔴 Critique | H31: Baccarat interne / École des Arts | I31: France | J31: 45000 | K31: 70000 | L31: 36000 | M31: 190 | N31: ↘️ | O31: ✅ | P31: ✅
B32: M29 | C32: Textile | D32: Dentellière au fuseau | E32: 10 | F32: 8 ans | G32: =IF(E32>=9,"🔴 Critique",IF(E32>=7,"🟡 Tendu","🟢 OK")) -> 🔴 Critique | H32: Conservatoire Dentelle Calais | I32: France / Belgique | J32: 42000 | K32: N/D | L32: 34000 | M32: 95 | N32: ↘️ | O32: ✅ | P32: ✅
B33: M30 | C33: Maroquinerie | D33: Sellier équestre | E33: 8 | F33: 5 ans | G33: =IF(E33>=9,"🔴 Critique",IF(E33>=7,"🟡 Tendu","🟢 OK")) -> 🟡 Tendu | H33: IFCE / École du Cadre Noir | I33: France | J33: 38000 | K33: 62000 | L33: 30000 | M33: 760 | N33: ↘️ | O33: ✅ | P33: ✅
B34: TOTAL — 30 métiers référencés | E34: =AVERAGE(E4:E33) -> 8.4
B36: ▌ STATISTIQUES PAR FAMILLE
B37: Famille | C37: Nb métiers | D37: Rareté moy. | E37: Praticiens total | F37: % Risque critique
B38: Maroquinerie | C38: =COUNTIF($C$4:$C$33,B38) -> 6 | D38: =IFERROR(AVERAGEIF($C$4:$C$33,B38,$E$4:$E$33),"—") -> 7.5 | E38: =IFERROR(SUMIF($C$4:$C$33,B38,$M$4:$M$33),"—") -> 12980 | F38: =IFERROR(COUNTIFS($C$4:$C$33,B38,$E$4:$E$33,">=9")/COUNTIF($C$4:$C$33,B38),"—") -> 0.16666667
B39: Joaillerie | C39: =COUNTIF($C$4:$C$33,B39) -> 6 | D39: =IFERROR(AVERAGEIF($C$4:$C$33,B39,$E$4:$E$33),"—") -> 8.3333333 | E39: =IFERROR(SUMIF($C$4:$C$33,B39,$M$4:$M$33),"—") -> 10100 | F39: =IFERROR(COUNTIFS($C$4:$C$33,B39,$E$4:$E$33,">=9")/COUNTIF($C$4:$C$33,B39),"—") -> 0.5
B40: Horlogerie | C40: =COUNTIF($C$4:$C$33,B40) -> 4 | D40: =IFERROR(AVERAGEIF($C$4:$C$33,B40,$E$4:$E$33),"—") -> 8.75 | E40: =IFERROR(SUMIF($C$4:$C$33,B40,$M$4:$M$33),"—") -> 4185 | F40: =IFERROR(COUNTIFS($C$4:$C$33,B40,$E$4:$E$33,">=9")/COUNTIF($C$4:$C$33,B40),"—") -> 0.5
B41: Couture | C41: =COUNTIF($C$4:$C$33,B41) -> 5 | D41: =IFERROR(AVERAGEIF($C$4:$C$33,B41,$E$4:$E$33),"—") -> 9 | E41: =IFERROR(SUMIF($C$4:$C$33,B41,$M$4:$M$33),"—") -> 2280 | F41: =IFERROR(COUNTIFS($C$4:$C$33,B41,$E$4:$E$33,">=9")/COUNTIF($C$4:$C$33,B41),"—") -> 0.8
...

Sheet 03b_MAPPING
B1: ⚙️ NEURAL — 03b_MAPPING · Correspondance Compétences → Dimensions de Scoring
B2: Matrice de conversion 13 compétences détaillées → 5 dimensions · Utilisée par 04_SCORING pour calcul automatique /100
B4: ▌ MATRICE DE MAPPING — 13 Compétences × 5 Dimensions de Scoring
B5: # | C5: Compétence détaillée | D5: Catégorie source | E5: Dimension Scoring | F5: Poids (01_PARAM)
B6: 1 | C6: Connaissance matières premières | D6: Techniques Fondamentales | E6: Maîtrise technique | F6: 0.35
B7: 2 | C7: Geste de précision / dextérité | D7: Techniques Fondamentales | E7: Maîtrise technique | F7: 0.35
B8: 3 | C8: Lecture plans / croquis techniques | D8: Techniques Fondamentales | E8: Maîtrise technique | F8: 0.35
B9: 4 | C9: Contrôle qualité & finition | D9: Techniques Fondamentales | E9: Maîtrise technique | F9: 0.35
B10: 5 | C10: Outillage spécifique métier | D10: Techniques Fondamentales | E10: Maîtrise technique | F10: 0.35
B11: 6 | C11: Innovation & adaptation technique | D11: Techniques Avancées | E11: Rareté savoir-faire | F11: 0.2
B12: 7 | C12: Prototypage & maquette | D12: Techniques Avancées | E12: Rareté savoir-faire | F12: 0.2
B13: 8 | C13: Restauration / service après-vente | D13: Techniques Avancées | E13: Années d'expérience | F13: 0.2
B14: 9 | C14: Maîtrise des techniques rares | D14: Techniques Avancées | E14: Rareté savoir-faire | F14: 0.2
B15: 10 | C15: Transmission & mentorat | D15: Compétences Transverses | E15: Potentiel transmission | F15: 0.15
B16: 11 | C16: Créativité & proposition | D16: Compétences Transverses | E16: Adéquation culturelle | F16: 0.1
B17: 12 | C17: Travail en atelier collectif | D17: Compétences Transverses | E17: Potentiel transmission | F17: 0.15
... B19: 14 | C19: Sens esthétique & raffinement | D19: Compétences Transverses | E19: Adéquation culturelle | F19: 0.1
B21: ▌ SYNTHÈSE PAR DIMENSION — Nb compétences mappées & poids associé
B22: Dimension | C22: Nb compétences | D22: Poids scoring | E22: Formule conversion /100
B23: Maîtrise technique | C23: =COUNTIF(E6:E19,"Maîtrise technique") -> 5 | D23: =AVERAGEIF(E6:E19,"Maîtrise technique",F6:F19) -> 0.35 | E23: =AVERAGEIF(E6:E19,"Maîtrise technique",F6:F19)*100&"%" -> 35%
B24: Années d'expérience | C24: =COUNTIF(E6:E19,"Années d'expérience") -> 1 | D24: =AVERAGEIF(E6:E19,"Années d'expérience",F6:F19) -> 0.2 | E24: =AVERAGEIF(E6:E19,"Années d'expérience",F6:F19)*100&"%" -> 20%
B25: Rareté savoir-faire | C25: =COUNTIF(E6:E19,"Rareté savoir-faire") -> 3 | D25: =AVERAGEIF(E6:E19,"Rareté savoir-faire",F6:F19) -> 0.2 | E25: =AVERAGEIF(E6:E19,"Rareté savoir-faire",F6:F19)*100&"%" -> 20%
B26: Potentiel transmission | C26: =COUNTIF(E6:E19,"Potentiel transmission") -> 2 | D26: =AVERAGEIF(E6:E19,"Potentiel transmission",F6:F19) -> 0.15 | E26: =AVERAGEIF(E6:E19,"Potentiel transmission",F6:F19)*100&"%" -> 15%
B27: Adéquation culturelle | C27: =COUNTIF(E6:E19,"Adéquation culturelle") -> 3 | D27: =AVERAGEIF(E6:E19,"Adéquation culturelle",F6:F19) -> 0.1 | E27: =AVERAGEIF(E6:E19,"Adéquation culturelle",F6:F19)*100&"%" -> 10%
B29: 💡 USAGE 04_SCORING : Score dimension = AVERAGEIF(03b_MAPPING!$E$6:$E$19, "[dimension]", [scores cand. /5]) / 5 * 100
B31: NEURAL — Intelligence Augmentée pour l'Entreprise · neural-platform.vercel.app · Données simulées à des fins de démonstration

Sheet 03_COMPETENCES
B1: 📋 NEURAL — COMPETENCES · Matrice des Compétences par Métier d'Art
B2: Niveau attendu par compétence × métier · Pondéré par les paramètres de scoring
B3: Compétence | C3: M01 | D3: M05 | E3: M07 | F3: M09 | G3: M10 | H3: M12 | I3: M13 | J3: M14 | K3: M17 | L3: M19 | M3: M20 | N3: Poids Scoring
B4: — Catégorie — | C4: Sellier- maroq. | D4: Sertisseur | E4: Lapidaire | F4: Guillocheur | G4: Horloger | H4: Émailleur | I4: Première main | J4: Plumassier | K4: Nez | L4: Tailleur cristal | M4: Tisserand soie | N4: Description
B5: ▌ TECHNIQUES FONDAMENTALES
B6: Connaissance matières premières | C6: 5 | D6: 5 | E6: 5 | F6: 4 | G6: 3 | H6: 4 | I6: 4 | J6: 5 | K6: 5 | L6: 5 | M6: 5 | N6: Cuir/pierre/alliage/tissu selon métier
B7: Geste de précision / dextérité | C7: 5 | D7: 5 | E7: 5 | F7: 5 | G7: 5 | H7: 5 | I7: 5 | J7: 5 | K7: 2 | L7: 5 | M7: 4 | N7: Maîtrise du geste artisanal
B8: Lecture plans / croquis techniques | C8: 4 | D8: 4 | E8: 5 | F8: 5 | G8: 5 | H8: 4 | I8: 5 | J8: 4 | K8: 1 | L8: 4 | M8: 3 | N8: Interprétation des schémas
B9: Contrôle qualité & finition | C9: 5 | D9: 5 | E9: 5 | F9: 5 | G9: 5 | H9: 5 | I9: 5 | J9: 5 | K9: 3 | L9: 5 | M9: 5 | N9: Exigence du niveau luxe
B10: Outillage spécifique métier | C10: 5 | D10: 5 | E10: 5 | F10: 5 | G10: 5 | H10: 5 | I10: 3 | J10: 3 | K10: 1 | L10: 5 | M10: 4 | N10: Maîtrise des outils propres au métier
B11: ▌ TECHNIQUES AVANCÉES
B12: Innovation & adaptation technique | C12: 3 | D12: 3 | E12: 4 | F12: 4 | G12: 4 | H12: 5 | I12: 3 | J12: 4 | K12: 5 | L12: 3 | M12: 3 | N12: Capacité à évoluer et innover
B13: Prototypage & maquette | C13: 4 | D13: 4 | E13: 4 | F13: 3 | G13: 4 | H13: 4 | I13: 5 | J13: 5 | K13: 3 | L13: 4 | M13: 3 | N13: Réalisation de prototypes
B14: Restauration / service après-vente | C14: 3 | D14: 4 | E14: 5 | F14: 4 | G14: 5 | H14: 3 | I14: 2 | J14: 2 | K14: 1 | L14: 4 | M14: 2 | N14: Maintenance et réparation pièces
B15: Maîtrise des techniques rares | C15: 4 | D15: 5 | E15: 5 | F15: 5 | G15: 4 | H15: 5 | I15: 4 | J15: 5 | K15: 5 | L15: 5 | M15: 5 | N15: Savoir-faire en voie de disparition
B16: ▌ COMPÉTENCES TRANSVERSES
B17: Transmission & mentorat | C17: 4 | D17: 4 | E17: 3 | F17: 4 | G17: 3 | H17: 4 | I17: 4 | J17: 4 | K17: 3 | L17: 3 | M17: 4 | N17: Capacité à former les apprentis
B18: Créativité & proposition | C18: 3 | D18: 3 | E18: 3 | F18: 3 | G18: 2 | H18: 4 | I18: 5 | J18: 5 | K18: 5 | L18: 4 | M18: 4 | N18: Apport créatif au-delà de l'exécution
B19: Travail en atelier collectif | C19: 5 | D19: 5 | E19: 4 | F19: 4 | G19: 4 | H19: 4 | I19: 5 | J19: 4 | K19: 2 | L19: 4 | M19: 4 | N19: Intégration dans l'environnement atelier
B20: Culture de la maison | C20: 3 | D20: 3 | E20: 3 | F20: 4 | G20: 3 | H20: 4 | I20: 4 | J20: 4 | K20: 4 | L20: 3 | M20: 3 | N20: Adhésion aux valeurs et codes
B21: Sens esthétique & raffinement | C21: 4 | D21: 5 | E21: 4 | F21: 4 | G21: 3 | H21: 5 | I21: 5 | J21: 5 | K21: 5 | L21: 5 | M21: 5 | N21: Perception du beau propre au luxe
B22: SCORE TOTAL PONDÉRÉ (référence idéale) | C22: =ROUND(SUMPRODUCT((C6:C21)*ISNUMBER(C6:C21),ISNUMBER(C6:C21)*1)/SUMPRODUCT(ISNUMBER(C6:C21)*1)*20,1) -> 81.4 | D22: =ROUND(SUMPRODUCT((D6:D21)*ISNUMBER(D6:D21),ISNUMBER(D6:D21)*1)/SUMPRODUCT(ISNUMBER(D6:D21)*1)*20,1) -> 85.7 | E22: =ROUND(SUMPRODUCT((E6:E21)*ISNUMBER(E6:E21),ISNUMBER(E6:E21)*1)/SUMPRODUCT(ISNUMBER(E6:E21)*1)*20,1) -> 85.7 | F22: =ROUND(SUMPRODUCT((F6:F21)*ISNUMBER(F6:F21),ISNUMBER(F6:F21)*1)/SUMPRODUCT(ISNUMBER(F6:F21)*1)*20,1) -> 84.3 | G22: =ROUND(SUMPRODUCT((G6:G21)*ISNUMBER(G6:G21),ISNUMBER(G6:G21)*1)/SUMPRODUCT(ISNUMBER(G6:G21)*1)*20,1) -> 78.6 | H22: =ROUND(SUMPRODUCT((H6:H21)*ISNUMBER(H6:H21),ISNUMBER(H6:H21)*1)/SUMPRODUCT(ISNUMBER(H6:H21)*1)*20,1) -> 87.1 | I22: =ROUND(SUMPRODUCT((I6:I21)*ISNUMBER(I6:I21),ISNUMBER(I6:I21)*1)/SUMPRODUCT(ISNUMBER(I6:I21)*1)*20,1) -> 84.3 | J22: =ROUND(SUMPRODUCT((J6:J21)*ISNUMBER(J6:J21),ISNUMBER(J6:J21)*1)/SUMPRODUCT(ISNUMBER(J6:J21)*1)*20,1) -> 85.7 | ... M22: =ROUND(SUMPRODUCT((M6:M21)*ISNUMBER(M6:M21),ISNUMBER(M6:M21)*1)/SUMPRODUCT(ISNUMBER(M6:M21)*1)*20,1) -> 77.1 | N22: Note /20 pondérée par dimension
B24: ▌ LÉGENDE — Niveaux Attendus par Compétence
B25: 5 | C25: Indispensable — Maîtrise excellente requise
B26: 4 | C26: Très important — Bonne maîtrise attendue
B27: 3 | C27: Important — Maîtrise correcte
B28: 2 | C28: Secondaire — Notions suffisantes
B29: 1 | C29: Optionnel — Sensibilisation
B30: 0 | C30: Non applicable (N/A)
B32: NEURAL — Intelligence Augmentée pour l'Entreprise · neural-platform.vercel.app · Données simulées à des fins de démonstration

Sheet 04_SCORING_CANDIDATS
B1: 📋 NEURAL — SCORING_CANDIDATS · Évaluation Multicritère Automatique
B2: =IF('01_PARAMETRES'!C5="","Scoring pour : [Maison non définie]","Scoring pour : "&'01_PARAMETRES'!C5) -> Scoring pour : [Maison non définie]
D3: Candidats total | E3: =COUNTA(C7:C106) -> 30 | F3: Score moyen | G3: =IFERROR(AVERAGE(J7:J106),"—") -> 72.823333 | H3: Maîtres d'Art 🟢 | I3: =COUNTIF(L7:L106,"🟢*") -> 30 | J3: Experts 🔵 | K3: =COUNTIF(L7:L106,"🔵*") -> 0 | L3: Avg délai recrutement | M3: "67 jours"
B5: ▌ GRILLE D'ÉVALUATION MULTICRITÈRE — Saisie et Scoring Automatique
B6: # | C6: Candidat | D6: Métier visé | E6: Maîtrise technique /100 × 35% | F6: Expérience /100 × 20% | G6: Rareté Savoir-faire /100 × 20% | H6: Potentiel Transmission /100 × 15% | I6: Adéquation Culturelle /100 × 10% | J6: SCORE GLOBAL /100 | K6: RANG | L6: AVIS | M6: Source candidat | N6: Prétention salariale | O6: Dispo. (date) | P6: Mobilité géo. | Q6: Notes évaluateur | R6: Test technique | S6: Benchmark salaire
B7: 1 | C7: Marie D. | D7: M01 | E7: 92 | F7: 85 | G7: 90 | H7: 78 | I7: 88 | J7: =ROUND(E7*'01_PARAMETRES'!$D$17+F7*'01_PARAMETRES'!$D$18+G7*'01_PARAMETRES'!$D$19+H7*'01_PARAMETRES'!$D$20+I7*'01_PARAMETRES'!$D$21,1) -> 87.7 | K7: =RANK(J7,$J$7:$J$106,0) -> 1 | L7: =IF(J7>='01_PARAMETRES'!$C$26,"🟢 Maître d'Art",IF(J7>='01_PARAMETRES'!$C$27,"🔵 Expert",IF(J7>='01_PARAMETRES'!$C$28,"🟡 Confirmé",IF(J7>='01_PARAMETRES'!$C$29,"🟠 Junior","🔴 Apprenti")))) -> 🟢 Maître d'Art | M7: Cooptation | N7: 42000 | O7: 01/04/2026 | P7: Oui | R7: En attente | S7: =IFERROR(N7/VLOOKUP(D7,'02_REF_METIERS'!$B$4:$J$33,9,FALSE()),"N/D") -> 1
B8: 2 | C8: Jean P. | D8: M01 | E8: 88 | F8: 70 | G8: 85 | H8: 82 | I8: 75 | J8: =ROUND(E8*'01_PARAMETRES'!$D$17+F8*'01_PARAMETRES'!$D$18+G8*'01_PARAMETRES'!$D$19+H8*'01_PARAMETRES'!$D$20+I8*'01_PARAMETRES'!$D$21,1) -> 81.6 | K8: =RANK(J8,$J$7:$J$106,0) -> 2 | L8: =IF(J8>='01_PARAMETRES'!$C$26,"🟢 Maître d'Art",IF(J8>='01_PARAMETRES'!$C$27,"🔵 Expert",IF(J8>='01_PARAMETRES'!$C$28,"🟡 Confirmé",IF(J8>='01_PARAMETRES'!$C$29,"🟠 Junior","🔴 Apprenti")))) -> 🟢 Maître d'Art | M8: École ENSAAMA | N8: 38000 | O8: 15/03/2026 | P8: Partielle | R8: En attente | S8: =IFERROR(N8/VLOOKUP(D8,'02_REF_METIERS'!$B$4:$J$33,9,FALSE()),"N/D") -> 0.9047619
B9: 3 | C9: Akiko T. | D9: M05 | E9: 95 | F9: 60 | G9: 95 | H9: 70 | I9: 65 | J9: =ROUND(E9*'01_PARAMETRES'!$D$17+F9*'01_PARAMETRES'!$D$18+G9*'01_PARAMETRES'!$D$19+H9*'01_PARAMETRES'!$D$20+I9*'01_PARAMETRES'!$D$21,1) -> 81.3 | K9: =RANK(J9,$J$7:$J$106,0) -> 3 | L9: =IF(J9>='01_PARAMETRES'!$C$26,"🟢 Maître d'Art",IF(J9>='01_PARAMETRES'!$C$27,"🔵 Expert",IF(J9>='01_PARAMETRES'!$C$28,"🟡 Confirmé",IF(J9>='01_PARAMETRES'!$C$29,"🟠 Junior","🔴 Apprenti")))) -> 🟢 Maître d'Art | M9: Chasseur | N9: 55000 | O9: 01/06/2026 | P9: Non | R9: En attente | S9: =IFERROR(N9/VLOOKUP(D9,'02_REF_METIERS'!$B$4:$J$33,9,FALSE()),"N/D") -> 1.2222222
B10: 4 | C10: Pierre L. | D10: M01 | E10: 75 | F10: 90 | G10: 60 | H10: 85 | I10: 70 | J10: =ROUND(E10*'01_PARAMETRES'!$D$17+F10*'01_PARAMETRES'!$D$18+G10*'01_PARAMETRES'!$D$19+H10*'01_PARAMETRES'!$D$20+I10*'01_PARAMETRES'!$D$21,1) -> 76 | K10: =RANK(J10,$J$7:$J$106,0) -> 11 | L10: =IF(J10>='01_PARAMETRES'!$C$26,"🟢 Maître d'Art",IF(J10>='01_PARAMETRES'!$C$27,"🔵 Expert",IF(J10>='01_PARAMETRES'!$C$28,"🟡 Confirmé",IF(J10>='01_PARAMETRES'!$C$29,"🟠 Junior","🔴 Apprenti")))) -> 🟢 Maître d'Art | M10: Interne | N10: 40000 | O10: 01/02/2026 | P10: Oui | R10: En attente | S10: =IFERROR(N10/VLOOKUP(D10,'02_REF_METIERS'!$B$4:$J$33,9,FALSE()),"N/D") -> 0.95238095
B11: 5 | C11: Sofia R. | D11: M13 | E11: 70 | F11: 45 | G11: 80 | H11: 60 | I11: 90 | J11: =ROUND(E11*'01_PARAMETRES'!$D$17+F11*'01_PARAMETRES'!$D$18+G11*'01_PARAMETRES'!$D$19+H11*'01_PARAMETRES'!$D$20+I11*'01_PARAMETRES'!$D$21,1) -> 67.5 | K11: =RANK(J11,$J$7:$J$106,0) -> 24 | L11: =IF(J11>='01_PARAMETRES'!$C$26,"🟢 Maître d'Art",IF(J11>='01_PARAMETRES'!$C$27,"🔵 Expert",IF(J11>='01_PARAMETRES'!$C$28,"🟡 Confirmé",IF(J11>='01_PARAMETRES'!$C$29,"🟠 Junior","🔴 Apprenti")))) -> 🟢 Maître d'Art | M11: Candidature | N11: 44000 | O11: 15/04/2026 | P11: Oui | R11: En attente | S11: =IFERROR(N11/VLOOKUP(D11,'02_REF_METIERS'!$B$4:$J$33,9,FALSE()),"N/D") -> 0.95652174
B12: 6 | C12: Hiroshi M. | D12: M07 | E12: 88 | F12: 72 | G12: 96 | H12: 65 | I12: 60 | J12: =ROUND(E12*'01_PARAMETRES'!$D$17+F12*'01_PARAMETRES'!$D$18+G12*'01_PARAMETRES'!$D$19+H12*'01_PARAMETRES'!$D$20+I12*'01_PARAMETRES'!$D$21,1) -> 80.2 | K12: =RANK(J12,$J$7:$J$106,0) -> 4 | L12: =IF(J12>='01_PARAMETRES'!$C$26,"🟢 Maître d'Art",IF(J12>='01_PARAMETRES'!$C$27,"🔵 Expert",IF(J12>='01_PARAMETRES'!$C$28,"🟡 Confirmé",IF(J12>='01_PARAMETRES'!$C$29,"🟠 Junior","🔴 Apprenti")))) -> 🟢 Maître d'Art | M12: Chasseur | N12: 68000 | O12: 01/07/2026 | P12: Non | R12: En attente | S12: =IFERROR(N12/VLOOKUP(D12,'02_REF_METIERS'!$B$4:$J$33,9,FALSE()),"N/D") -> 1.2363636
B13: 7 | C13: Camille B. | D13: M13 | E13: 82 | F13: 55 | G13: 78 | H13: 88 | I13: 92 | J13: =ROUND(E13*'01_PARAMETRES'!$D$17+F13*'01_PARAMETRES'!$D$18+G13*'01_PARAMETRES'!$D$19+H13*'01_PARAMETRES'!$D$20+I13*'01_PARAMETRES'!$D$21,1) -> 77.7 | K13: =RANK(J13,$J$7:$J$106,0) -> 7 | L13: =IF(J13>='01_PARAMETRES'!$C$26,"🟢 Maître d'Art",IF(J13>='01_PARAMETRES'!$C$27,"🔵 Expert",IF(J13>='01_PARAMETRES'!$C$28,"🟡 Confirmé",IF(J13>='01_PARAMETRES'!$C$29,"🟠 Junior","🔴 Apprenti")))) -> 🟢 Maître d'Art | M13: Cooptation | N13: 42000 | O13: 01/04/2026 | P13: Partielle | R13: En attente | S13: =IFERROR(N13/VLOOKUP(D13,'02_REF_METIERS'!$B$4:$J$33,9,FALSE()),"N/D") -> 0.91304348
B14: 8 | C14: Lukas S. | D14: M10 | E14: 79 | F14: 88 | G14: 82 | H14: 72 | I14: 68 | J14: =ROUND(E14*'01_PARAMETRES'!$D$17+F14*'01_PARAMETRES'!$D$18+G14*'01_PARAMETRES'!$D$19+H14*'01_PARAMETRES'!$D$20+I14*'01_PARAMETRES'!$D$21,1) -> 79.3 | K14: =RANK(J14,$J$7:$J$106,0) -> 5 | L14: =IF(J14>='01_PARAMETRES'!$C$26,"🟢 Maître d'Art",IF(J14>='01_PARAMETRES'!$C$27,"🔵 Expert",IF(J14>='01_PARAMETRES'!$C$28,"🟡 Confirmé",IF(J14>='01_PARAMETRES'!$C$29,"🟠 Junior","🔴 Apprenti")))) -> 🟢 Maître d'Art | M14: École ENSP | N14: 50000 | O14: 15/05/2026 | P14: Non | R14: En attente | S14: =IFERROR(N14/VLOOKUP(D14,'02_REF_METIERS'!$B$4:$J$33,9,FALSE()),"N/D") -> 1.0416667
B15: 9 | C15: Fatima O. | D15: M15 | E15: 86 | F15: 50 | G15: 74 | H15: 78 | I15: 80 | J15: =ROUND(E15*'01_PARAMETRES'!$D$17+F15*'01_PARAMETRES'!$D$18+G15*'01_PARAMETRES'!$D$19+H15*'01_PARAMETRES'!$D$20+I15*'01_PARAMETRES'!$D$21,1) -> 74.6 | K15: =RANK(J15,$J$7:$J$106,0) -> 14 | L15: =IF(J15>='01_PARAMETRES'!$C$26,"🟢 Maître d'Art",IF(J15>='01_PARAMETRES'!$C$27,"🔵 Expert",IF(J15>='01_PARAMETRES'!$C$28,"🟡 Confirmé",IF(J15>='01_PARAMETRES'!$C$29,"🟠 Junior","🔴 Apprenti")))) -> 🟢 Maître d'Art | M15: Candidature | N15: 36000 | O15: 01/03/2026 | P15: Oui | R15: En attente | S15: =IFERROR(N15/VLOOKUP(D15,'02_REF_METIERS'!$B$4:$J$33,9,FALSE()),"N/D") -> 0.9
B16: 10 | C16: Antoine V. | D16: M05 | E16: 74 | F16: 65 | G16: 88 | H16: 60 | I16: 58 | J16: =ROUND(E16*'01_PARAMETRES'!$D$17+F16*'01_PARAMETRES'!$D$18+G16*'01_PARAMETRES'!$D$19+H16*'01_PARAMETRES'!$D$20+I16*'01_PARAMETRES'!$D$21,1) -> 71.3 | K16: =RANK(J16,$J$7:$J$106,0) -> 19 | L16: =IF(J16>='01_PARAMETRES'!$C$26,"🟢 Maître d'Art",IF(J16>='01_PARAMETRES'!$C$27,"🔵 Expert",IF(J16>='01_PARAMETRES'!$C$28,"🟡 Confirmé",IF(J16>='01_PARAMETRES'!$C$29,"🟠 Junior","🔴 Apprenti")))) -> 🟢 Maître d'Art | M16: LinkedIn | N16: 48000 | O16: 01/06/2026 | P16: Partielle | R16: En attente | S16: =IFERROR(N16/VLOOKUP(D16,'02_REF_METIERS'!$B$4:$J$33,9,FALSE()),"N/D") -> 1.0666667
B17: 11 | C17: Yolanda G. | D17: M20 | E17: 80 | F17: 78 | G17: 85 | H17: 70 | I17: 75 | J17: =ROUND(E17*'01_PARAMETRES'!$D$17+F17*'01_PARAMETRES'!$D$18+G17*'01_PARAMETRES'!$D$19+H17*'01_PARAMETRES'!$D$20+I17*'01_PARAMETRES'!$D$21,1) -> 78.6 | K17: =RANK(J17,$J$7:$J$106,0) -> 6 | L17: =IF(J17>='01_PARAMETRES'!$C$26,"🟢 Maître d'Art",IF(J17>='01_PARAMETRES'!$C$27,"🔵 Expert",IF(J17>='01_PARAMETRES'!$C$28,"🟡 Confirmé",IF(J17>='01_PARAMETRES'!$C$29,"🟠 Junior","🔴 Apprenti")))) -> 🟢 Maître d'Art | M17: Cooptation | N17: 35000 | O17: 15/03/2026 | P17: Oui | R17: En attente | S17: =IFERROR(N17/VLOOKUP(D17,'02_REF_METIERS'!$B$4:$J$33,9,FALSE()),"N/D") -> 0.92105263
B18: 12 | C18: Marco F. | D18: M08 | E18: 76 | F18: 82 | G18: 72 | H18: 66 | I18: 64 | J18: =ROUND(E18*'01_PARAMETRES'!$D$17+F18*'01_PARAMETRES'!$D$18+G18*'01_PARAMETRES'!$D$19+H18*'01_PARAMETRES'!$D$20+I18*'01_PARAMETRES'!$D$21,1) -> 73.7 | K18: =RANK(J18,$J$7:$J$106,0) -> 15 | L18: =IF(J18>='01_PARAMETRES'!$C$26,"🟢 Maître d'Art",IF(J18>='01_PARAMETRES'!$C$27,"🔵 Expert",IF(J18>='01_PARAMETRES'!$C$28,"🟡 Confirmé",IF(J18>='01_PARAMETRES'!$C$29,"🟠 Junior","🔴 Apprenti")))) -> 🟢 Maître d'Art | M18: Chasseur | N18: 46000 | O18: 01/05/2026 | P18: Non | R18: En attente | S18: =IFERROR(N18/VLOOKUP(D18,'02_REF_METIERS'!$B$4:$J$33,9,FALSE()),"N/D") -> 1.0952381
... B36: 30 | C36: Emma W. | D36: M16 | E36: 72 | F36: 42 | G36: 76 | H36: 70 | I36: 82 | J36: =ROUND(E36*'01_PARAMETRES'!$D$17+F36*'01_PARAMETRES'!$D$18+G36*'01_PARAMETRES'!$D$19+H36*'01_PARAMETRES'!$D$20+I36*'01_PARAMETRES'!$D$21,1) -> 67.5 | K36: =RANK(J36,$J$7:$J$106,0) -> 24 | L36: =IF(J36>='01_PARAMETRES'!$C$26,"🟢 Maître d'Art",IF(J36>='01_PARAMETRES'!$C$27,"🔵 Expert",IF(J36>='01_PARAMETRES'!$C$28,"🟡 Confirmé",IF(J36>='01_PARAMETRES'!$C$29,"🟠 Junior","🔴 Apprenti")))) -> 🟢 Maître d'Art | M36: Cooptation | N36: 38000 | O36: 01/04/2026 | P36: Partielle | R36: En attente | S36: =IFERROR(N36/VLOOKUP(D36,'02_REF_METIERS'!$B$4:$J$33,9,FALSE()),"N/D") -> 0.86363636
B39: NEURAL — Intelligence Augmentée pour l'Entreprise · neural-platform.vercel.app · Données simulées à des fins de démonstration

Sheet 05_VIVIER_TALENTS
B1: 📋 NEURAL — VIVIER_TALENTS · Pipeline de Recrutement & Suivi Candidatures
B2: Suivi temps réel · Alertes relance automatiques · Funnel recrutement
B3: =COUNTA(C8:C107)-COUNTBLANK(C8:C107) -> -60 | D3: =COUNTIF(F8:F107,"🟢 Actif") -> 13 | F3: =IFERROR(COUNTIF(G8:G107,"Intégré")/COUNTA(C8:C107),"0%") -> 0 | H3: "67 jours" | J3: =COUNTIF(M8:M107,"⚠️*")+COUNTIF(M8:M107,"🔴 DORMANT*") -> 17
B4: 👥 CANDIDATS TOTAL VIVIER | D4: 🟢 EN COURS PIPELINE ACTIF | F4: ✅ TAUX DE CONVERSION | H4: ⏱️ DÉLAI MOYEN RECRUTEMENT | J4: ⚠️🔴 ALERTES RELANCE + DORMANTS
B6: ▌ PIPELINE DE RECRUTEMENT — Suivi Individuel des Candidatures
B7: # | C7: Candidat | D7: Métier visé | E7: Score (lien 04) | F7: Statut | G7: Étape actuelle | H7: Date mise à jour | I7: Source | J7: Coût recr. estimé (€) | K7: Maître tuteur identifié | L7: Date intégr. prévisionnelle | M7: Alerte Relance
B8: 1 | C8: Marie D. | D8: M01 | E8: =IFERROR(VLOOKUP(C8,'04_SCORING_CANDIDATS'!$C$7:$J$106,8,FALSE()),"—") -> 87.7 | F8: 🟢 Actif | G8: 7. Offre émise | H8: 15/02/2026 | I8: Cooptation | J8: 15000 | K8: Robert M. | L8: 01/04/2026 | M8: =IF(OR(F8="🔴 Refusé",F8="✅ Intégré"),"",IF(NOT(ISNUMBER(DATEVALUE(H8))),"⚠️ Vérifier date",IF(TODAY()-DATEVALUE(H8)>30,"🔴 DORMANT — "&C8&" · "&TEXT(TODAY()-DATEVALUE(H8),"0")&"j · "&G8,IF(TODAY()-DATEVALUE(H8)>14,"⚠️ Relancer · "&TEXT(TODAY()-DATEVALUE(H8),"0")&"j · "&G8,"✅ À jour")))) -> 🔴 DORMANT — Marie D. · 45j · 7. Offre émise
B9: 2 | C9: Jean P. | D9: M01 | E9: =IFERROR(VLOOKUP(C9,'04_SCORING_CANDIDATS'!$C$7:$J$106,8,FALSE()),"—") -> 81.6 | F9: 🟢 Actif | G9: 5. Pièce d'essai / Test technique | H9: 12/02/2026 | I9: École ENSAAMA | J9: 12000 | K9: Robert M. | L9: 15/04/2026 | M9: =IF(OR(F9="🔴 Refusé",F9="✅ Intégré"),"",IF(NOT(ISNUMBER(DATEVALUE(H9))),"⚠️ Vérifier date",IF(TODAY()-DATEVALUE(H9)>30,"🔴 DORMANT — "&C9&" · "&TEXT(TODAY()-DATEVALUE(H9),"0")&"j · "&G9,IF(TODAY()-DATEVALUE(H9)>14,"⚠️ Relancer · "&TEXT(TODAY()-DATEVALUE(H9),"0")&"j · "&G9,"✅ À jour")))) -> 🔴 DORMANT — Jean P. · 48j · 5. Pièce d'essai / Test technique
B10: 3 | C10: Akiko T. | D10: M05 | E10: =IFERROR(VLOOKUP(C10,'04_SCORING_CANDIDATS'!$C$7:$J$106,8,FALSE()),"—") -> 81.3 | F10: 🟡 Stand-by | G10: 4. Entretien #2 (Maître d'atelier) | H10: 01/02/2026 | I10: Chasseur | J10: 20000 | K10: Yuki H. | L10: 01/06/2026 | M10: =IF(OR(F10="🔴 Refusé",F10="✅ Intégré"),"",IF(NOT(ISNUMBER(DATEVALUE(H10))),"⚠️ Vérifier date",IF(TODAY()-DATEVALUE(H10)>30,"🔴 DORMANT — "&C10&" · "&TEXT(TODAY()-DATEVALUE(H10),"0")&"j · "&G10,IF(TODAY()-DATEVALUE(H10)>14,"⚠️ Relancer · "&TEXT(TODAY()-DATEVALUE(H10),"0")&"j · "&G10,"✅ À jour")))) -> 🔴 DORMANT — Akiko T. · 59j · 4. Entretien #2 (Maître d'atelier)
B11: 4 | C11: Pierre L. | D11: M01 | E11: =IFERROR(VLOOKUP(C11,'04_SCORING_CANDIDATS'!$C$7:$J$106,8,FALSE()),"—") -> 76 | F11: 🔴 Refusé | G11: ❌ Refusé / Retiré | H11: 28/01/2026 | I11: Interne | J11: — | K11: — | L11: — | M11: =IF(OR(F11="🔴 Refusé",F11="✅ Intégré"),"",IF(NOT(ISNUMBER(DATEVALUE(H11))),"⚠️ Vérifier date",IF(TODAY()-DATEVALUE(H11)>30,"🔴 DORMANT — "&C11&" · "&TEXT(TODAY()-DATEVALUE(H11),"0")&"j · "&G11,IF(TODAY()-DATEVALUE(H11)>14,"⚠️ Relancer · "&TEXT(TODAY()-DATEVALUE(H11),"0")&"j · "&G11,"✅ À jour"))))
B12: 5 | C12: Sofia R. | D12: M13 | E12: =IFERROR(VLOOKUP(C12,'04_SCORING_CANDIDATS'!$C$7:$J$106,8,FALSE()),"—") -> 67.5 | F12: 🟢 Actif | G12: 3. Entretien #1 (RH) | H12: 10/02/2026 | I12: Candidature | J12: 8000 | K12: Antoine G. | L12: 01/05/2026 | M12: =IF(OR(F12="🔴 Refusé",F12="✅ Intégré"),"",IF(NOT(ISNUMBER(DATEVALUE(H12))),"⚠️ Vérifier date",IF(TODAY()-DATEVALUE(H12)>30,"🔴 DORMANT — "&C12&" · "&TEXT(TODAY()-DATEVALUE(H12),"0")&"j · "&G12,IF(TODAY()-DATEVALUE(H12)>14,"⚠️ Relancer · "&TEXT(TODAY()-DATEVALUE(H12),"0")&"j · "&G12,"✅ À jour")))) -> 🔴 DORMANT — Sofia R. · 50j · 3. Entretien #1 (RH)
B13: 6 | C13: Hiroshi M. | D13: M07 | E13: =IFERROR(VLOOKUP(C13,'04_SCORING_CANDIDATS'!$C$7:$J$106,8,FALSE()),"—") -> 80.2 | F13: 🟢 Actif | G13: 2. Premier contact | H13: 20/02/2026 | I13: Chasseur | J13: 25000 | K13: — | L13: 01/07/2026 | M13: =IF(OR(F13="🔴 Refusé",F13="✅ Intégré"),"",IF(NOT(ISNUMBER(DATEVALUE(H13))),"⚠️ Vérifier date",IF(TODAY()-DATEVALUE(H13)>30,"🔴 DORMANT — "&C13&" · "&TEXT(TODAY()-DATEVALUE(H13),"0")&"j · "&G13,IF(TODAY()-DATEVALUE(H13)>14,"⚠️ Relancer · "&TEXT(TODAY()-DATEVALUE(H13),"0")&"j · "&G13,"✅ À jour")))) -> 🔴 DORMANT — Hiroshi M. · 40j · 2. Premier contact
B14: 7 | C14: Camille B. | D14: M13 | E14: =IFERROR(VLOOKUP(C14,'04_SCORING_CANDIDATS'!$C$7:$J$106,8,FALSE()),"—") -> 77.7 | F14: 🟢 Actif | G14: 4. Entretien #2 (Maître d'atelier) | H14: 18/02/2026 | I14: Cooptation | J14: 10000 | K14: Antoine G. | L14: 15/04/2026 | M14: =IF(OR(F14="🔴 Refusé",F14="✅ Intégré"),"",IF(NOT(ISNUMBER(DATEVALUE(H14))),"⚠️ Vérifier date",IF(TODAY()-DATEVALUE(H14)>30,"🔴 DORMANT — "&C14&" · "&TEXT(TODAY()-DATEVALUE(H14),"0")&"j · "&G14,IF(TODAY()-DATEVALUE(H14)>14,"⚠️ Relancer · "&TEXT(TODAY()-DATEVALUE(H14),"0")&"j · "&G14,"✅ À jour")))) -> 🔴 DORMANT — Camille B. · 42j · 4. Entretien #2 (Maître d'atelier)
B15: 8 | C15: Lukas S. | D15: M10 | E15: =IFERROR(VLOOKUP(C15,'04_SCORING_CANDIDATS'!$C$7:$J$106,8,FALSE()),"—") -> 79.3 | F15: 🟡 Stand-by | G15: 3. Entretien #1 (RH) | H15: 05/02/2026 | I15: École ENSP | J15: 12000 | K15: Isabelle F. | L15: 01/06/2026 | M15: =IF(OR(F15="🔴 Refusé",F15="✅ Intégré"),"",IF(NOT(ISNUMBER(DATEVALUE(H15))),"⚠️ Vérifier date",IF(TODAY()-DATEVALUE(H15)>30,"🔴 DORMANT — "&C15&" · "&TEXT(TODAY()-DATEVALUE(H15),"0")&"j · "&G15,IF(TODAY()-DATEVALUE(H15)>14,"⚠️ Relancer · "&TEXT(TODAY()-DATEVALUE(H15),"0")&"j · "&G15,"✅ À jour")))) -> 🔴 DORMANT — Lukas S. · 55j · 3. Entretien #1 (RH)
B16: 9 | C16: Fatima O. | D16: M15 | E16: =IFERROR(VLOOKUP(C16,'04_SCORING_CANDIDATS'!$C$7:$J$106,8,FALSE()),"—") -> 74.6 | F16: 🟢 Actif | G16: 3. Entretien #1 (RH) | H16: 14/02/2026 | I16: Candidature | J16: 8000 | K16: — | L16: 15/05/2026 | M16: =IF(OR(F16="🔴 Refusé",F16="✅ Intégré"),"",IF(NOT(ISNUMBER(DATEVALUE(H16))),"⚠️ Vérifier date",IF(TODAY()-DATEVALUE(H16)>30,"🔴 DORMANT — "&C16&" · "&TEXT(TODAY()-DATEVALUE(H16),"0")&"j · "&G16,IF(TODAY()-DATEVALUE(H16)>14,"⚠️ Relancer · "&TEXT(TODAY()-DATEVALUE(H16),"0")&"j · "&G16,"✅ À jour")))) -> 🔴 DORMANT — Fatima O. · 46j · 3. Entretien #1 (RH)
B17: 10 | C17: Antoine V. | D17: M05 | E17: =IFERROR(VLOOKUP(C17,'04_SCORING_CANDIDATS'!$C$7:$J$106,8,FALSE()),"—") -> 71.3 | F17: 🟡 Stand-by | G17: 2. Premier contact | H17: 28/01/2026 | I17: LinkedIn | J17: 18000 | K17: Yuki H. | L17: 01/07/2026 | M17: =IF(OR(F17="🔴 Refusé",F17="✅ Intégré"),"",IF(NOT(ISNUMBER(DATEVALUE(H17))),"⚠️ Vérifier date",IF(TODAY()-DATEVALUE(H17)>30,"🔴 DORMANT — "&C17&" · "&TEXT(TODAY()-DATEVALUE(H17),"0")&"j · "&G17,IF(TODAY()-DATEVALUE(H17)>14,"⚠️ Relancer · "&TEXT(TODAY()-DATEVALUE(H17),"0")&"j · "&G17,"✅ À jour")))) -> 🔴 DORMANT — Antoine V. · 63j · 2. Premier contact
B18: 11 | C18: Yolanda G. | D18: M20 | E18: =IFERROR(VLOOKUP(C18,'04_SCORING_CANDIDATS'!$C$7:$J$106,8,FALSE()),"—") -> 78.6 | F18: 🟢 Actif | G18: 5. Pièce d'essai / Test technique | H18: 16/02/2026 | I18: Cooptation | J18: 10000 | K18: — | L18: 01/05/2026 | M18: =IF(OR(F18="🔴 Refusé",F18="✅ Intégré"),"",IF(NOT(ISNUMBER(DATEVALUE(H18))),"⚠️ Vérifier date",IF(TODAY()-DATEVALUE(H18)>30,"🔴 DORMANT — "&C18&" · "&TEXT(TODAY()-DATEVALUE(H18),"0")&"j · "&G18,IF(TODAY()-DATEVALUE(H18)>14,"⚠️ Relancer · "&TEXT(TODAY()-DATEVALUE(H18),"0")&"j · "&G18,"✅ À jour")))) -> 🔴 DORMANT — Yolanda G. · 44j · 5. Pièce d'essai / Test technique
B19: 12 | C19: Thomas K. | D19: M10 | E19: =IFERROR(VLOOKUP(C19,'04_SCORING_CANDIDATS'!$C$7:$J$106,8,FALSE()),"—") -> 73 | F19: ✅ Intégré | G19: 10. Intégré | H19: 01/02/2026 | I19: Interne | J19: 5000 | K19: Isabelle F. | L19: 01/02/2026 | M19: =IF(OR(F19="🔴 Refusé",F19="✅ Intégré"),"",IF(NOT(ISNUMBER(DATEVALUE(H19))),"⚠️ Vérifier date",IF(TODAY()-DATEVALUE(H19)>30,"🔴 DORMANT — "&C19&" · "&TEXT(TODAY()-DATEVALUE(H19),"0")&"j · "&G19,IF(TODAY()-DATEVALUE(H19)>14,"⚠️ Relancer · "&TEXT(TODAY()-DATEVALUE(H19),"0")&"j · "&G19,"✅ À jour"))))
B20: 13 | C20: Ambre L. | D20: M16 | E20: =IFERROR(VLOOKUP(C20,'04_SCORING_CANDIDATS'!$C$7:$J$106,8,FALSE()),"—") -> 73.6 | F20: 🟢 Actif | G20: 3. Entretien #1 (RH) | H20: 19/02/2026 | I20: École ESMOD | J20: 10000 | K20: — | L20: 15/05/2026 | M20: =IF(OR(F20="🔴 Refusé",F20="✅ Intégré"),"",IF(NOT(ISNUMBER(DATEVALUE(H20))),"⚠️ Vérifier date",IF(TODAY()-DATEVALUE(H20)>30,"🔴 DORMANT — "&C20&" · "&TEXT(TODAY()-DATEVALUE(H20),"0")&"j · "&G20,IF(TODAY()-DATEVALUE(H20)>14,"⚠️ Relancer · "&TEXT(TODAY()-DATEVALUE(H20),"0")&"j · "&G20,"✅ À jour")))) -> 🔴 DORMANT — Ambre L. · 41j · 3. Entretien #1 (RH)
B21: 14 | C21: Kenji W. | D21: M09 | E21: =IFERROR(VLOOKUP(C21,'04_SCORING_CANDIDATS'!$C$7:$J$106,8,FALSE()),"—") -> 77.3 | F21: 🟢 Actif | G21: 1. Sourcing identifié | H21: 22/02/2026 | I21: Chasseur | J21: 30000 | K21: — | L21: 01/09/2026 | M21: =IF(OR(F21="🔴 Refusé",F21="✅ Intégré"),"",IF(NOT(ISNUMBER(DATEVALUE(H21))),"⚠️ Vérifier date",IF(TODAY()-DATEVALUE(H21)>30,"🔴 DORMANT — "&C21&" · "&TEXT(TODAY()-DATEVALUE(H21),"0")&"j · "&G21,IF(TODAY()-DATEVALUE(H21)>14,"⚠️ Relancer · "&TEXT(TODAY()-DATEVALUE(H21),"0")&"j · "&G21,"✅ À jour")))) -> 🔴 DORMANT — Kenji W. · 38j · 1. Sourcing identifié
B22: 15 | C22: Isabelle C. | D22: M14 | E22: =IFERROR(VLOOKUP(C22,'04_SCORING_CANDIDATS'!$C$7:$J$106,8,FALSE()),"—") -> 77.5 | F22: 🟢 Actif | G22: 4. Entretien #2 (Maître d'atelier) | H22: 17/02/2026 | I22: Cooptation | J22: 12000 | K22: — | L22: 01/06/2026 | M22: =IF(OR(F22="🔴 Refusé",F22="✅ Intégré"),"",IF(NOT(ISNUMBER(DATEVALUE(H22))),"⚠️ Vérifier date",IF(TODAY()-DATEVALUE(H22)>30,"🔴 DORMANT — "&C22&" · "&TEXT(TODAY()-DATEVALUE(H22),"0")&"j · "&G22,IF(TODAY()-DATEVALUE(H22)>14,"⚠️ Relancer · "&TEXT(TODAY()-DATEVALUE(H22),"0")&"j · "&G22,"✅ À jour")))) -> 🔴 DORMANT — Isabelle C. · 43j · 4. Entretien #2 (Maître d'atelier)
B23: 16 | C23: Hugo C. | D23: M01 | E23: =IFERROR(VLOOKUP(C23,'04_SCORING_CANDIDATS'!$C$7:$J$106,8,FALSE()),"—") -> 61.6 | F23: 🔴 Refusé | G23: ❌ Refusé / Retiré | H23: 10/02/2026 | I23: Candidature | J23: — | K23: — | L23: — | M23: =IF(OR(F23="🔴 Refusé",F23="✅ Intégré"),"",IF(NOT(ISNUMBER(DATEVALUE(H23))),"⚠️ Vérifier date",IF(TODAY()-DATEVALUE(H23)>30,"🔴 DORMANT — "&C23&" · "&TEXT(TODAY()-DATEVALUE(H23),"0")&"j · "&G23,IF(TODAY()-DATEVALUE(H23)>14,"⚠️ Relancer · "&TEXT(TODAY()-DATEVALUE(H23),"0")&"j · "&G23,"✅ À jour"))))
B24: 17 | C24: Ryo T. | D24: M12 | E24: =IFERROR(VLOOKUP(C24,'04_SCORING_CANDIDATS'!$C$7:$J$106,8,FALSE()),"—") -> 75.4 | F24: 🟢 Actif | G24: 2. Premier contact | H24: 21/02/2026 | I24: Chasseur | J24: 28000 | K24: — | L24: 01/08/2026 | M24: =IF(OR(F24="🔴 Refusé",F24="✅ Intégré"),"",IF(NOT(ISNUMBER(DATEVALUE(H24))),"⚠️ Vérifier date",IF(TODAY()-DATEVALUE(H24)>30,"🔴 DORMANT — "&C24&" · "&TEXT(TODAY()-DATEVALUE(H24),"0")&"j · "&G24,IF(TODAY()-DATEVALUE(H24)>14,"⚠️ Relancer · "&TEXT(TODAY()-DATEVALUE(H24),"0")&"j · "&G24,"✅ À jour")))) -> 🔴 DORMANT — Ryo T. · 39j · 2. Premier contact
B25: 18 | C25: Clara N. | D25: M15 | E25: =IFERROR(VLOOKUP(C25,'04_SCORING_CANDIDATS'!$C$7:$J$106,8,FALSE()),"—") -> 75.1 | F25: 🟢 Actif | G25: 3. Entretien #1 (RH) | H25: 15/02/2026 | I25: Cooptation | J25: 8000 | K25: — | L25: 15/04/2026 | M25: =IF(OR(F25="🔴 Refusé",F25="✅ Intégré"),"",IF(NOT(ISNUMBER(DATEVALUE(H25))),"⚠️ Vérifier date",IF(TODAY()-DATEVALUE(H25)>30,"🔴 DORMANT — "&C25&" · "&TEXT(TODAY()-DATEVALUE(H25),"0")&"j · "&G25,IF(TODAY()-DATEVALUE(H25)>14,"⚠️ Relancer · "&TEXT(TODAY()-DATEVALUE(H25),"0")&"j · "&G25,"✅ À jour")))) -> 🔴 DORMANT — Clara N. · 45j · 3. Entretien #1 (RH)
B26: 19 | C26: David H. | D26: M07 | E26: =IFERROR(VLOOKUP(C26,'04_SCORING_CANDIDATS'!$C$7:$J$106,8,FALSE()),"—") -> 72 | F26: 🟡 Stand-by | G26: 2. Premier contact | H26: 08/02/2026 | I26: LinkedIn | J26: 22000 | K26: — | L26: 01/08/2026 | M26: =IF(OR(F26="🔴 Refusé",F26="✅ Intégré"),"",IF(NOT(ISNUMBER(DATEVALUE(H26))),"⚠️ Vérifier date",IF(TODAY()-DATEVALUE(H26)>30,"🔴 DORMANT — "&C26&" · "&TEXT(TODAY()-DATEVALUE(H26),"0")&"j · "&G26,IF(TODAY()-DATEVALUE(H26)>14,"⚠️ Relancer · "&TEXT(TODAY()-DATEVALUE(H26),"0")&"j · "&G26,"✅ À jour")))) -> 🔴 DORMANT — David H. · 52j · 2. Premier contact
B27: 20 | C27: Elisa R. | D27: M17 | E27: =IFERROR(VLOOKUP(C27,'04_SCORING_CANDIDATS'!$C$7:$J$106,8,FALSE()),"—") -> 68.3 | F27: 🟢 Actif | G27: 1. Sourcing identifié | H27: 23/02/2026 | I27: Chasseur | J27: 35000 | K27: — | L27: 01/10/2026 | M27: =IF(OR(F27="🔴 Refusé",F27="✅ Intégré"),"",IF(NOT(ISNUMBER(DATEVALUE(H27))),"⚠️ Vérifier date",IF(TODAY()-DATEVALUE(H27)>30,"🔴 DORMANT — "&C27&" · "&TEXT(TODAY()-DATEVALUE(H27),"0")&"j · "&G27,IF(TODAY()-DATEVALUE(H27)>14,"⚠️ Relancer · "&TEXT(TODAY()-DATEVALUE(H27),"0")&"j · "&G27,"✅ À jour")))) -> 🔴 DORMANT — Elisa R. · 37j · 1. Sourcing identifié
B30: NEURAL — Intelligence Augmentée pour l'Entreprise · neural-platform.vercel.app · Données simulées à des fins de démonstration

Sheet 06_CARTO
B1: 📋 NEURAL — CARTOGRAPHIE · Compétences Actuelles des Collaborateurs en Poste
B2: Matrice compétences × collaborateurs · Pyramide des âges · Risques départ
B3: =COUNTA(B8:B57) -> 38 | D3: =COUNTIF(I8:I57,"🔴*") -> 0 | F3: =IFERROR(AVERAGE(H8:H57),"—") -> 79.98 | H3: =COUNTIF(J8:J57,"Oui") -> 0 | J3: =IFERROR(AVERAGE(L8:L57),"—") -> —
B4: 👥 ARTISANS EN POSTE | D4: 🔴 RISQUE DÉPART CRITIQUE | F4: ⭐ SCORE MOYEN ÉQUIPE | H4: 🎓 MOF EN POSTE | J4: 📚 CAPACITÉ TRANSMISSION
B6: ▌ CARTOGRAPHIE DES COLLABORATEURS EN POSTE — Scores & Risques
B7: Collaborateur | C7: Métier | D7: Maîtrise tech. /100 | E7: Expér. /100 | F7: Rareté /100 | G7: Trans- mission /100 | H7: SCORE GLOBAL /100 | I7: Âge | J7: Risque départ | K7: Ancien- neté (ans) | L7: Label MOF | M7: Nb apprentis | N7: Capacité transmis. /5 | O7: Plan successeur
B8: Robert M. | C8: M01 | D8: 98 | E8: 95 | F8: 95 | G8: 90 | H8: =ROUND(D8*'01_PARAMETRES'!$D$17+E8*'01_PARAMETRES'!$D$18+F8*'01_PARAMETRES'!$D$19+G8*'01_PARAMETRES'!$D$20+75*'01_PARAMETRES'!$D$21,1) -> 93.3 | I8: 62 | J8: =IF(I8>=60,"🔴 Critique (<3 ans retraite)",IF(I8>=55,"🟡 Vigilance (<8 ans)",IF(AND(K8<3,I8<35),"🟡 Turnover risqué","🟢 Stable"))) -> 🔴 Critique (<3 ans retraite) | K8: 32 | L8: Oui | M8: 2 | N8: 5 | O8: Oui
B9: Yuki H. | C9: M05 | D9: 92 | E9: 80 | F9: 90 | G9: 85 | H9: =ROUND(D9*'01_PARAMETRES'!$D$17+E9*'01_PARAMETRES'!$D$18+F9*'01_PARAMETRES'!$D$19+G9*'01_PARAMETRES'!$D$20+75*'01_PARAMETRES'!$D$21,1) -> 86.5 | I9: 55 | J9: =IF(I9>=60,"🔴 Critique (<3 ans retraite)",IF(I9>=55,"🟡 Vigilance (<8 ans)",IF(AND(K9<3,I9<35),"🟡 Turnover risqué","🟢 Stable"))) -> 🟡 Vigilance (<8 ans) | K9: 22 | L9: Oui | M9: 1 | N9: 4 | O9: Non
B10: Antoine G. | C10: M13 | D10: 88 | E10: 75 | F10: 85 | G10: 92 | H10: =ROUND(D10*'01_PARAMETRES'!$D$17+E10*'01_PARAMETRES'!$D$18+F10*'01_PARAMETRES'!$D$19+G10*'01_PARAMETRES'!$D$20+75*'01_PARAMETRES'!$D$21,1) -> 84.1 | I10: 48 | J10: =IF(I10>=60,"🔴 Critique (<3 ans retraite)",IF(I10>=55,"🟡 Vigilance (<8 ans)",IF(AND(K10<3,I10<35),"🟡 Turnover risqué","🟢 Stable"))) -> 🟢 Stable | K10: 18 | L10: Oui | M10: 3 | N10: 5 | O10: Oui
B11: Isabelle F. | C11: M10 | D11: 90 | E11: 88 | F11: 88 | G11: 70 | H11: =ROUND(D11*'01_PARAMETRES'!$D$17+E11*'01_PARAMETRES'!$D$18+F11*'01_PARAMETRES'!$D$19+G11*'01_PARAMETRES'!$D$20+75*'01_PARAMETRES'!$D$21,1) -> 84.7 | I11: 58 | J11: =IF(I11>=60,"🔴 Critique (<3 ans retraite)",IF(I11>=55,"🟡 Vigilance (<8 ans)",IF(AND(K11<3,I11<35),"🟡 Turnover risqué","🟢 Stable"))) -> 🟡 Vigilance (<8 ans) | K11: 26 | L11: Non | M11: 1 | N11: 4 | O11: Non
B12: Léa P. | C12: M01 | D12: 70 | E12: 40 | F12: 75 | G12: 60 | H12: =ROUND(D12*'01_PARAMETRES'!$D$17+E12*'01_PARAMETRES'!$D$18+F12*'01_PARAMETRES'!$D$19+G12*'01_PARAMETRES'!$D$20+75*'01_PARAMETRES'!$D$21,1) -> 64 | I12: 28 | J12: =IF(I12>=60,"🔴 Critique (<3 ans retraite)",IF(I12>=55,"🟡 Vigilance (<8 ans)",IF(AND(K12<3,I12<35),"🟡 Turnover risqué","🟢 Stable"))) -> 🟢 Stable | K12: 5 | L12: Non | M12: 0 | N12: 3 | O12: Non
B13: Pierre M. | C13: M05 | D13: 85 | E13: 72 | F13: 88 | G13: 78 | H13: =ROUND(D13*'01_PARAMETRES'!$D$17+E13*'01_PARAMETRES'!$D$18+F13*'01_PARAMETRES'!$D$19+G13*'01_PARAMETRES'!$D$20+75*'01_PARAMETRES'!$D$21,1) -> 81 | I13: 45 | J13: =IF(I13>=60,"🔴 Critique (<3 ans retraite)",IF(I13>=55,"🟡 Vigilance (<8 ans)",IF(AND(K13<3,I13<35),"🟡 Turnover risqué","🟢 Stable"))) -> 🟢 Stable | K13: 14 | L13: Oui | M13: 2 | N13: 4 | O13: Oui
B14: Clara D. | C14: M15 | D14: 80 | E14: 65 | F14: 72 | G14: 82 | H14: =ROUND(D14*'01_PARAMETRES'!$D$17+E14*'01_PARAMETRES'!$D$18+F14*'01_PARAMETRES'!$D$19+G14*'01_PARAMETRES'!$D$20+75*'01_PARAMETRES'!$D$21,1) -> 75.2 | I14: 38 | J14: =IF(I14>=60,"🔴 Critique (<3 ans retraite)",IF(I14>=55,"🟡 Vigilance (<8 ans)",IF(AND(K14<3,I14<35),"🟡 Turnover risqué","🟢 Stable"))) -> 🟢 Stable | K14: 10 | L14: Non | M14: 1 | N14: 4 | O14: Non
B15: Hiromi T. | C15: M07 | D15: 94 | E15: 85 | F15: 96 | G15: 68 | H15: =ROUND(D15*'01_PARAMETRES'!$D$17+E15*'01_PARAMETRES'!$D$18+F15*'01_PARAMETRES'!$D$19+G15*'01_PARAMETRES'!$D$20+75*'01_PARAMETRES'!$D$21,1) -> 86.8 | I15: 52 | J15: =IF(I15>=60,"🔴 Critique (<3 ans retraite)",IF(I15>=55,"🟡 Vigilance (<8 ans)",IF(AND(K15<3,I15<35),"🟡 Turnover risqué","🟢 Stable"))) -> 🟢 Stable | K15: 20 | L15: Oui | M15: 1 | N15: 3 | O15: Oui
B16: Jean-Louis B. | C16: M08 | D16: 88 | E16: 92 | F16: 86 | G16: 88 | H16: =ROUND(D16*'01_PARAMETRES'!$D$17+E16*'01_PARAMETRES'!$D$18+F16*'01_PARAMETRES'!$D$19+G16*'01_PARAMETRES'!$D$20+75*'01_PARAMETRES'!$D$21,1) -> 87.1 | I16: 59 | J16: =IF(I16>=60,"🔴 Critique (<3 ans retraite)",IF(I16>=55,"🟡 Vigilance (<8 ans)",IF(AND(K16<3,I16<35),"🟡 Turnover risqué","🟢 Stable"))) -> 🟡 Vigilance (<8 ans) | K16: 30 | L16: Oui | M16: 2 | N16: 5 | O16: Oui
B17: Sarah K. | C17: M13 | D17: 76 | E17: 55 | F17: 78 | G17: 80 | H17: =ROUND(D17*'01_PARAMETRES'!$D$17+E17*'01_PARAMETRES'!$D$18+F17*'01_PARAMETRES'!$D$19+G17*'01_PARAMETRES'!$D$20+75*'01_PARAMETRES'!$D$21,1) -> 72.7 | I17: 32 | J17: =IF(I17>=60,"🔴 Critique (<3 ans retraite)",IF(I17>=55,"🟡 Vigilance (<8 ans)",IF(AND(K17<3,I17<35),"🟡 Turnover risqué","🟢 Stable"))) -> 🟢 Stable | K17: 6 | L17: Non | M17: 0 | N17: 3 | O17: Non
B18: Michel V. | C18: M10 | D18: 82 | E18: 88 | F18: 80 | G18: 72 | H18: =ROUND(D18*'01_PARAMETRES'!$D$17+E18*'01_PARAMETRES'!$D$18+F18*'01_PARAMETRES'!$D$19+G18*'01_PARAMETRES'!$D$20+75*'01_PARAMETRES'!$D$21,1) -> 80.6 | I18: 56 | J18: =IF(I18>=60,"🔴 Critique (<3 ans retraite)",IF(I18>=55,"🟡 Vigilance (<8 ans)",IF(AND(K18<3,I18<35),"🟡 Turnover risqué","🟢 Stable"))) -> 🟡 Vigilance (<8 ans) | K18: 24 | L18: Non | M18: 1 | N18: 4 | O18: Non
B19: Nathalie B. | C19: M16 | D19: 78 | E19: 62 | F19: 80 | G19: 85 | H19: =ROUND(D19*'01_PARAMETRES'!$D$17+E19*'01_PARAMETRES'!$D$18+F19*'01_PARAMETRES'!$D$19+G19*'01_PARAMETRES'!$D$20+75*'01_PARAMETRES'!$D$21,1) -> 76 | I19: 42 | J19: =IF(I19>=60,"🔴 Critique (<3 ans retraite)",IF(I19>=55,"🟡 Vigilance (<8 ans)",IF(AND(K19<3,I19<35),"🟡 Turnover risqué","🟢 Stable"))) -> 🟢 Stable | K19: 14 | L19: Non | M19: 1 | N19: 4 | O19: Oui
... B37: Colette D. | C37: M13 | D37: 90 | E37: 85 | F37: 88 | G37: 92 | H37: =ROUND(D37*'01_PARAMETRES'!$D$17+E37*'01_PARAMETRES'!$D$18+F37*'01_PARAMETRES'!$D$19+G37*'01_PARAMETRES'!$D$20+75*'01_PARAMETRES'!$D$21,1) -> 87.4 | I37: 58 | J37: =IF(I37>=60,"🔴 Critique (<3 ans retraite)",IF(I37>=55,"🟡 Vigilance (<8 ans)",IF(AND(K37<3,I37<35),"🟡 Turnover risqué","🟢 Stable"))) -> 🟡 Vigilance (<8 ans) | K37: 28 | L37: Oui | M37: 3 | N37: 5 | O37: Oui
B40: ▌ PYRAMIDE DES ÂGES — Données (alimentent le graphique)
B41: Tranche d'âge | C41: Nb collaborateurs | D41: % total | E41: Risque
B42: < 30 ans | C42: =COUNTIFS($I$8:$I$37,">="&0,$I$8:$I$37,"<="&29) -> 3 | D42: =IFERROR(C42/COUNTA($B$8:$B$37),0) -> 0.1 | E42: 🟢 Faible
B43: 30–39 ans | C43: =COUNTIFS($I$8:$I$37,">="&30,$I$8:$I$37,"<="&39) -> 5 | D43: =IFERROR(C43/COUNTA($B$8:$B$37),0) -> 0.16666667 | E43: 🟢 Faible
B44: 40–49 ans | C44: =COUNTIFS($I$8:$I$37,">="&40,$I$8:$I$37,"<="&49) -> 8 | D44: =IFERROR(C44/COUNTA($B$8:$B$37),0) -> 0.26666667 | E44: 🟡 Modéré
B45: 50–59 ans | C45: =COUNTIFS($I$8:$I$37,">="&50,$I$8:$I$37,"<="&59) -> 11 | D45: =IFERROR(C45/COUNTA($B$8:$B$37),0) -> 0.36666667 | E45: 🟡 Élevé
B46: 60 ans + | C46: =COUNTIFS($I$8:$I$37,">="&60,$I$8:$I$37,"<="&99) -> 3 | D46: =IFERROR(C46/COUNTA($B$8:$B$37),0) -> 0.1 | E46: 🔴 Critique
B49: NEURAL — Intelligence Augmentée pour l'Entreprise · neural-platform.vercel.app · Données simulées à des fins de démonstration

Sheet 07_GAP_ANALYSIS
B1: 📋 NEURAL — GAP_ANALYSIS · Écart Compétences Actuelles vs Besoins
B2: Calcul automatique des gaps · Prise en compte départs retraite · Priorités recrutement
B3: =COUNTIF(H8:H21,"<0") -> 14 | D3: =COUNTIF(I8:I21,"<=-3") -> 8 | F3: =COUNTIF(H8:H21,">0") -> 0 | H3: =SUM(H8:H21) -> -59 | J3: =SUM(G8:G21) -> 8
B4: POSTES EN DÉFICIT | D4: URGENCES CRITIQUES ⚡ | F4: POSTES EN SURPLUS | H4: GAP TOTAL BRUT | J4: DÉPARTS RETRAITE < 3 ANS
B6: ▌ ANALYSE DES ÉCARTS PAR MÉTIER — Priorités de Recrutement
B7: ID | C7: Famille | D7: Métier | E7: Besoin cible FTE | F7: Effectif actuel FTE | G7: Dont dép. retraite < 3 ans | H7: GAP brut | I7: Urgence ajustée | J7: Priorité | K7: Proj. N+1 Âge retraite-1 | L7: Proj. N+3 (param. C45) | M7: Proj. N+5 Âge retraite-5 | N7: Statut action
B8: M01 | C8: Maroquinerie | D8: Sellier-maroquinier | E8: 15 | F8: =IFERROR(COUNTIF('06_CARTO'!$C$8:$C$57,B8),11) -> 3 | G8: 2 | H8: =F8-E8 -> -12 | I8: =H8-G8 -> -14 | J8: =IF(I8<=-3,"⚡ "&RANK(I8,$I$8:$I$21,1),IF(I8<0,RANK(I8,$I$8:$I$21,1),"—")) -> ⚡ 1 | K8: =F8-IFERROR(COUNTIFS('06_CARTO'!$C$8:$C$57,B8,'06_CARTO'!$I$8:$I$57,">="&('01_PARAMETRES'!$C$48-1)),0) -> 3 | L8: =F8-IFERROR(COUNTIFS('06_CARTO'!$C$8:$C$57,B8,'06_CARTO'!$I$8:$I$57,">="&('01_PARAMETRES'!$C$48-'01_PARAMETRES'!$C$45)),0) -> 1 | M8: =F8-IFERROR(COUNTIFS('06_CARTO'!$C$8:$C$57,B8,'06_CARTO'!$I$8:$I$57,">="&('01_PARAMETRES'!$C$48-5)),0) -> 1 | N8: En cours
B9: M02 | C9: Maroquinerie | D9: Coupeur cuir | E9: 8 | F9: =IFERROR(COUNTIF('06_CARTO'!$C$8:$C$57,B9),7) -> 2 | G9: 0 | H9: =F9-E9 -> -6 | I9: =H9-G9 -> -6 | J9: =IF(I9<=-3,"⚡ "&RANK(I9,$I$8:$I$21,1),IF(I9<0,RANK(I9,$I$8:$I$21,1),"—")) -> ⚡ 4 | K9: =F9-IFERROR(COUNTIFS('06_CARTO'!$C$8:$C$57,B9,'06_CARTO'!$I$8:$I$57,">="&('01_PARAMETRES'!$C$48-1)),0) -> 2 | L9: =F9-IFERROR(COUNTIFS('06_CARTO'!$C$8:$C$57,B9,'06_CARTO'!$I$8:$I$57,">="&('01_PARAMETRES'!$C$48-'01_PARAMETRES'!$C$45)),0) -> 2 | M9: =F9-IFERROR(COUNTIFS('06_CARTO'!$C$8:$C$57,B9,'06_CARTO'!$I$8:$I$57,">="&('01_PARAMETRES'!$C$48-5)),0) -> 2 | N9: En cours
B10: M03 | C10: Maroquinerie | D10: Piqueur main | E10: 6 | F10: =IFERROR(COUNTIF('06_CARTO'!$C$8:$C$57,B10),4) -> 0 | G10: 1 | H10: =F10-E10 -> -6 | I10: =H10-G10 -> -7 | J10: =IF(I10<=-3,"⚡ "&RANK(I10,$I$8:$I$21,1),IF(I10<0,RANK(I10,$I$8:$I$21,1),"—")) -> ⚡ 3 | K10: =F10-IFERROR(COUNTIFS('06_CARTO'!$C$8:$C$57,B10,'06_CARTO'!$I$8:$I$57,">="&('01_PARAMETRES'!$C$48-1)),0) -> 0 | L10: =F10-IFERROR(COUNTIFS('06_CARTO'!$C$8:$C$57,B10,'06_CARTO'!$I$8:$I$57,">="&('01_PARAMETRES'!$C$48-'01_PARAMETRES'!$C$45)),0) -> 0 | M10: =F10-IFERROR(COUNTIFS('06_CARTO'!$C$8:$C$57,B10,'06_CARTO'!$I$8:$I$57,">="&('01_PARAMETRES'!$C$48-5)),0) -> 0 | N10: En cours
B11: M05 | C11: Joaillerie | D11: Sertisseur | E11: 8 | F11: =IFERROR(COUNTIF('06_CARTO'!$C$8:$C$57,B11),5) -> 3 | G11: 1 | H11: =F11-E11 -> -5 | I11: =H11-G11 -> -6 | J11: =IF(I11<=-3,"⚡ "&RANK(I11,$I$8:$I$21,1),IF(I11<0,RANK(I11,$I$8:$I$21,1),"—")) -> ⚡ 4 | K11: =F11-IFERROR(COUNTIFS('06_CARTO'!$C$8:$C$57,B11,'06_CARTO'!$I$8:$I$57,">="&('01_PARAMETRES'!$C$48-1)),0) -> 3 | L11: =F11-IFERROR(COUNTIFS('06_CARTO'!$C$8:$C$57,B11,'06_CARTO'!$I$8:$I$57,">="&('01_PARAMETRES'!$C$48-'01_PARAMETRES'!$C$45)),0) -> 3 | M11: =F11-IFERROR(COUNTIFS('06_CARTO'!$C$8:$C$57,B11,'06_CARTO'!$I$8:$I$57,">="&('01_PARAMETRES'!$C$48-5)),0) -> 3 | N11: En cours
B12: M07 | C12: Joaillerie | D12: Lapidaire | E12: 3 | F12: =IFERROR(COUNTIF('06_CARTO'!$C$8:$C$57,B12),2) -> 2 | G12: 1 | H12: =F12-E12 -> -1 | I12: =H12-G12 -> -2 | J12: =IF(I12<=-3,"⚡ "&RANK(I12,$I$8:$I$21,1),IF(I12<0,RANK(I12,$I$8:$I$21,1),"—")) -> 9 | K12: =F12-IFERROR(COUNTIFS('06_CARTO'!$C$8:$C$57,B12,'06_CARTO'!$I$8:$I$57,">="&('01_PARAMETRES'!$C$48-1)),0) -> 2 | L12: =F12-IFERROR(COUNTIFS('06_CARTO'!$C$8:$C$57,B12,'06_CARTO'!$I$8:$I$57,">="&('01_PARAMETRES'!$C$48-'01_PARAMETRES'!$C$45)),0) -> 2 | M12: =F12-IFERROR(COUNTIFS('06_CARTO'!$C$8:$C$57,B12,'06_CARTO'!$I$8:$I$57,">="&('01_PARAMETRES'!$C$48-5)),0) -> 2 | N12: En cours
B13: M08 | C13: Joaillerie | D13: Orfèvre | E13: 5 | F13: =IFERROR(COUNTIF('06_CARTO'!$C$8:$C$57,B13),5) -> 2 | G13: 0 | H13: =F13-E13 -> -3 | I13: =H13-G13 -> -3 | J13: =IF(I13<=-3,"⚡ "&RANK(I13,$I$8:$I$21,1),IF(I13<0,RANK(I13,$I$8:$I$21,1),"—")) -> ⚡ 8 | K13: =F13-IFERROR(COUNTIFS('06_CARTO'!$C$8:$C$57,B13,'06_CARTO'!$I$8:$I$57,">="&('01_PARAMETRES'!$C$48-1)),0) -> 2 | L13: =F13-IFERROR(COUNTIFS('06_CARTO'!$C$8:$C$57,B13,'06_CARTO'!$I$8:$I$57,">="&('01_PARAMETRES'!$C$48-'01_PARAMETRES'!$C$45)),0) -> 2 | M13: =F13-IFERROR(COUNTIFS('06_CARTO'!$C$8:$C$57,B13,'06_CARTO'!$I$8:$I$57,">="&('01_PARAMETRES'!$C$48-5)),0) -> 1 | N13: Planifié
B14: M09 | C14: Joaillerie | D14: Guillocheur | E14: 2 | F14: =IFERROR(COUNTIF('06_CARTO'!$C$8:$C$57,B14),1) -> 1 | G14: 0 | H14: =F14-E14 -> -1 | I14: =H14-G14 -> -1 | J14: =IF(I14<=-3,"⚡ "&RANK(I14,$I$8:$I$21,1),IF(I14<0,RANK(I14,$I$8:$I$21,1),"—")) -> 12 | K14: =F14-IFERROR(COUNTIFS('06_CARTO'!$C$8:$C$57,B14,'06_CARTO'!$I$8:$I$57,">="&('01_PARAMETRES'!$C$48-1)),0) -> 1 | L14: =F14-IFERROR(COUNTIFS('06_CARTO'!$C$8:$C$57,B14,'06_CARTO'!$I$8:$I$57,">="&('01_PARAMETRES'!$C$48-'01_PARAMETRES'!$C$45)),0) -> 1 | M14: =F14-IFERROR(COUNTIFS('06_CARTO'!$C$8:$C$57,B14,'06_CARTO'!$I$8:$I$57,">="&('01_PARAMETRES'!$C$48-5)),0) -> 1 | N14: Planifié
B15: M10 | C15: Horlogerie | D15: Horloger | E15: 12 | F15: =IFERROR(COUNTIF('06_CARTO'!$C$8:$C$57,B15),14) -> 3 | G15: 3 | H15: =F15-E15 -> -9 | I15: =H15-G15 -> -12 | J15: =IF(I15<=-3,"⚡ "&RANK(I15,$I$8:$I$21,1),IF(I15<0,RANK(I15,$I$8:$I$21,1),"—")) -> ⚡ 2 | K15: =F15-IFERROR(COUNTIFS('06_CARTO'!$C$8:$C$57,B15,'06_CARTO'!$I$8:$I$57,">="&('01_PARAMETRES'!$C$48-1)),0) -> 3 | L15: =F15-IFERROR(COUNTIFS('06_CARTO'!$C$8:$C$57,B15,'06_CARTO'!$I$8:$I$57,">="&('01_PARAMETRES'!$C$48-'01_PARAMETRES'!$C$45)),0) -> 3 | M15: =F15-IFERROR(COUNTIFS('06_CARTO'!$C$8:$C$57,B15,'06_CARTO'!$I$8:$I$57,">="&('01_PARAMETRES'!$C$48-5)),0) -> 2 | N15: Planifié
B16: M12 | C16: Horlogerie | D16: Émailleur | E16: 2 | F16: =IFERROR(COUNTIF('06_CARTO'!$C$8:$C$57,B16),1) -> 1 | G16: 0 | H16: =F16-E16 -> -1 | I16: =H16-G16 -> -1 | J16: =IF(I16<=-3,"⚡ "&RANK(I16,$I$8:$I$21,1),IF(I16<0,RANK(I16,$I$8:$I$21,1),"—")) -> 12 | K16: =F16-IFERROR(COUNTIFS('06_CARTO'!$C$8:$C$57,B16,'06_CARTO'!$I$8:$I$57,">="&('01_PARAMETRES'!$C$48-1)),0) -> 1 | L16: =F16-IFERROR(COUNTIFS('06_CARTO'!$C$8:$C$57,B16,'06_CARTO'!$I$8:$I$57,">="&('01_PARAMETRES'!$C$48-'01_PARAMETRES'!$C$45)),0) -> 1 | M16: =F16-IFERROR(COUNTIFS('06_CARTO'!$C$8:$C$57,B16,'06_CARTO'!$I$8:$I$57,">="&('01_PARAMETRES'!$C$48-5)),0) -> 1 | N16: Planifié
