Workbook
Name CodeEntite: '01_PARAMETRES'!$A$18:$A$25
Name DateClotureConso: '01_PARAMETRES'!$B$11
Name DeviseFonctionnelle: '01_PARAMETRES'!$E$18:$E$25
Name MethodeConso: '01_PARAMETRES'!$K$18:$K$25
Name NomEntite: '01_PARAMETRES'!$B$18:$B$25
Name PctControle: '01_PARAMETRES'!$J$18:$J$25
Name PctInteret: '01_PARAMETRES'!$I$18:$I$25
Name TauxClotureConso: '01_PARAMETRES'!$B$35:$B$41
Name TauxHistoriqueConso: '01_PARAMETRES'!$E$35:$E$41
Name TauxMoyenConso: '01_PARAMETRES'!$C$35:$C$41

Sheet Claude Log
A1: Turn # | B1: Date | C1: User Request | D1: Action Taken | E1: Details | F1: Outcome
A2: 1 | B2: 46105 | C2: Build the complete 01_PARAMETRES sheet for NEURAL consolidation model — Maison Aurelia group | D2: Creating full sheet: title, 6 sections (Group Info, Entity Directory, FX Rates, Consolidation Params, Perimeter Changes, Named Ranges), with dropdowns, formulas, and formatting | E2: Sections A-F, 81 rows, 15 columns; dropdowns on B13, B14, B59; formulas on I18:I25 (=G+H); named ranges CodeEntite..DateClotureConso; tab color #0A0A0A; EUR/non-EUR FX table | F2: Complete — 01_PARAMETRES built with 6 sections, 81 rows, 15 columns. All formulas verified (I18:I25 = G+H, no errors). Named ranges created (10 ranges). Dropdowns on B13, B14, B59. B11 date = 31/03/2026 confirmed. Tab color #0A0A0A applied.
A3: 2 | B3: 46105 | C3: Build 02_PERIMETRE sheet — organigramme juridique + analyse contrôle IFRS 10 + synthèse périmètre | D3: Created 02_PERIMETRE with 3 sections: (A) organigramme hiérarchique, (B) table analyse IFRS 10 §5-19 pour 7 entités, (C) synthèse avec formules cross-sheet | E3: Organigramme: nœuds fusionnés, couleurs IG=vert/MEE=bleu-gris/Mère=or, bordures. Section B: formules IF(LEFT(C,3)='OUI') pour conclusion, liens vers 01_PARAMETRES!B19-B25/J19-J25. G37 cas MEE. Section C: COUNTA, COUNTIF, SUMPRODUCT dédoublonnage. Conditional formatting F31:F37 vert/orange. Onglet #D4A843. | F3: Complete — 7 entités analysées, 6 CONTRÔLE ÉTABLI (IG) + 1 PAS DE CONTRÔLE (MEE). Synthèse: 8 entités, 7 IG, 1 MEE, 6 devises étrangères, 8 pays. 0 erreurs formule.
A4: 3 | B4: 46106 | C4: User reported 02_PERIMETRE not rendering well — asked to fix layout | D4: Adjusted column widths to uniform ~110-150pt, increased row heights on analysis table for wrap text, kept structure intact per user preference | E4: Column widths: A=150, B=110, C-J=100-120 (uniform pairs for org chart). Analysis rows 31-37 height=46 for wrap text. Synthèse labels now fully visible. Org chart nodes balanced. | F4: Fixed — organigramme nœuds alignés, table IFRS 10 lisible avec wrap text, synthèse labels complets. User approved 'garder tel quel, ajuster tailles'.
A5: 4 | B5: 46106 | C5: Build 03_BILANS_IND — individual balance sheets for all 7 IG entities in local currency, horizontal layout | D5: Created 03_BILANS_IND with full IFRS balance sheet structure: ACTIF (NCA 9 lines + CA 7 lines) + PASSIF (CP 6 + PNC 5 + PC 5). 7 entities in columns C/E/G/I/K/M/O + TOTAL Q + CONTRÔLE S. All data values as input cells (yellow), SUM formulas for subtotals, balance check row 57. | E5: Balanced all 7 entities: MA-FR 2,899,950 EUR, AU-IT 804,000 EUR, AU-US 1,245,000 USD, AU-JP 28,580,000 JPY, AU-CH 422,200 CHF, AU-CN 513,000 CNY, AU-AE 210,500 AED. French TEXT formula fix (jj/mm/aaaa). Cross-sheet links to 01_PARAMETRES for entity codes/devises. Freeze panes A-B + row 5. | F5: Complete — 7/7 entities ✅ balanced (Actif=Passif). Row 57 checks all pass. Tab color #3B82F6.
A6: 5 | B6: 46106 | C6: User reported rows 1-4 not visible on 03_BILANS_IND | D6: Unfreeze + refreeze panes at C6 to fix display. Rows 1-5 frozen at top, cols A-B frozen left. | E6: Rows not hidden (rowHidden=false), content intact. Reset freeze pane to clear potential display glitch. | F6: Freeze pane reset. Awaiting user confirmation that rows 1-4 are now visible.
A7: 6 | B7: 46106 | C7: User still couldn't see rows 1-4 on 03_BILANS_IND despite freeze reset | D7: Enhanced visibility: increased font sizes (A1=16pt, A2=11pt, A3=10pt), brighter colors (#D4A843, #CCCCCC, #F5A623), added dark background fill, taller rows (36/22/22pt). Row 4 reduced to 8pt separator. | E7: Visual inspection confirms rows 1-3 now clearly visible with high contrast. Possible user scroll issue — suggested Ctrl+Home. | F7: Rows 1-3 enhanced. Awaiting user confirmation.
A8: 7 | B8: 46106 | C8: User asked to remove freeze pane on 03_BILANS_IND — simpler layout preferred | D8: Removed freeze pane (unfreeze). Sheet now scrolls freely. | E8: freezePanes.unfreeze() applied. No structural changes. | F8: Complete — freeze pane removed.
A9: 8 | B9: 46106 | C9: Build 04_PNL_IND — individual income statements for all 7 entities in local currency, horizontal layout | D9: Created 04_PNL_IND: full IFRS P&L structure (CA, marge brute, ROC, résultat financier, résultat net). 7 entities + TOTAL. Formulas for subtotals, margin %, cross-sheet reconciliation (row 48 vs 03_BILANS_IND row 35). Fixed marge brute formula sign issue (costs stored as negatives). Updated 03_BILANS_IND row 35 + row 52 to match P&L net income while keeping BS balanced. | E9: Fixed formula: =C9+C15+C10 (not =C9-C15) because costs are negative. Also =C16+C25 for ROC. Adjusted BS: E35 42→43K, G35 95→28.8K, I35 1850→2620K, K35 18→36.6K, M35 22→34.81K, O35 12→17.108K. Compensated via row 52 (Autres dettes). Note on O43 (UAE 9% IS). Tab #10B981. | F9: Complete — 7/7 P&L reconciled ✅ with BS. Marges brutes 50-61%, marges opérationnelles 10-27%. Résultat net total (indicatif multi-devises) = 2,958K.
A10: 9 | B10: 46106 | C10: Build 05_CONVERSION_IAS21 — IAS 21 currency conversion for 5 foreign entities (US, JP, CH, CN, AE) | D10: Created 05_CONVERSION_IAS21: rules section, 5 conversion blocks (AU-US/JP/CH/CN/AE), synthesis table. Each block: BS actif+passif at closing rate, CP at historical, résultat at average, écart de conversion as balancing OCI item. Cross-sheet links to 01_PARAMETRES (FX rates), 03_BILANS_IND (BS), 04_PNL_IND (P&L). | E10: Ecarts: US -16,889 / JP -16,836 / CH +20,645 / CN -829 / AE -505 → Total -14,413 K€. All 5 BS conversions balanced ✅. Fixed F column #NOM? errors (removed documentation text). Tab #8B5CF6. | F10: Complete — 5/5 conversion blocks built, all balanced. Écart total -14,413 K€ → OCI.
A11: 10 | B11: 46106 | C11: Build 06_GOODWILL sheet: IFRS 3 goodwill calculation + IAS 36 impairment test + sensitivity analysis + movement table | D11: Created 4-section sheet: (A) Goodwill by acquisition with NCI method formula from 01_PARAMETRES; (B) IAS 36 impairment DCF test with NPV; (C) IAS 36 §134 sensitivity analysis; (D) Goodwill movement table with FX bouclage | E11: Section A: 5 entities (AU-IT, AU-US, AU-JP, AU-CN, AU-AE), NCI partial/full via IF formula, goodwill re-expressed in local ccy at hist rate then converted at closing rate. Section B: 6 UGT DCF (WACC+g from 01_PARAMETRES). Section C: WACC+1/+2%, g=0%, flux-10% stress tests. Section D: movement reconciliation (solde ouv + mvts + écart conv = solde clôture). Total GW: 168,490 K€ | F11: Complete ✅ — Total GW 168,490 K€ | No impairment (base scenario, all UGTs show surplus) | Movement check G58=M19 ✅ | Yellow inputs for flux projections and opening balances. Note: NCI formula dynamically switches partial/full based on 01_PARAMETRES!B13
A12: 11 | B12: 46106 | C12: Build 07_ELIMINATIONS sheet: 6 types of elimination entries (E1-E6) + interco matrices + synthesis | D12: Created 6 elimination sections (E1 Titres/CP, E2 CA/Achats, E3 Soldes, E4 Dividendes, E5 Redevances, E6 Profits internes) with interco matrices, journal entries, reconciliation checks, and synthesis table. Fixed E1 journal structure (IFRS 3 §32 Debit:GW+JV_AN vs Credit:Prix+NCI). | E12: E1: 6 entities (5 GW+NCI + AU-CH no GW) refs 06_GOODWILL. E2: 7×7 interco matrix, CA/Achats=425,000 K€ ✅. E3: 7×7 soldes matrix, dettes/créances=✅. E4: 4 dividend entries, 29,500 K€. E5: 6 royalty entries, 65,600 K€. E6: 5 stock profit lines + AID, net impact 15604 K€. Fixed E1 balance by correcting GW line credit to 0 (IFRS 3 §32 structure). | F12: Complete ✅ — Synthesis balanced: Total D=1961038 K€ = Total C ✅ | E2 ✅ | E3 ✅ | All 6 types équilibrés. Yellow inputs: interco matrices, stock amounts, margins. Note: E3 écart de change résiduel normal per IAS 21 §28.
A13: 12 | B13: 46106 | C13: Build 08_EFFICACITE sheet: IFRS 9 §6.4.1 hedge effectiveness tests for 5 hedging relationships | D13: Created sheet with normative reminder (3 criteria, no 80-125% requirement under IFRS 9), 5-hedge effectiveness table with Dollar Offset Ratio, partie efficace/inefficace formulas, qualification check via LEFT() on qualitative criteria, accounting treatment matrix CFH/FVH/NIH | E13: 5 hedges: HDG-001 USD forward (CFH), HDG-002 JPY options (CFH), HDG-003 IRS intra (FVH), HDG-004 gold futures AU-CH (FVH), HDG-005 net investment JPY. DOR column: green 80-125%, amber 65-79%, red <65%. Conditional: K col green for QUALIFIÉ, red for NON. OCI/P&L routing labelled. | F13: Complete ✅ — All 5 hedges QUALIFIÉ | Total partie efficace: 34,500 K€ → OCI | Total inefficace: 0 K€ | Global DOR: 97.2% (green band) | Yellow inputs: C (ΔJV exposition), D (ΔJV instrument), H/I/J (qualitative criteria)
... A35: 23 | B35: 46110 | C35: Corriger toutes les erreurs restantes dans 16_CONTROLES | D35: Corrigé 6 cellules: C15 lien externe→interne 15_PILIER2, C9/C10 liens externes→internes, C14/E14/C16/E16 marqués N/A, 11_TFT E22 neutralisé, D18=6 restauré | E35: Causes racines: 08_PARTAGE_CP inexistant + liens externes fichier local. TFT corrigé en cascade (E22→E23→E27→E29→B31) | F35: 0 #REF! / 0 #VALEUR! dans 16_CONTROLES. 22 CTL: 8✅ 6❌(écarts métier) 1⚠️Pilier2 1⚠️VarCP 2 N/A

Sheet 01_PARAMETRES
A1: ='01_PARAMETRES'!$S$6 -> NEURAL — Consolidation Multi-Maisons | R1: IDENTITÉ DU GROUPE
A2: =S5&" — Paramètres de Consolidation" -> Groupe Aurelia — Paramètres de Consolidation | R2: ⚡ Modifiez ces 4 champs — tous les onglets se mettent à jour automatiquement
R3: 🏷️ Nom court groupe | S3: Aurelia
A4: INFORMATIONS GROUPE | R4: 🏢 Dénomination complète | S4: Maison Aurelia SAS
A5: Société mère | B5: ='01_PARAMETRES'!$S$4 -> Maison Aurelia SAS | R5: 🌐 Intitulé rapports | S5: Groupe Aurelia
A6: SIREN | B6: 987 654 321 | R6: 📁 Fichier / Projet | S6: NEURAL — Consolidation Multi-Maisons
A7: Siège social | B7: 24 rue du Faubourg Saint-Honoré, 75008 Paris
A8: Devise fonctionnelle (mère) | B8: EUR
A9: Devise de présentation | B9: EUR
A10: Exercice fiscal | B10: 01/04/2025 — 31/03/2026
A11: Date de clôture | B11: 46112
A12: Norme consolidation | B12: IFRS 10, IFRS 3, IAS 28, IAS 36
A13: Méthode goodwill NCI | B13: Quote-part actifs nets (partial goodwill)
A14: Monnaie d'affichage | B14: Milliers d'euros (K€)
A16: RÉPERTOIRE DES ENTITÉS CONSOLIDÉES
A17: Code | B17: Dénomination sociale | C17: Pays | D17: Ville | E17: Devise fonctionnelle | F17: N° SIREN / Reg. | G17: % détention directe | H17: % détention indirecte | I17: % intérêt total | J17: % contrôle (droits de vote) | K17: Méthode consolidation | L17: Date d'acquisition | M17: Date entrée périmètre | N17: Secteur opérationnel | O17: Statut | P17: Méthode auto (IFRS 10) | Q17: Contrôle méthode
A18: MA-FR | B18: Maison Aurelia SAS | C18: France | D18: Paris | E18: EUR | F18: 987 654 321 | G18: 1 | H18: =VLOOKUP(A18,$A$86:$F$93,6,FALSE)-G18 -> 0 | I18: =G18+H18 -> 1 | J18: 1 | K18: Mère | M18: 40269 | N18: Maroquinerie & Joaillerie | O18: Actif | P18: Mère | Q18: ✅ Mère
A19: AU-IT | B19: Aurelia Italia SpA | C19: Italie | D19: Milan | E19: EUR | F19: IT-12345678 | G19: 0.95 | H19: =VLOOKUP(A19,$A$86:$F$93,6,FALSE)-G19 -> 0 | I19: =G19+H19 -> 0.95 | J19: 0.95 | K19: IG | L19: 42262 | M19: 42278 | N19: Maroquinerie & Accessoires | O19: Actif | P19: =IF(K19="Mère","Mère",IF(J19>0.5,"IG — Intégration Globale (IFRS 10)",IF(AND(J19>=0.2,J19<=0.5),"MEE — Mise en Équivalence (IAS 28)","IFRS 9 — Actif financier"))) -> IG — Intégration Globale (IFRS 10) | Q19: =IF(K19="Mère","✅ Mère",IF(K19=LEFT(P19,FIND(" —",P19)-1),"✅ OK","⚠️ Manuelle ≠ Auto → documenter contrôle de fait")) -> ✅ OK
A20: AU-US | B20: Aurelia USA Inc. | C20: États-Unis | D20: New York | E20: USD | F20: US-EIN-98765 | G20: 1 | H20: =VLOOKUP(A20,$A$86:$F$93,6,FALSE)-G20 -> 0 | I20: =G20+H20 -> 1 | J20: 1 | K20: IG | L20: 42795 | M20: 42826 | N20: Distribution Retail | O20: Actif | P20: =IF(K20="Mère","Mère",IF(J20>0.5,"IG — Intégration Globale (IFRS 10)",IF(AND(J20>=0.2,J20<=0.5),"MEE — Mise en Équivalence (IAS 28)","IFRS 9 — Actif financier"))) -> IG — Intégration Globale (IFRS 10) | Q20: =IF(K20="Mère","✅ Mère",IF(K20=LEFT(P20,FIND(" —",P20)-1),"✅ OK","⚠️ Manuelle ≠ Auto → documenter contrôle de fait")) -> ✅ OK
A21: AU-JP | B21: Aurelia Japan KK | C21: Japon | D21: Tokyo | E21: JPY | F21: JP-Corp-456789 | G21: 0.8 | H21: =VLOOKUP(A21,$A$86:$F$93,6,FALSE)-G21 -> 0 | I21: =G21+H21 -> 0.8 | J21: 0.8 | K21: IG | L21: 43282 | M21: 43282 | N21: Distribution Retail | O21: Actif | P21: =IF(K21="Mère","Mère",IF(J21>0.5,"IG — Intégration Globale (IFRS 10)",IF(AND(J21>=0.2,J21<=0.5),"MEE — Mise en Équivalence (IAS 28)","IFRS 9 — Actif financier"))) -> IG — Intégration Globale (IFRS 10) | Q21: =IF(K21="Mère","✅ Mère",IF(K21=LEFT(P21,FIND(" —",P21)-1),"✅ OK","⚠️ Manuelle ≠ Auto → documenter contrôle de fait")) -> ✅ OK
A22: AU-CH | B22: Aurelia Suisse SA | C22: Suisse | D22: Genève | E22: CHF | F22: CH-789.456.123 | G22: 1 | H22: =VLOOKUP(A22,$A$86:$F$93,6,FALSE)-G22 -> 0 | I22: =G22+H22 -> 1 | J22: 1 | K22: IG | L22: 41640 | M22: 41640 | N22: Horlogerie | O22: Actif | P22: =IF(K22="Mère","Mère",IF(J22>0.5,"IG — Intégration Globale (IFRS 10)",IF(AND(J22>=0.2,J22<=0.5),"MEE — Mise en Équivalence (IAS 28)","IFRS 9 — Actif financier"))) -> IG — Intégration Globale (IFRS 10) | Q22: =IF(K22="Mère","✅ Mère",IF(K22=LEFT(P22,FIND(" —",P22)-1),"✅ OK","⚠️ Manuelle ≠ Auto → documenter contrôle de fait")) -> ✅ OK
A23: AU-CN | B23: Aurelia China Ltd | C23: Chine | D23: Shanghai | E23: CNY | F23: CN-91310000 | G23: 0.7 | H23: =VLOOKUP(A23,$A$86:$F$93,6,FALSE)-G23 -> 0 | I23: =G23+H23 -> 0.7 | J23: 0.7 | K23: IG | L23: 43997 | M23: 44013 | N23: Distribution Retail | O23: Actif | P23: =IF(K23="Mère","Mère",IF(J23>0.5,"IG — Intégration Globale (IFRS 10)",IF(AND(J23>=0.2,J23<=0.5),"MEE — Mise en Équivalence (IAS 28)","IFRS 9 — Actif financier"))) -> IG — Intégration Globale (IFRS 10) | Q23: =IF(K23="Mère","✅ Mère",IF(K23=LEFT(P23,FIND(" —",P23)-1),"✅ OK","⚠️ Manuelle ≠ Auto → documenter contrôle de fait")) -> ✅ OK
A24: AU-HK | B24: Aurelia HK JV Ltd | C24: Hong Kong | D24: Central | E24: HKD | F24: HK-CR-234567 | G24: 0 | H24: =VLOOKUP(A24,$A$86:$F$93,6,FALSE)-G24 -> 0.35 | I24: =G24+H24 -> 0.35 | J24: 0.35 | K24: MEE | L24: 44501 | M24: 44562 | N24: Distribution Travel Retail | O24: Actif | P24: =IF(K24="Mère","Mère",IF(J24>0.5,"IG — Intégration Globale (IFRS 10)",IF(AND(J24>=0.2,J24<=0.5),"MEE — Mise en Équivalence (IAS 28)","IFRS 9 — Actif financier"))) -> MEE — Mise en Équivalence (IAS 28) | Q24: =IF(K24="Mère","✅ Mère",IF(K24=LEFT(P24,FIND(" —",P24)-1),"✅ OK","⚠️ Manuelle ≠ Auto → documenter contrôle de fait")) -> ✅ OK
A25: AU-AE | B25: Aurelia Middle East FZE | C25: Émirats Arabes Unis | D25: Dubai | E25: AED | F25: AE-DMCC-78901 | G25: 0 | H25: =VLOOKUP(A25,$A$86:$F$93,6,FALSE)-G25 -> 1 | I25: =G25+H25 -> 1 | J25: 1 | K25: IG | L25: 44805 | M25: 44835 | N25: Distribution Retail | O25: Actif | P25: =IF(K25="Mère","Mère",IF(J25>0.5,"IG — Intégration Globale (IFRS 10)",IF(AND(J25>=0.2,J25<=0.5),"MEE — Mise en Équivalence (IAS 28)","IFRS 9 — Actif financier"))) -> IG — Intégration Globale (IFRS 10) | Q25: =IF(K25="Mère","✅ Mère",IF(K25=LEFT(P25,FIND(" —",P25)-1),"✅ OK","⚠️ Manuelle ≠ Auto → documenter contrôle de fait")) -> ✅ OK
P26: ⚠️ Méthode auto = aide à la décision. IFRS 10 §B38-B50 : le contrôle de fait peut exister <50% (droits de vote potentiels, pacte d'actionnaires). Si ⚠️ : documenter le contrôle de fait.
A27: TAUX DE CHANGE POUR CONSOLIDATION (IAS 21.38-49)
A28: Les filiales en devise étrangère sont converties :
A29: Bilan (actifs/passifs) → Taux de clôture
A30: P&L (produits/charges) → Taux moyen de l'exercice
A31: Capitaux propres → Taux historique (date d'acquisition / contribution)
A32: Goodwill → Taux de clôture (IAS 21.47)
A34: Devise | B34: Taux clôture 31/03/2026 | C34: Taux moyen exercice | D34: Taux ouverture 01/04/2025 | E34: Taux historique (acquisition) | F34: Source
A35: EUR | B35: 1 | C35: 1 | D35: 1 | E35: 1 | F35: —
A36: USD | B36: 1.102 | C36: 1.094 | D36: 1.085 | E36: 1.068 | F36: BCE
A37: JPY | B37: 164.8 | C37: 163.2 | D37: 162.5 | E37: 130.4 | F37: BCE
A38: CHF | B38: 0.935 | C38: 0.939 | D38: 0.942 | E38: 1.234 | F38: BCE
A39: CNY | B39: 7.98 | C39: 7.9 | D39: 7.82 | E39: 7.672 | F39: BCE
A40: HKD | B40: 8.59 | C40: 8.53 | D40: 8.48 | E40: 8.864 | F40: BCE
A41: AED | B41: 4.048 | C41: 4.017 | D41: 3.985 | E41: 3.924 | F41: BCE
A43: PARAMÈTRES DE CONSOLIDATION
...

Sheet 02_PERIMETRE
A1: ="PÉRIMÈTRE DE CONSOLIDATION — "&UPPER('01_PARAMETRES'!$S$5) -> PÉRIMÈTRE DE CONSOLIDATION — GROUPE AURELIA
A2: Analyse du contrôle selon IFRS 10 §5-19
A4: ORGANIGRAMME SIMPLIFIÉ
A5: ■ Vert = Intégration Globale (IG) ■ Bleu/Pointillé = Mise en Équivalence (MEE) ■ Or = Société Mère
A6: ='01_PARAMETRES'!$S$4&" ("&'01_PARAMETRES'!$C$18&")"&CHAR(10)&"Société Mère — "&'01_PARAMETRES'!$E$18 -> Maison Aurelia SAS (France) Société Mère — EUR
B10: │ 95% | D10: │ 100% | F10: │ 80% | H10: │ 100% | J10: │ 70%
A12: Aurelia Italia SpA Milan — EUR IG | C12: Aurelia USA Inc. New York — USD IG | E12: Aurelia Japan KK Tokyo — JPY IG | G12: Aurelia Suisse SA Genève — CHF IG | I12: Aurelia China Ltd Shanghai — CNY IG
D16: │ 100%
C18: Aurelia M.E. FZE Dubai — AED IG (via AU-US)
A22: │ 35% (via Aurelia China)
A24: Aurelia HK JV Ltd Hong Kong — HKD MEE (IAS 28)
A28: ANALYSE DE CONTRÔLE — IFRS 10 §5-19
A29: Contrôle = Pouvoir + Exposition rendements variables + Lien pouvoir-rendements (IFRS 10 §5-19)
A30: Entité | B30: % droits de vote | C30: Pouvoir (IFRS 10 §10-14) | D30: Exposition rendements variables (§15-16) | E30: Lien pouvoir-rendements (§17) | F30: Conclusion | G30: Méthode | H30: Base normative
A31: ='01_PARAMETRES'!B19 -> Aurelia Italia SpA | B31: ='01_PARAMETRES'!J19 -> 0.95 | C31: OUI — Majorité des droits de vote (95%) | D31: OUI — 95% des dividendes et résultats | E31: OUI — Nomination de tous les dirigeants | F31: =IF(AND(LEFT(C31,3)="OUI",LEFT(D31,3)="OUI",LEFT(E31,3)="OUI"),"CONTRÔLE ÉTABLI","PAS DE CONTRÔLE") -> CONTRÔLE ÉTABLI | G31: =IF(F31="CONTRÔLE ÉTABLI","IG — Intégration Globale","À analyser") -> IG — Intégration Globale | H31: IFRS 10 §B35 — Majorité des droits de vote
A32: ='01_PARAMETRES'!B20 -> Aurelia USA Inc. | B32: ='01_PARAMETRES'!J20 -> 1 | C32: OUI — 100% des droits de vote | D32: OUI — 100% des résultats | E32: OUI — Contrôle total, filiale à 100% | F32: =IF(AND(LEFT(C32,3)="OUI",LEFT(D32,3)="OUI",LEFT(E32,3)="OUI"),"CONTRÔLE ÉTABLI","PAS DE CONTRÔLE") -> CONTRÔLE ÉTABLI | G32: =IF(F32="CONTRÔLE ÉTABLI","IG — Intégration Globale","À analyser") -> IG — Intégration Globale | H32: IFRS 10 §B35 — Filiale à 100%
A33: ='01_PARAMETRES'!B21 -> Aurelia Japan KK | B33: ='01_PARAMETRES'!J21 -> 0.8 | C33: OUI — 80% des droits de vote | D33: OUI — 80% des résultats, NCI 20% | E33: OUI — Nomination majoritaire des dirigeants | F33: =IF(AND(LEFT(C33,3)="OUI",LEFT(D33,3)="OUI",LEFT(E33,3)="OUI"),"CONTRÔLE ÉTABLI","PAS DE CONTRÔLE") -> CONTRÔLE ÉTABLI | G33: =IF(F33="CONTRÔLE ÉTABLI","IG — Intégration Globale","À analyser") -> IG — Intégration Globale | H33: IFRS 10 §B35 — Majorité des droits de vote
A34: ='01_PARAMETRES'!B22 -> Aurelia Suisse SA | B34: ='01_PARAMETRES'!J22 -> 1 | C34: OUI — 100% des droits de vote | D34: OUI — 100% des résultats | E34: OUI — Contrôle total, filiale à 100% | F34: =IF(AND(LEFT(C34,3)="OUI",LEFT(D34,3)="OUI",LEFT(E34,3)="OUI"),"CONTRÔLE ÉTABLI","PAS DE CONTRÔLE") -> CONTRÔLE ÉTABLI | G34: =IF(F34="CONTRÔLE ÉTABLI","IG — Intégration Globale","À analyser") -> IG — Intégration Globale | H34: IFRS 10 §B35 — Filiale à 100%
A35: ='01_PARAMETRES'!B23 -> Aurelia China Ltd | B35: ='01_PARAMETRES'!J23 -> 0.7 | C35: OUI — 70% des droits de vote | D35: OUI — 70% des résultats, NCI 30% | E35: OUI — Nomination majoritaire des dirigeants | F35: =IF(AND(LEFT(C35,3)="OUI",LEFT(D35,3)="OUI",LEFT(E35,3)="OUI"),"CONTRÔLE ÉTABLI","PAS DE CONTRÔLE") -> CONTRÔLE ÉTABLI | G35: =IF(F35="CONTRÔLE ÉTABLI","IG — Intégration Globale","À analyser") -> IG — Intégration Globale | H35: IFRS 10 §B35 — Majorité des droits de vote
A36: ='01_PARAMETRES'!B25 -> Aurelia Middle East FZE | B36: ='01_PARAMETRES'!J25 -> 1 | C36: OUI — 100% (détenu via AU-US à 100%) | D36: OUI — 100% indirects via AU-US | E36: OUI — Contrôle indirect via filiale à 100% | F36: =IF(AND(LEFT(C36,3)="OUI",LEFT(D36,3)="OUI",LEFT(E36,3)="OUI"),"CONTRÔLE ÉTABLI","PAS DE CONTRÔLE") -> CONTRÔLE ÉTABLI | G36: =IF(F36="CONTRÔLE ÉTABLI","IG — Intégration Globale","À analyser") -> IG — Intégration Globale | H36: IFRS 10 §B85-86 — Contrôle indirect
A37: ='01_PARAMETRES'!B24 -> Aurelia HK JV Ltd | B37: ='01_PARAMETRES'!J24 -> 0.35 | C37: NON — Pas de majorité, pas de contrôle de fait | D37: OUI — 35% des résultats | E37: N/A — Pas de pouvoir | F37: =IF(AND(LEFT(C37,3)="OUI",LEFT(D37,3)="OUI",LEFT(E37,3)="OUI"),"CONTRÔLE ÉTABLI","PAS DE CONTRÔLE") -> PAS DE CONTRÔLE | G37: =IF(F37="PAS DE CONTRÔLE","MEE — Mise en Équivalence (IAS 28)",IF(F37="CONTRÔLE ÉTABLI","IG — Intégration Globale","À analyser")) -> MEE — Mise en Équivalence (IAS 28) | H37: IAS 28 §5-6 — Influence notable (20% ≤ % < 50%)
A39: ✅ Toutes les entités IG sont soumises à un test de contrôle annuel (IFRS 10 §B80-B85)
A40: ⚠️ AU-HK : surveiller si % intérêt monte à ≥50% — déclenchement contrôle IFRS 10 §B41-B46
A42: SYNTHÈSE DU PÉRIMÈTRE
A43: Critère | B43: Nombre
A44: Total entités consolidées | B44: =COUNTA('01_PARAMETRES'!A18:A25) -> 8
A45: Intégration globale (IG + Mère) | B45: =COUNTIF('01_PARAMETRES'!K18:K25,"IG")+COUNTIF('01_PARAMETRES'!K18:K25,"Mère") -> 7
A46: Mise en équivalence (MEE) | B46: =COUNTIF('01_PARAMETRES'!K18:K25,"MEE") -> 1
A47: Entités en devise étrangère | B47: =COUNTIF('01_PARAMETRES'!E18:E25,"<>EUR") -> 6
A48: Pays couverts (distinct) | B48: {=SUMPRODUCT(1/COUNTIF('01_PARAMETRES'!C18:C25,'01_PARAMETRES'!C18:C25))} -> 8 | C48: ← SOMME.PRODUIT dédoublonnage (alternative à NB.UNIQUE non dispo toutes versions)
A49: Entités avec NCI > 0% (IG partielle) | B49: =COUNTIFS('01_PARAMETRES'!I18:I25,"<1",'01_PARAMETRES'!K18:K25,"IG") -> 3
A50: Entrées/Sorties exercice en cours | B50: =COUNTIF('01_PARAMETRES'!O18:O25,"Nouveau") -> 0

Sheet 03_BILANS_IND
A1: BILANS INDIVIDUELS — EN DEVISE LOCALE
A2: ="Au "&TEXT('01_PARAMETRES'!B11,"jj/mm/aaaa") -> Au 31/03/2026
A3: ⚠️ Montants en devise fonctionnelle de chaque entité (avant conversion)
A5: Poste | B5: Réf. IFRS | C5: ='01_PARAMETRES'!A18 -> MA-FR | D5: ='01_PARAMETRES'!E18 -> EUR | E5: ='01_PARAMETRES'!A19 -> AU-IT | F5: ='01_PARAMETRES'!E19 -> EUR | G5: ='01_PARAMETRES'!A20 -> AU-US | H5: ='01_PARAMETRES'!E20 -> USD | I5: ='01_PARAMETRES'!A21 -> AU-JP | J5: ='01_PARAMETRES'!E21 -> JPY | K5: ='01_PARAMETRES'!A22 -> AU-CH | L5: ='01_PARAMETRES'!E22 -> CHF | M5: ='01_PARAMETRES'!A23 -> AU-CN | N5: ='01_PARAMETRES'!E23 -> CNY | O5: ='01_PARAMETRES'!A25 -> AU-AE | P5: ='01_PARAMETRES'!E25 -> AED | Q5: TOTAL (K€) | R5: (EUR clôture) | S5: CONTRÔLE
A6: ACTIF
A7: Actifs non courants
A8: Goodwill | B8: IFRS 3 | C8: 0 | E8: 0 | G8: 0 | I8: 0 | K8: 0 | M8: 0 | O8: 0 | Q8: =C8+E8+G8/'01_PARAMETRES'!$B$36+I8/'01_PARAMETRES'!$B$37+K8/'01_PARAMETRES'!$B$38+M8/'01_PARAMETRES'!$B$39+O8/'01_PARAMETRES'!$B$41 -> 0 | S8: Vérifications
A9: Immobilisations incorporelles | B9: IAS 38 | C9: 185000 | E9: 95000 | G9: 68000 | I9: 2800000 | K9: 42000 | M9: 35000 | O9: 12000 | Q9: =C9+E9+G9/'01_PARAMETRES'!$B$36+I9/'01_PARAMETRES'!$B$37+K9/'01_PARAMETRES'!$B$38+M9/'01_PARAMETRES'!$B$39+O9/'01_PARAMETRES'!$B$41 -> 410966.46 | S9: =IF(ABS(C28-C55)<1,"MA-FR ✅","MA-FR ❌ Écart: "&TEXT(C28-C55,"#,##0")) -> MA-FR ✅
A10: Immobilisations corporelles | B10: IAS 16 | C10: 420000 | E10: 180000 | G10: 295000 | I10: 4500000 | K10: 85000 | M10: 120000 | O10: 45000 | Q10: =C10+E10+G10/'01_PARAMETRES'!$B$36+I10/'01_PARAMETRES'!$B$37+K10/'01_PARAMETRES'!$B$38+M10/'01_PARAMETRES'!$B$39+O10/'01_PARAMETRES'!$B$41 -> 1012064.2 | S10: =IF(ABS(E28-E55)<1,"AU-IT ✅","AU-IT ❌ Écart: "&TEXT(E28-E55,"#,##0")) -> AU-IT ✅
A11: Droits d'utilisation (IFRS 16) | B11: IFRS 16 | C11: 310000 | E11: 125000 | G11: 480000 | I11: 8200000 | K11: 62000 | M11: 180000 | O11: 85000 | Q11: =C11+E11+G11/'01_PARAMETRES'!$B$36+I11/'01_PARAMETRES'!$B$37+K11/'01_PARAMETRES'!$B$38+M11/'01_PARAMETRES'!$B$39+O11/'01_PARAMETRES'!$B$41 -> 1030193.5 | S11: =IF(ABS(G28-G55)<1,"AU-US ✅","AU-US ❌ Écart: "&TEXT(G28-G55,"#,##0")) -> AU-US ✅
A12: Participations dans filiales | B12: IFRS 10/IAS 27 | C12: 892000 | E12: 0 | G12: 0 | I12: 0 | K12: 0 | M12: 0 | O12: 0 | Q12: =C12+E12+G12/'01_PARAMETRES'!$B$36+I12/'01_PARAMETRES'!$B$37+K12/'01_PARAMETRES'!$B$38+M12/'01_PARAMETRES'!$B$39+O12/'01_PARAMETRES'!$B$41 -> 892000 | S12: =IF(ABS(I28-I55)<1,"AU-JP ✅","AU-JP ❌ Écart: "&TEXT(I28-I55,"#,##0")) -> AU-JP ✅
A13: Participations MEE | B13: IAS 28 | C13: 0 | E13: 0 | G13: 0 | I13: 0 | K13: 0 | M13: 0 | O13: 0 | Q13: =C13+E13+G13/'01_PARAMETRES'!$B$36+I13/'01_PARAMETRES'!$B$37+K13/'01_PARAMETRES'!$B$38+M13/'01_PARAMETRES'!$B$39+O13/'01_PARAMETRES'!$B$41 -> 0 | S13: =IF(ABS(K28-K55)<1,"AU-CH ✅","AU-CH ❌ Écart: "&TEXT(K28-K55,"#,##0")) -> AU-CH ✅
A14: Actifs financiers non courants | B14: IFRS 9 | C14: 45000 | E14: 12000 | G14: 22000 | I14: 450000 | K14: 8500 | M14: 8000 | O14: 3500 | Q14: =C14+E14+G14/'01_PARAMETRES'!$B$36+I14/'01_PARAMETRES'!$B$37+K14/'01_PARAMETRES'!$B$38+M14/'01_PARAMETRES'!$B$39+O14/'01_PARAMETRES'!$B$41 -> 90652.325 | S14: =IF(ABS(M28-M55)<1,"AU-CN ✅","AU-CN ❌ Écart: "&TEXT(M28-M55,"#,##0")) -> AU-CN ✅
A15: Actifs d'impôt différé | B15: IAS 12 | C15: 38000 | E15: 15000 | G15: 35000 | I15: 680000 | K15: 5200 | M15: 12000 | O15: 0 | Q15: =C15+E15+G15/'01_PARAMETRES'!$B$36+I15/'01_PARAMETRES'!$B$37+K15/'01_PARAMETRES'!$B$38+M15/'01_PARAMETRES'!$B$39+O15/'01_PARAMETRES'!$B$41 -> 95951.906 | S15: =IF(ABS(O28-O55)<1,"AU-AE ✅","AU-AE ❌ Écart: "&TEXT(O28-O55,"#,##0")) -> AU-AE ✅
A16: Créances intra-groupe non courantes | B16: → ÉLIM | C16: 185000 | E16: 0 | G16: 0 | I16: 0 | K16: 0 | M16: 0 | O16: 0 | Q16: =C16+E16+G16/'01_PARAMETRES'!$B$36+I16/'01_PARAMETRES'!$B$37+K16/'01_PARAMETRES'!$B$38+M16/'01_PARAMETRES'!$B$39+O16/'01_PARAMETRES'!$B$41 -> 185000
A17: Total actifs non courants | C17: =SUM(C8:C16) -> 2075000 | E17: =SUM(E8:E16) -> 427000 | G17: =SUM(G8:G16) -> 900000 | I17: =SUM(I8:I16) -> 16630000 | K17: =SUM(K8:K16) -> 202700 | M17: =SUM(M8:M16) -> 355000 | O17: =SUM(O8:O16) -> 145500 | Q17: =SUM(Q8:Q16) -> 3716828.4
A19: Actifs courants
A20: Stocks et en-cours | B20: IAS 2 | C20: 280000 | E20: 156000 | G20: 85000 | I20: 3200000 | K20: 95000 | M20: 42000 | O20: 18000 | Q20: =C20+E20+G20/'01_PARAMETRES'!$B$36+I20/'01_PARAMETRES'!$B$37+K20/'01_PARAMETRES'!$B$38+M20/'01_PARAMETRES'!$B$39+O20/'01_PARAMETRES'!$B$41 -> 643864.04
A21: Créances clients | B21: IFRS 9/15 | C21: 145000 | E21: 78000 | G21: 125000 | I21: 4100000 | K21: 38000 | M21: 65000 | O21: 22000 | Q21: =C21+E21+G21/'01_PARAMETRES'!$B$36+I21/'01_PARAMETRES'!$B$37+K21/'01_PARAMETRES'!$B$38+M21/'01_PARAMETRES'!$B$39+O21/'01_PARAMETRES'!$B$41 -> 415530.63
A22: Créances intra-groupe courantes | B22: → ÉLIM | C22: 95000 | E22: 45000 | G22: 0 | I22: 0 | K22: 25000 | M22: 0 | O22: 0 | Q22: =C22+E22+G22/'01_PARAMETRES'!$B$36+I22/'01_PARAMETRES'!$B$37+K22/'01_PARAMETRES'!$B$38+M22/'01_PARAMETRES'!$B$39+O22/'01_PARAMETRES'!$B$41 -> 166737.97
A23: Autres créances | B23: IAS 1 | C23: 52000 | E23: 28000 | G23: 42000 | I23: 1500000 | K23: 12000 | M23: 18000 | O23: 8000 | Q23: =C23+E23+G23/'01_PARAMETRES'!$B$36+I23/'01_PARAMETRES'!$B$37+K23/'01_PARAMETRES'!$B$38+M23/'01_PARAMETRES'!$B$39+O23/'01_PARAMETRES'!$B$41 -> 144280.61
A24: Charges constatées d'avance | B24: IAS 1 | C24: 18000 | E24: 8000 | G24: 15000 | I24: 350000 | K24: 4500 | M24: 5000 | O24: 2000 | Q24: =C24+E24+G24/'01_PARAMETRES'!$B$36+I24/'01_PARAMETRES'!$B$37+K24/'01_PARAMETRES'!$B$38+M24/'01_PARAMETRES'!$B$39+O24/'01_PARAMETRES'!$B$41 -> 47668.873
A25: Instruments dérivés actifs | B25: IFRS 9 | C25: =MAX(0,'08_EFFICACITE'!F17) -> 34500 | E25: 0 | G25: 0 | I25: 0 | K25: 0 | M25: 0 | O25: 0 | Q25: =C25+E25+G25/'01_PARAMETRES'!$B$36+I25/'01_PARAMETRES'!$B$37+K25/'01_PARAMETRES'!$B$38+M25/'01_PARAMETRES'!$B$39+O25/'01_PARAMETRES'!$B$41 -> 34500
A26: Trésorerie et équivalents | B26: IAS 7 | C26: 185000 | E26: 62000 | G26: 78000 | I26: 2800000 | K26: 45000 | M26: 28000 | O26: 15000 | Q26: =C26+E26+G26/'01_PARAMETRES'!$B$36+I26/'01_PARAMETRES'!$B$37+K26/'01_PARAMETRES'!$B$38+M26/'01_PARAMETRES'!$B$39+O26/'01_PARAMETRES'!$B$41 -> 390113.34
A27: Total actifs courants | C27: =SUM(C20:C26) -> 809500 | E27: =SUM(E20:E26) -> 377000 | G27: =SUM(G20:G26) -> 345000 | I27: =SUM(I20:I26) -> 11950000 | K27: =SUM(K20:K26) -> 219500 | M27: =SUM(M20:M26) -> 158000 | O27: =SUM(O20:O26) -> 65000 | Q27: =SUM(Q20:Q26) -> 1842695.5
A28: TOTAL ACTIF | C28: =C17+C27 -> 2884500 | E28: =E17+E27 -> 804000 | G28: =G17+G27 -> 1245000 | I28: =I17+I27 -> 28580000 | K28: =K17+K27 -> 422200 | M28: =M17+M27 -> 513000 | O28: =O17+O27 -> 210500 | Q28: =Q17+Q27 -> 5559523.9
A30: PASSIF & CAPITAUX PROPRES
A31: Capitaux propres
A32: Capital social | B32: IAS 1 | C32: 150000 | E32: 50000 | G32: 100000 | I32: 1500000 | K32: 30000 | M32: 40000 | O32: 15000 | Q32: =C32+E32+G32/'01_PARAMETRES'!$B$36+I32/'01_PARAMETRES'!$B$37+K32/'01_PARAMETRES'!$B$38+M32/'01_PARAMETRES'!$B$39+O32/'01_PARAMETRES'!$B$41 -> 340649.67
A33: Primes d'émission | B33: IAS 1 | C33: 280000 | E33: 80000 | G33: 150000 | I33: 2000000 | K33: 45000 | M33: 25000 | O33: 10000 | Q33: =C33+E33+G33/'01_PARAMETRES'!$B$36+I33/'01_PARAMETRES'!$B$37+K33/'01_PARAMETRES'!$B$38+M33/'01_PARAMETRES'!$B$39+O33/'01_PARAMETRES'!$B$41 -> 561983.6
A34: Réserves | B34: IAS 1 | C34: 850000 | E34: 185000 | G34: 320000 | I34: 6800000 | K34: 105000 | M34: 88000 | O34: 35000 | Q34: =C34+E34+G34/'01_PARAMETRES'!$B$36+I34/'01_PARAMETRES'!$B$37+K34/'01_PARAMETRES'!$B$38+M34/'01_PARAMETRES'!$B$39+O34/'01_PARAMETRES'!$B$41 -> 1498616.5
A35: Résultat de l'exercice | B35: IAS 1 | C35: ='04_PNL_IND'!C47 -> 178000 | E35: ='04_PNL_IND'!E47 -> 28600 | G35: ='04_PNL_IND'!G47 -> 0 | I35: ='04_PNL_IND'!I47 -> 735000 | K35: ='04_PNL_IND'!K47 -> 36600 | M35: ='04_PNL_IND'!M47 -> 34810 | O35: ='04_PNL_IND'!O47 -> 17108 | Q35: =C35+E35+G35/'01_PARAMETRES'!$B$36+I35/'01_PARAMETRES'!$B$37+K35/'01_PARAMETRES'!$B$38+M35/'01_PARAMETRES'!$B$39+O35/'01_PARAMETRES'!$B$41 -> 258792.78
A36: Écarts de conversion | B36: IAS 21 | C36: 0 | E36: 0 | G36: 0 | I36: 0 | K36: 0 | M36: 0 | O36: 0 | Q36: =C36+E36+G36/'01_PARAMETRES'!$B$36+I36/'01_PARAMETRES'!$B$37+K36/'01_PARAMETRES'!$B$38+M36/'01_PARAMETRES'!$B$39+O36/'01_PARAMETRES'!$B$41 -> 0
A37: Autres éléments du résultat global | B37: IAS 1 | C37: 12000 | E37: 5000 | G37: 8000 | I37: 120000 | K37: 2200 | M37: 3000 | O37: 500 | Q37: =C37+E37+G37/'01_PARAMETRES'!$B$36+I37/'01_PARAMETRES'!$B$37+K37/'01_PARAMETRES'!$B$38+M37/'01_PARAMETRES'!$B$39+O37/'01_PARAMETRES'!$B$41 -> 27840.082
A38: Total capitaux propres | C38: =SUM(C32:C37) -> 1470000 | E38: =SUM(E32:E37) -> 348600 | G38: =SUM(G32:G37) -> 578000 | I38: =SUM(I32:I37) -> 11155000 | K38: =SUM(K32:K37) -> 218800 | M38: =SUM(M32:M37) -> 190810 | O38: =SUM(O32:O37) -> 77608 | Q38: =SUM(Q32:Q37) -> 2687882.7
A40: Passifs non courants
A41: Emprunts et dettes financières | B41: IFRS 9 | C41: 520000 | E41: 120000 | G41: 180000 | I41: 5200000 | K41: 55000 | M41: 85000 | O41: 42000 | Q41: =C41+E41+G41/'01_PARAMETRES'!$B$36+I41/'01_PARAMETRES'!$B$37+K41/'01_PARAMETRES'!$B$38+M41/'01_PARAMETRES'!$B$39+O41/'01_PARAMETRES'!$B$41 -> 914743.43
A42: Obligations locatives (IFRS 16) | B42: IFRS 16 | C42: 285000 | E42: 115000 | G42: 145000 | I42: 3800000 | K42: 58000 | M42: 95000 | O42: 48000 | Q42: =C42+E42+G42/'01_PARAMETRES'!$B$36+I42/'01_PARAMETRES'!$B$37+K42/'01_PARAMETRES'!$B$38+M42/'01_PARAMETRES'!$B$39+O42/'01_PARAMETRES'!$B$41 -> 640431.75
A43: Provisions non courantes | B43: IAS 37 | C43: 45000 | E43: 18000 | G43: 25000 | I43: 850000 | K43: 12000 | M43: 15000 | O43: 5000 | Q43: =C43+E43+G43/'01_PARAMETRES'!$B$36+I43/'01_PARAMETRES'!$B$37+K43/'01_PARAMETRES'!$B$38+M43/'01_PARAMETRES'!$B$39+O43/'01_PARAMETRES'!$B$41 -> 106792.89
A44: Passifs d'impôt différé | B44: IAS 12 | C44: 62000 | E44: 22000 | G44: 18000 | I44: 420000 | K44: 8000 | M44: 12000 | O44: 3000 | Q44: =C44+E44+G44/'01_PARAMETRES'!$B$36+I44/'01_PARAMETRES'!$B$37+K44/'01_PARAMETRES'!$B$38+M44/'01_PARAMETRES'!$B$39+O44/'01_PARAMETRES'!$B$41 -> 113683.5
...

Sheet 04_PNL_IND
A1: COMPTES DE RÉSULTAT INDIVIDUELS — EN DEVISE LOCALE
A2: Exercice du 01/04/2025 au 31/03/2026
A3: ⚠️ Montants en devise fonctionnelle de chaque entité (avant conversion)
A5: Poste | B5: Réf. IFRS | C5: ='01_PARAMETRES'!A18 -> MA-FR | D5: ='01_PARAMETRES'!E18 -> EUR | E5: ='01_PARAMETRES'!A19 -> AU-IT | F5: ='01_PARAMETRES'!E19 -> EUR | G5: ='01_PARAMETRES'!A20 -> AU-US | H5: ='01_PARAMETRES'!E20 -> USD | I5: ='01_PARAMETRES'!A21 -> AU-JP | J5: ='01_PARAMETRES'!E21 -> JPY | K5: ='01_PARAMETRES'!A22 -> AU-CH | L5: ='01_PARAMETRES'!E22 -> CHF | M5: ='01_PARAMETRES'!A23 -> AU-CN | N5: ='01_PARAMETRES'!E23 -> CNY | O5: ='01_PARAMETRES'!A25 -> AU-AE | P5: ='01_PARAMETRES'!E25 -> AED | Q5: TOTAL
A6: PRODUITS D'EXPLOITATION
A7: Chiffre d'affaires — tiers | B7: IFRS 15 | C7: 725000 | E7: 140000 | G7: 480000 | I7: 42000000 | K7: 75000 | M7: 350000 | O7: 125000 | Q7: =C7+E7+G7+I7+K7+M7+O7 -> 43895000
A8: Chiffre d'affaires — intra-groupe | B8: → ÉLIM | C8: 125000 | E8: 180000 | G8: 0 | I8: 0 | K8: 120000 | M8: 0 | O8: 0 | Q8: =C8+E8+G8+I8+K8+M8+O8 -> 425000
A9: Total chiffre d'affaires | C9: =C7+C8 -> 850000 | E9: =E7+E8 -> 320000 | G9: =G7+G8 -> 480000 | I9: =I7+I8 -> 42000000 | K9: =K7+K8 -> 195000 | M9: =M7+M8 -> 350000 | O9: =O7+O8 -> 125000 | Q9: =Q7+Q8 -> 44320000
A10: Autres produits d'exploitation | B10: IAS 1 | C10: 8000 | E10: 8000 | G10: 8000 | I10: 0 | K10: 0 | M10: 0 | O10: 0 | Q10: =C10+E10+G10+I10+K10+M10+O10 -> 24000
A11: dont redevances de marque reçues (interco) | B11: → ÉLIM E5 | C11: ='07_ELIMINATIONS'!D85 -> 65600 | E11: 0 | G11: 0 | I11: 0 | K11: 0 | M11: 0 | O11: 0 | Q11: =C11+E11+G11+I11+K11+M11+O11 -> 65600
A13: CHARGES D'EXPLOITATION
A14: Coût des ventes — achats tiers | B14: IAS 2 | C14: -295000 | E14: -95000 | G14: -168000 | I14: -16800000 | K14: -48000 | M14: -140000 | O14: -50000 | Q14: =C14+E14+G14+I14+K14+M14+O14 -> -17596000
A15: Coût des ventes — achats intra-groupe | B15: → ÉLIM | C15: -45000 | E15: -50000 | G15: -42000 | I15: -2500000 | K15: -34000 | M15: -28000 | O15: -12000 | Q15: =C15+E15+G15+I15+K15+M15+O15 -> -2711000
A16: Total coût des ventes | C16: =C14+C15 -> -340000 | E16: =E14+E15 -> -145000 | G16: =G14+G15 -> -210000 | I16: =I14+I15 -> -19300000 | K16: =K14+K15 -> -82000 | M16: =M14+M15 -> -168000 | O16: =O14+O15 -> -62000 | Q16: =Q14+Q15 -> -20307000
A17: MARGE BRUTE | C17: =C9+C16+C10 -> 518000 | E17: =E9+E16+E10 -> 183000 | G17: =G9+G16+G10 -> 278000 | I17: =I9+I16+I10 -> 22700000 | K17: =K9+K16+K10 -> 113000 | M17: =M9+M16+M10 -> 182000 | O17: =O9+O16+O10 -> 63000 | Q17: =Q9+Q16+Q10 -> 24037000
A18: Marge brute % | C18: =IF(C9=0,"",C17/C9) -> 0.60941176 | E18: =IF(E9=0,"",E17/E9) -> 0.571875 | G18: =IF(G9=0,"",G17/G9) -> 0.57916667 | I18: =IF(I9=0,"",I17/I9) -> 0.54047619 | K18: =IF(K9=0,"",K17/K9) -> 0.57948718 | M18: =IF(M9=0,"",M17/M9) -> 0.52 | O18: =IF(O9=0,"",O17/O9) -> 0.504 | Q18: =IF(Q9=0,"",Q17/Q9) -> 0.54235108
A20: Charges de personnel | B20: IAS 19 | C20: -128000 | E20: -52000 | G20: -85000 | I20: -8500000 | K20: -28000 | M20: -65000 | O20: -18000 | Q20: =C20+E20+G20+I20+K20+M20+O20 -> -8876000
A21: Loyers et charges locatives | B21: IFRS 16 | C21: -22000 | E21: -12000 | G21: -35000 | I21: -2200000 | K21: -6500 | M21: -18000 | O21: -8000 | Q21: =C21+E21+G21+I21+K21+M21+O21 -> -2301500
A22: Marketing et communication | C22: -45000 | E22: -15000 | G22: -32000 | I22: -2800000 | K22: -8000 | M22: -22000 | O22: -5500 | Q22: =C22+E22+G22+I22+K22+M22+O22 -> -2927500
A23: Dépréciation et amortissement | B23: IAS 16/38 | C23: -38000 | E23: -14000 | G23: -28000 | I23: -1800000 | K23: -7500 | M23: -12500 | O23: -4200 | Q23: =C23+E23+G23+I23+K23+M23+O23 -> -1904200
A24: Redevances de marque — intra-groupe | B24: → ÉLIM | C24: 0 | E24: -14400 | G24: -28800 | I24: -1885000 | K24: 0 | M24: 0 | O24: 0 | Q24: =C24+E24+G24+I24+K24+M24+O24 -> -1928200
A25: dont redevances de marque — détail interco | B25: → ÉLIM E5 | C25: 0 | E25: =E24 -> -14400 | G25: =G24 -> -28800 | I25: =I24 -> -1885000 | K25: 0 | M25: 0 | O25: 0 | Q25: =C25+E25+G25+I25+K25+M25+O25 -> -1928200
A26: Autres charges opérationnelles | C26: -55000 | E26: -18000 | G26: -22000 | I26: -1500000 | K26: -16000 | M26: -15000 | O26: -6000 | Q26: =C26+E26+G26+I26+K26+M26+O26 -> -1632000
A27: Total charges opérationnelles | C27: =SUM(C20:C26) -> -288000 | E27: =SUM(E20:E26) -> -139800 | G27: =SUM(G20:G26) -> -259600 | I27: =SUM(I20:I26) -> -20570000 | K27: =SUM(K20:K26) -> -66000 | M27: =SUM(M20:M26) -> -132500 | O27: =SUM(O20:O26) -> -41700 | Q27: =SUM(Q20:Q26) -> -21497600
A29: RÉSULTAT OPÉRATIONNEL COURANT | C29: =C17+C27 -> 230000 | E29: =E17+E27 -> 43200 | G29: =G17+G27 -> 18400 | I29: =I17+I27 -> 2130000 | K29: =K17+K27 -> 47000 | M29: =M17+M27 -> 49500 | O29: =O17+O27 -> 21300 | Q29: =Q17+Q27 -> 2539400
A30: Marge opérationnelle % | C30: =IF(C9=0,"",C29/C9) -> 0.27058824 | E30: =IF(E9=0,"",E29/E9) -> 0.135 | G30: =IF(G9=0,"",G29/G9) -> 0.038333333 | I30: =IF(I9=0,"",I29/I9) -> 0.050714286 | K30: =IF(K9=0,"",K29/K9) -> 0.24102564 | M30: =IF(M9=0,"",M29/M9) -> 0.14142857 | O30: =IF(O9=0,"",O29/O9) -> 0.1704 | Q30: =IF(Q9=0,"",Q29/Q9) -> 0.057296931
A32: Autres produits et charges opérationnels | B32: IAS 1 | C32: 0 | E32: 0 | G32: 0 | I32: 0 | K32: 0 | M32: 0 | O32: 0 | Q32: =C32+E32+G32+I32+K32+M32+O32 -> 0
A33: Dépréciation goodwill | B33: IAS 36 | C33: 0 | E33: 0 | G33: 0 | I33: 0 | K33: 0 | M33: 0 | O33: 0 | Q33: =C33+E33+G33+I33+K33+M33+O33 -> 0
A34: Résultat de cession | B34: IFRS 5 | C34: 0 | E34: 0 | G34: 0 | I34: 0 | K34: 0 | M34: 0 | O34: 0 | Q34: =C34+E34+G34+I34+K34+M34+O34 -> 0
A35: RÉSULTAT OPÉRATIONNEL | C35: =C29+C32+C33+C34 -> 230000 | E35: =E29+E32+E33+E34 -> 43200 | G35: =G29+G32+G33+G34 -> 18400 | I35: =I29+I32+I33+I34 -> 2130000 | K35: =K29+K32+K33+K34 -> 47000 | M35: =M29+M32+M33+M34 -> 49500 | O35: =O29+O32+O33+O34 -> 21300 | Q35: =Q29+Q32+Q33+Q34 -> 2539400
A37: RÉSULTAT FINANCIER
A38: Produits financiers | B38: IFRS 9 | C38: 62000 | E38: 5200 | G38: 2800 | I38: 280000 | K38: 3200 | M38: 1800 | O38: 500 | Q38: =C38+E38+G38+I38+K38+M38+O38 -> 355500
A39: Charges financières | B39: IFRS 9 | C39: -38000 | E39: -8400 | G39: -12500 | I39: -850000 | K39: -4800 | M39: -5200 | O39: -2800 | Q39: =C39+E39+G39+I39+K39+M39+O39 -> -921700
A40: Gains/pertes de change | B40: IAS 21 (→ MultiCurrency!B50) | C40: 3500 | E40: 800 | G40: -2100 | I40: 125000 | K40: 500 | M40: -350 | O40: -200 | Q40: =C40+E40+G40+I40+K40+M40+O40 -> 127150
A41: Dividendes reçus intra-groupe | B41: → ÉLIM | C41: 12000 | E41: 0 | G41: 0 | I41: 0 | K41: 0 | M41: 0 | O41: 0 | Q41: =C41+E41+G41+I41+K41+M41+O41 -> 12000
A42: Total résultat financier | C42: =C38+C39+C40+C41 -> 39500 | E42: =E38+E39+E40+E41 -> -2400 | G42: =G38+G39+G40+G41 -> -11800 | I42: =I38+I39+I40+I41 -> -445000 | K42: =K38+K39+K40+K41 -> -1100 | M42: =M38+M39+M40+M41 -> -3750 | O42: =O38+O39+O40+O41 -> -2500 | Q42: =Q38+Q39+Q40+Q41 -> -427050
A44: RÉSULTAT AVANT IMPÔT | C44: =C35+C42 -> 269500 | E44: =E35+E42 -> 40800 | G44: =G35+G42 -> 6600 | I44: =I35+I42 -> 1685000 | K44: =K35+K42 -> 45900 | M44: =M35+M42 -> 45750 | O44: =O35+O42 -> 18800 | Q44: =Q35+Q42 -> 2112350
A45: Impôt sur les sociétés | B45: IAS 12 | C45: -82000 | E45: -13800 | G45: -7400 | I45: -1070000 | K45: -9900 | M45: -11440 | O45: -1692 | Q45: =C45+E45+G45+I45+K45+M45+O45 -> -1196232
A46: Impôt différé | B46: IAS 12 | C46: -9500 | E46: 1600 | G46: 800 | I46: 120000 | K46: 600 | M46: 500 | O46: 0 | Q46: =C46+E46+G46+I46+K46+M46+O46 -> 114000
A47: RÉSULTAT NET | C47: =C44+C45+C46 -> 178000 | E47: =E44+E45+E46 -> 28600 | G47: =G44+G45+G46 -> 0 | I47: =I44+I45+I46 -> 735000 | K47: =K44+K45+K46 -> 36600 | M47: =M44+M45+M46 -> 34810 | O47: =O44+O45+O46 -> 17108 | Q47: =Q44+Q45+Q46 -> 1030118
...

Sheet 05_CONVERSION_IAS21
A1: CONVERSION DES ÉTATS FINANCIERS — IAS 21 §38-49
A2: Méthode du cours de clôture
A4: RÈGLES DE CONVERSION
A5: Actifs et Passifs → Taux de clôture (§39a)
A6: Produits et Charges → Taux moyen de l'exercice (§39b)
A7: Capitaux propres → Taux historique (date contribution/acquisition)
A8: Goodwill (IFRS 3) → Taux de clôture, actif de l'entité acquise (§47)
A9: Écart résultant → OCI — Écarts de conversion (§39c) — recyclable
A12: AURELIA USA Inc. — Conversion USD → EUR
A13: Poste | B13: Montant USD (K) | C13: Règle IAS 21 | D13: Taux appliqué | E13: Montant EUR (K) | F13: Formule
A14: BILAN — ACTIF
A15: Goodwill | B15: ='03_BILANS_IND'!G8 -> 0 | C15: Clôture (§47) | D15: ='01_PARAMETRES'!$B$36 -> 1.102 | E15: =B15/D15 -> 0 | F15: =B/D (clôture §47 Goodwill)
A16: Immo. incorporelles | B16: ='03_BILANS_IND'!G9 -> 68000 | C16: Clôture (§39a) | D16: ='01_PARAMETRES'!$B$36 -> 1.102 | E16: =B16/D16 -> 61705.989 | F16: =B/D (taux clôture §39a)
A17: Immo. corporelles | B17: ='03_BILANS_IND'!G10 -> 295000 | C17: Clôture (§39a) | D17: ='01_PARAMETRES'!$B$36 -> 1.102 | E17: =B17/D17 -> 267695.1 | F17: =B/D (taux clôture §39a)
A18: Droits d'utilisation | B18: ='03_BILANS_IND'!G11 -> 480000 | C18: Clôture (§39a) | D18: ='01_PARAMETRES'!$B$36 -> 1.102 | E18: =B18/D18 -> 435571.69 | F18: =B/D (taux clôture §39a)
A19: Participations filiales | B19: ='03_BILANS_IND'!G12 -> 0 | C19: Clôture (§39a) | D19: ='01_PARAMETRES'!$B$36 -> 1.102 | E19: =B19/D19 -> 0 | F19: =B/D (taux clôture §39a)
A20: Actifs financiers NC | B20: ='03_BILANS_IND'!G14 -> 22000 | C20: Clôture (§39a) | D20: ='01_PARAMETRES'!$B$36 -> 1.102 | E20: =B20/D20 -> 19963.702 | F20: =B/D (taux clôture §39a)
A21: Actifs impôt différé | B21: ='03_BILANS_IND'!G15 -> 35000 | C21: Clôture (§39a) | D21: ='01_PARAMETRES'!$B$36 -> 1.102 | E21: =B21/D21 -> 31760.436 | F21: =B/D (taux clôture §39a)
A22: Stocks | B22: ='03_BILANS_IND'!G20 -> 85000 | C22: Clôture (§39a) | D22: ='01_PARAMETRES'!$B$36 -> 1.102 | E22: =B22/D22 -> 77132.486 | F22: =B/D (taux clôture §39a)
A23: Créances clients | B23: ='03_BILANS_IND'!G21 -> 125000 | C23: Clôture (§39a) | D23: ='01_PARAMETRES'!$B$36 -> 1.102 | E23: =B23/D23 -> 113430.13 | F23: =B/D (taux clôture §39a)
A24: Autres créances | B24: ='03_BILANS_IND'!G23 -> 42000 | C24: Clôture (§39a) | D24: ='01_PARAMETRES'!$B$36 -> 1.102 | E24: =B24/D24 -> 38112.523 | F24: =B/D (taux clôture §39a)
A25: CCA | B25: ='03_BILANS_IND'!G24 -> 15000 | C25: Clôture (§39a) | D25: ='01_PARAMETRES'!$B$36 -> 1.102 | E25: =B25/D25 -> 13611.615 | F25: =B/D (taux clôture §39a)
A26: Trésorerie | B26: ='03_BILANS_IND'!G26 -> 78000 | C26: Clôture (§39a) | D26: ='01_PARAMETRES'!$B$36 -> 1.102 | E26: =B26/D26 -> 70780.399 | F26: =B/D (taux clôture §39a)
A27: TOTAL ACTIF CONVERTI | B27: ='03_BILANS_IND'!G28 -> 1245000 | E27: =SUM(E15:E26) -> 1129764.1 | F27: =SUM(actif converti)
A29: BILAN — PASSIF
A30: Emprunts et dettes fin. | B30: ='03_BILANS_IND'!G41 -> 180000 | C30: Clôture (§39a) | D30: ='01_PARAMETRES'!$B$36 -> 1.102 | E30: =B30/D30 -> 163339.38 | F30: B/D (taux clôture)
A31: Obligations locatives | B31: ='03_BILANS_IND'!G42 -> 145000 | C31: Clôture (§39a) | D31: ='01_PARAMETRES'!$B$36 -> 1.102 | E31: =B31/D31 -> 131578.95 | F31: B/D (taux clôture)
A32: Provisions NC | B32: ='03_BILANS_IND'!G43 -> 25000 | C32: Clôture (§39a) | D32: ='01_PARAMETRES'!$B$36 -> 1.102 | E32: =B32/D32 -> 22686.025 | F32: B/D (taux clôture)
A33: Passifs impôt différé | B33: ='03_BILANS_IND'!G44 -> 18000 | C33: Clôture (§39a) | D33: ='01_PARAMETRES'!$B$36 -> 1.102 | E33: =B33/D33 -> 16333.938 | F33: B/D (taux clôture)
A34: Fournisseurs | B34: ='03_BILANS_IND'!G49 -> 98000 | C34: Clôture (§39a) | D34: ='01_PARAMETRES'!$B$36 -> 1.102 | E34: =B34/D34 -> 88929.22 | F34: B/D (taux clôture)
A35: Dettes fiscales/sociales | B35: ='03_BILANS_IND'!G51 -> 62000 | C35: Clôture (§39a) | D35: ='01_PARAMETRES'!$B$36 -> 1.102 | E35: =B35/D35 -> 56261.343 | F35: B/D (taux clôture)
A36: Autres dettes | B36: ='03_BILANS_IND'!G52 -> 133000 | C36: Clôture (§39a) | D36: ='01_PARAMETRES'!$B$36 -> 1.102 | E36: =B36/D36 -> 120689.66 | F36: B/D (taux clôture)
A37: Dérivés passifs | B37: ='03_BILANS_IND'!G53 -> 6000 | C37: Clôture (§39a) | D37: ='01_PARAMETRES'!$B$36 -> 1.102 | E37: =B37/D37 -> 5444.6461 | F37: B/D (taux clôture)
A38: Total dettes converties | E38: =SUM(E30:E37) -> 605263.16 | F38: =SUM(passif converti)
A40: CAPITAUX PROPRES
A41: Capital social | B41: ='03_BILANS_IND'!G32 -> 100000 | C41: Historique (acquisition) | D41: ='01_PARAMETRES'!$E$36 -> 1.068 | E41: =B41/D41 -> 93632.959 | F41: =B/D (taux historique §39c)
A42: Primes d'émission | B42: ='03_BILANS_IND'!G33 -> 150000 | C42: Historique | D42: ='01_PARAMETRES'!$E$36 -> 1.068 | E42: =B42/D42 -> 140449.44 | F42: =B/D (taux historique §39c)
A43: Réserves | B43: ='03_BILANS_IND'!G34 -> 320000 | C43: Historique (cumulatif) | D43: ='01_PARAMETRES'!$E$36 -> 1.068 | E43: =B43/D43 -> 299625.47 | F43: =B/D (taux historique §39c)
A44: Résultat de l'exercice | B44: ='04_PNL_IND'!G47 -> 0 | C44: Taux moyen (via P&L) | D44: ='01_PARAMETRES'!$C$36 -> 1.094 | E44: =B44/D44 -> 0 | F44: =B/D (taux moyen §39b)
A45: Autres éléments OCI | B45: ='03_BILANS_IND'!G37 -> 8000 | C45: Historique | D45: ='01_PARAMETRES'!$E$36 -> 1.068 | E45: =B45/D45 -> 7490.6367 | F45: =B/D (taux historique §39c)
...

Sheet 06_GOODWILL
A2: IFRS 3 — Calcul initial | IAS 36 — Test annuel obligatoire
A3: ⚠️ Projet IASB (2025) : disclosure renforcée sur les hypothèses — ANTICIPER
A5: DÉTERMINATION DU GOODWILL — IFRS 3 §32
A6: Goodwill = (a) + (b) + (c) − (d)
A7: (a) Contrepartie transférée (prix d'acquisition)
A8: (b) Montant des NCI — dépend méthode : partial GW (quote-part AN) ou full GW (JV)
A9: (c) JV de la participation antérieure (si step acquisition)
A10: (d) JV des actifs nets identifiables acquis à la date d'acquisition
A12: Entité acquise | B12: Date acquisition | C12: % acquis | D12: (a) Prix acquisition (K€) | E12: (b) NCI à date acq. (K€) | F12: (c) Particip. antérieure | G12: (d) JV actifs nets ident. (K€) | H12: Goodwill initial (K€) | I12: Méthode NCI | J12: Devise | K12: Goodwill en devise orig. | L12: Taux clôture | M12: Goodwill converti 31/03/2026 (K€)
A13: Aurelia Italia SpA | B13: 42262 | C13: 0.95 | D13: 385000 | E13: =IF('01_PARAMETRES'!$B$13="Quote-part actifs nets (partial goodwill)",(1-C13)*G13,(1-C13)*(D13/C13)) -> 17000 | F13: 0 | G13: 340000 | H13: =D13+E13+F13-G13 -> 62000 | I13: ='01_PARAMETRES'!$B$13 -> Quote-part actifs nets (partial goodwill) | J13: EUR | K13: =H13 -> 62000 | L13: 1 | M13: =K13/L13 -> 62000
A14: Aurelia USA Inc. | B14: 42795 | C14: 1 | D14: 142000 | E14: =IF('01_PARAMETRES'!$B$13="Quote-part actifs nets (partial goodwill)",(1-C14)*G14,(1-C14)*(D14/C14)) -> 0 | F14: 0 | G14: 98000 | H14: =D14+E14+F14-G14 -> 44000 | I14: ='01_PARAMETRES'!$B$13 -> Quote-part actifs nets (partial goodwill) | J14: USD | K14: =H14*'01_PARAMETRES'!$E$36 -> 46992 | L14: ='01_PARAMETRES'!$B$36 -> 1.102 | M14: =K14/L14 -> 42642.468
A15: Aurelia Japan KK | B15: 43282 | C15: 0.8 | D15: 95000 | E15: =IF('01_PARAMETRES'!$B$13="Quote-part actifs nets (partial goodwill)",(1-C15)*G15,(1-C15)*(D15/C15)) -> 12400 | F15: 0 | G15: 62000 | H15: =D15+E15+F15-G15 -> 45400 | I15: ='01_PARAMETRES'!$B$13 -> Quote-part actifs nets (partial goodwill) | J15: JPY | K15: =H15*'01_PARAMETRES'!$E$37 -> 5920160 | L15: ='01_PARAMETRES'!$B$37 -> 164.8 | M15: =K15/L15 -> 35923.301
A16: Aurelia China Ltd | B16: 43997 | C16: 0.7 | D16: 48000 | E16: =IF('01_PARAMETRES'!$B$13="Quote-part actifs nets (partial goodwill)",(1-C16)*G16,(1-C16)*(D16/C16)) -> 10500 | F16: 0 | G16: 35000 | H16: =D16+E16+F16-G16 -> 23500 | I16: ='01_PARAMETRES'!$B$13 -> Quote-part actifs nets (partial goodwill) | J16: CNY | K16: =H16*'01_PARAMETRES'!$E$39 -> 180292 | L16: ='01_PARAMETRES'!$B$39 -> 7.98 | M16: =K16/L16 -> 22592.982
A17: Aurelia Middle East FZE | B17: 44805 | C17: 1 | D17: 18000 | E17: =IF('01_PARAMETRES'!$B$13="Quote-part actifs nets (partial goodwill)",(1-C17)*G17,(1-C17)*(D17/C17)) -> 0 | F17: 0 | G17: 12500 | H17: =D17+E17+F17-G17 -> 5500 | I17: ='01_PARAMETRES'!$B$13 -> Quote-part actifs nets (partial goodwill) | J17: AED | K17: =H17*'01_PARAMETRES'!$E$41 -> 21582 | L17: ='01_PARAMETRES'!$B$41 -> 4.048 | M17: =K17/L17 -> 5331.5217
A18: Aurelia Suisse SA — Pas de goodwill (acquisition à la JV des actifs nets, pas de survaleur)
A19: TOTAL GOODWILL BRUT AU 31/03/2026 | M19: =SUM(M13:M17) -> 168490.27
A22: TEST DE DÉPRÉCIATION ANNUEL — IAS 36 §10, §80
A23: Le goodwill est alloué aux Unités Génératrices de Trésorerie (UGT) — IAS 36 §80-82
A24: ="Méthode : "&'01_PARAMETRES'!B59 -> Méthode :
A25: ="WACC : "&TEXT('01_PARAMETRES'!B56,"0.00%")&" | Taux croissance terminal : "&TEXT('01_PARAMETRES'!B57,"0.00%")&" | Horizon : "&'01_PARAMETRES'!B58&" ans" -> WACC : 0.10% | Taux croissance terminal : 0.02% | Horizon : 5 ans
A27: UGT | B27: Goodwill alloué (K€) | C27: Actifs nets UGT (K€) | D27: Valeur comptable totale (K€) | E27: Flux N+1 (K€) | F27: Flux N+2 | G27: Flux N+3 | H27: Flux N+4 | I27: Flux N+5 | J27: Valeur terminale (K€) | K27: VAN des flux (K€) | L27: Valeur recouvrable (K€) | M27: Excédent / (Dépréciation) | N27: Dépréciation à compta.
A28: Maroquinerie Italie | B28: =M13 -> 62000 | C28: 370000 | D28: =B28+C28 -> 432000 | E28: 65000 | F28: 70000 | G28: 75000 | H28: 78000 | I28: 82000 | J28: =I28*(1+'01_PARAMETRES'!$B$57)/('01_PARAMETRES'!$B$56-'01_PARAMETRES'!$B$57) -> 1045500 | K28: =NPV('01_PARAMETRES'!$B$56,E28:I28)+J28/((1+'01_PARAMETRES'!$B$56)^'01_PARAMETRES'!$B$58) -> 926654.6 | L28: =K28 -> 926654.6 | M28: =L28-D28 -> 494654.6 | N28: =IF(M28<0,MIN(-M28,B28),0) -> 0
A29: Distribution USA | B29: =M14 -> 42642.468 | C29: 1245000 | D29: =B29+C29 -> 1287642.5 | E29: 95000 | F29: 102000 | G29: 110000 | H29: 115000 | I29: 122000 | J29: =I29*(1+'01_PARAMETRES'!$B$57)/('01_PARAMETRES'!$B$56-'01_PARAMETRES'!$B$57) -> 1555500 | K29: =NPV('01_PARAMETRES'!$B$56,E29:I29)+J29/((1+'01_PARAMETRES'!$B$56)^'01_PARAMETRES'!$B$58) -> 1373447.9 | L29: =K29 -> 1373447.9 | M29: =L29-D29 -> 85805.384 | N29: =IF(M29<0,MIN(-M29,B29),0) -> 0
A30: Distribution Japon | B30: =M15 -> 35923.301 | C30: 148000 | D30: =B30+C30 -> 183923.3 | E30: 22000 | F30: 24000 | G30: 26000 | H30: 27000 | I30: 29000 | J30: =I30*(1+'01_PARAMETRES'!$B$57)/('01_PARAMETRES'!$B$56-'01_PARAMETRES'!$B$57) -> 369750 | K30: =NPV('01_PARAMETRES'!$B$56,E30:I30)+J30/((1+'01_PARAMETRES'!$B$56)^'01_PARAMETRES'!$B$58) -> 325402.64 | L30: =K30 -> 325402.64 | M30: =L30-D30 -> 141479.34 | N30: =IF(M30<0,MIN(-M30,B30),0) -> 0
A31: Horlogerie Suisse | B31: 0 | C31: 422000 | D31: =B31+C31 -> 422000 | E31: 52000 | F31: 55000 | G31: 58000 | H31: 60000 | I31: 63000 | J31: =I31*(1+'01_PARAMETRES'!$B$57)/('01_PARAMETRES'!$B$56-'01_PARAMETRES'!$B$57) -> 803250 | K31: =NPV('01_PARAMETRES'!$B$56,E31:I31)+J31/((1+'01_PARAMETRES'!$B$56)^'01_PARAMETRES'!$B$58) -> 715157.43 | L31: =K31 -> 715157.43 | M31: =L31-D31 -> 293157.43 | N31: =IF(M31<0,MIN(-M31,B31),0) -> 0
A32: Distribution Chine | B32: =M16 -> 22592.982 | C32: 390000 | D32: =B32+C32 -> 412592.98 | E32: 35000 | F32: 38000 | G32: 40000 | H32: 42000 | I32: 45000 | J32: =I32*(1+'01_PARAMETRES'!$B$57)/('01_PARAMETRES'!$B$56-'01_PARAMETRES'!$B$57) -> 573750 | K32: =NPV('01_PARAMETRES'!$B$56,E32:I32)+J32/((1+'01_PARAMETRES'!$B$56)^'01_PARAMETRES'!$B$58) -> 506157.37 | L32: =K32 -> 506157.37 | M32: =L32-D32 -> 93564.384 | N32: =IF(M32<0,MIN(-M32,B32),0) -> 0
A33: Distribution M-E Dubai | B33: =M17 -> 5331.5217 | C33: 180000 | D33: =B33+C33 -> 185331.52 | E33: 12000 | F33: 14000 | G33: 15000 | H33: 16000 | I33: 18000 | J33: =I33*(1+'01_PARAMETRES'!$B$57)/('01_PARAMETRES'!$B$56-'01_PARAMETRES'!$B$57) -> 229500 | K33: =NPV('01_PARAMETRES'!$B$56,E33:I33)+J33/((1+'01_PARAMETRES'!$B$56)^'01_PARAMETRES'!$B$58) -> 198355.3 | L33: =K33 -> 198355.3 | M33: =L33-D33 -> 13023.782 | N33: =IF(M33<0,MIN(-M33,B33),0) -> 0
A34: TOTAL | B34: =SUM(B28:B33) -> 168490.27 | L34: =SUM(L28:L33) -> 4045175.2 | N34: =SUM(N28:N33) -> 0
A37: ANALYSE DE SENSIBILITÉ — IAS 36 §134(f)
A38: ⚠️ Projet IASB 2025 : disclosure renforcée — anticiper ces informations
A40: UGT | B40: Scénario base (K€) | C40: WACC +1% | D40: WACC +2% | E40: Croissance 0% | F40: Flux −10% | G40: WACC breakeven (%) | H40: Flux t=0 | I40: Flux t=1 | J40: Flux t=2 | K40: Flux t=3 | L40: Flux t=4 | M40: Flux t=5+VT
A41: Maroquinerie Italie | B41: =M28 -> 494654.6 | C41: =NPV('01_PARAMETRES'!$B$56+1%,E28:I28)+J28/((1+'01_PARAMETRES'!$B$56+1%)^'01_PARAMETRES'!$B$58)-D28 -> 458708.87 | D41: =NPV('01_PARAMETRES'!$B$56+2%,E28:I28)+J28/((1+'01_PARAMETRES'!$B$56+2%)^'01_PARAMETRES'!$B$58)-D28 -> 424566.99 | E41: =NPV('01_PARAMETRES'!$B$56,E28:I28)+I28*1/('01_PARAMETRES'!$B$56-0)-D28 -> 665481.36 | F41: =NPV('01_PARAMETRES'!$B$56,E28*0.9,F28*0.9,G28*0.9,H28*0.9,I28*0.9)+I28*0.9*(1+'01_PARAMETRES'!$B$57)/('01_PARAMETRES'!$B$56-'01_PARAMETRES'!$B$57)-D28 -> 758683.22 | G41: =IRR(H41:M41,0.1) -> 0.31778229 | H41: =-D28 -> -432000 | I41: =E28 -> 65000 | J41: =F28 -> 70000 | K41: =G28 -> 75000 | L41: =H28 -> 78000 | M41: =I28+J28 -> 1127500
A42: Distribution USA | B42: =M29 -> 85805.384 | C42: =NPV('01_PARAMETRES'!$B$56+1%,E29:I29)+J29/((1+'01_PARAMETRES'!$B$56+1%)^'01_PARAMETRES'!$B$58)-D29 -> 32428.322 | D42: =NPV('01_PARAMETRES'!$B$56+2%,E29:I29)+J29/((1+'01_PARAMETRES'!$B$56+2%)^'01_PARAMETRES'!$B$58)-D29 -> -18268.307 | E42: =NPV('01_PARAMETRES'!$B$56,E29:I29)+I29*1/('01_PARAMETRES'!$B$56-0)-D29 -> 339962.27 | F42: =NPV('01_PARAMETRES'!$B$56,E29*0.9,F29*0.9,G29*0.9,H29*0.9,I29*0.9)+I29*0.9*(1+'01_PARAMETRES'!$B$57)/('01_PARAMETRES'!$B$56-'01_PARAMETRES'!$B$57)-D29 -> 479151.79 | G42: =IRR(H42:M42,0.1) -> 0.11633721 | H42: =-D29 -> -1287642.5 | I42: =E29 -> 95000 | J42: =F29 -> 102000 | K42: =G29 -> 110000 | L42: =H29 -> 115000 | M42: =I29+J29 -> 1677500
A43: Distribution Japon | B43: =M30 -> 141479.34 | C43: =NPV('01_PARAMETRES'!$B$56+1%,E30:I30)+J30/((1+'01_PARAMETRES'!$B$56+1%)^'01_PARAMETRES'!$B$58)-D30 -> 128810.89 | D43: =NPV('01_PARAMETRES'!$B$56+2%,E30:I30)+J30/((1+'01_PARAMETRES'!$B$56+2%)^'01_PARAMETRES'!$B$58)-D30 -> 116778.94 | E43: =NPV('01_PARAMETRES'!$B$56,E30:I30)+I30*1/('01_PARAMETRES'!$B$56-0)-D30 -> 201893.68 | F43: =NPV('01_PARAMETRES'!$B$56,E30*0.9,F30*0.9,G30*0.9,H30*0.9,I30*0.9)+I30*0.9*(1+'01_PARAMETRES'!$B$57)/('01_PARAMETRES'!$B$56-'01_PARAMETRES'!$B$57)-D30 -> 235086.98 | G43: =IRR(H43:M43,0.1) -> 0.25657091 | H43: =-D30 -> -183923.3 | I43: =E30 -> 22000 | J43: =F30 -> 24000 | K43: =G30 -> 26000 | L43: =H30 -> 27000 | M43: =I30+J30 -> 398750
A44: Horlogerie Suisse | B44: =M31 -> 293157.43 | C44: =NPV('01_PARAMETRES'!$B$56+1%,E31:I31)+J31/((1+'01_PARAMETRES'!$B$56+1%)^'01_PARAMETRES'!$B$58)-D31 -> 265496.25 | D44: =NPV('01_PARAMETRES'!$B$56+2%,E31:I31)+J31/((1+'01_PARAMETRES'!$B$56+2%)^'01_PARAMETRES'!$B$58)-D31 -> 239222.09 | E44: =NPV('01_PARAMETRES'!$B$56,E31:I31)+I31*1/('01_PARAMETRES'!$B$56-0)-D31 -> 424402.38 | F44: =NPV('01_PARAMETRES'!$B$56,E31*0.9,F31*0.9,G31*0.9,H31*0.9,I31*0.9)+I31*0.9*(1+'01_PARAMETRES'!$B$57)/('01_PARAMETRES'!$B$56-'01_PARAMETRES'!$B$57)-D31 -> 495687.14 | G44: =IRR(H44:M44,0.1) -> 0.24491283 | H44: =-D31 -> -422000 | I44: =E31 -> 52000 | J44: =F31 -> 55000 | K44: =G31 -> 58000 | L44: =H31 -> 60000 | M44: =I31+J31 -> 866250
A45: Distribution Chine | B45: =M32 -> 93564.384 | C45: =NPV('01_PARAMETRES'!$B$56+1%,E32:I32)+J32/((1+'01_PARAMETRES'!$B$56+1%)^'01_PARAMETRES'!$B$58)-D32 -> 73892.567 | D45: =NPV('01_PARAMETRES'!$B$56+2%,E32:I32)+J32/((1+'01_PARAMETRES'!$B$56+2%)^'01_PARAMETRES'!$B$58)-D32 -> 55208.721 | E45: =NPV('01_PARAMETRES'!$B$56,E32:I32)+I32*1/('01_PARAMETRES'!$B$56-0)-D32 -> 187310.77 | F45: =NPV('01_PARAMETRES'!$B$56,E32*0.9,F32*0.9,G32*0.9,H32*0.9,I32*0.9)+I32*0.9*(1+'01_PARAMETRES'!$B$57)/('01_PARAMETRES'!$B$56-'01_PARAMETRES'!$B$57)-D32 -> 238695.4 | G45: =IRR(H45:M45,0.1) -> 0.15290546 | H45: =-D32 -> -412592.98 | I45: =E32 -> 35000 | J45: =F32 -> 38000 | K45: =G32 -> 40000 | L45: =H32 -> 42000 | M45: =I32+J32 -> 618750
A46: Distribution M-E Dubai | B46: =M33 -> 13023.782 | C46: =NPV('01_PARAMETRES'!$B$56+1%,E33:I33)+J33/((1+'01_PARAMETRES'!$B$56+1%)^'01_PARAMETRES'!$B$58)-D33 -> 5228.7731 | D46: =NPV('01_PARAMETRES'!$B$56+2%,E33:I33)+J33/((1+'01_PARAMETRES'!$B$56+2%)^'01_PARAMETRES'!$B$58)-D33 -> -2173.382 | E46: =NPV('01_PARAMETRES'!$B$56,E33:I33)+I33*1/('01_PARAMETRES'!$B$56-0)-D33 -> 50522.338 | F46: =NPV('01_PARAMETRES'!$B$56,E33*0.9,F33*0.9,G33*0.9,H33*0.9,I33*0.9)+I33*0.9*(1+'01_PARAMETRES'!$B$57)/('01_PARAMETRES'!$B$56-'01_PARAMETRES'!$B$57)-D33 -> 71486.952 | G46: =IRR(H46:M46,0.1) -> 0.11701015 | H46: =-D33 -> -185331.52 | I46: =E33 -> 12000 | J46: =F33 -> 14000 | K46: =G33 -> 15000 | L46: =H33 -> 16000 | M46: =I33+J33 -> 247500
A47: 💡 WACC breakeven = taux qui annule l'excédent (L=D). Utiliser le Solveur Excel ou la fonction CHERCHE.CIBLE.
A50: MOUVEMENTS DU GOODWILL — EXERCICE
A51: Entité | B51: Solde ouverture (K€) | C51: Acquisitions (K€) | D51: Cessions (K€) | E51: Dépréciation (K€) | F51: Écart de conversion (K€) | G51: Solde clôture (K€) | H51: GW brut constant (K€) | I51: Dépréc. cumulées N-1 (K€) | J51: Solde net ouverture calculé (K€)
...

Sheet 07_ELIMINATIONS
A1: ="ÉCRITURES D'ÉLIMINATION INTRA-"&UPPER('01_PARAMETRES'!$S$3) -> ÉCRITURES D'ÉLIMINATION INTRA-AURELIA
A2: Les éliminations suivent un ordre systématique (E1 à E6) — IFRS 10 §B86, IAS 2, IAS 28
A3: ⚠️ Ordre d'élimination : E1 Titres → E2 CA/Achats → E3 Soldes → E4 Dividendes → E5 Redevances → E6 Profits internes
A5: E1 — ÉLIMINATION DES TITRES & PARTAGE DES CAPITAUX PROPRES
A6: IFRS 10 §B86 — Élimination de l'investissement de la mère contre les capitaux propres de la filiale à la date d'acquisition
A7: Résidu = Goodwill (IFRS 3 §32) | Solde CP × NCI% = Intérêts minoritaires initiaux
A9: N° Élim | B9: Entité / Flux | C9: Compte débité | D9: Débit (K€) | E9: Compte crédité | F9: Crédit (K€) | G9: Description | H9: Norme
A10: E1-001a | B10: Aurelia Italia SpA | C10: Capital & Réserves acquisition AU-IT | D10: ='06_GOODWILL'!G13 -> 340000 | E10: 261xxx — Titres participation AU-IT | F10: ='06_GOODWILL'!D13 -> 385000 | G10: Élim JV actifs nets (100%) vs titres AU-IT + goodwill IFRS 3 §32 | H10: IFRS 10 §B86
A11: E1-001b | B11: Aurelia Italia SpA | C11: 207000 — Goodwill | D11: ='06_GOODWILL'!H13 -> 62000 | E11: — (contrepartie automatique sur E1a + E1c) | F11: 0 | G11: Goodwill initial IFRS 3 §32 (montant EUR à date acq.) — conversion IAS 21 via 05_CONVERSION_IAS21 | H11: IFRS 3 §32
A12: E1-001c | B12: Aurelia Italia SpA | C12: (Solde élimination CP) | D12: 0 | E12: 105500 — Intérêts minoritaires (CP consolidé) | F12: ='06_GOODWILL'!E13 -> 17000 | G12: NCI initiaux — 5% des AN à l'acquisition | H12: IFRS 10 §22
A13: E1-002a | B13: Aurelia USA Inc. | C13: Capital & Réserves acquisition AU-US | D13: ='06_GOODWILL'!G14 -> 98000 | E13: 261xxx — Titres participation AU-US | F13: ='06_GOODWILL'!D14 -> 142000 | G13: Élim JV actifs nets (100%) vs titres AU-US + goodwill IFRS 3 §32 | H13: IFRS 10 §B86
A14: E1-002b | B14: Aurelia USA Inc. | C14: 207000 — Goodwill | D14: ='06_GOODWILL'!H14 -> 44000 | E14: — (contrepartie automatique sur E1a + E1c) | F14: 0 | G14: Goodwill initial IFRS 3 §32 (montant EUR à date acq.) — conversion IAS 21 via 05_CONVERSION_IAS21 | H14: IFRS 3 §32
