Workbook

Sheet Claude Log
A1: Turn # | B1: Date | C1: User Request | D1: Action Taken | E1: Details | F1: Outcome
A2: 1 | B2: 46115 | C2: Analyse complète du fichier SkillsMapAero + propositions d'améliorations formules/automatisation + ergonomie 01_PARAMETRES (menus déroulants) | D2: Audit complet des 18 onglets: formules, liaisons inter-onglets, bugs, et ergonomie | E2: BUGS CRITIQUES trouvés: (1) 03_ANNUAIRE!Q divise par B10 (date) au lieu de B15 (objectif polyvalence); (2) 02_REF!S compare à B9 (texte EASA) au lieu de B14 (nb min titulaires); (3) Dashboard TOP10 avec doublons. Propositions: menus déroulants, validation données, formules dynamiques pour 01_PARAMETRES. | F2: Recommandations détaillées fournies. En attente validation utilisateur pour implémenter.
A3: 2 | B3: 46115 | C3: Utilisateur valide les 4 corrections + améliorations ergonomiques proposées au Turn 1 | D3: Implémenté les 4 correctifs bugs + ajout menus déroulants et validation de données | E3: Bug1: 03_ANNUAIRE!Q5:Q64 corrigé B10→$B$15 (score polyvalence passe de ~0.00008 à 0.8). Bug2: 02_REF!S5:S34 corrigé B9→$B$14 (alerte titulaires fonctionne maintenant). Bug3: 02_REF!N5:N34 remplacé texte dur par formule SI(E>=5,Critique;E>=4,Eleve;E>=3,Moyen;Faible). Bug4: Dashboard TOP10 A28:C37 remplacé LARGE/MATCH par SORTBY → 10 compétences distinctes. Validation: B8 liste secteurs, B12 entier 1-5, B13 décimal 0-1, B14 entier 1-20, B15 entier 1-10, B16 positif. 03_ANNUAIRE D5:D64 dropdown sites, J5:J64 dropdown BUs. 04_MATRICE I5:I432 entier 0-4. | F3: Tous les bugs corrigés et vérifiés. Formules Q col donnent maintenant des scores significatifs (0.4-1.6). Alertes S col distinguent correctement Critique/Sous controle. Dashboard TOP10 affiche 10 compétences uniques. Validation données active sur paramètres, annuaire et matrice.

Sheet 01_PARAMETRES
A1: NEURAL - SkillsMapAero - Parametres
A2: Configuration de reference de l'agent
A4: REFERENTIEL D'ENTREPRISE
A5: Parametre | B5: Valeur | C5: Description
A6: Nom de l'entreprise | B6: Safran Aircraft Engines | C6: Reference d'entreprise
A7: Code entreprise | B7: SAF-AE | C7: Identifiant interne
A8: Secteur | B8: Aeronautique - Moteurs | C8: Activite principale
A9: Agrement EASA PART 21 | B9: FR.21G.0049 | C9: Numero d'agrement production
A10: Date de reference | B10: 02/04/2026 | C10: Date de calcul
A11: Exercice | B11: 2026 | C11: Annee de pilotage
A12: Niveau minimum requis | B12: 3 | C12: Seuil de conformite
A13: Taux de couverture cible | B13: 0.95 | C13: Objectif global
A14: Nb minimum titulaires competence critique | B14: 3 | C14: Seuil d'alerte
A15: Objectif polyvalence | B15: 5 | C15: Nombre de competences qualifiees vise
A16: Budget formation global | B16: 320000 | C16: Budget annuel de reference
A19: SITES
A20: Site 1 | B20: Villaroche (77)
A21: Site 2 | B21: Gennevilliers (92)
A22: Site 3 | B22: Chatellerault (86)
A23: Site 4 | B23: Bordes (64)
A24: Site 5 | B24: Istres (13)
A26: BUSINESS UNITS
A27: BU 1 | B27: Production
A28: BU 2 | B28: Maintenance (MRO)
A29: BU 3 | B29: Bureau d'etudes
A30: BU 4 | B30: Qualite
A31: BU 5 | B31: Supply Chain
A32: BU 6 | B32: HSE
A34: ECHELLE DE COMPETENCE
A35: Niveau | B35: Libelle | C35: Definition
A36: 1 | B36: Debutant | C36: Sensibilise, formation initiale suivie
A37: 2 | B37: Operationnel guide | C37: Execute sous supervision directe
A38: 3 | B38: Autonome | C38: Maitrise en situation courante
A39: 4 | B39: Expert | C39: Gere situations complexes, forme les autres
A40: 5 | B40: Referent | C40: Autorite reconnue, definit les standards

Sheet 02_REF_COMPETENCES
A1: Referentiel des competences aeronautiques
A2: Base catalogue et indicateurs de couverture
A4: ID | B4: Competence | C4: Categorie | D4: Sous-cat. | E4: Criticite | F4: Duree form. | G4: Cout form. | H4: Rarete | I4: Norme | J4: Cout rupture | K4: Impact | L4: Niveau moyen | M4: Nb evals | N4: Criticite libelle | O4: Nb titulaires niv>=4 | P4: Nb titulaires niv>=3 | Q4: Nb postes requis | R4: Ecart couvert. | S4: Alerte | T4: Invest. formation | U4: Indice rarete | V4: Indice risque | W4: Statut risque | X4: Taux couverture
A5: COMP-001 | B5: Soudure TIG aeronautique | C5: Procedes speciaux | D5: Soudure | E5: 5 | F5: 15 | G5: 6000 | H5: 5 | I5: AWS D17.1 / NF EN 4677 | J5: 50000 | K5: Arret ligne assemblage | L5: =IFERROR(AVERAGEIF('04_MATRICE_SKILLS'!F:F,A5,'04_MATRICE_SKILLS'!I:I),0) -> 3 | M5: =COUNTIF('04_MATRICE_SKILLS'!F:F,A5) -> 11 | N5: =IF(E5="","",IF(E5>=5,"Critique",IF(E5>=4,"Eleve",IF(E5>=3,"Moyen","Faible")))) -> Critique | O5: =COUNTIFS('04_MATRICE_SKILLS'!F:F,A5,'04_MATRICE_SKILLS'!I:I,">="&4) -> 3 | P5: =COUNTIFS('04_MATRICE_SKILLS'!F:F,A5,'04_MATRICE_SKILLS'!I:I,">="&3) -> 8 | Q5: =COUNTIF('05_GAP_ANALYSIS'!E:E,A5) -> 6 | R5: =P5-Q5 -> 2 | S5: =IF(AND(E5>=4,P5<'01_PARAMETRES'!$B$14),"Critique",IF(P5=0,"Alerte","Sous controle")) -> Sous controle | T5: =G5*MAX(1,Q5-P5) -> 6000 | U5: =H5*20 -> 100 | V5: =ROUND((E5*8)+(H5*6)+(MAX(0,Q5-P5)*10),0) -> 70 | W5: =IF(V5>=70,"Critique",IF(V5>=45,"Eleve",IF(V5>=25,"Moyen","Faible"))) -> Critique | X5: =IFERROR(P5/MAX(Q5,1),0) -> 1.3333333
A6: COMP-002 | B6: Soudure MIG/MAG aeronautique | C6: Procedes speciaux | D6: Soudure | E6: 4 | F6: 10 | G6: 4500 | H6: 4 | I6: AWS D17.1 | J6: 35000 | K6: Sous-traitance obligatoire | L6: =IFERROR(AVERAGEIF('04_MATRICE_SKILLS'!F:F,A6,'04_MATRICE_SKILLS'!I:I),0) -> 3.3 | M6: =COUNTIF('04_MATRICE_SKILLS'!F:F,A6) -> 10 | N6: =IF(E6="","",IF(E6>=5,"Critique",IF(E6>=4,"Eleve",IF(E6>=3,"Moyen","Faible")))) -> Eleve | O6: =COUNTIFS('04_MATRICE_SKILLS'!F:F,A6,'04_MATRICE_SKILLS'!I:I,">="&4) -> 5 | P6: =COUNTIFS('04_MATRICE_SKILLS'!F:F,A6,'04_MATRICE_SKILLS'!I:I,">="&3) -> 7 | Q6: =COUNTIF('05_GAP_ANALYSIS'!E:E,A6) -> 6 | R6: =P6-Q6 -> 1 | S6: =IF(AND(E6>=4,P6<'01_PARAMETRES'!$B$14),"Critique",IF(P6=0,"Alerte","Sous controle")) -> Sous controle | T6: =G6*MAX(1,Q6-P6) -> 4500 | U6: =H6*20 -> 80 | V6: =ROUND((E6*8)+(H6*6)+(MAX(0,Q6-P6)*10),0) -> 56 | W6: =IF(V6>=70,"Critique",IF(V6>=45,"Eleve",IF(V6>=25,"Moyen","Faible"))) -> Eleve | X6: =IFERROR(P6/MAX(Q6,1),0) -> 1.1666667
A7: COMP-003 | B7: Soudure faisceau electrons | C7: Procedes speciaux | D7: Soudure | E7: 5 | F7: 20 | G7: 12000 | H7: 5 | I7: AWS C7.1 | J7: 70000 | K7: Arret production pieces critiques | L7: =IFERROR(AVERAGEIF('04_MATRICE_SKILLS'!F:F,A7,'04_MATRICE_SKILLS'!I:I),0) -> 2.5 | M7: =COUNTIF('04_MATRICE_SKILLS'!F:F,A7) -> 2 | N7: =IF(E7="","",IF(E7>=5,"Critique",IF(E7>=4,"Eleve",IF(E7>=3,"Moyen","Faible")))) -> Critique | O7: =COUNTIFS('04_MATRICE_SKILLS'!F:F,A7,'04_MATRICE_SKILLS'!I:I,">="&4) -> 0 | P7: =COUNTIFS('04_MATRICE_SKILLS'!F:F,A7,'04_MATRICE_SKILLS'!I:I,">="&3) -> 1 | Q7: =COUNTIF('05_GAP_ANALYSIS'!E:E,A7) -> 0 | R7: =P7-Q7 -> 1 | S7: =IF(AND(E7>=4,P7<'01_PARAMETRES'!$B$14),"Critique",IF(P7=0,"Alerte","Sous controle")) -> Critique | T7: =G7*MAX(1,Q7-P7) -> 12000 | U7: =H7*20 -> 100 | V7: =ROUND((E7*8)+(H7*6)+(MAX(0,Q7-P7)*10),0) -> 70 | W7: =IF(V7>=70,"Critique",IF(V7>=45,"Eleve",IF(V7>=25,"Moyen","Faible"))) -> Critique | X7: =IFERROR(P7/MAX(Q7,1),0) -> 1
A8: COMP-004 | B8: Brasage aeronautique | C8: Procedes speciaux | D8: Brasage | E8: 4 | F8: 8 | G8: 3500 | H8: 4 | I8: AWS C3.6 / AMS 2675 | J8: 25000 | K8: Retard assemblage | L8: =IFERROR(AVERAGEIF('04_MATRICE_SKILLS'!F:F,A8,'04_MATRICE_SKILLS'!I:I),0) -> 2.7 | M8: =COUNTIF('04_MATRICE_SKILLS'!F:F,A8) -> 10 | N8: =IF(E8="","",IF(E8>=5,"Critique",IF(E8>=4,"Eleve",IF(E8>=3,"Moyen","Faible")))) -> Eleve | O8: =COUNTIFS('04_MATRICE_SKILLS'!F:F,A8,'04_MATRICE_SKILLS'!I:I,">="&4) -> 3 | P8: =COUNTIFS('04_MATRICE_SKILLS'!F:F,A8,'04_MATRICE_SKILLS'!I:I,">="&3) -> 5 | Q8: =COUNTIF('05_GAP_ANALYSIS'!E:E,A8) -> 3 | R8: =P8-Q8 -> 2 | S8: =IF(AND(E8>=4,P8<'01_PARAMETRES'!$B$14),"Critique",IF(P8=0,"Alerte","Sous controle")) -> Sous controle | T8: =G8*MAX(1,Q8-P8) -> 3500 | U8: =H8*20 -> 80 | V8: =ROUND((E8*8)+(H8*6)+(MAX(0,Q8-P8)*10),0) -> 56 | W8: =IF(V8>=70,"Critique",IF(V8>=45,"Eleve",IF(V8>=25,"Moyen","Faible"))) -> Eleve | X8: =IFERROR(P8/MAX(Q8,1),0) -> 1.6666667
A9: COMP-005 | B9: Ressuage PT Niveau 2 | C9: CND/NDT | D9: Ressuage | E9: 4 | F9: 10 | G9: 4000 | H9: 3 | I9: NAS 410 / EN 4179 | J9: 28000 | K9: Liberation pieces bloquee | L9: =IFERROR(AVERAGEIF('04_MATRICE_SKILLS'!F:F,A9,'04_MATRICE_SKILLS'!I:I),0) -> 3.1578947 | M9: =COUNTIF('04_MATRICE_SKILLS'!F:F,A9) -> 19 | N9: =IF(E9="","",IF(E9>=5,"Critique",IF(E9>=4,"Eleve",IF(E9>=3,"Moyen","Faible")))) -> Eleve | O9: =COUNTIFS('04_MATRICE_SKILLS'!F:F,A9,'04_MATRICE_SKILLS'!I:I,">="&4) -> 9 | P9: =COUNTIFS('04_MATRICE_SKILLS'!F:F,A9,'04_MATRICE_SKILLS'!I:I,">="&3) -> 13 | Q9: =COUNTIF('05_GAP_ANALYSIS'!E:E,A9) -> 15 | R9: =P9-Q9 -> -2 | S9: =IF(AND(E9>=4,P9<'01_PARAMETRES'!$B$14),"Critique",IF(P9=0,"Alerte","Sous controle")) -> Sous controle | T9: =G9*MAX(1,Q9-P9) -> 8000 | U9: =H9*20 -> 60 | V9: =ROUND((E9*8)+(H9*6)+(MAX(0,Q9-P9)*10),0) -> 70 | W9: =IF(V9>=70,"Critique",IF(V9>=45,"Eleve",IF(V9>=25,"Moyen","Faible"))) -> Critique | X9: =IFERROR(P9/MAX(Q9,1),0) -> 0.86666667
A10: COMP-006 | B10: Magnetoscopie MT Niveau 2 | C10: CND/NDT | D10: Magnetoscopie | E10: 4 | F10: 10 | G10: 4000 | H10: 3 | I10: NAS 410 / EN 4179 | J10: 28000 | K10: Liberation pieces bloquee | L10: =IFERROR(AVERAGEIF('04_MATRICE_SKILLS'!F:F,A10,'04_MATRICE_SKILLS'!I:I),0) -> 3.4166667 | M10: =COUNTIF('04_MATRICE_SKILLS'!F:F,A10) -> 12 | N10: =IF(E10="","",IF(E10>=5,"Critique",IF(E10>=4,"Eleve",IF(E10>=3,"Moyen","Faible")))) -> Eleve | O10: =COUNTIFS('04_MATRICE_SKILLS'!F:F,A10,'04_MATRICE_SKILLS'!I:I,">="&4) -> 6 | P10: =COUNTIFS('04_MATRICE_SKILLS'!F:F,A10,'04_MATRICE_SKILLS'!I:I,">="&3) -> 8 | Q10: =COUNTIF('05_GAP_ANALYSIS'!E:E,A10) -> 9 | R10: =P10-Q10 -> -1 | S10: =IF(AND(E10>=4,P10<'01_PARAMETRES'!$B$14),"Critique",IF(P10=0,"Alerte","Sous controle")) -> Sous controle | T10: =G10*MAX(1,Q10-P10) -> 4000 | U10: =H10*20 -> 60 | V10: =ROUND((E10*8)+(H10*6)+(MAX(0,Q10-P10)*10),0) -> 60 | W10: =IF(V10>=70,"Critique",IF(V10>=45,"Eleve",IF(V10>=25,"Moyen","Faible"))) -> Eleve | X10: =IFERROR(P10/MAX(Q10,1),0) -> 0.88888889
A11: COMP-007 | B11: Ultrasons UT Niveau 2 | C11: CND/NDT | D11: Ultrasons | E11: 5 | F11: 15 | G11: 5500 | H11: 4 | I11: NAS 410 / EN 4179 | J11: 42000 | K11: Arret controle pieces forgees | L11: =IFERROR(AVERAGEIF('04_MATRICE_SKILLS'!F:F,A11,'04_MATRICE_SKILLS'!I:I),0) -> 3.625 | M11: =COUNTIF('04_MATRICE_SKILLS'!F:F,A11) -> 8 | N11: =IF(E11="","",IF(E11>=5,"Critique",IF(E11>=4,"Eleve",IF(E11>=3,"Moyen","Faible")))) -> Critique | O11: =COUNTIFS('04_MATRICE_SKILLS'!F:F,A11,'04_MATRICE_SKILLS'!I:I,">="&4) -> 4 | P11: =COUNTIFS('04_MATRICE_SKILLS'!F:F,A11,'04_MATRICE_SKILLS'!I:I,">="&3) -> 7 | Q11: =COUNTIF('05_GAP_ANALYSIS'!E:E,A11) -> 6 | R11: =P11-Q11 -> 1 | S11: =IF(AND(E11>=4,P11<'01_PARAMETRES'!$B$14),"Critique",IF(P11=0,"Alerte","Sous controle")) -> Sous controle | T11: =G11*MAX(1,Q11-P11) -> 5500 | U11: =H11*20 -> 80 | V11: =ROUND((E11*8)+(H11*6)+(MAX(0,Q11-P11)*10),0) -> 64 | W11: =IF(V11>=70,"Critique",IF(V11>=45,"Eleve",IF(V11>=25,"Moyen","Faible"))) -> Eleve | X11: =IFERROR(P11/MAX(Q11,1),0) -> 1.1666667
A12: COMP-008 | B12: Radiographie RT Niveau 2 | C12: CND/NDT | D12: Radiographie | E12: 5 | F12: 15 | G12: 6000 | H12: 5 | I12: NAS 410 / EN 4179 | J12: 42000 | K12: Arret controle soudures | L12: =IFERROR(AVERAGEIF('04_MATRICE_SKILLS'!F:F,A12,'04_MATRICE_SKILLS'!I:I),0) -> 2.5384615 | M12: =COUNTIF('04_MATRICE_SKILLS'!F:F,A12) -> 13 | N12: =IF(E12="","",IF(E12>=5,"Critique",IF(E12>=4,"Eleve",IF(E12>=3,"Moyen","Faible")))) -> Critique | O12: =COUNTIFS('04_MATRICE_SKILLS'!F:F,A12,'04_MATRICE_SKILLS'!I:I,">="&4) -> 4 | P12: =COUNTIFS('04_MATRICE_SKILLS'!F:F,A12,'04_MATRICE_SKILLS'!I:I,">="&3) -> 6 | Q12: =COUNTIF('05_GAP_ANALYSIS'!E:E,A12) -> 6 | R12: =P12-Q12 -> 0 | S12: =IF(AND(E12>=4,P12<'01_PARAMETRES'!$B$14),"Critique",IF(P12=0,"Alerte","Sous controle")) -> Sous controle | T12: =G12*MAX(1,Q12-P12) -> 6000 | U12: =H12*20 -> 100 | V12: =ROUND((E12*8)+(H12*6)+(MAX(0,Q12-P12)*10),0) -> 70 | W12: =IF(V12>=70,"Critique",IF(V12>=45,"Eleve",IF(V12>=25,"Moyen","Faible"))) -> Critique | X12: =IFERROR(P12/MAX(Q12,1),0) -> 1
A13: COMP-009 | B13: Courants de Foucault ET N2 | C13: CND/NDT | D13: Foucault | E13: 4 | F13: 12 | G13: 5000 | H13: 4 | I13: NAS 410 / EN 4179 | J13: 30000 | K13: Controle surface degrade | L13: =IFERROR(AVERAGEIF('04_MATRICE_SKILLS'!F:F,A13,'04_MATRICE_SKILLS'!I:I),0) -> 2.75 | M13: =COUNTIF('04_MATRICE_SKILLS'!F:F,A13) -> 12 | N13: =IF(E13="","",IF(E13>=5,"Critique",IF(E13>=4,"Eleve",IF(E13>=3,"Moyen","Faible")))) -> Eleve | O13: =COUNTIFS('04_MATRICE_SKILLS'!F:F,A13,'04_MATRICE_SKILLS'!I:I,">="&4) -> 5 | P13: =COUNTIFS('04_MATRICE_SKILLS'!F:F,A13,'04_MATRICE_SKILLS'!I:I,">="&3) -> 6 | Q13: =COUNTIF('05_GAP_ANALYSIS'!E:E,A13) -> 6 | R13: =P13-Q13 -> 0 | S13: =IF(AND(E13>=4,P13<'01_PARAMETRES'!$B$14),"Critique",IF(P13=0,"Alerte","Sous controle")) -> Sous controle | T13: =G13*MAX(1,Q13-P13) -> 5000 | U13: =H13*20 -> 80 | V13: =ROUND((E13*8)+(H13*6)+(MAX(0,Q13-P13)*10),0) -> 56 | W13: =IF(V13>=70,"Critique",IF(V13>=45,"Eleve",IF(V13>=25,"Moyen","Faible"))) -> Eleve | X13: =IFERROR(P13/MAX(Q13,1),0) -> 1
A14: COMP-010 | B14: Usinage CN 3 axes | C14: Usinage & fabrication | D14: Usinage | E14: 3 | F14: 10 | G14: 3000 | H14: 2 | I14: Interne | J14: 18000 | K14: Reaffectation possible | L14: =IFERROR(AVERAGEIF('04_MATRICE_SKILLS'!F:F,A14,'04_MATRICE_SKILLS'!I:I),0) -> 3.6153846 | M14: =COUNTIF('04_MATRICE_SKILLS'!F:F,A14) -> 13 | N14: =IF(E14="","",IF(E14>=5,"Critique",IF(E14>=4,"Eleve",IF(E14>=3,"Moyen","Faible")))) -> Moyen | O14: =COUNTIFS('04_MATRICE_SKILLS'!F:F,A14,'04_MATRICE_SKILLS'!I:I,">="&4) -> 6 | P14: =COUNTIFS('04_MATRICE_SKILLS'!F:F,A14,'04_MATRICE_SKILLS'!I:I,">="&3) -> 12 | Q14: =COUNTIF('05_GAP_ANALYSIS'!E:E,A14) -> 12 | R14: =P14-Q14 -> 0 | S14: =IF(AND(E14>=4,P14<'01_PARAMETRES'!$B$14),"Critique",IF(P14=0,"Alerte","Sous controle")) -> Sous controle | T14: =G14*MAX(1,Q14-P14) -> 3000 | U14: =H14*20 -> 40 | V14: =ROUND((E14*8)+(H14*6)+(MAX(0,Q14-P14)*10),0) -> 36 | W14: =IF(V14>=70,"Critique",IF(V14>=45,"Eleve",IF(V14>=25,"Moyen","Faible"))) -> Moyen | X14: =IFERROR(P14/MAX(Q14,1),0) -> 1
A15: COMP-011 | B15: Usinage CN 5 axes | C15: Usinage & fabrication | D15: Usinage | E15: 5 | F15: 20 | G15: 8000 | H15: 5 | I15: Interne | J15: 60000 | K15: Arret production pieces complexes | L15: =IFERROR(AVERAGEIF('04_MATRICE_SKILLS'!F:F,A15,'04_MATRICE_SKILLS'!I:I),0) -> 3.2 | M15: =COUNTIF('04_MATRICE_SKILLS'!F:F,A15) -> 10 | N15: =IF(E15="","",IF(E15>=5,"Critique",IF(E15>=4,"Eleve",IF(E15>=3,"Moyen","Faible")))) -> Critique | O15: =COUNTIFS('04_MATRICE_SKILLS'!F:F,A15,'04_MATRICE_SKILLS'!I:I,">="&4) -> 4 | P15: =COUNTIFS('04_MATRICE_SKILLS'!F:F,A15,'04_MATRICE_SKILLS'!I:I,">="&3) -> 7 | Q15: =COUNTIF('05_GAP_ANALYSIS'!E:E,A15) -> 9 | R15: =P15-Q15 -> -2 | S15: =IF(AND(E15>=4,P15<'01_PARAMETRES'!$B$14),"Critique",IF(P15=0,"Alerte","Sous controle")) -> Sous controle | T15: =G15*MAX(1,Q15-P15) -> 16000 | U15: =H15*20 -> 100 | V15: =ROUND((E15*8)+(H15*6)+(MAX(0,Q15-P15)*10),0) -> 90 | W15: =IF(V15>=70,"Critique",IF(V15>=45,"Eleve",IF(V15>=25,"Moyen","Faible"))) -> Critique | X15: =IFERROR(P15/MAX(Q15,1),0) -> 0.77777778
A16: COMP-012 | B16: Tournage CN | C16: Usinage & fabrication | D16: Tournage | E16: 3 | F16: 8 | G16: 2500 | H16: 2 | I16: Interne | J16: 15000 | K16: Reaffectation possible | L16: =IFERROR(AVERAGEIF('04_MATRICE_SKILLS'!F:F,A16,'04_MATRICE_SKILLS'!I:I),0) -> 2.8461538 | M16: =COUNTIF('04_MATRICE_SKILLS'!F:F,A16) -> 13 | N16: =IF(E16="","",IF(E16>=5,"Critique",IF(E16>=4,"Eleve",IF(E16>=3,"Moyen","Faible")))) -> Moyen | O16: =COUNTIFS('04_MATRICE_SKILLS'!F:F,A16,'04_MATRICE_SKILLS'!I:I,">="&4) -> 4 | P16: =COUNTIFS('04_MATRICE_SKILLS'!F:F,A16,'04_MATRICE_SKILLS'!I:I,">="&3) -> 6 | Q16: =COUNTIF('05_GAP_ANALYSIS'!E:E,A16) -> 6 | R16: =P16-Q16 -> 0 | S16: =IF(AND(E16>=4,P16<'01_PARAMETRES'!$B$14),"Critique",IF(P16=0,"Alerte","Sous controle")) -> Sous controle | T16: =G16*MAX(1,Q16-P16) -> 2500 | U16: =H16*20 -> 40 | V16: =ROUND((E16*8)+(H16*6)+(MAX(0,Q16-P16)*10),0) -> 36 | W16: =IF(V16>=70,"Critique",IF(V16>=45,"Eleve",IF(V16>=25,"Moyen","Faible"))) -> Moyen | X16: =IFERROR(P16/MAX(Q16,1),0) -> 1
... A34: COMP-030 | B34: First Article Inspection FAI | C34: Qualite & methodes | D34: FAI | E34: 4 | F34: 3 | G34: 1200 | H34: 3 | I34: AS9102 | J34: 16000 | K34: Premiere piece non liberable | L34: =IFERROR(AVERAGEIF('04_MATRICE_SKILLS'!F:F,A34,'04_MATRICE_SKILLS'!I:I),0) -> 3.173913 | M34: =COUNTIF('04_MATRICE_SKILLS'!F:F,A34) -> 23 | N34: =IF(E34="","",IF(E34>=5,"Critique",IF(E34>=4,"Eleve",IF(E34>=3,"Moyen","Faible")))) -> Eleve | O34: =COUNTIFS('04_MATRICE_SKILLS'!F:F,A34,'04_MATRICE_SKILLS'!I:I,">="&4) -> 10 | P34: =COUNTIFS('04_MATRICE_SKILLS'!F:F,A34,'04_MATRICE_SKILLS'!I:I,">="&3) -> 16 | Q34: =COUNTIF('05_GAP_ANALYSIS'!E:E,A34) -> 21 | R34: =P34-Q34 -> -5 | S34: =IF(AND(E34>=4,P34<'01_PARAMETRES'!$B$14),"Critique",IF(P34=0,"Alerte","Sous controle")) -> Sous controle | T34: =G34*MAX(1,Q34-P34) -> 6000 | U34: =H34*20 -> 60 | V34: =ROUND((E34*8)+(H34*6)+(MAX(0,Q34-P34)*10),0) -> 100 | W34: =IF(V34>=70,"Critique",IF(V34>=45,"Eleve",IF(V34>=25,"Moyen","Faible"))) -> Critique | X34: =IFERROR(P34/MAX(Q34,1),0) -> 0.76190476

Sheet 03_ANNUAIRE
A1: Annuaire du personnel
A2: Population de reference reliee a la matrice des competences
A4: ID Employe | B4: Nom | C4: Prenom | D4: Site | E4: Business Unit | F4: Poste | G4: Categorie | H4: Date entree | I4: Manager ID | J4: Contrat | K4: Statut | L4: Anciennete | M4: Nb evals | N4: Niveau moyen | O4: Statut RH | P4: Nb competences qualifiees | Q4: Score polyvalence | R4: Taux couverture
A5: EMP-001 | B5: DUPONT | C5: Jean-Marc | D5: Villaroche (77) | E5: Production | F5: Soudeur TIG qualifie | G5: Operateur | H5: 43862 | J5: CDI | K5: Actif | L5: =DATEDIF(H5,TODAY(),"Y") -> 6 | M5: =COUNTIF('04_MATRICE_SKILLS'!B:B,A5) -> 10 | N5: =IFERROR(AVERAGEIF('04_MATRICE_SKILLS'!B:B,A5,'04_MATRICE_SKILLS'!I:I),0) -> 1.9 | O5: =IF(K5<>"Actif","Inactif",IF(N5<2,"Sous-qualifie",IF(Q5<0.6,"Polyvalence faible","OK"))) -> Sous-qualifie | P5: =COUNTIFS('04_MATRICE_SKILLS'!B:B,A5,'04_MATRICE_SKILLS'!I:I,">="&3) -> 4 | Q5: =IFERROR(P5/'01_PARAMETRES'!$B$15,0) -> 0.8 | R5: =IFERROR(COUNTIFS('04_MATRICE_SKILLS'!B:B,A5,'04_MATRICE_SKILLS'!L:L,"Conforme")/MAX(M5,1),0) -> 0.4
A6: EMP-002 | B6: MARTIN | C6: Pierre | D6: Gennevilliers (92) | E6: Production | F6: Soudeur polyvalent | G6: Operateur | H6: 41369 | I6: EMP-001 | J6: CDI | K6: Actif | L6: =DATEDIF(H6,TODAY(),"Y") -> 12 | M6: =COUNTIF('04_MATRICE_SKILLS'!B:B,A6) -> 7 | N6: =IFERROR(AVERAGEIF('04_MATRICE_SKILLS'!B:B,A6,'04_MATRICE_SKILLS'!I:I),0) -> 3.4285714 | O6: =IF(K6<>"Actif","Inactif",IF(N6<2,"Sous-qualifie",IF(Q6<0.6,"Polyvalence faible","OK"))) -> OK | P6: =COUNTIFS('04_MATRICE_SKILLS'!B:B,A6,'04_MATRICE_SKILLS'!I:I,">="&3) -> 5 | Q6: =IFERROR(P6/'01_PARAMETRES'!$B$15,0) -> 1 | R6: =IFERROR(COUNTIFS('04_MATRICE_SKILLS'!B:B,A6,'04_MATRICE_SKILLS'!L:L,"Conforme")/MAX(M6,1),0) -> 0.71428571
A7: EMP-003 | B7: BERNARD | C7: Thomas | D7: Chatellerault (86) | E7: Qualite | F7: Operateur CND Niveau 2 | G7: Technicien | H7: 44183 | I7: EMP-001 | J7: CDI | K7: Actif | L7: =DATEDIF(H7,TODAY(),"Y") -> 5 | M7: =COUNTIF('04_MATRICE_SKILLS'!B:B,A7) -> 8 | N7: =IFERROR(AVERAGEIF('04_MATRICE_SKILLS'!B:B,A7,'04_MATRICE_SKILLS'!I:I),0) -> 3.125 | O7: =IF(K7<>"Actif","Inactif",IF(N7<2,"Sous-qualifie",IF(Q7<0.6,"Polyvalence faible","OK"))) -> OK | P7: =COUNTIFS('04_MATRICE_SKILLS'!B:B,A7,'04_MATRICE_SKILLS'!I:I,">="&3) -> 6 | Q7: =IFERROR(P7/'01_PARAMETRES'!$B$15,0) -> 1.2 | R7: =IFERROR(COUNTIFS('04_MATRICE_SKILLS'!B:B,A7,'04_MATRICE_SKILLS'!L:L,"Conforme")/MAX(M7,1),0) -> 0.375
A8: EMP-004 | B8: PETIT | C8: Nicolas | D8: Bordes (64) | E8: Qualite | F8: Operateur CND Niveau 3 | G8: Technicien | H8: 43648 | I8: EMP-001 | J8: CDI | K8: Actif | L8: =DATEDIF(H8,TODAY(),"Y") -> 6 | M8: =COUNTIF('04_MATRICE_SKILLS'!B:B,A8) -> 8 | N8: =IFERROR(AVERAGEIF('04_MATRICE_SKILLS'!B:B,A8,'04_MATRICE_SKILLS'!I:I),0) -> 4.125 | O8: =IF(K8<>"Actif","Inactif",IF(N8<2,"Sous-qualifie",IF(Q8<0.6,"Polyvalence faible","OK"))) -> OK | P8: =COUNTIFS('04_MATRICE_SKILLS'!B:B,A8,'04_MATRICE_SKILLS'!I:I,">="&3) -> 8 | Q8: =IFERROR(P8/'01_PARAMETRES'!$B$15,0) -> 1.6 | R8: =IFERROR(COUNTIFS('04_MATRICE_SKILLS'!B:B,A8,'04_MATRICE_SKILLS'!L:L,"Conforme")/MAX(M8,1),0) -> 0.75
A9: EMP-005 | B9: ROBERT | C9: Julien | D9: Istres (13) | E9: Production | F9: Operateur usinage CN 5 axes | G9: Operateur | H9: 40641 | I9: EMP-001 | J9: CDD | K9: Actif | L9: =DATEDIF(H9,TODAY(),"Y") -> 14 | M9: =COUNTIF('04_MATRICE_SKILLS'!B:B,A9) -> 7 | N9: =IFERROR(AVERAGEIF('04_MATRICE_SKILLS'!B:B,A9,'04_MATRICE_SKILLS'!I:I),0) -> 3.1428571 | O9: =IF(K9<>"Actif","Inactif",IF(N9<2,"Sous-qualifie",IF(Q9<0.6,"Polyvalence faible","OK"))) -> OK | P9: =COUNTIFS('04_MATRICE_SKILLS'!B:B,A9,'04_MATRICE_SKILLS'!I:I,">="&3) -> 5 | Q9: =IFERROR(P9/'01_PARAMETRES'!$B$15,0) -> 1 | R9: =IFERROR(COUNTIFS('04_MATRICE_SKILLS'!B:B,A9,'04_MATRICE_SKILLS'!L:L,"Conforme")/MAX(M9,1),0) -> 0.71428571
A10: EMP-006 | B10: RICHARD | C10: Antoine | D10: Villaroche (77) | E10: Production | F10: Operateur usinage CN 3 axes | G10: Operateur | H10: 43483 | I10: EMP-006 | J10: CDI | K10: Actif | L10: =DATEDIF(H10,TODAY(),"Y") -> 7 | M10: =COUNTIF('04_MATRICE_SKILLS'!B:B,A10) -> 7 | N10: =IFERROR(AVERAGEIF('04_MATRICE_SKILLS'!B:B,A10,'04_MATRICE_SKILLS'!I:I),0) -> 2.2857143 | O10: =IF(K10<>"Actif","Inactif",IF(N10<2,"Sous-qualifie",IF(Q10<0.6,"Polyvalence faible","OK"))) -> Polyvalence faible | P10: =COUNTIFS('04_MATRICE_SKILLS'!B:B,A10,'04_MATRICE_SKILLS'!I:I,">="&3) -> 2 | Q10: =IFERROR(P10/'01_PARAMETRES'!$B$15,0) -> 0.4 | R10: =IFERROR(COUNTIFS('04_MATRICE_SKILLS'!B:B,A10,'04_MATRICE_SKILLS'!L:L,"Conforme")/MAX(M10,1),0) -> 0.28571429
A11: EMP-007 | B11: DURAND | C11: Sebastien | D11: Gennevilliers (92) | E11: Production | F11: Technicien traitement thermique | G11: Technicien | H11: 44523 | I11: EMP-006 | J11: CDD | K11: Actif | L11: =DATEDIF(H11,TODAY(),"Y") -> 4 | M11: =COUNTIF('04_MATRICE_SKILLS'!B:B,A11) -> 9 | N11: =IFERROR(AVERAGEIF('04_MATRICE_SKILLS'!B:B,A11,'04_MATRICE_SKILLS'!I:I),0) -> 2 | O11: =IF(K11<>"Actif","Inactif",IF(N11<2,"Sous-qualifie",IF(Q11<0.6,"Polyvalence faible","OK"))) -> OK | P11: =COUNTIFS('04_MATRICE_SKILLS'!B:B,A11,'04_MATRICE_SKILLS'!I:I,">="&3) -> 3 | Q11: =IFERROR(P11/'01_PARAMETRES'!$B$15,0) -> 0.6 | R11: =IFERROR(COUNTIFS('04_MATRICE_SKILLS'!B:B,A11,'04_MATRICE_SKILLS'!L:L,"Conforme")/MAX(M11,1),0) -> 0.44444444
A12: EMP-008 | B12: MOREAU | C12: Francois | D12: Chatellerault (86) | E12: Production | F12: Technicien traitement surface | G12: Technicien | H12: 42475 | I12: EMP-006 | J12: Interimaire | K12: Actif | L12: =DATEDIF(H12,TODAY(),"Y") -> 9 | M12: =COUNTIF('04_MATRICE_SKILLS'!B:B,A12) -> 6 | N12: =IFERROR(AVERAGEIF('04_MATRICE_SKILLS'!B:B,A12,'04_MATRICE_SKILLS'!I:I),0) -> 2.6666667 | O12: =IF(K12<>"Actif","Inactif",IF(N12<2,"Sous-qualifie",IF(Q12<0.6,"Polyvalence faible","OK"))) -> OK | P12: =COUNTIFS('04_MATRICE_SKILLS'!B:B,A12,'04_MATRICE_SKILLS'!I:I,">="&3) -> 3 | Q12: =IFERROR(P12/'01_PARAMETRES'!$B$15,0) -> 0.6 | R12: =IFERROR(COUNTIFS('04_MATRICE_SKILLS'!B:B,A12,'04_MATRICE_SKILLS'!L:L,"Conforme")/MAX(M12,1),0) -> 0.5
A13: EMP-009 | B13: LAURENT | C13: Christophe | D13: Bordes (64) | E13: Bureau d'etudes | F13: Ingenieur conception CATIA | G13: Ingenieur | H13: 41664 | I13: EMP-006 | J13: CDI | K13: Actif | L13: =DATEDIF(H13,TODAY(),"Y") -> 12 | M13: =COUNTIF('04_MATRICE_SKILLS'!B:B,A13) -> 8 | N13: =IFERROR(AVERAGEIF('04_MATRICE_SKILLS'!B:B,A13,'04_MATRICE_SKILLS'!I:I),0) -> 3.125 | O13: =IF(K13<>"Actif","Inactif",IF(N13<2,"Sous-qualifie",IF(Q13<0.6,"Polyvalence faible","OK"))) -> OK | P13: =COUNTIFS('04_MATRICE_SKILLS'!B:B,A13,'04_MATRICE_SKILLS'!I:I,">="&3) -> 5 | Q13: =IFERROR(P13/'01_PARAMETRES'!$B$15,0) -> 1 | R13: =IFERROR(COUNTIFS('04_MATRICE_SKILLS'!B:B,A13,'04_MATRICE_SKILLS'!L:L,"Conforme")/MAX(M13,1),0) -> 0.625
A14: EMP-010 | B14: SIMON | C14: Laurent | D14: Istres (13) | E14: Bureau d'etudes | F14: Ingenieur calcul structures | G14: Ingenieur | H14: 44388 | I14: EMP-006 | J14: CDI | K14: Actif | L14: =DATEDIF(H14,TODAY(),"Y") -> 4 | M14: =COUNTIF('04_MATRICE_SKILLS'!B:B,A14) -> 5 | N14: =IFERROR(AVERAGEIF('04_MATRICE_SKILLS'!B:B,A14,'04_MATRICE_SKILLS'!I:I),0) -> 4.4 | O14: =IF(K14<>"Actif","Inactif",IF(N14<2,"Sous-qualifie",IF(Q14<0.6,"Polyvalence faible","OK"))) -> OK | P14: =COUNTIFS('04_MATRICE_SKILLS'!B:B,A14,'04_MATRICE_SKILLS'!I:I,">="&3) -> 5 | Q14: =IFERROR(P14/'01_PARAMETRES'!$B$15,0) -> 1 | R14: =IFERROR(COUNTIFS('04_MATRICE_SKILLS'!B:B,A14,'04_MATRICE_SKILLS'!L:L,"Conforme")/MAX(M14,1),0) -> 1
A15: EMP-011 | B15: MICHEL | C15: Mathieu | D15: Villaroche (77) | E15: Qualite | F15: Responsable qualite PART 21 | G15: Cadre | H15: 41024 | I15: EMP-011 | J15: CDI | K15: Actif | L15: =DATEDIF(H15,TODAY(),"Y") -> 13 | M15: =COUNTIF('04_MATRICE_SKILLS'!B:B,A15) -> 10 | N15: =IFERROR(AVERAGEIF('04_MATRICE_SKILLS'!B:B,A15,'04_MATRICE_SKILLS'!I:I),0) -> 3.3 | O15: =IF(K15<>"Actif","Inactif",IF(N15<2,"Sous-qualifie",IF(Q15<0.6,"Polyvalence faible","OK"))) -> OK | P15: =COUNTIFS('04_MATRICE_SKILLS'!B:B,A15,'04_MATRICE_SKILLS'!I:I,">="&3) -> 6 | Q15: =IFERROR(P15/'01_PARAMETRES'!$B$15,0) -> 1.2 | R15: =IFERROR(COUNTIFS('04_MATRICE_SKILLS'!B:B,A15,'04_MATRICE_SKILLS'!L:L,"Conforme")/MAX(M15,1),0) -> 0.6
A16: EMP-012 | B16: LEFEVRE | C16: David | D16: Gennevilliers (92) | E16: Qualite | F16: Auditeur interne EN 9100 | G16: Cadre | H16: 40587 | I16: EMP-011 | J16: CDI | K16: Actif | L16: =DATEDIF(H16,TODAY(),"Y") -> 15 | M16: =COUNTIF('04_MATRICE_SKILLS'!B:B,A16) -> 9 | N16: =IFERROR(AVERAGEIF('04_MATRICE_SKILLS'!B:B,A16,'04_MATRICE_SKILLS'!I:I),0) -> 3.1111111 | O16: =IF(K16<>"Actif","Inactif",IF(N16<2,"Sous-qualifie",IF(Q16<0.6,"Polyvalence faible","OK"))) -> OK | P16: =COUNTIFS('04_MATRICE_SKILLS'!B:B,A16,'04_MATRICE_SKILLS'!I:I,">="&3) -> 6 | Q16: =IFERROR(P16/'01_PARAMETRES'!$B$15,0) -> 1.2 | R16: =IFERROR(COUNTIFS('04_MATRICE_SKILLS'!B:B,A16,'04_MATRICE_SKILLS'!L:L,"Conforme")/MAX(M16,1),0) -> 0.55555556
A17: EMP-013 | B17: LEROY | C17: Philippe | D17: Chatellerault (86) | E17: Production | F17: Chef d'atelier production | G17: Manager | H17: 42175 | I17: EMP-011 | J17: CDI | K17: Actif | L17: =DATEDIF(H17,TODAY(),"Y") -> 10 | M17: =COUNTIF('04_MATRICE_SKILLS'!B:B,A17) -> 9 | N17: =IFERROR(AVERAGEIF('04_MATRICE_SKILLS'!B:B,A17,'04_MATRICE_SKILLS'!I:I),0) -> 3.2222222 | O17: =IF(K17<>"Actif","Inactif",IF(N17<2,"Sous-qualifie",IF(Q17<0.6,"Polyvalence faible","OK"))) -> OK | P17: =COUNTIFS('04_MATRICE_SKILLS'!B:B,A17,'04_MATRICE_SKILLS'!I:I,">="&3) -> 7 | Q17: =IFERROR(P17/'01_PARAMETRES'!$B$15,0) -> 1.4 | R17: =IFERROR(COUNTIFS('04_MATRICE_SKILLS'!B:B,A17,'04_MATRICE_SKILLS'!L:L,"Conforme")/MAX(M17,1),0) -> 0.66666667
... A64: EMP-060 | B64: PERRIN | C64: Melanie | D64: Istres (13) | E64: Supply Chain | F64: Coordinateur Supply Chain | G64: Cadre | H64: 42993 | I64: EMP-056 | J64: CDI | K64: Actif | L64: =DATEDIF(H64,TODAY(),"Y") -> 8 | M64: =COUNTIF('04_MATRICE_SKILLS'!B:B,A64) -> 6 | N64: =IFERROR(AVERAGEIF('04_MATRICE_SKILLS'!B:B,A64,'04_MATRICE_SKILLS'!I:I),0) -> 2.8333333 | O64: =IF(K64<>"Actif","Inactif",IF(N64<2,"Sous-qualifie",IF(Q64<0.6,"Polyvalence faible","OK"))) -> OK | P64: =COUNTIFS('04_MATRICE_SKILLS'!B:B,A64,'04_MATRICE_SKILLS'!I:I,">="&3) -> 4 | Q64: =IFERROR(P64/'01_PARAMETRES'!$B$15,0) -> 0.8 | R64: =IFERROR(COUNTIFS('04_MATRICE_SKILLS'!B:B,A64,'04_MATRICE_SKILLS'!L:L,"Conforme")/MAX(M64,1),0) -> 0.66666667

Sheet 04_MATRICE_SKILLS
A1: Matrice des competences
A2: Population x competence avec niveaux reels et requis
A4: ID Ligne | B4: ID Employe | C4: Nom employe | D4: Site | E4: Poste | F4: ID Competence | G4: Categorie | H4: Criticite | I4: Niveau reel | J4: Niveau requis | K4: Gap | L4: Statut | M4: Source | N4: Date eval. | O4: Commentaire
A5: MAT-0001 | B5: EMP-001 | C5: DUPONT Jean-Marc | D5: Villaroche (77) | E5: Soudeur TIG qualifie | F5: COMP-001 | G5: Procedes speciaux | H5: Critique | I5: 3 | J5: 4 | K5: =IF(J5="","",I5-J5) -> -1 | L5: =IF(J5="","Bonus",IF(K5>=0,"Conforme",IF(K5=-1,"Ecart mineur","Ecart critique"))) -> Ecart mineur | M5: test | N5: 46072
A6: MAT-0002 | B6: EMP-001 | C6: DUPONT Jean-Marc | D6: Villaroche (77) | E6: Soudeur TIG qualifie | F6: COMP-002 | G6: Procedes speciaux | H6: Eleve | I6: 3 | J6: 3 | K6: =IF(J6="","",I6-J6) -> 0 | L6: =IF(J6="","Bonus",IF(K6>=0,"Conforme",IF(K6=-1,"Ecart mineur","Ecart critique"))) -> Conforme | M6: manager | N6: 45959
A7: MAT-0003 | B7: EMP-001 | C7: DUPONT Jean-Marc | D7: Villaroche (77) | E7: Soudeur TIG qualifie | F7: COMP-005 | G7: CND/NDT | H7: Eleve | I7: 1 | J7: 2 | K7: =IF(J7="","",I7-J7) -> -1 | L7: =IF(J7="","Bonus",IF(K7>=0,"Conforme",IF(K7=-1,"Ecart mineur","Ecart critique"))) -> Ecart mineur | M7: auto-eval | N7: 45782
A8: MAT-0004 | B8: EMP-001 | C8: DUPONT Jean-Marc | D8: Villaroche (77) | E8: Soudeur TIG qualifie | F8: COMP-006 | G8: CND/NDT | H8: Eleve | I8: 1 | K8: =IF(J8="","",I8-J8) | L8: =IF(J8="","Bonus",IF(K8>=0,"Conforme",IF(K8=-1,"Ecart mineur","Ecart critique"))) -> Bonus | M8: manager | N8: 45973
A9: MAT-0005 | B9: EMP-001 | C9: DUPONT Jean-Marc | D9: Villaroche (77) | E9: Soudeur TIG qualifie | F9: COMP-008 | G9: CND/NDT | H9: Critique | I9: 1 | K9: =IF(J9="","",I9-J9) | L9: =IF(J9="","Bonus",IF(K9>=0,"Conforme",IF(K9=-1,"Ecart mineur","Ecart critique"))) -> Bonus | M9: test | N9: 45752
A10: MAT-0006 | B10: EMP-001 | C10: DUPONT Jean-Marc | D10: Villaroche (77) | E10: Soudeur TIG qualifie | F10: COMP-013 | G10: Usinage & fabrication | H10: Eleve | I10: 1 | K10: =IF(J10="","",I10-J10) | L10: =IF(J10="","Bonus",IF(K10>=0,"Conforme",IF(K10=-1,"Ecart mineur","Ecart critique"))) -> Bonus | M10: auto-eval | N10: 45868
A11: MAT-0007 | B11: EMP-001 | C11: DUPONT Jean-Marc | D11: Villaroche (77) | E11: Soudeur TIG qualifie | F11: COMP-022 | G11: Bureau d'etudes | H11: Critique | I11: 2 | K11: =IF(J11="","",I11-J11) | L11: =IF(J11="","Bonus",IF(K11>=0,"Conforme",IF(K11=-1,"Ecart mineur","Ecart critique"))) -> Bonus | M11: manager | N11: 45810
A12: MAT-0008 | B12: EMP-001 | C12: DUPONT Jean-Marc | D12: Villaroche (77) | E12: Soudeur TIG qualifie | F12: COMP-024 | G12: Bureau d'etudes | H12: Eleve | I12: 3 | J12: 2 | K12: =IF(J12="","",I12-J12) -> 1 | L12: =IF(J12="","Bonus",IF(K12>=0,"Conforme",IF(K12=-1,"Ecart mineur","Ecart critique"))) -> Conforme | M12: test | N12: 46044
A13: MAT-0009 | B13: EMP-001 | C13: DUPONT Jean-Marc | D13: Villaroche (77) | E13: Soudeur TIG qualifie | F13: COMP-027 | G13: Qualite & methodes | H13: Eleve | I13: 3 | J13: 2 | K13: =IF(J13="","",I13-J13) -> 1 | L13: =IF(J13="","Bonus",IF(K13>=0,"Conforme",IF(K13=-1,"Ecart mineur","Ecart critique"))) -> Conforme | M13: manager | N13: 45789
A14: MAT-0010 | B14: EMP-001 | C14: DUPONT Jean-Marc | D14: Villaroche (77) | E14: Soudeur TIG qualifie | F14: COMP-028 | G14: Qualite & methodes | H14: Moyen | I14: 1 | J14: 1 | K14: =IF(J14="","",I14-J14) -> 0 | L14: =IF(J14="","Bonus",IF(K14>=0,"Conforme",IF(K14=-1,"Ecart mineur","Ecart critique"))) -> Conforme | M14: test | N14: 46061
A15: MAT-0011 | B15: EMP-002 | C15: MARTIN Pierre | D15: Gennevilliers (92) | E15: Soudeur polyvalent | F15: COMP-001 | G15: Procedes speciaux | H15: Critique | I15: 3 | J15: 3 | K15: =IF(J15="","",I15-J15) -> 0 | L15: =IF(J15="","Bonus",IF(K15>=0,"Conforme",IF(K15=-1,"Ecart mineur","Ecart critique"))) -> Conforme | M15: manager | N15: 45965
A16: MAT-0012 | B16: EMP-002 | C16: MARTIN Pierre | D16: Gennevilliers (92) | E16: Soudeur polyvalent | F16: COMP-002 | G16: Procedes speciaux | H16: Eleve | I16: 5 | J16: 4 | K16: =IF(J16="","",I16-J16) -> 1 | L16: =IF(J16="","Bonus",IF(K16>=0,"Conforme",IF(K16=-1,"Ecart mineur","Ecart critique"))) -> Conforme | M16: auto-eval | N16: 45942 | O16: Expertise cle
A17: MAT-0013 | B17: EMP-002 | C17: MARTIN Pierre | D17: Gennevilliers (92) | E17: Soudeur polyvalent | F17: COMP-004 | G17: Procedes speciaux | H17: Eleve | I17: 5 | J17: 3 | K17: =IF(J17="","",I17-J17) -> 2 | L17: =IF(J17="","Bonus",IF(K17>=0,"Conforme",IF(K17=-1,"Ecart mineur","Ecart critique"))) -> Conforme | M17: auto-eval | N17: 46001 | O17: Expertise cle
A18: MAT-0014 | B18: EMP-002 | C18: MARTIN Pierre | D18: Gennevilliers (92) | E18: Soudeur polyvalent | F18: COMP-005 | G18: CND/NDT | H18: Eleve | I18: 4 | J18: 2 | K18: =IF(J18="","",I18-J18) -> 2 | L18: =IF(J18="","Bonus",IF(K18>=0,"Conforme",IF(K18=-1,"Ecart mineur","Ecart critique"))) -> Conforme | M18: test | N18: 45977 | O18: Expertise cle
A19: MAT-0015 | B19: EMP-002 | C19: MARTIN Pierre | D19: Gennevilliers (92) | E19: Soudeur polyvalent | F19: COMP-021 | G19: Bureau d'etudes | H19: Moyen | I19: 2 | K19: =IF(J19="","",I19-J19) | L19: =IF(J19="","Bonus",IF(K19>=0,"Conforme",IF(K19=-1,"Ecart mineur","Ecart critique"))) -> Bonus | M19: auto-eval | N19: 45879
A20: MAT-0016 | B20: EMP-002 | C20: MARTIN Pierre | D20: Gennevilliers (92) | E20: Soudeur polyvalent | F20: COMP-022 | G20: Bureau d'etudes | H20: Critique | I20: 3 | K20: =IF(J20="","",I20-J20) | L20: =IF(J20="","Bonus",IF(K20>=0,"Conforme",IF(K20=-1,"Ecart mineur","Ecart critique"))) -> Bonus | M20: manager | N20: 45923
A21: MAT-0017 | B21: EMP-002 | C21: MARTIN Pierre | D21: Gennevilliers (92) | E21: Soudeur polyvalent | F21: COMP-028 | G21: Qualite & methodes | H21: Moyen | I21: 2 | J21: 1 | K21: =IF(J21="","",I21-J21) -> 1 | L21: =IF(J21="","Bonus",IF(K21>=0,"Conforme",IF(K21=-1,"Ecart mineur","Ecart critique"))) -> Conforme | M21: test | N21: 45797
A22: MAT-0018 | B22: EMP-003 | C22: BERNARD Thomas | D22: Chatellerault (86) | E22: Operateur CND Niveau 2 | F22: COMP-005 | G22: CND/NDT | H22: Eleve | I22: 5 | J22: 4 | K22: =IF(J22="","",I22-J22) -> 1 | L22: =IF(J22="","Bonus",IF(K22>=0,"Conforme",IF(K22=-1,"Ecart mineur","Ecart critique"))) -> Conforme | M22: manager | N22: 46038 | O22: Expertise cle
A23: MAT-0019 | B23: EMP-003 | C23: BERNARD Thomas | D23: Chatellerault (86) | E23: Operateur CND Niveau 2 | F23: COMP-006 | G23: CND/NDT | H23: Eleve | I23: 3 | J23: 4 | K23: =IF(J23="","",I23-J23) -> -1 | L23: =IF(J23="","Bonus",IF(K23>=0,"Conforme",IF(K23=-1,"Ecart mineur","Ecart critique"))) -> Ecart mineur | M23: test | N23: 46006
A24: MAT-0020 | B24: EMP-003 | C24: BERNARD Thomas | D24: Chatellerault (86) | E24: Operateur CND Niveau 2 | F24: COMP-007 | G24: CND/NDT | H24: Critique | I24: 3 | J24: 3 | K24: =IF(J24="","",I24-J24) -> 0 | L24: =IF(J24="","Bonus",IF(K24>=0,"Conforme",IF(K24=-1,"Ecart mineur","Ecart critique"))) -> Conforme | M24: test | N24: 45868
A25: MAT-0021 | B25: EMP-003 | C25: BERNARD Thomas | D25: Chatellerault (86) | E25: Operateur CND Niveau 2 | F25: COMP-008 | G25: CND/NDT | H25: Critique | I25: 2 | J25: 3 | K25: =IF(J25="","",I25-J25) -> -1 | L25: =IF(J25="","Bonus",IF(K25>=0,"Conforme",IF(K25=-1,"Ecart mineur","Ecart critique"))) -> Ecart mineur | M25: auto-eval | N25: 45887
A26: MAT-0022 | B26: EMP-003 | C26: BERNARD Thomas | D26: Chatellerault (86) | E26: Operateur CND Niveau 2 | F26: COMP-009 | G26: CND/NDT | H26: Eleve | I26: 5 | J26: 3 | K26: =IF(J26="","",I26-J26) -> 2 | L26: =IF(J26="","Bonus",IF(K26>=0,"Conforme",IF(K26=-1,"Ecart mineur","Ecart critique"))) -> Conforme | M26: auto-eval | N26: 45814 | O26: Expertise cle
A27: MAT-0023 | B27: EMP-003 | C27: BERNARD Thomas | D27: Chatellerault (86) | E27: Operateur CND Niveau 2 | F27: COMP-012 | G27: Usinage & fabrication | H27: Moyen | I27: 3 | K27: =IF(J27="","",I27-J27) | L27: =IF(J27="","Bonus",IF(K27>=0,"Conforme",IF(K27=-1,"Ecart mineur","Ecart critique"))) -> Bonus | M27: test | N27: 46026
A28: MAT-0024 | B28: EMP-003 | C28: BERNARD Thomas | D28: Chatellerault (86) | E28: Operateur CND Niveau 2 | F28: COMP-019 | G28: Traitements | H28: Critique | I28: 3 | K28: =IF(J28="","",I28-J28) | L28: =IF(J28="","Bonus",IF(K28>=0,"Conforme",IF(K28=-1,"Ecart mineur","Ecart critique"))) -> Bonus | M28: test | N28: 45950
A29: MAT-0025 | B29: EMP-003 | C29: BERNARD Thomas | D29: Chatellerault (86) | E29: Operateur CND Niveau 2 | F29: COMP-030 | G29: Qualite & methodes | H29: Eleve | I29: 1 | J29: 2 | K29: =IF(J29="","",I29-J29) -> -1 | L29: =IF(J29="","Bonus",IF(K29>=0,"Conforme",IF(K29=-1,"Ecart mineur","Ecart critique"))) -> Ecart mineur | M29: auto-eval | N29: 45778
A30: MAT-0026 | B30: EMP-004 | C30: PETIT Nicolas | D30: Bordes (64) | E30: Operateur CND Niveau 3 | F30: COMP-005 | G30: CND/NDT | H30: Eleve | I30: 5 | J30: 5 | K30: =IF(J30="","",I30-J30) -> 0 | L30: =IF(J30="","Bonus",IF(K30>=0,"Conforme",IF(K30=-1,"Ecart mineur","Ecart critique"))) -> Conforme | M30: manager | N30: 45962 | O30: Expertise cle
A31: MAT-0027 | B31: EMP-004 | C31: PETIT Nicolas | D31: Bordes (64) | E31: Operateur CND Niveau 3 | F31: COMP-006 | G31: CND/NDT | H31: Eleve | I31: 5 | J31: 5 | K31: =IF(J31="","",I31-J31) -> 0 | L31: =IF(J31="","Bonus",IF(K31>=0,"Conforme",IF(K31=-1,"Ecart mineur","Ecart critique"))) -> Conforme | M31: manager | N31: 45794 | O31: Expertise cle
A32: MAT-0028 | B32: EMP-004 | C32: PETIT Nicolas | D32: Bordes (64) | E32: Operateur CND Niveau 3 | F32: COMP-007 | G32: CND/NDT | H32: Critique | I32: 4 | J32: 5 | K32: =IF(J32="","",I32-J32) -> -1 | L32: =IF(J32="","Bonus",IF(K32>=0,"Conforme",IF(K32=-1,"Ecart mineur","Ecart critique"))) -> Ecart mineur | M32: manager | N32: 45836 | O32: Expertise cle
A33: MAT-0029 | B33: EMP-004 | C33: PETIT Nicolas | D33: Bordes (64) | E33: Operateur CND Niveau 3 | F33: COMP-008 | G33: CND/NDT | H33: Critique | I33: 4 | J33: 4 | K33: =IF(J33="","",I33-J33) -> 0 | L33: =IF(J33="","Bonus",IF(K33>=0,"Conforme",IF(K33=-1,"Ecart mineur","Ecart critique"))) -> Conforme | M33: test | N33: 46019 | O33: Expertise cle
A34: MAT-0030 | B34: EMP-004 | C34: PETIT Nicolas | D34: Bordes (64) | E34: Operateur CND Niveau 3 | F34: COMP-009 | G34: CND/NDT | H34: Eleve | I34: 5 | J34: 4 | K34: =IF(J34="","",I34-J34) -> 1 | L34: =IF(J34="","Bonus",IF(K34>=0,"Conforme",IF(K34=-1,"Ecart mineur","Ecart critique"))) -> Conforme | M34: manager | N34: 45803 | O34: Expertise cle
A35: MAT-0031 | B35: EMP-004 | C35: PETIT Nicolas | D35: Bordes (64) | E35: Operateur CND Niveau 3 | F35: COMP-026 | G35: Qualite & methodes | H35: Eleve | I35: 3 | J35: 3 | K35: =IF(J35="","",I35-J35) -> 0 | L35: =IF(J35="","Bonus",IF(K35>=0,"Conforme",IF(K35=-1,"Ecart mineur","Ecart critique"))) -> Conforme | M35: manager | N35: 45783
A36: MAT-0032 | B36: EMP-004 | C36: PETIT Nicolas | D36: Bordes (64) | E36: Operateur CND Niveau 3 | F36: COMP-027 | G36: Qualite & methodes | H36: Eleve | I36: 3 | K36: =IF(J36="","",I36-J36) | L36: =IF(J36="","Bonus",IF(K36>=0,"Conforme",IF(K36=-1,"Ecart mineur","Ecart critique"))) -> Bonus | M36: manager | N36: 45761
A37: MAT-0033 | B37: EMP-004 | C37: PETIT Nicolas | D37: Bordes (64) | E37: Operateur CND Niveau 3 | F37: COMP-030 | G37: Qualite & methodes | H37: Eleve | I37: 4 | J37: 3 | K37: =IF(J37="","",I37-J37) -> 1 | L37: =IF(J37="","Bonus",IF(K37>=0,"Conforme",IF(K37=-1,"Ecart mineur","Ecart critique"))) -> Conforme | M37: test | N37: 46048 | O37: Expertise cle
A38: MAT-0034 | B38: EMP-005 | C38: ROBERT Julien | D38: Istres (13) | E38: Operateur usinage CN 5 axes | F38: COMP-010 | G38: Usinage & fabrication | H38: Moyen | I38: 4 | J38: 3 | K38: =IF(J38="","",I38-J38) -> 1 | L38: =IF(J38="","Bonus",IF(K38>=0,"Conforme",IF(K38=-1,"Ecart mineur","Ecart critique"))) -> Conforme | M38: manager | N38: 46036 | O38: Expertise cle
A39: MAT-0035 | B39: EMP-005 | C39: ROBERT Julien | D39: Istres (13) | E39: Operateur usinage CN 5 axes | F39: COMP-011 | G39: Usinage & fabrication | H39: Critique | I39: 5 | J39: 4 | K39: =IF(J39="","",I39-J39) -> 1 | L39: =IF(J39="","Bonus",IF(K39>=0,"Conforme",IF(K39=-1,"Ecart mineur","Ecart critique"))) -> Conforme | M39: auto-eval | N39: 45903 | O39: Expertise cle
A40: MAT-0036 | B40: EMP-005 | C40: ROBERT Julien | D40: Istres (13) | E40: Operateur usinage CN 5 axes | F40: COMP-014 | G40: Usinage & fabrication | H40: Eleve | I40: 3 | K40: =IF(J40="","",I40-J40) | L40: =IF(J40="","Bonus",IF(K40>=0,"Conforme",IF(K40=-1,"Ecart mineur","Ecart critique"))) -> Bonus | M40: manager | N40: 45754
A41: MAT-0037 | B41: EMP-005 | C41: ROBERT Julien | D41: Istres (13) | E41: Operateur usinage CN 5 axes | F41: COMP-015 | G41: Usinage & fabrication | H41: Eleve | I41: 3 | J41: 3 | K41: =IF(J41="","",I41-J41) -> 0 | L41: =IF(J41="","Bonus",IF(K41>=0,"Conforme",IF(K41=-1,"Ecart mineur","Ecart critique"))) -> Conforme | M41: test | N41: 45878
...

Sheet 05_GAP_ANALYSIS
A1: Gap analysis
A2: Analyse des ecarts de competences et priorisation des actions
A4: ID | B4: Employe ID | C4: Employe | D4: Site | E4: Competence ID | F4: Niv actuel | G4: Niv requis | H4: Severite | I4: Score | J4: Traitement | K4: Plan formation | L4: Action recommandee
A5: GAP-0001 | B5: EMP-001 | C5: DUPONT Jean-Marc | D5: Villaroche (77) | E5: COMP-001 | F5: 3 | G5: 4 | H5: =IF(F5-G5>=0,"🟢 OK",IF(F5-G5=-1,"🟡 Modere","🔴 Critique")) -> 🟡 Modere | I5: =MAX(0,(G5-F5)*20)+IF(H5="🔴 Critique",25,0) -> 20 | J5: =IF(H5="🟢 OK","Traite",IF(H5="🔴 Critique","Non traite","A planifier")) -> A planifier | K5: =IF(H5="🟢 OK","","PF-"&TEXT(ROW()-4,"0000")) -> PF-0001 | L5: =IF(H5="🟢 OK","Maintien",IF(H5="🔴 Critique","Formation urgente","Coaching interne")) -> Coaching interne
A6: GAP-0002 | B6: EMP-001 | C6: DUPONT Jean-Marc | D6: Villaroche (77) | E6: COMP-002 | F6: 3 | G6: 3 | H6: =IF(F6-G6>=0,"🟢 OK",IF(F6-G6=-1,"🟡 Modere","🔴 Critique")) -> 🟢 OK | I6: =MAX(0,(G6-F6)*20)+IF(H6="🔴 Critique",25,0) -> 0 | J6: =IF(H6="🟢 OK","Traite",IF(H6="🔴 Critique","Non traite","A planifier")) -> Traite | K6: =IF(H6="🟢 OK","","PF-"&TEXT(ROW()-4,"0000")) | L6: =IF(H6="🟢 OK","Maintien",IF(H6="🔴 Critique","Formation urgente","Coaching interne")) -> Maintien
A7: GAP-0003 | B7: EMP-001 | C7: DUPONT Jean-Marc | D7: Villaroche (77) | E7: COMP-005 | F7: 1 | G7: 2 | H7: =IF(F7-G7>=0,"🟢 OK",IF(F7-G7=-1,"🟡 Modere","🔴 Critique")) -> 🟡 Modere | I7: =MAX(0,(G7-F7)*20)+IF(H7="🔴 Critique",25,0) -> 20 | J7: =IF(H7="🟢 OK","Traite",IF(H7="🔴 Critique","Non traite","A planifier")) -> A planifier | K7: =IF(H7="🟢 OK","","PF-"&TEXT(ROW()-4,"0000")) -> PF-0003 | L7: =IF(H7="🟢 OK","Maintien",IF(H7="🔴 Critique","Formation urgente","Coaching interne")) -> Coaching interne
A8: GAP-0004 | B8: EMP-001 | C8: DUPONT Jean-Marc | D8: Villaroche (77) | E8: COMP-024 | F8: 3 | G8: 2 | H8: =IF(F8-G8>=0,"🟢 OK",IF(F8-G8=-1,"🟡 Modere","🔴 Critique")) -> 🟢 OK | I8: =MAX(0,(G8-F8)*20)+IF(H8="🔴 Critique",25,0) -> 0 | J8: =IF(H8="🟢 OK","Traite",IF(H8="🔴 Critique","Non traite","A planifier")) -> Traite | K8: =IF(H8="🟢 OK","","PF-"&TEXT(ROW()-4,"0000")) | L8: =IF(H8="🟢 OK","Maintien",IF(H8="🔴 Critique","Formation urgente","Coaching interne")) -> Maintien
A9: GAP-0005 | B9: EMP-001 | C9: DUPONT Jean-Marc | D9: Villaroche (77) | E9: COMP-027 | F9: 3 | G9: 2 | H9: =IF(F9-G9>=0,"🟢 OK",IF(F9-G9=-1,"🟡 Modere","🔴 Critique")) -> 🟢 OK | I9: =MAX(0,(G9-F9)*20)+IF(H9="🔴 Critique",25,0) -> 0 | J9: =IF(H9="🟢 OK","Traite",IF(H9="🔴 Critique","Non traite","A planifier")) -> Traite | K9: =IF(H9="🟢 OK","","PF-"&TEXT(ROW()-4,"0000")) | L9: =IF(H9="🟢 OK","Maintien",IF(H9="🔴 Critique","Formation urgente","Coaching interne")) -> Maintien
A10: GAP-0006 | B10: EMP-001 | C10: DUPONT Jean-Marc | D10: Villaroche (77) | E10: COMP-028 | F10: 1 | G10: 1 | H10: =IF(F10-G10>=0,"🟢 OK",IF(F10-G10=-1,"🟡 Modere","🔴 Critique")) -> 🟢 OK | I10: =MAX(0,(G10-F10)*20)+IF(H10="🔴 Critique",25,0) -> 0 | J10: =IF(H10="🟢 OK","Traite",IF(H10="🔴 Critique","Non traite","A planifier")) -> Traite | K10: =IF(H10="🟢 OK","","PF-"&TEXT(ROW()-4,"0000")) | L10: =IF(H10="🟢 OK","Maintien",IF(H10="🔴 Critique","Formation urgente","Coaching interne")) -> Maintien
A11: GAP-0007 | B11: EMP-002 | C11: MARTIN Pierre | D11: Gennevilliers (92) | E11: COMP-001 | F11: 3 | G11: 3 | H11: =IF(F11-G11>=0,"🟢 OK",IF(F11-G11=-1,"🟡 Modere","🔴 Critique")) -> 🟢 OK | I11: =MAX(0,(G11-F11)*20)+IF(H11="🔴 Critique",25,0) -> 0 | J11: =IF(H11="🟢 OK","Traite",IF(H11="🔴 Critique","Non traite","A planifier")) -> Traite | K11: =IF(H11="🟢 OK","","PF-"&TEXT(ROW()-4,"0000")) | L11: =IF(H11="🟢 OK","Maintien",IF(H11="🔴 Critique","Formation urgente","Coaching interne")) -> Maintien
A12: GAP-0008 | B12: EMP-002 | C12: MARTIN Pierre | D12: Gennevilliers (92) | E12: COMP-002 | F12: 5 | G12: 4 | H12: =IF(F12-G12>=0,"🟢 OK",IF(F12-G12=-1,"🟡 Modere","🔴 Critique")) -> 🟢 OK | I12: =MAX(0,(G12-F12)*20)+IF(H12="🔴 Critique",25,0) -> 0 | J12: =IF(H12="🟢 OK","Traite",IF(H12="🔴 Critique","Non traite","A planifier")) -> Traite | K12: =IF(H12="🟢 OK","","PF-"&TEXT(ROW()-4,"0000")) | L12: =IF(H12="🟢 OK","Maintien",IF(H12="🔴 Critique","Formation urgente","Coaching interne")) -> Maintien
A13: GAP-0009 | B13: EMP-002 | C13: MARTIN Pierre | D13: Gennevilliers (92) | E13: COMP-004 | F13: 5 | G13: 3 | H13: =IF(F13-G13>=0,"🟢 OK",IF(F13-G13=-1,"🟡 Modere","🔴 Critique")) -> 🟢 OK | I13: =MAX(0,(G13-F13)*20)+IF(H13="🔴 Critique",25,0) -> 0 | J13: =IF(H13="🟢 OK","Traite",IF(H13="🔴 Critique","Non traite","A planifier")) -> Traite | K13: =IF(H13="🟢 OK","","PF-"&TEXT(ROW()-4,"0000")) | L13: =IF(H13="🟢 OK","Maintien",IF(H13="🔴 Critique","Formation urgente","Coaching interne")) -> Maintien
A14: GAP-0010 | B14: EMP-002 | C14: MARTIN Pierre | D14: Gennevilliers (92) | E14: COMP-005 | F14: 4 | G14: 2 | H14: =IF(F14-G14>=0,"🟢 OK",IF(F14-G14=-1,"🟡 Modere","🔴 Critique")) -> 🟢 OK | I14: =MAX(0,(G14-F14)*20)+IF(H14="🔴 Critique",25,0) -> 0 | J14: =IF(H14="🟢 OK","Traite",IF(H14="🔴 Critique","Non traite","A planifier")) -> Traite | K14: =IF(H14="🟢 OK","","PF-"&TEXT(ROW()-4,"0000")) | L14: =IF(H14="🟢 OK","Maintien",IF(H14="🔴 Critique","Formation urgente","Coaching interne")) -> Maintien
A15: GAP-0011 | B15: EMP-002 | C15: MARTIN Pierre | D15: Gennevilliers (92) | E15: COMP-028 | F15: 2 | G15: 1 | H15: =IF(F15-G15>=0,"🟢 OK",IF(F15-G15=-1,"🟡 Modere","🔴 Critique")) -> 🟢 OK | I15: =MAX(0,(G15-F15)*20)+IF(H15="🔴 Critique",25,0) -> 0 | J15: =IF(H15="🟢 OK","Traite",IF(H15="🔴 Critique","Non traite","A planifier")) -> Traite | K15: =IF(H15="🟢 OK","","PF-"&TEXT(ROW()-4,"0000")) | L15: =IF(H15="🟢 OK","Maintien",IF(H15="🔴 Critique","Formation urgente","Coaching interne")) -> Maintien
A16: GAP-0012 | B16: EMP-003 | C16: BERNARD Thomas | D16: Chatellerault (86) | E16: COMP-005 | F16: 5 | G16: 4 | H16: =IF(F16-G16>=0,"🟢 OK",IF(F16-G16=-1,"🟡 Modere","🔴 Critique")) -> 🟢 OK | I16: =MAX(0,(G16-F16)*20)+IF(H16="🔴 Critique",25,0) -> 0 | J16: =IF(H16="🟢 OK","Traite",IF(H16="🔴 Critique","Non traite","A planifier")) -> Traite | K16: =IF(H16="🟢 OK","","PF-"&TEXT(ROW()-4,"0000")) | L16: =IF(H16="🟢 OK","Maintien",IF(H16="🔴 Critique","Formation urgente","Coaching interne")) -> Maintien
... A310: GAP-0306 | B310: EMP-060 | C310: PERRIN Melanie | D310: Istres (13) | E310: COMP-030 | F310: 3 | G310: 3 | H310: =IF(F310-G310>=0,"🟢 OK",IF(F310-G310=-1,"🟡 Modere","🔴 Critique")) -> 🟢 OK | I310: =MAX(0,(G310-F310)*20)+IF(H310="🔴 Critique",25,0) -> 0 | J310: =IF(H310="🟢 OK","Traite",IF(H310="🔴 Critique","Non traite","A planifier")) -> Traite | K310: =IF(H310="🟢 OK","","PF-"&TEXT(ROW()-4,"0000")) | L310: =IF(H310="🟢 OK","Maintien",IF(H310="🔴 Critique","Formation urgente","Coaching interne")) -> Maintien

Sheet 06_SUCCESSION
A1: Plans de succession
A2: Couverture des postes critiques et preparation des successeurs
A4: ID | B4: Poste | C4: Site | D4: Titulaire ID | E4: Criticite | F4: Titulaire | G4: Successeur 1 | H4: Pret 1 | I4: Successeur 2 | J4: Pret 2 | K4: Risque depart | L4: Maj plan | M4: Plan action
A5: SUC-001 | B5: Ingenieur conception CATIA | C5: Bordes (64) | D5: EMP-009 | E5: Eleve | F5: LAURENT Christophe | G5: EMP-008 | H5: 0.48 | I5: EMP-012 | J5: 0.37 | K5: Faible | L5: 45908 | M5: =IF(K5="Critique","Transfert immediat + mentoring",IF(H5<0.6,"Programme 12 mois","Suivi semestriel")) -> Programme 12 mois
A6: SUC-002 | B6: Ingenieur calcul structures | C6: Istres (13) | D6: EMP-010 | E6: Eleve | F6: SIMON Laurent | G6: EMP-009 | H6: 0.71 | I6: EMP-013 | J6: 0.37 | K6: Faible | L6: 45890 | M6: =IF(K6="Critique","Transfert immediat + mentoring",IF(H6<0.6,"Programme 12 mois","Suivi semestriel")) -> Suivi semestriel
A7: SUC-003 | B7: Responsable qualite PART 21 | C7: Villaroche (77) | D7: EMP-011 | E7: Critique | F7: MICHEL Mathieu | G7: EMP-010 | H7: 0.47 | I7: EMP-014 | J7: 0.44 | K7: Eleve | L7: 46017 | M7: =IF(K7="Critique","Transfert immediat + mentoring",IF(H7<0.6,"Programme 12 mois","Suivi semestriel")) -> Programme 12 mois
A8: SUC-004 | B8: Auditeur interne EN 9100 | C8: Gennevilliers (92) | D8: EMP-012 | E8: Critique | F8: LEFEVRE David | G8: EMP-011 | H8: 0.48 | I8: EMP-015 | J8: 0.3 | K8: Moyen | L8: 46018 | M8: =IF(K8="Critique","Transfert immediat + mentoring",IF(H8<0.6,"Programme 12 mois","Suivi semestriel")) -> Programme 12 mois
A9: SUC-005 | B9: Chef d'atelier production | C9: Chatellerault (86) | D9: EMP-013 | E9: Critique | F9: LEROY Philippe | G9: EMP-012 | H9: 0.8 | I9: EMP-016 | J9: 0.41 | K9: Moyen | L9: 46063 | M9: =IF(K9="Critique","Transfert immediat + mentoring",IF(H9<0.6,"Programme 12 mois","Suivi semestriel")) -> Suivi semestriel
A10: SUC-006 | B10: Ingenieur methodes | C10: Istres (13) | D10: EMP-015 | E10: Eleve | F10: DAVID Frederic | G10: EMP-013 | H10: 0.45 | I10: EMP-017 | J10: 0.47 | K10: Faible | L10: 45880 | M10: =IF(K10="Critique","Transfert immediat + mentoring",IF(H10<0.6,"Programme 12 mois","Suivi semestriel")) -> Programme 12 mois
A11: SUC-007 | B11: Ingenieur materiaux | C11: Gennevilliers (92) | D11: EMP-017 | E11: Eleve | F11: MOREL Alexandre | G11: EMP-014 | H11: 0.83 | I11: EMP-018 | J11: 0.44 | K11: Faible | L11: 46103 | M11: =IF(K11="Critique","Transfert immediat + mentoring",IF(H11<0.6,"Programme 12 mois","Suivi semestriel")) -> Suivi semestriel
A12: SUC-008 | B12: Responsable HSE | C12: Bordes (64) | D12: EMP-019 | E12: Critique | F12: GIRARD Cedric | G12: EMP-015 | H12: 0.65 | I12: EMP-019 | J12: 0.66 | K12: Critique | L12: 46078 | M12: =IF(K12="Critique","Transfert immediat + mentoring",IF(H12<0.6,"Programme 12 mois","Suivi semestriel")) -> Transfert immediat + mentoring
A13: SUC-009 | B13: Coordinateur Supply Chain | C13: Istres (13) | D13: EMP-020 | E13: Critique | F13: BONNET Benoit | G13: EMP-016 | H13: 0.47 | I13: EMP-020 | J13: 0.25 | K13: Moyen | L13: 46072 | M13: =IF(K13="Critique","Transfert immediat + mentoring",IF(H13<0.6,"Programme 12 mois","Suivi semestriel")) -> Programme 12 mois
A14: SUC-010 | B14: Ingenieur conception CATIA | C14: Bordes (64) | D14: EMP-029 | E14: Eleve | F14: BARBIER Pascal | G14: EMP-017 | H14: 0.46 | I14: EMP-021 | J14: 0.38 | K14: Critique | L14: 45958 | M14: =IF(K14="Critique","Transfert immediat + mentoring",IF(H14<0.6,"Programme 12 mois","Suivi semestriel")) -> Transfert immediat + mentoring
A15: SUC-011 | B15: Ingenieur calcul structures | C15: Istres (13) | D15: EMP-030 | E15: Eleve | F15: PERRIN Damien | G15: EMP-018 | H15: 0.75 | I15: EMP-022 | J15: 0.36 | K15: Critique | L15: 45890 | M15: =IF(K15="Critique","Transfert immediat + mentoring",IF(H15<0.6,"Programme 12 mois","Suivi semestriel")) -> Transfert immediat + mentoring
A16: SUC-012 | B16: Responsable qualite PART 21 | C16: Villaroche (77) | D16: EMP-031 | E16: Critique | F16: DUPONT Sophie | G16: EMP-019 | H16: 0.47 | I16: EMP-023 | J16: 0.69 | K16: Eleve | L16: 46017 | M16: =IF(K16="Critique","Transfert immediat + mentoring",IF(H16<0.6,"Programme 12 mois","Suivi semestriel")) -> Programme 12 mois
... A24: SUC-020 | B24: Ingenieur calcul structures | C24: Istres (13) | D24: EMP-050 | E24: Eleve | F24: BONNET Stephanie | G24: EMP-027 | H24: 0.66 | I24: EMP-031 | J24: 0.41 | K24: Critique | L24: 45878 | M24: =IF(K24="Critique","Transfert immediat + mentoring",IF(H24<0.6,"Programme 12 mois","Suivi semestriel")) -> Transfert immediat + mentoring

Sheet 07_PLAN_FORMATION
A1: Plan de formation
A2: Actions de montee en competences deduites des gaps prioritaires
A4: ID Plan | B4: Competence | C4: Employe ID | D4: Employe | E4: Site | F4: Priorite | G4: Date session | H4: Duree j | I4: Niv actuel | J4: Niv cible | K4: Modalite | L4: Organisme | M4: Budget prevu | N4: Budget engage | O4: Manager | P4: Cout complet | Q4: Resultat | R4: Rappel | S4: Statut
A5: PF-0001 | B5: Soudure TIG aeronautique | C5: EMP-001 | D5: DUPONT Jean-Marc | E5: Villaroche (77) | F5: Important | G5: 46333 | H5: 3 | I5: 3 | J5: 4 | K5: Coaching | L5: Academie interne | M5: 2767 | N5: =IF(S5="Realise",M5,IF(S5="En cours",M5*0.6,IF(S5="Planifie",M5*0.3,0))) -> 830.1 | O5: =IFERROR(VLOOKUP(C5,'03_ANNUAIRE'!A:I,9,FALSE),"") -> 0 | P5: =M5+ROUND(M5*0.15,0) -> 3182 | Q5: =IF(S5="Realise","A reevaluer",IF(S5="En cours","Progression","En attente")) -> En attente | R5: =IF(G5<TODAY(),"Echeance depassee","A suivre") -> A suivre | S5: Planifie
A6: PF-0002 | B6: Ressuage PT Niveau 2 | C6: EMP-001 | D6: DUPONT Jean-Marc | E6: Villaroche (77) | F6: Important | G6: 46190 | H6: 3 | I6: 1 | J6: 2 | K6: Compagnonnage | L6: Academie interne | M6: 2335 | N6: =IF(S6="Realise",M6,IF(S6="En cours",M6*0.6,IF(S6="Planifie",M6*0.3,0))) -> 700.5 | O6: =IFERROR(VLOOKUP(C6,'03_ANNUAIRE'!A:I,9,FALSE),"") -> 0 | P6: =M6+ROUND(M6*0.15,0) -> 2685 | Q6: =IF(S6="Realise","A reevaluer",IF(S6="En cours","Progression","En attente")) -> En attente | R6: =IF(G6<TODAY(),"Echeance depassee","A suivre") -> A suivre | S6: Planifie
A7: PF-0003 | B7: Magnetoscopie MT Niveau 2 | C7: EMP-003 | D7: BERNARD Thomas | E7: Chatellerault (86) | F7: Important | G7: 46250 | H7: 3 | I7: 3 | J7: 4 | K7: Formation interne | L7: Academie interne | M7: 2587 | N7: =IF(S7="Realise",M7,IF(S7="En cours",M7*0.6,IF(S7="Planifie",M7*0.3,0))) -> 0 | O7: =IFERROR(VLOOKUP(C7,'03_ANNUAIRE'!A:I,9,FALSE),"") -> EMP-001 | P7: =M7+ROUND(M7*0.15,0) -> 2975 | Q7: =IF(S7="Realise","A reevaluer",IF(S7="En cours","Progression","En attente")) -> En attente | R7: =IF(G7<TODAY(),"Echeance depassee","A suivre") -> A suivre | S7: A planifier
A8: PF-0004 | B8: Radiographie RT Niveau 2 | C8: EMP-003 | D8: BERNARD Thomas | E8: Chatellerault (86) | F8: Important | G8: 46271 | H8: 3 | I8: 2 | J8: 3 | K8: Formation interne | L8: Academie interne | M8: 3125 | N8: =IF(S8="Realise",M8,IF(S8="En cours",M8*0.6,IF(S8="Planifie",M8*0.3,0))) -> 0 | O8: =IFERROR(VLOOKUP(C8,'03_ANNUAIRE'!A:I,9,FALSE),"") -> EMP-001 | P8: =M8+ROUND(M8*0.15,0) -> 3594 | Q8: =IF(S8="Realise","A reevaluer",IF(S8="En cours","Progression","En attente")) -> En attente | R8: =IF(G8<TODAY(),"Echeance depassee","A suivre") -> A suivre | S8: A planifier
A9: PF-0005 | B9: First Article Inspection FAI | C9: EMP-003 | D9: BERNARD Thomas | E9: Chatellerault (86) | F9: Important | G9: 46346 | H9: 3 | I9: 1 | J9: 2 | K9: Coaching | L9: Academie interne | M9: 2158 | N9: =IF(S9="Realise",M9,IF(S9="En cours",M9*0.6,IF(S9="Planifie",M9*0.3,0))) -> 1294.8 | O9: =IFERROR(VLOOKUP(C9,'03_ANNUAIRE'!A:I,9,FALSE),"") -> EMP-001 | P9: =M9+ROUND(M9*0.15,0) -> 2482 | Q9: =IF(S9="Realise","A reevaluer",IF(S9="En cours","Progression","En attente")) -> Progression | R9: =IF(G9<TODAY(),"Echeance depassee","A suivre") -> A suivre | S9: En cours
A10: PF-0006 | B10: Ultrasons UT Niveau 2 | C10: EMP-004 | D10: PETIT Nicolas | E10: Bordes (64) | F10: Important | G10: 46173 | H10: 3 | I10: 4 | J10: 5 | K10: Compagnonnage | L10: Academie interne | M10: 3138 | N10: =IF(S10="Realise",M10,IF(S10="En cours",M10*0.6,IF(S10="Planifie",M10*0.3,0))) -> 1882.8 | O10: =IFERROR(VLOOKUP(C10,'03_ANNUAIRE'!A:I,9,FALSE),"") -> EMP-001 | P10: =M10+ROUND(M10*0.15,0) -> 3609 | Q10: =IF(S10="Realise","A reevaluer",IF(S10="En cours","Progression","En attente")) -> Progression | R10: =IF(G10<TODAY(),"Echeance depassee","A suivre") -> A suivre | S10: En cours
A11: PF-0007 | B11: Tournage CN | C11: EMP-006 | D11: RICHARD Antoine | E11: Villaroche (77) | F11: Important | G11: 46175 | H11: 3 | I11: 2 | J11: 3 | K11: Coaching | L11: Academie interne | M11: 2758 | N11: =IF(S11="Realise",M11,IF(S11="En cours",M11*0.6,IF(S11="Planifie",M11*0.3,0))) -> 0 | O11: =IFERROR(VLOOKUP(C11,'03_ANNUAIRE'!A:I,9,FALSE),"") -> EMP-006 | P11: =M11+ROUND(M11*0.15,0) -> 3172 | Q11: =IF(S11="Realise","A reevaluer",IF(S11="En cours","Progression","En attente")) -> En attente | R11: =IF(G11<TODAY(),"Echeance depassee","A suivre") -> A suivre | S11: A planifier
A12: PF-0008 | B12: Programmation FAO CATIA Mfg | C12: EMP-006 | D12: RICHARD Antoine | E12: Villaroche (77) | F12: Important | G12: 46151 | H12: 3 | I12: 1 | J12: 2 | K12: Formation interne | L12: Academie interne | M12: 2633 | N12: =IF(S12="Realise",M12,IF(S12="En cours",M12*0.6,IF(S12="Planifie",M12*0.3,0))) -> 2633 | O12: =IFERROR(VLOOKUP(C12,'03_ANNUAIRE'!A:I,9,FALSE),"") -> EMP-006 | P12: =M12+ROUND(M12*0.15,0) -> 3028 | Q12: =IF(S12="Realise","A reevaluer",IF(S12="En cours","Progression","En attente")) -> A reevaluer | R12: =IF(G12<TODAY(),"Echeance depassee","A suivre") -> A suivre | S12: Realise
A13: PF-0009 | B13: Traitement thermique aero | C13: EMP-007 | D13: DURAND Sebastien | E13: Gennevilliers (92) | F13: Important | G13: 46249 | H13: 3 | I13: 3 | J13: 4 | K13: Compagnonnage | L13: Academie interne | M13: 2562 | N13: =IF(S13="Realise",M13,IF(S13="En cours",M13*0.6,IF(S13="Planifie",M13*0.3,0))) -> 768.6 | O13: =IFERROR(VLOOKUP(C13,'03_ANNUAIRE'!A:I,9,FALSE),"") -> EMP-006 | P13: =M13+ROUND(M13*0.15,0) -> 2946 | Q13: =IF(S13="Realise","A reevaluer",IF(S13="En cours","Progression","En attente")) -> En attente | R13: =IF(G13<TODAY(),"Echeance depassee","A suivre") -> A suivre | S13: Planifie
A14: PF-0010 | B14: Shot peening controle | C14: EMP-008 | D14: MOREAU Francois | E14: Chatellerault (86) | F14: Important | G14: 46147 | H14: 3 | I14: 2 | J14: 3 | K14: Compagnonnage | L14: Academie interne | M14: 2509 | N14: =IF(S14="Realise",M14,IF(S14="En cours",M14*0.6,IF(S14="Planifie",M14*0.3,0))) -> 2509 | O14: =IFERROR(VLOOKUP(C14,'03_ANNUAIRE'!A:I,9,FALSE),"") -> EMP-006 | P14: =M14+ROUND(M14*0.15,0) -> 2885 | Q14: =IF(S14="Realise","A reevaluer",IF(S14="En cours","Progression","En attente")) -> A reevaluer | R14: =IF(G14<TODAY(),"Echeance depassee","A suivre") -> A suivre | S14: Realise
A15: PF-0011 | B15: Lean Manufacturing / 6 Sigma | C15: EMP-015 | D15: DAVID Frederic | E15: Istres (13) | F15: Important | G15: 46241 | H15: 3 | I15: 2 | J15: 3 | K15: Formation interne | L15: Academie interne | M15: 3203 | N15: =IF(S15="Realise",M15,IF(S15="En cours",M15*0.6,IF(S15="Planifie",M15*0.3,0))) -> 0 | O15: =IFERROR(VLOOKUP(C15,'03_ANNUAIRE'!A:I,9,FALSE),"") -> EMP-011 | P15: =M15+ROUND(M15*0.15,0) -> 3683 | Q15: =IF(S15="Realise","A reevaluer",IF(S15="En cours","Progression","En attente")) -> En attente | R15: =IF(G15<TODAY(),"Echeance depassee","A suivre") -> A suivre | S15: A planifier
A16: PF-0012 | B16: Tournage CN | C16: EMP-016 | D16: BERTRAND Olivier | E16: Villaroche (77) | F16: Important | G16: 46154 | H16: 3 | I16: 2 | J16: 3 | K16: Formation interne | L16: Academie interne | M16: 2534 | N16: =IF(S16="Realise",M16,IF(S16="En cours",M16*0.6,IF(S16="Planifie",M16*0.3,0))) -> 760.2 | O16: =IFERROR(VLOOKUP(C16,'03_ANNUAIRE'!A:I,9,FALSE),"") -> EMP-016 | P16: =M16+ROUND(M16*0.15,0) -> 2914 | Q16: =IF(S16="Realise","A reevaluer",IF(S16="En cours","Progression","En attente")) -> En attente | R16: =IF(G16<TODAY(),"Echeance depassee","A suivre") -> A suivre | S16: Planifie
... A56: PF-0052 | B56: AMDEC/FMEA aeronautique | C56: EMP-055 | D56: BLANC Lucie | E56: Istres (13) | F56: Important | G56: 46164 | H56: 3 | I56: 2 | J56: 3 | K56: Coaching | L56: Academie interne | M56: 2200 | N56: =IF(S56="Realise",M56,IF(S56="En cours",M56*0.6,IF(S56="Planifie",M56*0.3,0))) -> 660 | O56: =IFERROR(VLOOKUP(C56,'03_ANNUAIRE'!A:I,9,FALSE),"") -> EMP-051 | P56: =M56+ROUND(M56*0.15,0) -> 2530 | Q56: =IF(S56="Realise","A reevaluer",IF(S56="En cours","Progression","En attente")) -> En attente | R56: =IF(G56<TODAY(),"Echeance depassee","A suivre") -> A suivre | S56: Planifie

Sheet 08_BUDGET
A1: Budget formation
A2: Pilotage budgetaire par site et categorie
