Workbook
Name ANNEE_REF: '01_PARAMETRES'!$C$8
Name DEVISE_REF: '01_PARAMETRES'!$C$7
Name TX_CHF: '01_PARAMETRES'!$C$34
Name TX_GBP: '01_PARAMETRES'!$C$35
Name TX_JPY: '01_PARAMETRES'!$C$36
Name TX_USD: '01_PARAMETRES'!$C$33

Sheet 01_PARAMETRES
B1: ⚙️ NEURAL — LuxeCompBenchmark · Paramètres Généraux
B2: Configuration globale · Devises · Niveaux · Conventions collectives
B4: ▌ SECTION A — CONFIGURATION GÉNÉRALE
B5: Paramètre | C5: Valeur (saisie) | D5: Info
B6: Maison / Groupe | D6: Hermès / LVMH / Kering / Richemont / Chanel / Cartier / Boucheron / Van Cleef / Dior / Berluti / Personnalisé
B7: Devise de référence | D7: EUR / USD / CHF / GBP / JPY / CNY
B8: Année de référence | C8: 2026 | D8: Année N pour les projections
B9: Convention collective | D9: Bijouterie-Joaillerie / Couture / Maroquinerie / Horlogerie / Commerce détail
B10: Pays siège | D10: FR / IT / CH / GB / US / JP / HK
B11: Périmètre analyse | D11: France seul / Multi-pays / Global
B12: Date d'analyse | C12: =TODAY() -> 46113
B13: Analyste NEURAL
B16: ▌ SECTION B — GRILLE DE NIVEAUX HIÉRARCHIQUES
B17: Code Niveau | C17: Intitulé | D17: Expérience type | E17: Grade HRIS
B18: N1 | C18: Apprenti / Stagiaire | D18: 0-1 an | E18: Grade 1
B19: N2 | C19: Artisan Junior | D19: < 3 ans | E19: Grade 2
B20: N3 | C20: Artisan Confirmé | D20: 3-7 ans | E20: Grade 3
B21: N4 | C21: Artisan Senior / Chef adj. | D21: 7-12 ans | E21: Grade 4
B22: N5 | C22: Maître Artisan / Chef atelier | D22: 12-20 ans | E22: Grade 5
B23: N6 | C23: Directeur atelier / Maître d'Art | D23: 20+ ans | E23: Grade 6
B24: N7 | C24: Directeur création artisanale | D24: Expert total | E24: Grade 7
B25: M1 | C25: Manager opérationnel | D25: 5-10 ans | E25: M-Grade 1
B26: M2 | C26: Directeur de département | D26: 10-15 ans | E26: M-Grade 2
B27: M3 | C27: VP / Directeur régional | D27: 15+ ans | E27: M-Grade 3
B28: M4 | C28: C-Level / Comex | D28: 20+ ans | E28: M-Grade 4
B31: ▌ SECTION C — TAUX DE CHANGE (vers EUR)
B32: Paire | C32: Taux (saisie) | D32: Inverse | E32: Source / Date
B33: EUR/USD | C33: 1.085 | D33: =IFERROR(1/C33,"—") -> 0.92165899 | E33: BCE / Banque Nationale Suisse — Source: simul. NEURAL
B34: EUR/CHF | C34: 0.942 | D34: =IFERROR(1/C34,"—") -> 1.0615711 | E34: BCE / Banque Nationale Suisse — Source: simul. NEURAL
B35: EUR/GBP | C35: 0.856 | D35: =IFERROR(1/C35,"—") -> 1.1682243 | E35: BCE / Banque Nationale Suisse — Source: simul. NEURAL
B36: EUR/JPY | C36: 163.5 | D36: =IFERROR(1/C36,"—") -> 0.006116208 | E36: BCE / Banque Nationale Suisse — Source: simul. NEURAL
B37: EUR/CNY | C37: 7.82 | D37: =IFERROR(1/C37,"—") -> 0.12787724 | E37: BCE / Banque Nationale Suisse — Source: simul. NEURAL
B38: EUR/HKD | C38: 8.47 | D38: =IFERROR(1/C38,"—") -> 0.11806375 | E38: BCE / Banque Nationale Suisse — Source: simul. NEURAL
B39: EUR/AED | C39: 3.985 | D39: =IFERROR(1/C39,"—") -> 0.25094103 | E39: BCE / Banque Nationale Suisse — Source: simul. NEURAL
B42: ▌ SECTION D — PAYS ANALYSÉS & CONTEXTE LÉGAL
B43: Code pays | C43: Pays | D43: Devise locale | E43: Charges patron. moy.
B44: FR | C44: France | D44: EUR | E44: ~45%
B45: IT | C45: Italie | D45: EUR | E45: ~40%
B46: CH | C46: Suisse | D46: CHF | E46: ~13%
B47: GB | C47: Royaume-Uni | D47: GBP | E47: ~15%
...

Sheet 02_GRILLE_REMUNERATION
B1: 📋 NEURAL — GRILLE_REMUNERATION · Salaires par Métier × Niveau × Pays
B2: Grille salariale de référence · Compa-ratio automatique · Conversion multi-devises
B4: ▌ FILTRES ACTIFS — Pays / Famille Métier / Niveau
B5: Pays | C5: Tous | D5: Famille métier | E5: Tous | F5: Niveau | G5: Tous
B7: ID Métier | C7: Famille | D7: Niv. | E7: Pays | F7: Base brut annuel | G7: Variable cible % | H7: Base + Variable | I7: Total cash | J7: Compa- ratio | K7: Statut marché
B8: M01 | C8: Maroquinerie | D8: N2 | E8: FR | F8: 28000 | G8: 0 | H8: =F8*(1+G8) -> 28000 | I8: =H8 -> 28000 | J8: =IFERROR(F8/25000,1) -> 1.12 | K8: =IF(J8>1.1,"🔴 Surpayé",IF(J8>=0.95,"🟢 Dans cible",IF(J8>=0.85,"🟡 Sous-payé léger","🔴 Risque rétention"))) -> 🔴 Surpayé
B9: M01 | C9: Maroquinerie | D9: N3 | E9: FR | F9: 38000 | G9: 0.05 | H9: =F9*(1+G9) -> 39900 | I9: =H9 -> 39900 | J9: =IFERROR(F9/38000,1) -> 1 | K9: =IF(J9>1.1,"🔴 Surpayé",IF(J9>=0.95,"🟢 Dans cible",IF(J9>=0.85,"🟡 Sous-payé léger","🔴 Risque rétention"))) -> 🟢 Dans cible
B10: M01 | C10: Maroquinerie | D10: N4 | E10: FR | F10: 48000 | G10: 0.08 | H10: =F10*(1+G10) -> 51840 | I10: =H10 -> 51840 | J10: =IFERROR(F10/50000,1) -> 0.96 | K10: =IF(J10>1.1,"🔴 Surpayé",IF(J10>=0.95,"🟢 Dans cible",IF(J10>=0.85,"🟡 Sous-payé léger","🔴 Risque rétention"))) -> 🟢 Dans cible
B11: M01 | C11: Maroquinerie | D11: N5 | E11: FR | F11: 62000 | G11: 0.1 | H11: =F11*(1+G11) -> 68200 | I11: =H11 -> 68200 | J11: =IFERROR(F11/60000,1) -> 1.0333333 | K11: =IF(J11>1.1,"🔴 Surpayé",IF(J11>=0.95,"🟢 Dans cible",IF(J11>=0.85,"🟡 Sous-payé léger","🔴 Risque rétention"))) -> 🟢 Dans cible
B12: M01 | C12: Maroquinerie | D12: N6 | E12: FR | F12: 82000 | G12: 0.12 | H12: =F12*(1+G12) -> 91840 | I12: =H12 -> 91840 | J12: =IFERROR(F12/80000,1) -> 1.025 | K12: =IF(J12>1.1,"🔴 Surpayé",IF(J12>=0.95,"🟢 Dans cible",IF(J12>=0.85,"🟡 Sous-payé léger","🔴 Risque rétention"))) -> 🟢 Dans cible
B13: M01 | C13: Maroquinerie | D13: N3 | E13: IT | F13: 34500 | G13: 0.05 | H13: =F13*(1+G13) -> 36225 | I13: =H13 -> 36225 | J13: =IFERROR(F13/33000,1) -> 1.0454545 | K13: =IF(J13>1.1,"🔴 Surpayé",IF(J13>=0.95,"🟢 Dans cible",IF(J13>=0.85,"🟡 Sous-payé léger","🔴 Risque rétention"))) -> 🟢 Dans cible
B14: M01 | C14: Maroquinerie | D14: N4 | E14: IT | F14: 44000 | G14: 0.08 | H14: =F14*(1+G14) -> 47520 | I14: =H14 -> 47520 | J14: =IFERROR(F14/44000,1) -> 1 | K14: =IF(J14>1.1,"🔴 Surpayé",IF(J14>=0.95,"🟢 Dans cible",IF(J14>=0.85,"🟡 Sous-payé léger","🔴 Risque rétention"))) -> 🟢 Dans cible
B15: M01 | C15: Maroquinerie | D15: N5 | E15: IT | F15: 56000 | G15: 0.1 | H15: =F15*(1+G15) -> 61600 | I15: =H15 -> 61600 | J15: =IFERROR(F15/56000,1) -> 1 | K15: =IF(J15>1.1,"🔴 Surpayé",IF(J15>=0.95,"🟢 Dans cible",IF(J15>=0.85,"🟡 Sous-payé léger","🔴 Risque rétention"))) -> 🟢 Dans cible
B16: M01 | C16: Maroquinerie | D16: N3 | E16: CH | F16: 62000 | G16: 0.08 | H16: =F16*(1+G16) -> 66960 | I16: =H16 -> 66960 | J16: =IFERROR(F16/64000,1) -> 0.96875 | K16: =IF(J16>1.1,"🔴 Surpayé",IF(J16>=0.95,"🟢 Dans cible",IF(J16>=0.85,"🟡 Sous-payé léger","🔴 Risque rétention"))) -> 🟢 Dans cible
B17: M01 | C17: Maroquinerie | D17: N4 | E17: CH | F17: 78000 | G17: 0.1 | H17: =F17*(1+G17) -> 85800 | I17: =H17 -> 85800 | J17: =IFERROR(F17/82000,1) -> 0.95121951 | K17: =IF(J17>1.1,"🔴 Surpayé",IF(J17>=0.95,"🟢 Dans cible",IF(J17>=0.85,"🟡 Sous-payé léger","🔴 Risque rétention"))) -> 🟢 Dans cible
B18: M01 | C18: Maroquinerie | D18: N5 | E18: CH | F18: 98000 | G18: 0.12 | H18: =F18*(1+G18) -> 109760 | I18: =H18 -> 109760 | J18: =IFERROR(F18/100000,1) -> 0.98 | K18: =IF(J18>1.1,"🔴 Surpayé",IF(J18>=0.95,"🟢 Dans cible",IF(J18>=0.85,"🟡 Sous-payé léger","🔴 Risque rétention"))) -> 🟢 Dans cible
B19: M05 | C19: Joaillerie | D19: N3 | E19: FR | F19: 44000 | G19: 0.05 | H19: =F19*(1+G19) -> 46200 | I19: =H19 -> 46200 | J19: =IFERROR(F19/44000,1) -> 1 | K19: =IF(J19>1.1,"🔴 Surpayé",IF(J19>=0.95,"🟢 Dans cible",IF(J19>=0.85,"🟡 Sous-payé léger","🔴 Risque rétention"))) -> 🟢 Dans cible
B20: M05 | C20: Joaillerie | D20: N4 | E20: FR | F20: 56000 | G20: 0.08 | H20: =F20*(1+G20) -> 60480 | I20: =H20 -> 60480 | J20: =IFERROR(F20/58000,1) -> 0.96551724 | K20: =IF(J20>1.1,"🔴 Surpayé",IF(J20>=0.95,"🟢 Dans cible",IF(J20>=0.85,"🟡 Sous-payé léger","🔴 Risque rétention"))) -> 🟢 Dans cible
B21: M05 | C21: Joaillerie | D21: N5 | E21: FR | F21: 72000 | G21: 0.1 | H21: =F21*(1+G21) -> 79200 | I21: =H21 -> 79200 | J21: =IFERROR(F21/74000,1) -> 0.97297297 | K21: =IF(J21>1.1,"🔴 Surpayé",IF(J21>=0.95,"🟢 Dans cible",IF(J21>=0.85,"🟡 Sous-payé léger","🔴 Risque rétention"))) -> 🟢 Dans cible
B22: M05 | C22: Joaillerie | D22: N6 | E22: FR | F22: 95000 | G22: 0.12 | H22: =F22*(1+G22) -> 106400 | I22: =H22 -> 106400 | J22: =IFERROR(F22/97000,1) -> 0.97938144 | K22: =IF(J22>1.1,"🔴 Surpayé",IF(J22>=0.95,"🟢 Dans cible",IF(J22>=0.85,"🟡 Sous-payé léger","🔴 Risque rétention"))) -> 🟢 Dans cible
B23: M05 | C23: Joaillerie | D23: N4 | E23: CH | F23: 88000 | G23: 0.1 | H23: =F23*(1+G23) -> 96800 | I23: =H23 -> 96800 | J23: =IFERROR(F23/90000,1) -> 0.97777778 | K23: =IF(J23>1.1,"🔴 Surpayé",IF(J23>=0.95,"🟢 Dans cible",IF(J23>=0.85,"🟡 Sous-payé léger","🔴 Risque rétention"))) -> 🟢 Dans cible
B24: M05 | C24: Joaillerie | D24: N5 | E24: CH | F24: 115000 | G24: 0.12 | H24: =F24*(1+G24) -> 128800 | I24: =H24 -> 128800 | J24: =IFERROR(F24/118000,1) -> 0.97457627 | K24: =IF(J24>1.1,"🔴 Surpayé",IF(J24>=0.95,"🟢 Dans cible",IF(J24>=0.85,"🟡 Sous-payé léger","🔴 Risque rétention"))) -> 🟢 Dans cible
B25: M07 | C25: Joaillerie | D25: N5 | E25: FR | F25: 85000 | G25: 0.1 | H25: =F25*(1+G25) -> 93500 | I25: =H25 -> 93500 | J25: =IFERROR(F25/87000,1) -> 0.97701149 | K25: =IF(J25>1.1,"🔴 Surpayé",IF(J25>=0.95,"🟢 Dans cible",IF(J25>=0.85,"🟡 Sous-payé léger","🔴 Risque rétention"))) -> 🟢 Dans cible
B26: M07 | C26: Joaillerie | D26: N6 | E26: FR | F26: 110000 | G26: 0.12 | H26: =F26*(1+G26) -> 123200 | I26: =H26 -> 123200 | J26: =IFERROR(F26/112000,1) -> 0.98214286 | K26: =IF(J26>1.1,"🔴 Surpayé",IF(J26>=0.95,"🟢 Dans cible",IF(J26>=0.85,"🟡 Sous-payé léger","🔴 Risque rétention"))) -> 🟢 Dans cible
B27: M07 | C27: Joaillerie | D27: N5 | E27: CH | F27: 130000 | G27: 0.12 | H27: =F27*(1+G27) -> 145600 | I27: =H27 -> 145600 | J27: =IFERROR(F27/133000,1) -> 0.97744361 | K27: =IF(J27>1.1,"🔴 Surpayé",IF(J27>=0.95,"🟢 Dans cible",IF(J27>=0.85,"🟡 Sous-payé léger","🔴 Risque rétention"))) -> 🟢 Dans cible
B28: M09 | C28: Joaillerie | D28: N5 | E28: CH | F28: 135000 | G28: 0.12 | H28: =F28*(1+G28) -> 151200 | I28: =H28 -> 151200 | J28: =IFERROR(F28/138000,1) -> 0.97826087 | K28: =IF(J28>1.1,"🔴 Surpayé",IF(J28>=0.95,"🟢 Dans cible",IF(J28>=0.85,"🟡 Sous-payé léger","🔴 Risque rétention"))) -> 🟢 Dans cible
B29: M09 | C29: Joaillerie | D29: N6 | E29: CH | F29: 165000 | G29: 0.15 | H29: =F29*(1+G29) -> 189750 | I29: =H29 -> 189750 | J29: =IFERROR(F29/168000,1) -> 0.98214286 | K29: =IF(J29>1.1,"🔴 Surpayé",IF(J29>=0.95,"🟢 Dans cible",IF(J29>=0.85,"🟡 Sous-payé léger","🔴 Risque rétention"))) -> 🟢 Dans cible
B30: M10 | C30: Horlogerie | D30: N3 | E30: CH | F30: 68000 | G30: 0.08 | H30: =F30*(1+G30) -> 73440 | I30: =H30 -> 73440 | J30: =IFERROR(F30/70000,1) -> 0.97142857 | K30: =IF(J30>1.1,"🔴 Surpayé",IF(J30>=0.95,"🟢 Dans cible",IF(J30>=0.85,"🟡 Sous-payé léger","🔴 Risque rétention"))) -> 🟢 Dans cible
B31: M10 | C31: Horlogerie | D31: N4 | E31: CH | F31: 88000 | G31: 0.1 | H31: =F31*(1+G31) -> 96800 | I31: =H31 -> 96800 | J31: =IFERROR(F31/90000,1) -> 0.97777778 | K31: =IF(J31>1.1,"🔴 Surpayé",IF(J31>=0.95,"🟢 Dans cible",IF(J31>=0.85,"🟡 Sous-payé léger","🔴 Risque rétention"))) -> 🟢 Dans cible
B32: M10 | C32: Horlogerie | D32: N5 | E32: CH | F32: 115000 | G32: 0.12 | H32: =F32*(1+G32) -> 128800 | I32: =H32 -> 128800 | J32: =IFERROR(F32/118000,1) -> 0.97457627 | K32: =IF(J32>1.1,"🔴 Surpayé",IF(J32>=0.95,"🟢 Dans cible",IF(J32>=0.85,"🟡 Sous-payé léger","🔴 Risque rétention"))) -> 🟢 Dans cible
B33: M10 | C33: Horlogerie | D33: N3 | E33: FR | F33: 42000 | G33: 0.05 | H33: =F33*(1+G33) -> 44100 | I33: =H33 -> 44100 | J33: =IFERROR(F33/43000,1) -> 0.97674419 | K33: =IF(J33>1.1,"🔴 Surpayé",IF(J33>=0.95,"🟢 Dans cible",IF(J33>=0.85,"🟡 Sous-payé léger","🔴 Risque rétention"))) -> 🟢 Dans cible
B34: M10 | C34: Horlogerie | D34: N4 | E34: FR | F34: 54000 | G34: 0.08 | H34: =F34*(1+G34) -> 58320 | I34: =H34 -> 58320 | J34: =IFERROR(F34/55000,1) -> 0.98181818 | K34: =IF(J34>1.1,"🔴 Surpayé",IF(J34>=0.95,"🟢 Dans cible",IF(J34>=0.85,"🟡 Sous-payé léger","🔴 Risque rétention"))) -> 🟢 Dans cible
B35: M12 | C35: Horlogerie | D35: N5 | E35: CH | F35: 140000 | G35: 0.12 | H35: =F35*(1+G35) -> 156800 | I35: =H35 -> 156800 | J35: =IFERROR(F35/143000,1) -> 0.97902098 | K35: =IF(J35>1.1,"🔴 Surpayé",IF(J35>=0.95,"🟢 Dans cible",IF(J35>=0.85,"🟡 Sous-payé léger","🔴 Risque rétention"))) -> 🟢 Dans cible
B36: M12 | C36: Horlogerie | D36: N6 | E36: CH | F36: 175000 | G36: 0.15 | H36: =F36*(1+G36) -> 201250 | I36: =H36 -> 201250 | J36: =IFERROR(F36/178000,1) -> 0.98314607 | K36: =IF(J36>1.1,"🔴 Surpayé",IF(J36>=0.95,"🟢 Dans cible",IF(J36>=0.85,"🟡 Sous-payé léger","🔴 Risque rétention"))) -> 🟢 Dans cible
B37: M13 | C37: Couture | D37: N3 | E37: FR | F37: 40000 | G37: 0.05 | H37: =F37*(1+G37) -> 42000 | I37: =H37 -> 42000 | J37: =IFERROR(F37/40000,1) -> 1 | K37: =IF(J37>1.1,"🔴 Surpayé",IF(J37>=0.95,"🟢 Dans cible",IF(J37>=0.85,"🟡 Sous-payé léger","🔴 Risque rétention"))) -> 🟢 Dans cible
B38: M13 | C38: Couture | D38: N4 | E38: FR | F38: 52000 | G38: 0.08 | H38: =F38*(1+G38) -> 56160 | I38: =H38 -> 56160 | J38: =IFERROR(F38/54000,1) -> 0.96296296 | K38: =IF(J38>1.1,"🔴 Surpayé",IF(J38>=0.95,"🟢 Dans cible",IF(J38>=0.85,"🟡 Sous-payé léger","🔴 Risque rétention"))) -> 🟢 Dans cible
B39: M13 | C39: Couture | D39: N5 | E39: FR | F39: 68000 | G39: 0.1 | H39: =F39*(1+G39) -> 74800 | I39: =H39 -> 74800 | J39: =IFERROR(F39/70000,1) -> 0.97142857 | K39: =IF(J39>1.1,"🔴 Surpayé",IF(J39>=0.95,"🟢 Dans cible",IF(J39>=0.85,"🟡 Sous-payé léger","🔴 Risque rétention"))) -> 🟢 Dans cible
B40: M13 | C40: Couture | D40: N6 | E40: FR | F40: 90000 | G40: 0.12 | H40: =F40*(1+G40) -> 100800 | I40: =H40 -> 100800 | J40: =IFERROR(F40/92000,1) -> 0.97826087 | K40: =IF(J40>1.1,"🔴 Surpayé",IF(J40>=0.95,"🟢 Dans cible",IF(J40>=0.85,"🟡 Sous-payé léger","🔴 Risque rétention"))) -> 🟢 Dans cible
B41: M14 | C41: Couture | D41: N5 | E41: FR | F41: 78000 | G41: 0.1 | H41: =F41*(1+G41) -> 85800 | I41: =H41 -> 85800 | J41: =IFERROR(F41/80000,1) -> 0.975 | K41: =IF(J41>1.1,"🔴 Surpayé",IF(J41>=0.95,"🟢 Dans cible",IF(J41>=0.85,"🟡 Sous-payé léger","🔴 Risque rétention"))) -> 🟢 Dans cible
B42: M14 | C42: Couture | D42: N6 | E42: FR | F42: 105000 | G42: 0.12 | H42: =F42*(1+G42) -> 117600 | I42: =H42 -> 117600 | J42: =IFERROR(F42/107000,1) -> 0.98130841 | K42: =IF(J42>1.1,"🔴 Surpayé",IF(J42>=0.95,"🟢 Dans cible",IF(J42>=0.85,"🟡 Sous-payé léger","🔴 Risque rétention"))) -> 🟢 Dans cible
...

Sheet 03_BENCHMARK_MARCHE
B1: 📋 NEURAL — BENCHMARK_MARCHÉ · Données P25 / P50 / P75 / P90 par Métier
B2: Sources : Robert Half Luxe · Hays Luxury · Willis Towers Watson · Comité Colbert — Données simulées NEURAL
B4: ▌ SÉLECTEUR — Métier & Pays pour visualisation Box Plot
B5: Métier affiché | C5: M01 | D5: Pays | E5: FR | F5: Année | G5: 2026
B7: ID Métier | C7: Famille | D7: Niv. | E7: Pays | F7: P25 (€) | G7: P50 Médiane (€) | H7: P75 (€) | I7: P90 (€) | J7: Trend YoY | K7: Source
B8: M01 | C8: Maroquinerie | D8: N2 | E8: FR | F8: 22000 | G8: 25000 | H8: 30000 | I8: 36000 | J8: +2.5% | K8: Robert Half Luxe 2025
B9: M01 | C9: Maroquinerie | D9: N3 | E9: FR | F9: 32000 | G9: 38000 | H9: 44000 | I9: 52000 | J9: +3.5% | K9: Robert Half Luxe 2025
B10: M01 | C10: Maroquinerie | D10: N4 | E10: FR | F10: 42000 | G10: 50000 | H10: 58000 | I10: 68000 | J10: +4.0% | K10: Hays Luxury 2025
B11: M01 | C11: Maroquinerie | D11: N5 | E11: FR | F11: 52000 | G11: 62000 | H11: 74000 | I11: 88000 | J11: +4.5% | K11: WTW Luxury Report
B12: M01 | C12: Maroquinerie | D12: N6 | E12: FR | F12: 66000 | G12: 80000 | H12: 96000 | I12: 115000 | J12: +5.0% | K12: WTW Luxury Report
B13: M01 | C13: Maroquinerie | D13: N3 | E13: IT | F13: 27000 | G13: 33000 | H13: 39000 | I13: 46000 | J13: +2.8% | K13: Hays Italy 2025
B14: M01 | C14: Maroquinerie | D14: N4 | E14: IT | F14: 36000 | G14: 44000 | H14: 52000 | I14: 62000 | J14: +3.2% | K14: Hays Italy 2025
B15: M01 | C15: Maroquinerie | D15: N5 | E15: IT | F15: 46000 | G15: 56000 | H15: 66000 | I15: 78000 | J15: +3.8% | K15: Michael Page IT
B16: M01 | C16: Maroquinerie | D16: N3 | E16: CH | F16: 55000 | G16: 64000 | H16: 75000 | I16: 88000 | J16: +4.1% | K16: Kienbaum CH 2025
B17: M01 | C17: Maroquinerie | D17: N4 | E17: CH | F17: 70000 | G17: 82000 | H17: 96000 | I17: 112000 | J17: +4.5% | K17: Kienbaum CH 2025
B18: M01 | C18: Maroquinerie | D18: N5 | E18: CH | F18: 85000 | G18: 100000 | H18: 118000 | I18: 138000 | J18: +5.0% | K18: WTW Switzerland
B19: M05 | C19: Joaillerie | D19: N3 | E19: FR | F19: 36000 | G19: 44000 | H19: 52000 | I19: 62000 | J19: +4.2% | K19: Robert Half Luxe
... B58: M-MGR | C58: Multi | D58: M4 | E58: CH | F58: 268000 | G58: 325000 | H58: 392000 | I58: 472000 | J58: +5.8% | K58: Korn Ferry CH
B59: MOYENNE MARCHÉ — 51 observations | F59: =AVERAGE(F8:F58) -> 79901.961 | G59: =AVERAGE(G8:G58) -> 95941.176 | H59: =AVERAGE(H8:H58) -> 114686.27 | I59: =AVERAGE(I8:I58) -> 137019.61
B61: ▌ LÉGENDE — Percentiles Marché Luxe
B62: P25 — Zone basse | C62: 25% des salaires sont inférieurs à ce seuil
B63: P50 — Médiane | C63: Référence de marché — Compa-ratio = Salaire / P50
B64: P75 — Zone haute | C64: Top 25% du marché — Objectif packages compétitifs
B65: P90 — Zone premium | C65: Top 10% — Réservé aux talents rares et postes critiques
B67: NEURAL — Intelligence Augmentée pour l'Entreprise · neural-platform.vercel.app · Données simulées à des fins de démonstration

Sheet 04_AVANTAGES_NATURE
B1: 📋 NEURAL — AVANTAGES_NATURE · Valorisation des Avantages Secteur Luxe
B2: Avantages spécifiques maison · Valorisation annuelle · Calcul dynamique par niveau
B4: ▌ FILTRE — Niveau sélectionné (détermine les avantages éligibles)
B5: Niveau collaborateur : | C5: N4 | D5: Maison : | E5: =IF('01_PARAMETRES'!C6="","Non définie",'01_PARAMETRES'!C6) -> Non définie | F5: ⚠️ Les cellules or sont modifiables — Les valeurs s'adaptent au niveau sélectionné | L5: =IFERROR(VLOOKUP(C5,$J$6:$K$16,2,FALSE()),4) -> 4
J6: N1 | K6: 1
B7: Avantage | C7: Niveau min. éligible | D7: Valeur / an estimée (€) | E7: Valeur perçue salarié (€) | F7: Charge patronale (€) | G7: Inclus dans simulateur | H7: Catégorie | J7: N2 | K7: 2
B8: Remise sur produits maison (30-50%) | C8: N1 | D8: 2500 | E8: 2500 | F8: 800 | G8: ✅ | H8: 🎁 Remise employé | J8: N3 | K8: 3
B9: Ventes privées exclusives | C9: N3 | D9: 500 | E9: 500 | F9: 0 | G9: ✅ | H9: 🎁 Remise employé | J9: N4 | K9: 4
B10: Attribution produits iconiques (coût) | C10: N5 | D10: 3000 | E10: 5000 | F10: 0 | G10: ✅ | H10: 🎁 Remise employé | J10: N5 | K10: 5
B11: Défilés & vernissages (invitations) | C11: N4 | D11: 1200 | E11: 1800 | F11: 0 | G11: — | H11: 🎫 Événements | J11: N6 | K11: 6
B12: Events clients VIP | C12: N5 | D12: 800 | E12: 2000 | F12: 0 | G12: — | H12: 🎫 Événements | J12: N7 | K12: 7
B13: Soirées Comité Colbert / ambassadeurs | C13: N6 | D13: 1500 | E13: 4000 | F13: 0 | G13: — | H13: 🎫 Événements | J13: M1 | K13: 8
B14: MOF / EPV préparation & accompagnement | C14: N4 | D14: 5000 | E14: 8000 | F14: 5000 | G14: ✅ | H14: 📚 Formation | J14: M2 | K14: 9
B15: Voyages savoir-faire (IT, JP, etc.) | C15: N5 | D15: 3000 | E15: 5000 | F15: 3000 | G15: ✅ | H15: 📚 Formation | J15: M3 | K15: 10
B16: Masterclass maîtres artisans | C16: N5 | D16: 2000 | E16: 3500 | F16: 2000 | G16: ✅ | H16: 📚 Formation | J16: M4 | K16: 11
B17: Executive Education (HEC, INSEAD) | C17: M2 | D17: 8000 | E17: 12000 | F17: 8000 | G17: ✅ | H17: 📚 Formation
B18: Mutuelle premium (famille) | C18: N1 | D18: 2400 | E18: 3200 | F18: 2400 | G18: ✅ | H18: 🏥 Protection soc.
B19: Prévoyance renforcée | C19: N1 | D19: 1200 | E19: 1800 | F19: 1200 | G19: ✅ | H19: 🏥 Protection soc.
B20: Retraite supplémentaire article 83 | C20: N5 | D20: 3000 | E20: 3000 | F20: 3000 | G20: ✅ | H20: 🏥 Protection soc.
B21: Assurance vie abondée maison | C21: M2 | D21: 4000 | E21: 4000 | F21: 4000 | G21: ✅ | H21: 🏥 Protection soc.
B22: Restaurant d'entreprise / tickets resto | C22: N1 | D22: 1500 | E22: 2200 | F22: 1500 | G22: ✅ | H22: 🏠 Vie quotidienne
B23: CE — activités culturelles & loisirs | C23: N1 | D23: 600 | E23: 900 | F23: 600 | G23: ✅ | H23: 🏠 Vie quotidienne
B24: Transport (pass navigo / voiture) | C24: N1 | D24: 450 | E24: 900 | F24: 450 | G24: ✅ | H24: 🏠 Vie quotidienne
B25: Crèche d'entreprise / CESU garde enfants | C25: N3 | D25: 1800 | E25: 2400 | F25: 1800 | G25: ✅ | H25: 🏠 Vie quotidienne
B26: Intéressement / participation | C26: N1 | D26: 1500 | E26: 1500 | F26: 0 | G26: ✅ | H26: 📈 LTI / Intéressement
B27: Plan d'épargne entreprise (abondement) | C27: N1 | D27: 1200 | E27: 1200 | F27: 1200 | G27: ✅ | H27: 📈 LTI / Intéressement
B28: Stock-options / RSU (valorisation moy.) | C28: M2 | D28: 15000 | E28: 15000 | F28: 0 | G28: ✅ | H28: 📈 LTI / Intéressement
B29: LTI — incentive pluriannuel | C29: M3 | D29: 25000 | E29: 25000 | F29: 0 | G29: ✅ | H29: 📈 LTI / Intéressement
B30: TOTAL AVANTAGES (niveau sélectionné) | C30: =C5 -> N4 | D30: =SUM(D8:D29) -> 85150 | E30: =SUM(E8:E29) -> 105400 | F30: =SUM(F8:F29) -> 34950 | G30: =COUNTIF(G8:G29,"✅") -> 19
B32: ▌ RÉCAPITULATIF PAR CATÉGORIE — Valorisation totale
B33: Catégorie | C33: Nb avantages | D33: Valeur totale / an | E33: Valeur perçue | F33: Charge patron.
B34: 🎁 Remise employé | C34: =COUNTIF($H$8:$H$29,B34) -> 3 | D34: =SUMIF($H$8:$H$29,B34,D$8:D$29) -> 6000 | E34: =SUMIF($H$8:$H$29,B34,E$8:E$29) -> 8000 | F34: =SUMIF($H$8:$H$29,B34,F$8:F$29) -> 800
B35: 🎫 Événements | C35: =COUNTIF($H$8:$H$29,B35) -> 3 | D35: =SUMIF($H$8:$H$29,B35,D$8:D$29) -> 3500 | E35: =SUMIF($H$8:$H$29,B35,E$8:E$29) -> 7800 | F35: =SUMIF($H$8:$H$29,B35,F$8:F$29) -> 0
B36: 📚 Formation | C36: =COUNTIF($H$8:$H$29,B36) -> 4 | D36: =SUMIF($H$8:$H$29,B36,D$8:D$29) -> 18000 | E36: =SUMIF($H$8:$H$29,B36,E$8:E$29) -> 28500 | F36: =SUMIF($H$8:$H$29,B36,F$8:F$29) -> 18000
B37: 🏥 Protection soc. | C37: =COUNTIF($H$8:$H$29,B37) -> 4 | D37: =SUMIF($H$8:$H$29,B37,D$8:D$29) -> 10600 | E37: =SUMIF($H$8:$H$29,B37,E$8:E$29) -> 12000 | F37: =SUMIF($H$8:$H$29,B37,F$8:F$29) -> 10600
B38: 🏠 Vie quotidienne | C38: =COUNTIF($H$8:$H$29,B38) -> 4 | D38: =SUMIF($H$8:$H$29,B38,D$8:D$29) -> 4350 | E38: =SUMIF($H$8:$H$29,B38,E$8:E$29) -> 6400 | F38: =SUMIF($H$8:$H$29,B38,F$8:F$29) -> 4350
B39: 📈 LTI / Intéressement | C39: =COUNTIF($H$8:$H$29,B39) -> 4 | D39: =SUMIF($H$8:$H$29,B39,D$8:D$29) -> 42700 | E39: =SUMIF($H$8:$H$29,B39,E$8:E$29) -> 42700 | F39: =SUMIF($H$8:$H$29,B39,F$8:F$29) -> 1200
B42: NEURAL — Intelligence Augmentée pour l'Entreprise · neural-platform.vercel.app · Données simulées à des fins de démonstration

Sheet 05_PACKAGE_SIMULATION
B1: 💎 NEURAL — PACKAGE_SIMULATION · Coût Complet Artisan Luxe
B2: Simulateur temps réel · Rémunération fixe + variable + avantages + charges · Comparaison multi-pays
B4: ▌ PARAMÈTRES DE SIMULATION — Sélectionnez le profil
B5: Métier ▼ | D5: M01 | E5: Niveau ▼ | G5: N5 | H5: Pays ▼ | J5: FR
B6: Ancienneté (années) | C6: 8 | D6: Convention 13e mois | E6: Oui | F6: Nb enfants (scolarité) | G6: 0 | I6: =IFERROR(INDEX('02_GRILLE_REMUNERATION'!$F$8:$F$57,MATCH(D5&G5&J5,'02_GRILLE_REMUNERATION'!$B$8:$B$57&'02_GRILLE_REMUNERATION'!$D$8:$D$57&'02_GRILLE_REMUNERATION'!$E$8:$E$57,0)),55000) -> 55000 | J6: =IFERROR(INDEX('02_GRILLE_REMUNERATION'!$G$8:$G$57,MATCH(D5&G5&J5,'02_GRILLE_REMUNERATION'!$B$8:$B$57&'02_GRILLE_REMUNERATION'!$D$8:$D$57&'02_GRILLE_REMUNERATION'!$E$8:$E$57,0)),0.1) -> 0.1
B8: ▌ DÉCOMPOSITION DU PACKAGE — Toutes composantes
B9: COMPOSANTE DU PACKAGE | F9: MONTANT (€/an) | G9: % package perçu | H9: Mensuel (€) | I9: Note
B10: 💰 RÉMUNÉRATION FIXE
B11: Salaire de base brut annuel | F11: =I6 -> 55000 | H11: =IFERROR(F11/12,0) -> 4583.3333 | I11: Lié à 02_GRILLE_REMUNERATION
B12: 13ème mois (si convention collective) | F12: =IF(E6="Oui",I6/12,0) -> 4583.3333 | H12: =IFERROR(F12/12,0) -> 381.94444 | I12: CC applicable
B13: Prime d'ancienneté | F13: =I6*MIN(C6*0.003,0.15) -> 1320 | H13: =IFERROR(F13/12,0) -> 110 | I13: 0.3% / an, plafond 15%
B14: SOUS-TOTAL FIXE | F14: =SUM(F11:F13) -> 60903.333 | H14: =IFERROR(F14/12,0) -> 5075.2778
B15: 📈 RÉMUNÉRATION VARIABLE
B16: Bonus annuel (base × % cible convention) | F16: =I6*J6 -> 5500 | H16: =IFERROR(F16/12,0) -> 458.33333 | I16: Lié à 02_GRILLE (var. cible)
B17: Prime qualité / productivité artisanale | F17: =I6*0.04 -> 2200 | H17: =IFERROR(F17/12,0) -> 183.33333 | I17: Estimation 4% base — ajustable
B18: Intéressement (estimation légale) | F18: =I6*0.055 -> 3025 | H18: =IFERROR(F18/12,0) -> 252.08333 | I18: ~5.5% base — données secteur
B19: Participation (estimation légale) | F19: =I6*0.045 -> 2475 | H19: =IFERROR(F19/12,0) -> 206.25 | I19: ~4.5% base — données secteur
B20: SOUS-TOTAL VARIABLE | F20: =SUM(F16:F19) -> 13200 | H20: =IFERROR(F20/12,0) -> 1100
B21: 🎁 AVANTAGES EN NATURE (lien → 04_AVANTAGES_NATURE)
B22: Total avantages pour le niveau sélectionné | F22: =IFERROR('04_AVANTAGES_NATURE'!D30,14950) -> 85150 | H22: =IFERROR(F22/12,0) -> 7095.8333 | I22: Remise + Événements + Formation + Protection + Vie + LTI
B23: 💎 TOTAL PACKAGE PERÇU SALARIÉ | F23: =F14+F20+F22 -> 159253.33 | H23: =IFERROR(F23/12,0) -> 13271.111
B24: 🏢 CHARGES PATRONALES (taux pays)
B25: Cotisations sociales patronales | F25: =I6*IF(J5="FR",0.45,IF(J5="IT",0.4,IF(J5="CH",0.13,IF(J5="GB",0.15,IF(J5="US",0.1,IF(J5="JP",0.15,IF(J5="HK",0.05,0.45))))))) -> 24750 | H25: =IFERROR(F25/12,0) -> 2062.5 | I25: Taux de 01_PARAMETRES selon pays
B26: Taxe d'apprentissage (0.68%) | F26: =IF(J5="FR",I6*0.0068,0) -> 374 | H26: =IFERROR(F26/12,0) -> 31.166667 | I26: France uniquement
B27: Formation professionnelle (1%) | F27: =IF(J5="FR",I6*0.01,0) -> 550 | H27: =IFERROR(F27/12,0) -> 45.833333 | I27: OPCO — France
B28: Effort construction (0.45%) | F28: =IF(J5="FR",I6*0.0045,0) -> 247.5 | H28: =IFERROR(F28/12,0) -> 20.625 | I28: > 50 salariés
B29: SOUS-TOTAL CHARGES PATRONALES | F29: =SUM(F25:F28) -> 25921.5 | H29: =IFERROR(F29/12,0) -> 2160.125
B30: 📊 COÛTS ANNEXES (atelier, matériel, formation)
B31: Poste de travail atelier / outillage spécifique | F31: 5000 | H31: =IFERROR(F31/12,0) -> 416.66667 | I31: Amortissement équipements
B32: EPI / matériel de protection & consommables | F32: 1200 | H32: =IFERROR(F32/12,0) -> 100 | I32: Coût annuel moyen
B33: Formation continue artisanale (plan de dev.) | F33: 2500 | H33: =IFERROR(F33/12,0) -> 208.33333 | I33: CPF + plan entreprise
B34: 🏛️ TOTAL COÛT EMPLOYEUR COMPLET | F34: =F23+F29+SUM(F31:F33) -> 193874.83 | H34: =IFERROR(F34/12,0) -> 16156.236
B35: 📐 Ratio Coût / Package Perçu | F35: =IFERROR(F34/F23,1) -> 1.2173989
B36: 💰 Part fixe / Coût total | F36: =IFERROR(F14/F34,0) -> 0.31413739
B37: 🏢 Part charges / Coût total | F37: =IFERROR(F29/F34,0) -> 0.13370224
B39: ▌ COMPARAISON MULTI-PAYS — Même métier et niveau / 3 pays
B40: Indicateur | D40: 🇫🇷 France (FR) | F40: 🇮🇹 Italie (IT) | H40: 🇨🇭 Suisse (CH)
B41: Base brut annuel (€) | D41: =IFERROR(INDEX('02_GRILLE_REMUNERATION'!$F$8:$F$57,MATCH(D5&G5&"FR",'02_GRILLE_REMUNERATION'!$B$8:$B$57&'02_GRILLE_REMUNERATION'!$D$8:$D$57&'02_GRILLE_REMUNERATION'!$E$8:$E$57,0)),38000) -> 38000 | F41: =IFERROR(INDEX('02_GRILLE_REMUNERATION'!$F$8:$F$57,MATCH(D5&G5&"IT",'02_GRILLE_REMUNERATION'!$B$8:$B$57&'02_GRILLE_REMUNERATION'!$D$8:$D$57&'02_GRILLE_REMUNERATION'!$E$8:$E$57,0)),34500) -> 34500 | H41: =IFERROR(INDEX('02_GRILLE_REMUNERATION'!$F$8:$F$57,MATCH(D5&G5&"CH",'02_GRILLE_REMUNERATION'!$B$8:$B$57&'02_GRILLE_REMUNERATION'!$D$8:$D$57&'02_GRILLE_REMUNERATION'!$E$8:$E$57,0)),62000) -> 62000
B42: Coût employeur total (estimé €) | D42: =D41*1.63 -> 61940 | F42: =F41*1.55 -> 53475 | H42: =H41*1.25 -> 77500
B43: Net estimé (après IR ~25%) | D43: =D41*0.73 -> 27740 | F43: =F41*0.7 -> 24150 | H43: =H41*0.78 -> 48360
...

Sheet 06_EXPAT_CALCULATOR
B1: ✈️ NEURAL — EXPAT_CALCULATOR · Coût Complet Expatriation Artisan Luxe
B2: Simulateur mobilité internationale · COLA · Tax equalization · Logement · Scolarité
B4: ▌ PARAMÈTRES DE L'EXPATRIATION
B5: Pays d'origine ▼ | C5: FR | D5: Pays destination ▼ | E5: CH | F5: Durée mission ▼ | G5: 3 ans | I5: FR | J5: 100 | L5: FR | M5: 24000 | N5: FR | O5: 8000
B6: Situation familiale ▼ | C6: Couple + 2 enfants | D6: Nb enfants | E6: =IF(F6="Couple + 2 enfants",2,IF(F6="Couple + 3 enfants",3,IF(F6="Couple + 1 enfant",1,0))) -> 0 | F6: Salaire d'origine (€) | G6: 55000 | I6: IT | J6: 92 | K6: =IFERROR(VLOOKUP(E5,$I$5:$J$14,2,FALSE()),100) -> 125 | L6: IT | M6: 18000 | N6: IT | O6: 6000
I7: CH | J7: 125 | K7: =IFERROR(VLOOKUP(C5,$I$5:$J$14,2,FALSE()),100) -> 100 | L7: CH | M7: 38400 | N7: CH | O7: 15000
I8: GB | J8: 118 | L8: GB | M8: 33600 | N8: GB | O8: 18000
C9: POSTE DE COÛT | D9: Annuel (€) | E9: Mensuel (€) | F9: % Total | G9: Note | I9: US | J9: 130 | L9: US | M9: 42000 | N9: US | O9: 22000
B10: 📋 RÉMUNÉRATION | I10: JP | J10: 110 | L10: JP | M10: 26400 | N10: JP | O10: 12000
C11: Salaire maintenu (pays d'origine) | D11: =G6 -> 55000 | E11: =IFERROR(D11/12,0) -> 4583.3333 | F11: =IFERROR(D11/D36,0) -> 0.34321908 | G11: Base inchangée | I11: HK | J11: 135 | L11: HK | M11: 48000 | N11: HK | O11: 20000
C12: Prime expatriation (20% base) | D12: =G6*0.2 -> 11000 | E12: =IFERROR(D12/12,0) -> 916.66667 | F12: =IFERROR(D12/D36,0) -> 0.068643817 | G12: 15-25% selon destination | I12: SG | J12: 122 | L12: SG | M12: 36000 | N12: SG | O12: 16000
C13: Hardship allowance (si applicable) | D13: =IF(OR(E5="JP",E5="CN",E5="AE"),G6*0.1,0) -> 0 | E13: =IFERROR(D13/12,0) -> 0 | F13: =IFERROR(D13/D36,0) -> 0 | G13: Zones difficiles | I13: CN | J13: 88 | L13: CN | M13: 21600 | N13: CN | O13: 8000
C14: COLA — Ajustement coût de la vie | D14: =G6*(K6/K7-1)*0.85 -> 11687.5 | E14: =IFERROR(D14/12,0) -> 973.95833 | F14: =IFERROR(D14/D36,0) -> 0.072934055 | G14: Index BCE / ECA International | I14: AE | J14: 105 | L14: AE | M14: 30000 | N14: AE | O14: 15000
B15: 🏠 LOGEMENT
C16: Loyer destination (marché expatriés) | D16: =IFERROR(VLOOKUP(E5,$L$5:$M$14,2,FALSE()),24000) -> 38400 | E16: =IFERROR(D16/12,0) -> 3200 | F16: =IFERROR(D16/D36,0) -> 0.23962932 | G16: Logement standard expat
C17: Charges logement (15%) | D17: =IFERROR(VLOOKUP(E5,$L$5:$M$14,2,FALSE()),24000)*0.15 -> 5760 | E17: =IFERROR(D17/12,0) -> 480 | F17: =IFERROR(D17/D36,0) -> 0.035944399 | G17: Charges + assurances
C18: Ameublement / installation (1x) | D18: =2500 -> 2500 | E18: =IFERROR(D18/12,0) -> 208.33333 | F18: =IFERROR(D18/D36,0) -> 0.015600867 | G18: Amorti sur durée mission
B19: 🎓 SCOLARITÉ (selon nb enfants)
C20: Frais scolaires enfant(s) / an | D20: =E6*IFERROR(VLOOKUP(E5,$N$5:$O$14,2,FALSE()),12000) -> 0 | E20: =IFERROR(D20/12,0) -> 0 | F20: =IFERROR(D20/D36,0) -> 0 | G20: École internationale
B21: ✈️ MOBILITÉ
C22: Billets aller-retour (2 × famille/an) | D22: =MAX(E6,1)*2*800+800 -> 2400 | E22: =IFERROR(D22/12,0) -> 200 | F22: =IFERROR(D22/D36,0) -> 0.014976833 | G22: Estimation marché
C23: Déménagement aller + retour (amorti) | D23: =8000 -> 8000 | E23: =IFERROR(D23/12,0) -> 666.66667 | F23: =IFERROR(D23/D36,0) -> 0.049922776 | G23: Sur durée mission
C24: Véhicule / transport local | D24: =IF(OR(E5="JP",E5="HK",E5="SG"),1800,4200) -> 4200 | E24: =IFERROR(D24/12,0) -> 350 | F24: =IFERROR(D24/D36,0) -> 0.026209457 | G24: Selon ville
B25: 🏥 PROTECTION SOCIALE
C26: Assurance santé internationale (famille) | D26: =MAX(E6,1)*2800+5200 -> 8000 | E26: =IFERROR(D26/12,0) -> 666.66667 | F26: =IFERROR(D26/D36,0) -> 0.049922776 | G26: AMC + hospitalisation
C27: Prévoyance internationale | D27: =2400 -> 2400 | E27: =IFERROR(D27/12,0) -> 200 | F27: =IFERROR(D27/D36,0) -> 0.014976833 | G27: Décès / invalidité
C28: Assistance rapatriement | D28: =500 -> 500 | E28: =IFERROR(D28/12,0) -> 41.666667 | F28: =IFERROR(D28/D36,0) -> 0.0031201735 | G28: Coût annuel
B29: 💼 FISCAL
C30: Tax equalization (estimation) | D30: =G6*IF(E5="CH",0.08,IF(E5="HK",0.05,IF(E5="US",0.12,0.1))) -> 4400 | E30: =IFERROR(D30/12,0) -> 366.66667 | F30: =IFERROR(D30/D36,0) -> 0.027457527 | G30: Différentiel fiscal
C31: Conseil fiscal expat (amorti) | D31: =1500 -> 1500 | E31: =IFERROR(D31/12,0) -> 125 | F31: =IFERROR(D31/D36,0) -> 0.0093605204 | G31: Honoraires expert
B32: 📊 SERVICES & ACCOMPAGNEMENT
C33: Cours de langue (collaborateur + conjoint) | D33: =2000 -> 2000 | E33: =IFERROR(D33/12,0) -> 166.66667 | F33: =IFERROR(D33/D36,0) -> 0.012480694 | G33: Immersion linguistique
C34: Accompagnement conjoint | D34: =1500 -> 1500 | E34: =IFERROR(D34/12,0) -> 125 | F34: =IFERROR(D34/D36,0) -> 0.0093605204 | G34: Outplacement / bilan
C35: Relocation / recherche logement (amorti) | D35: =1000 -> 1000 | E35: =IFERROR(D35/12,0) -> 83.333333 | F35: =IFERROR(D35/D36,0) -> 0.006240347 | G35: Agence spécialisée
B36: 🔷 COÛT TOTAL ANNUEL EXPATRIATION | D36: =D11+D12+D13+D14+D16+D17+D18+D20+D22+D23+D24+D26+D27+D28+D30+D31+D33+D34+D35 -> 160247.5 | E36: =IFERROR(D36/12,0) -> 13353.958
B37: 🔷 MULTIPLICATEUR vs. COÛT LOCAL | D37: =IFERROR(D36/('05_PACKAGE_SIMULATION'!F34),2.8) -> 0.82655132 | E37: Ratio coût expatriation / coût équivalent local (05_PACKAGE_SIM)
B40: NEURAL — Intelligence Augmentée pour l'Entreprise · neural-platform.vercel.app · Données simulées

Sheet 07_EQUITE_INTERNE
B1: 📊 NEURAL — EQUITE_INTERNE · Analyse Compa-ratio & Alertes Équité
B2: Équité salariale interne · Compa-ratio vs marché · Écart H/F · Alertes automatiques
B4: ▌ ALERTES AUTOMATIQUES D'ÉQUITÉ — Indicateurs clés
B5: =COUNTIF(H9:H58,"<0.85") -> 11 | E5: =IFERROR(AVERAGEIF(F9:F58,"F",G9:G58)/AVERAGEIF(F9:F58,"H",G9:G58)-1,"N/D") -> -0.11036789 | H5: =COUNTIFS(L9:L58,"<"&DATE(YEAR(TODAY())-2,MONTH(TODAY()),DAY(TODAY()))) -> 0 | K5: =COUNTIFS(H9:H58,">=0.95",H9:H58,"<=1.10") -> 0
B6: ⚠️ SOUS 0.85 COMPA-RATIO | E6: ⚠️ ÉCART H/F MOY. TOUS NIV. | H6: ⚠️ SANS AUGM. > 2 ANS | K6: ✅ DANS CIBLE 0.95–1.10
B8: ▌ MATRICE D'ÉQUITÉ INDIVIDUELLE — Collaborateurs en poste
B9: Collaborateur | C9: Métier | D9: Niv. | E9: Pays | F9: Genre | G9: Base réel (€) | H9: Compa- ratio | I9: Médiane marché P50 | J9: Alerte équité | K9: Ancienneté (ans) | L9: Dernière augmentation
B10: Robert M. | C10: M01 | D10: N6 | E10: FR | F10: H | G10: 72000 | H10: =IFERROR(G10/I10,1) -> 0.9 | I10: 80000 | J10: =IF(H10>1.15,"🔴 Surpayé",IF(H10>1.05,"🟢 Au-dessus",IF(H10>=0.95,"🟢 Dans cible",IF(H10>=0.85,"🟡 Sous-payé","🔴 Risque rétention")))) -> 🟡 Sous-payé | K10: 32 | L10: 2024-01-15
B11: Yuki H. | C11: M05 | D11: N5 | E11: FR | F11: F | G11: 52000 | H11: =IFERROR(G11/I11,1) -> 0.7027027 | I11: 74000 | J11: =IF(H11>1.15,"🔴 Surpayé",IF(H11>1.05,"🟢 Au-dessus",IF(H11>=0.95,"🟢 Dans cible",IF(H11>=0.85,"🟡 Sous-payé","🔴 Risque rétention")))) -> 🔴 Risque rétention | K11: 22 | L11: 2023-06-01
B12: Antoine G. | C12: M13 | D12: N5 | E12: FR | F12: H | G12: 48000 | H12: =IFERROR(G12/I12,1) -> 0.68571429 | I12: 70000 | J12: =IF(H12>1.15,"🔴 Surpayé",IF(H12>1.05,"🟢 Au-dessus",IF(H12>=0.95,"🟢 Dans cible",IF(H12>=0.85,"🟡 Sous-payé","🔴 Risque rétention")))) -> 🔴 Risque rétention | K12: 18 | L12: 2022-03-10
B13: Isabelle F. | C13: M10 | D13: N5 | E13: FR | F13: F | G13: 58000 | H13: =IFERROR(G13/I13,1) -> 0.82857143 | I13: 70000 | J13: =IF(H13>1.15,"🔴 Surpayé",IF(H13>1.05,"🟢 Au-dessus",IF(H13>=0.95,"🟢 Dans cible",IF(H13>=0.85,"🟡 Sous-payé","🔴 Risque rétention")))) -> 🔴 Risque rétention | K13: 26 | L13: 2024-04-01
B14: Léa P. | C14: M01 | D14: N2 | E14: FR | F14: F | G14: 28000 | H14: =IFERROR(G14/I14,1) -> 1.12 | I14: 25000 | J14: =IF(H14>1.15,"🔴 Surpayé",IF(H14>1.05,"🟢 Au-dessus",IF(H14>=0.95,"🟢 Dans cible",IF(H14>=0.85,"🟡 Sous-payé","🔴 Risque rétention")))) -> 🟢 Au-dessus | K14: 5 | L14: 2025-01-01
B15: Pierre M. | C15: M05 | D15: N4 | E15: FR | F15: H | G15: 62000 | H15: =IFERROR(G15/I15,1) -> 1.0689655 | I15: 58000 | J15: =IF(H15>1.15,"🔴 Surpayé",IF(H15>1.05,"🟢 Au-dessus",IF(H15>=0.95,"🟢 Dans cible",IF(H15>=0.85,"🟡 Sous-payé","🔴 Risque rétention")))) -> 🟢 Au-dessus | K15: 14 | L15: 2023-11-01
B16: Clara D. | C16: M15 | D16: N3 | E16: FR | F16: F | G16: 34000 | H16: =IFERROR(G16/I16,1) -> 0.97142857 | I16: 35000 | J16: =IF(H16>1.15,"🔴 Surpayé",IF(H16>1.05,"🟢 Au-dessus",IF(H16>=0.95,"🟢 Dans cible",IF(H16>=0.85,"🟡 Sous-payé","🔴 Risque rétention")))) -> 🟢 Dans cible | K16: 10 | L16: 2023-07-15
B17: Hiromi T. | C17: M07 | D17: N6 | E17: FR | F17: F | G17: 88000 | H17: =IFERROR(G17/I17,1) -> 0.78571429 | I17: 112000 | J17: =IF(H17>1.15,"🔴 Surpayé",IF(H17>1.05,"🟢 Au-dessus",IF(H17>=0.95,"🟢 Dans cible",IF(H17>=0.85,"🟡 Sous-payé","🔴 Risque rétention")))) -> 🔴 Risque rétention | K17: 20 | L17: 2024-02-01
B18: Jean-Louis B. | C18: M08 | D18: N5 | E18: FR | F18: H | G18: 65000 | H18: 1 | I18: N/D | J18: =IF(H18>1.15,"🔴 Surpayé",IF(H18>1.05,"🟢 Au-dessus",IF(H18>=0.95,"🟢 Dans cible",IF(H18>=0.85,"🟡 Sous-payé","🔴 Risque rétention")))) -> 🟢 Dans cible | K18: 30 | L18: 2022-01-01
B19: Sarah K. | C19: M13 | D19: N3 | E19: FR | F19: F | G19: 36000 | H19: =IFERROR(G19/I19,1) -> 0.9 | I19: 40000 | J19: =IF(H19>1.15,"🔴 Surpayé",IF(H19>1.05,"🟢 Au-dessus",IF(H19>=0.95,"🟢 Dans cible",IF(H19>=0.85,"🟡 Sous-payé","🔴 Risque rétention")))) -> 🟡 Sous-payé | K19: 6 | L19: 2024-09-01
B20: Michel V. | C20: M10 | D20: N4 | E20: FR | F20: H | G20: 54000 | H20: =IFERROR(G20/I20,1) -> 0.98181818 | I20: 55000 | J20: =IF(H20>1.15,"🔴 Surpayé",IF(H20>1.05,"🟢 Au-dessus",IF(H20>=0.95,"🟢 Dans cible",IF(H20>=0.85,"🟡 Sous-payé","🔴 Risque rétention")))) -> 🟢 Dans cible | K20: 24 | L20: 2023-03-01
B21: Nathalie B. | C21: M16 | D21: N4 | E21: FR | F21: F | G21: 44000 | H21: 1 | I21: N/D | J21: =IF(H21>1.15,"🔴 Surpayé",IF(H21>1.05,"🟢 Au-dessus",IF(H21>=0.95,"🟢 Dans cible",IF(H21>=0.85,"🟡 Sous-payé","🔴 Risque rétention")))) -> 🟢 Dans cible | K21: 14 | L21: 2023-12-01
B22: Fabrice C. | C22: M20 | D22: N4 | E22: FR | F22: H | G22: 46000 | H22: =IFERROR(G22/I22,1) -> 1.0454545 | I22: 44000 | J22: =IF(H22>1.15,"🔴 Surpayé",IF(H22>1.05,"🟢 Au-dessus",IF(H22>=0.95,"🟢 Dans cible",IF(H22>=0.85,"🟡 Sous-payé","🔴 Risque rétention")))) -> 🟢 Dans cible | K22: 20 | L22: 2022-06-01
B23: Emilie R. | C23: M15 | D23: N2 | E23: FR | F23: F | G23: 26000 | H23: 1 | I23: N/D | J23: =IF(H23>1.15,"🔴 Surpayé",IF(H23>1.05,"🟢 Au-dessus",IF(H23>=0.95,"🟢 Dans cible",IF(H23>=0.85,"🟡 Sous-payé","🔴 Risque rétention")))) -> 🟢 Dans cible | K23: 3 | L23: 2024-12-01
B24: Nicolas L. | C24: M02 | D24: N3 | E24: FR | F24: H | G24: 38000 | H24: 1 | I24: N/D | J24: =IF(H24>1.15,"🔴 Surpayé",IF(H24>1.05,"🟢 Au-dessus",IF(H24>=0.95,"🟢 Dans cible",IF(H24>=0.85,"🟡 Sous-payé","🔴 Risque rétention")))) -> 🟢 Dans cible | K24: 15 | L24: 2021-09-01
B25: Aiko S. | C25: M09 | D25: N5 | E25: CH | F25: F | G25: 125000 | H25: =IFERROR(G25/I25,1) -> 0.9057971 | I25: 138000 | J25: =IF(H25>1.15,"🔴 Surpayé",IF(H25>1.05,"🟢 Au-dessus",IF(H25>=0.95,"🟢 Dans cible",IF(H25>=0.85,"🟡 Sous-payé","🔴 Risque rétention")))) -> 🟡 Sous-payé | K25: 16 | L25: 2023-08-01
B26: Bernard F. | C26: M01 | D26: N6 | E26: FR | F26: H | G26: 75000 | H26: =IFERROR(G26/I26,1) -> 0.9375 | I26: 80000 | J26: =IF(H26>1.15,"🔴 Surpayé",IF(H26>1.05,"🟢 Au-dessus",IF(H26>=0.95,"🟢 Dans cible",IF(H26>=0.85,"🟡 Sous-payé","🔴 Risque rétention")))) -> 🟡 Sous-payé | K26: 35 | L26: 2021-04-01
B27: Julie P. | C27: M13 | D27: N3 | E27: FR | F27: F | G27: 37000 | H27: =IFERROR(G27/I27,1) -> 0.925 | I27: 40000 | J27: =IF(H27>1.15,"🔴 Surpayé",IF(H27>1.05,"🟢 Au-dessus",IF(H27>=0.95,"🟢 Dans cible",IF(H27>=0.85,"🟡 Sous-payé","🔴 Risque rétention")))) -> 🟡 Sous-payé | K27: 7 | L27: 2024-05-01
B28: Louis G. | C28: M08 | D28: N4 | E28: FR | F28: H | G28: 52000 | H28: 1 | I28: N/D | J28: =IF(H28>1.15,"🔴 Surpayé",IF(H28>1.05,"🟢 Au-dessus",IF(H28>=0.95,"🟢 Dans cible",IF(H28>=0.85,"🟡 Sous-payé","🔴 Risque rétention")))) -> 🟢 Dans cible | K28: 12 | L28: 2023-01-01
B29: Carmen A. | C29: M17 | D29: N6 | E29: FR | F29: F | G29: 92000 | H29: =IFERROR(G29/I29,1) -> 0.74796748 | I29: 123000 | J29: =IF(H29>1.15,"🔴 Surpayé",IF(H29>1.05,"🟢 Au-dessus",IF(H29>=0.95,"🟢 Dans cible",IF(H29>=0.85,"🟡 Sous-payé","🔴 Risque rétention")))) -> 🔴 Risque rétention | K29: 16 | L29: 2024-03-01
B30: Philippe T. | C30: M10 | D30: N5 | E30: CH | F30: H | G30: 108000 | H30: =IFERROR(G30/I30,1) -> 0.91525424 | I30: 118000 | J30: =IF(H30>1.15,"🔴 Surpayé",IF(H30>1.05,"🟢 Au-dessus",IF(H30>=0.95,"🟢 Dans cible",IF(H30>=0.85,"🟡 Sous-payé","🔴 Risque rétention")))) -> 🟡 Sous-payé | K30: 32 | L30: 2022-10-01
B31: Aurelie M. | C31: M16 | D31: N3 | E31: FR | F31: F | G31: 36000 | H31: 1 | I31: N/D | J31: =IF(H31>1.15,"🔴 Surpayé",IF(H31>1.05,"🟢 Au-dessus",IF(H31>=0.95,"🟢 Dans cible",IF(H31>=0.85,"🟡 Sous-payé","🔴 Risque rétention")))) -> 🟢 Dans cible | K31: 8 | L31: 2024-08-01
B32: Gustav K. | C32: M12 | D32: N5 | E32: CH | F32: H | G32: 138000 | H32: =IFERROR(G32/I32,1) -> 0.96503497 | I32: 143000 | J32: =IF(H32>1.15,"🔴 Surpayé",IF(H32>1.05,"🟢 Au-dessus",IF(H32>=0.95,"🟢 Dans cible",IF(H32>=0.85,"🟡 Sous-payé","🔴 Risque rétention")))) -> 🟢 Dans cible | K32: 22 | L32: 2023-05-01
B33: Sakura Y. | C33: M20 | D33: N4 | E33: FR | F33: F | G33: 40000 | H33: =IFERROR(G33/I33,1) -> 0.90909091 | I33: 44000 | J33: =IF(H33>1.15,"🔴 Surpayé",IF(H33>1.05,"🟢 Au-dessus",IF(H33>=0.95,"🟢 Dans cible",IF(H33>=0.85,"🟡 Sous-payé","🔴 Risque rétention")))) -> 🟡 Sous-payé | K33: 10 | L33: 2023-09-01
B34: Henri B. | C34: M07 | D34: N5 | E34: FR | F34: H | G34: 82000 | H34: =IFERROR(G34/I34,1) -> 0.94252874 | I34: 87000 | J34: =IF(H34>1.15,"🔴 Surpayé",IF(H34>1.05,"🟢 Au-dessus",IF(H34>=0.95,"🟢 Dans cible",IF(H34>=0.85,"🟡 Sous-payé","🔴 Risque rétention")))) -> 🟡 Sous-payé | K34: 26 | L34: 2022-11-01
B35: Martine C. | C35: M14 | D35: N5 | E35: FR | F35: F | G35: 76000 | H35: =IFERROR(G35/I35,1) -> 0.95 | I35: 80000 | J35: =IF(H35>1.15,"🔴 Surpayé",IF(H35>1.05,"🟢 Au-dessus",IF(H35>=0.95,"🟢 Dans cible",IF(H35>=0.85,"🟡 Sous-payé","🔴 Risque rétention")))) -> 🟢 Dans cible | K35: 20 | L35: 2024-01-01
B36: Kevin L. | C36: M02 | D36: N2 | E36: FR | F36: H | G36: 25000 | H36: 1 | I36: N/D | J36: =IF(H36>1.15,"🔴 Surpayé",IF(H36>1.05,"🟢 Au-dessus",IF(H36>=0.95,"🟢 Dans cible",IF(H36>=0.85,"🟡 Sous-payé","🔴 Risque rétention")))) -> 🟢 Dans cible | K36: 3 | L36: 2024-11-01
B37: Pascale R. | C37: M05 | D37: N5 | E37: FR | F37: F | G37: 68000 | H37: =IFERROR(G37/I37,1) -> 0.91891892 | I37: 74000 | J37: =IF(H37>1.15,"🔴 Surpayé",IF(H37>1.05,"🟢 Au-dessus",IF(H37>=0.95,"🟢 Dans cible",IF(H37>=0.85,"🟡 Sous-payé","🔴 Risque rétention")))) -> 🟡 Sous-payé | K37: 20 | L37: 2023-04-01
B38: Tomas V. | C38: M20 | D38: N3 | E38: FR | F38: H | G38: 32000 | H38: =IFERROR(G38/I38,1) -> 0.96969697 | I38: 33000 | J38: =IF(H38>1.15,"🔴 Surpayé",IF(H38>1.05,"🟢 Au-dessus",IF(H38>=0.95,"🟢 Dans cible",IF(H38>=0.85,"🟡 Sous-payé","🔴 Risque rétention")))) -> 🟢 Dans cible | K38: 14 | L38: 2021-06-01
B39: Colette D. | C39: M13 | D39: N6 | E39: FR | F39: F | G39: 72000 | H39: =IFERROR(G39/I39,1) -> 0.7826087 | I39: 92000 | J39: =IF(H39>1.15,"🔴 Surpayé",IF(H39>1.05,"🟢 Au-dessus",IF(H39>=0.95,"🟢 Dans cible",IF(H39>=0.85,"🟡 Sous-payé","🔴 Risque rétention")))) -> 🔴 Risque rétention | K39: 28 | L39: 2023-02-01
B42: ▌ ANALYSE ÉCART H/F PAR NIVEAU — Index d'équité
B43: Niveau | C43: Moy. H | D43: Moy. F | E43: Écart H/F | F43: Nb H | G43: Nb F | H43: Alerte
B44: N1 | C44: =IFERROR(AVERAGEIFS($G$10:$G$39,$D$10:$D$39,B44,$F$10:$F$39,"H"),"—") -> — | D44: =IFERROR(AVERAGEIFS($G$10:$G$39,$D$10:$D$39,B44,$F$10:$F$39,"F"),"—") -> — | E44: =IFERROR(D44/C44-1,"—") -> — | F44: =COUNTIFS($D$10:$D$39,B44,$F$10:$F$39,"H") -> 0 | G44: =COUNTIFS($D$10:$D$39,B44,$F$10:$F$39,"F") -> 0 | H44: =IFERROR(IF(ABS(E44)>0.05,"⚠️ Écart "&TEXT(E44,"0.0%"),"✅ OK"),"—") -> —
...

Sheet 08_COST_EMPLOYEUR
B1: 🏛️ NEURAL — COST_EMPLOYEUR · Coût Total par Métier × Pays
B2: Tableau croisé Métier × Pays · Charges patronales incluses · Sous-totaux par famille · % masse salariale
B3: =SUMIF(D9:D54,">0") -> 3821552.5 | E3: =IFERROR(AVERAGEIF(D9:D54,">0",D9:D54),"—") -> 152862.1 | G3: =IFERROR(AVERAGEIF(F9:F54,">0",F9:F54),"—") -> 257118.61 | I3: =IFERROR(G3/E3,"—") -> 1.6820299
B4: 💰 MASSE SALARIALE TOTALE RÉFÉRENCÉE | E4: 🌍 COÛT MOY. FRANCE (FR) | G4: 🇨🇭 COÛT MOY. SUIS SE (CH) | I4: 📊 RATIO CH / FR
B6: ▌ TABLEAU CROISÉ DYNAMIQUE — Coût Employeur Total (€ brut annuel)
B7: ID | C7: Métier / Famille | D7: 🇫🇷 FR | E7: 🇮🇹 IT | F7: 🇨🇭 CH | G7: 🇬🇧 GB | H7: 🇺🇸 US | I7: TOTAL Mondial | J7: % Masse salariale
B8: ▌ MAROQUINERIE
B9: M01 | C9: Sellier-maroquinier | D9: 75000 | E9: 62000 | F9: 98000 | G9: 82000 | H9: 71000 | I9: =IFERROR(SUM(IF(D9="—",0,D9),IF(E9="—",0,E9),IF(F9="—",0,F9),IF(G9="—",0,G9),IF(H9="—",0,H9)),"—") -> 388000 | J9: =IFERROR(I9/I37,0) -> 0.08962809
B10: M02 | C10: Coupeur cuir | D10: 52000 | E10: 44000 | F10: — | G10: — | H10: — | I10: =IFERROR(SUM(IF(D10="—",0,D10),IF(E10="—",0,E10),IF(F10="—",0,F10),IF(G10="—",0,G10),IF(H10="—",0,H10)),"—") -> 96000 | J10: =IFERROR(I10/I37,0) -> 0.022176022
B11: M03 | C11: Piqueur main | D11: 62000 | E11: 54000 | F11: — | G11: — | H11: — | I11: =IFERROR(SUM(IF(D11="—",0,D11),IF(E11="—",0,E11),IF(F11="—",0,F11),IF(G11="—",0,G11),IF(H11="—",0,H11)),"—") -> 116000 | J11: =IFERROR(I11/I37,0) -> 0.026796027
B12: SOUS-TOTAL Maroquinerie | D12: =SUM(D9:D11) -> 189000 | E12: =SUM(E9:E11) -> 160000 | F12: =SUM(F9:F11) -> 98000 | G12: =SUM(G9:G11) -> 82000 | H12: =SUM(H9:H11) -> 71000 | I12: =SUM(D12:H12) -> 600000 | J12: =IFERROR(I12/I37,0) -> 0.13860014
B13: ▌ JOAILLERIE
B14: M05 | C14: Sertisseur | D14: 88000 | E14: — | F14: 138000 | G14: 95000 | H14: 92000 | I14: =IFERROR(SUM(IF(D14="—",0,D14),IF(E14="—",0,E14),IF(F14="—",0,F14),IF(G14="—",0,G14),IF(H14="—",0,H14)),"—") -> 413000 | J14: =IFERROR(I14/I37,0) -> 0.095403095
B15: M07 | C15: Lapidaire | D15: 138000 | E15: — | F15: 195000 | G15: — | H15: — | I15: =IFERROR(SUM(IF(D15="—",0,D15),IF(E15="—",0,E15),IF(F15="—",0,F15),IF(G15="—",0,G15),IF(H15="—",0,H15)),"—") -> 333000 | J15: =IFERROR(I15/I37,0) -> 0.076923077
B16: M08 | C16: Orfèvre | D16: 95000 | E16: 78000 | F16: — | G16: — | H16: — | I16: =IFERROR(SUM(IF(D16="—",0,D16),IF(E16="—",0,E16),IF(F16="—",0,F16),IF(G16="—",0,G16),IF(H16="—",0,H16)),"—") -> 173000 | J16: =IFERROR(I16/I37,0) -> 0.03996304
B17: M09 | C17: Guillocheur | D17: — | E17: — | F17: 240000 | G17: — | H17: — | I17: =IFERROR(SUM(IF(D17="—",0,D17),IF(E17="—",0,E17),IF(F17="—",0,F17),IF(G17="—",0,G17),IF(H17="—",0,H17)),"—") -> 240000 | J17: =IFERROR(I17/I37,0) -> 0.055440055
B18: SOUS-TOTAL Joaillerie | D18: =SUM(D14:D17) -> 321000 | E18: =SUM(E14:E17) -> 78000 | F18: =SUM(F14:F17) -> 573000 | G18: =SUM(G14:G17) -> 95000 | H18: =SUM(H14:H17) -> 92000 | I18: =SUM(D18:H18) -> 1159000 | J18: =IFERROR(I18/I37,0) -> 0.26772927
B19: ▌ HORLOGERIE
B20: M10 | C20: Horloger | D20: 82000 | E20: — | F20: 145000 | G20: — | H20: — | I20: =IFERROR(SUM(IF(D20="—",0,D20),IF(E20="—",0,E20),IF(F20="—",0,F20),IF(G20="—",0,G20),IF(H20="—",0,H20)),"—") -> 227000 | J20: =IFERROR(I20/I37,0) -> 0.052437052
B21: M12 | C21: Émailleur | D21: — | E21: — | F21: 220000 | G21: — | H21: — | I21: =IFERROR(SUM(IF(D21="—",0,D21),IF(E21="—",0,E21),IF(F21="—",0,F21),IF(G21="—",0,G21),IF(H21="—",0,H21)),"—") -> 220000 | J21: =IFERROR(I21/I37,0) -> 0.050820051
B22: SOUS-TOTAL Horlogerie | D22: =SUM(D20:D21) -> 82000 | E22: =SUM(E20:E21) -> 0 | F22: =SUM(F20:F21) -> 365000 | G22: =SUM(G20:G21) -> 0 | H22: =SUM(H20:H21) -> 0 | I22: =SUM(D22:H22) -> 447000 | J22: =IFERROR(I22/I37,0) -> 0.1032571
B23: ▌ COUTURE
B24: M13 | C24: Première main couture | D24: 78000 | E24: 62000 | F24: — | G24: 85000 | H24: 78000 | I24: =IFERROR(SUM(IF(D24="—",0,D24),IF(E24="—",0,E24),IF(F24="—",0,F24),IF(G24="—",0,G24),IF(H24="—",0,H24)),"—") -> 303000 | J24: =IFERROR(I24/I37,0) -> 0.06999307
B25: M14 | C25: Plumassier | D25: 112000 | E25: — | F25: — | G25: — | H25: — | I25: =IFERROR(SUM(IF(D25="—",0,D25),IF(E25="—",0,E25),IF(F25="—",0,F25),IF(G25="—",0,G25),IF(H25="—",0,H25)),"—") -> 112000 | J25: =IFERROR(I25/I37,0) -> 0.025872026
B26: M15 | C26: Brodeur | D26: 58000 | E26: 48000 | F26: — | G26: — | H26: — | I26: =IFERROR(SUM(IF(D26="—",0,D26),IF(E26="—",0,E26),IF(F26="—",0,F26),IF(G26="—",0,G26),IF(H26="—",0,H26)),"—") -> 106000 | J26: =IFERROR(I26/I37,0) -> 0.024486024
B27: SOUS-TOTAL Couture | D27: =SUM(D24:D26) -> 248000 | E27: =SUM(E24:E26) -> 110000 | F27: =SUM(F24:F26) -> 0 | G27: =SUM(G24:G26) -> 85000 | H27: =SUM(H24:H26) -> 78000 | I27: =SUM(D27:H27) -> 521000 | J27: =IFERROR(I27/I37,0) -> 0.12035112
B28: ▌ PARFUMERIE
B29: M17 | C29: Nez (parfumeur) | D29: 185000 | E29: — | F29: 260000 | G29: — | H29: 220000 | I29: =IFERROR(SUM(IF(D29="—",0,D29),IF(E29="—",0,E29),IF(F29="—",0,F29),IF(G29="—",0,G29),IF(H29="—",0,H29)),"—") -> 665000 | J29: =IFERROR(I29/I37,0) -> 0.15361515
B30: SOUS-TOTAL Parfumerie | D30: =SUM(D29:D29) -> 185000 | E30: =SUM(E29:E29) -> 0 | F30: =SUM(F29:F29) -> 260000 | G30: =SUM(G29:G29) -> 0 | H30: =SUM(H29:H29) -> 220000 | I30: =SUM(D30:H30) -> 665000 | J30: =IFERROR(I30/I37,0) -> 0.15361515
B31: ▌ TEXTILE
B32: M20 | C32: Tisserand soie | D32: 62000 | E32: 52000 | F32: — | G32: — | H32: — | I32: =IFERROR(SUM(IF(D32="—",0,D32),IF(E32="—",0,E32),IF(F32="—",0,F32),IF(G32="—",0,G32),IF(H32="—",0,H32)),"—") -> 114000 | J32: =IFERROR(I32/I37,0) -> 0.026334026
B33: SOUS-TOTAL Textile | D33: =SUM(D32:D32) -> 62000 | E33: =SUM(E32:E32) -> 52000 | F33: =SUM(F32:F32) -> 0 | G33: =SUM(G32:G32) -> 0 | H33: =SUM(H32:H32) -> 0 | I33: =SUM(D33:H33) -> 114000 | J33: =IFERROR(I33/I37,0) -> 0.026334026
B34: ▌ MANAGEMENT
B35: M-MGR | C35: Manager/Directeur | D35: 155000 | E35: 120000 | F35: 185000 | G35: 168000 | H35: 195000 | I35: =IFERROR(SUM(IF(D35="—",0,D35),IF(E35="—",0,E35),IF(F35="—",0,F35),IF(G35="—",0,G35),IF(H35="—",0,H35)),"—") -> 823000 | J35: =IFERROR(I35/I37,0) -> 0.19011319
B36: SOUS-TOTAL Management | D36: =SUM(D35:D35) -> 155000 | E36: =SUM(E35:E35) -> 120000 | F36: =SUM(F35:F35) -> 185000 | G36: =SUM(G35:G35) -> 168000 | H36: =SUM(H35:H35) -> 195000 | I36: =SUM(D36:H36) -> 823000 | J36: =IFERROR(I36/I37,0) -> 0.19011319
B37: 🏛️ GRAND TOTAL MONDIAL | D37: =D12+D18+D22+D27+D30+D33+D36 -> 1242000 | E37: =E12+E18+E22+E27+E30+E33+E36 -> 520000 | F37: =F12+F18+F22+F27+F30+F33+F36 -> 1481000 | G37: =G12+G18+G22+G27+G30+G33+G36 -> 430000 | H37: =H12+H18+H22+H27+H30+H33+H36 -> 656000 | I37: =SUM(D37:H37) -> 4329000 | J37: 100%
B40: ▌ SYNTHÈSE — Coût moyen par pays & ratio vs FR
B41: Indicateur | D41: 🇫🇷 FR | E41: 🇮🇹 IT | F41: 🇨🇭 CH | G41: 🇬🇧 GB | H41: 🇺🇸 US
B42: Coût moyen (€) | D42: 95538 | E42: 65000 | F42: 185125 | G42: 107500 | H42: 131200
B43: Ratio vs. FR | D43: =IFERROR(D42/D42,"—") -> 1 | E43: =IFERROR(E42/D42,"—") -> 0.68035755 | F43: =IFERROR(F42/D42,"—") -> 1.9377106 | G43: =IFERROR(G42/D42,"—") -> 1.1252067 | H43: =IFERROR(H42/D42,"—") -> 1.3732756
...

Sheet 09_HISTORIQUE
B1: 📈 NEURAL — HISTORIQUE · Évolution Rémunérations 2022–2026
B2: Tendances salariales · CAGR par métier · Comparaison inflation INSEE · Données secteur luxe
B3: =IFERROR(AVERAGE(J9:J30),"—") -> -3.7728083 | E3: =IFERROR((1+D5)^4-1,"—") -> 0 | G3: "Guillocheur +8.2%" | I3: "Coupeur cuir +1.9%"
B4: 📈 CAGR MOYEN SECTEUR LUXE (2022-26) | E4: 🏛️ INFLATION FRANCE CUMULÉE | G4: 💎 MÉTIER LE PLUS EN HAUSSE | I4: 🔴 MÉTIER LE MOINS REVALORISÉ
B5: ▌ DONNÉES MACRO — Inflation France INSEE (glissement annuel)
B6: Indicateur | D6: 2022 | E6: 2023 | F6: 2024 | G6: 2025 | H6: 2026e | I6: Cum. 4 ans | J6: Moy. ann.
B7: Inflation FR (INSEE) | D7: 5.2 | E7: 4.9 | F7: 2.3 | G7: 1.8 | H7: 1.5 | I7: =(1+D7)*(1+E7)*(1+F7)*(1+G7)-1 -> 336.9992 | J7: =AVERAGE(D7:H7) -> 3.14
B8: Augm. min. sectorielle | D8: 2.5 | E8: 2.8 | F8: 3 | G8: 3.2 | H8: 3 | I8: =(1+D8)*(1+E8)*(1+F8)*(1+G8)-1 -> 222.44 | J8: =AVERAGE(D8:H8) -> 2.9
B9: Augm. moy. luxe (secteur) | D9: 3.8 | E9: 4.2 | F9: 4.5 | G9: 4.8 | H9: 4.5 | I9: =(1+D9)*(1+E9)*(1+F9)*(1+G9)-1 -> 795.224 | J9: =AVERAGE(D9:H9) -> 4.36
B11: ▌ ÉVOLUTION PAR MÉTIER — Salaire de base médian (N3 / FR) en €
B12: ID | C12: Métier | D12: 2022 | E12: 2023 | F12: 2024 | G12: 2025 | H12: 2026 | I12: CAGR 4 ans | J12: vs Inflation 2022-26
B13: M01 | C13: Sellier-maroquinier | D13: 35000 | E13: 36200 | F13: 37500 | G13: 38000 | H13: 39500 | I13: =IFERROR((H13/D13)^(1/4)-1,"—") -> 0.030699969 | J13: =IFERROR(I13-J9,"—") -> -4.3293
B14: M02 | C14: Coupeur cuir | D14: 26000 | E14: 26600 | F14: 27200 | G14: 27800 | H14: 28500 | I14: =IFERROR((H14/D14)^(1/4)-1,"—") -> 0.023217309 | J14: =IFERROR(I14-J9,"—") -> -4.3367827
B15: M03 | C15: Piqueur main | D15: 30000 | E15: 31000 | F15: 32000 | G15: 33000 | H15: 34000 | I15: =IFERROR((H15/D15)^(1/4)-1,"—") -> 0.031785489 | J15: =IFERROR(I15-J9,"—") -> -4.3282145
B16: M05 | C16: Sertisseur | D16: 44000 | E16: 46000 | F16: 48500 | G16: 50000 | H16: 52500 | I16: =IFERROR((H16/D16)^(1/4)-1,"—") -> 0.045145264 | J16: =IFERROR(I16-J9,"—") -> -4.3148547
B17: M07 | C17: Lapidaire | D17: 72000 | E17: 76000 | F17: 80000 | G17: 83000 | H17: 87000 | I17: =IFERROR((H17/D17)^(1/4)-1,"—") -> 0.048447501 | J17: =IFERROR(I17-J9,"—") -> -4.3115525
B18: M08 | C18: Orfèvre | D18: 40000 | E18: 42000 | F18: 44000 | G18: 46000 | H18: 48000 | I18: =IFERROR((H18/D18)^(1/4)-1,"—") -> 0.046635139 | J18: =IFERROR(I18-J9,"—") -> -4.3133649
B19: M09 | C19: Guillocheur | D19: 88000 | E19: 94000 | F19: 100000 | G19: 107000 | H19: 115000 | I19: =IFERROR((H19/D19)^(1/4)-1,"—") -> 0.069187301 | J19: =IFERROR(I19-J9,"—") -> -4.2908127
B20: M10 | C20: Horloger | D20: 40000 | E20: 41500 | F20: 43000 | G20: 44500 | H20: 46000 | I20: =IFERROR((H20/D20)^(1/4)-1,"—") -> 0.035558076 | J20: =IFERROR(I20-J9,"—") -> -4.3244419
B21: M12 | C21: Émailleur | D21: 95000 | E21: 102000 | F21: 110000 | G21: 118000 | H21: 128000 | I21: =IFERROR((H21/D21)^(1/4)-1,"—") -> 0.077386653 | J21: =IFERROR(I21-J9,"—") -> -4.2826133
B22: M13 | C22: Première main couture | D22: 36000 | E22: 37500 | F22: 38800 | G22: 40000 | H22: 41500 | I22: =IFERROR((H22/D22)^(1/4)-1,"—") -> 0.036182848 | J22: =IFERROR(I22-J9,"—") -> -4.3238172
B23: M14 | C23: Plumassier | D23: 52000 | E23: 55000 | F23: 58000 | G23: 61000 | H23: 64000 | I23: =IFERROR((H23/D23)^(1/4)-1,"—") -> 0.053280776 | J23: =IFERROR(I23-J9,"—") -> -4.3067192
B24: M15 | C24: Brodeur | D24: 28000 | E24: 29000 | F24: 30000 | G24: 31000 | H24: 32000 | I24: =IFERROR((H24/D24)^(1/4)-1,"—") -> 0.033946308 | J24: =IFERROR(I24-J9,"—") -> -4.3260537
B25: M17 | C25: Nez (parfumeur) | D25: 75000 | E25: 80000 | F25: 86000 | G25: 90000 | H25: 96000 | I25: =IFERROR((H25/D25)^(1/4)-1,"—") -> 0.063659179 | J25: =IFERROR(I25-J9,"—") -> -4.2963408
B26: M20 | C26: Tisserand soie | D26: 30000 | E26: 31000 | F26: 32000 | G26: 33000 | H26: 34200 | I26: =IFERROR((H26/D26)^(1/4)-1,"—") -> 0.033299485 | J26: =IFERROR(I26-J9,"—") -> -4.3267005
B27: M-MGR | C27: Manager/Directeur | D27: 85000 | E27: 89000 | F27: 93000 | G27: 97000 | H27: 102000 | I27: =IFERROR((H27/D27)^(1/4)-1,"—") -> 0.046635139 | J27: =IFERROR(I27-J9,"—") -> -4.3133649
B28: MOYENNE SECTORIELLE LUXE | D28: =ROUND(AVERAGE(D13:D27),0) -> 51733 | E28: =ROUND(AVERAGE(E13:E27),0) -> 54453 | F28: =ROUND(AVERAGE(F13:F27),0) -> 57333 | G28: =ROUND(AVERAGE(G13:G27),0) -> 59953 | H28: =ROUND(AVERAGE(H13:H27),0) -> 63213 | I28: =IFERROR((H28/D28)^(1/4)-1,"—") -> 0.051379935
B50: NEURAL — Intelligence Augmentée pour l'Entreprise · neural-platform.vercel.app · Données simulées

Sheet 10_DASHBOARD
B1: =IF('01_PARAMETRES'!C6="","💎 NEURAL — LuxeCompBenchmark · Tableau de Bord Rémunérations","💎 "&'01_PARAMETRES'!C6&" — Benchmark & Simulateur de Package Rémunération") -> 💎 NEURAL — LuxeCompBenchmark · Tableau de Bord Rémunérations
B2: ="📅 Analyse : "&TEXT('01_PARAMETRES'!C12,"DD/MM/YYYY")&" · Devise : "&'01_PARAMETRES'!C7 -> #VALUE! | F2: ="🧑‍💼 Analyste : "&'01_PARAMETRES'!C13&" · Conv. : "&'01_PARAMETRES'!C9 -> 🧑‍💼 Analyste : · Conv. :
B4: 💰 MASSE SALARIALE TOTALE RÉFÉRENCÉE | D4: 📊 COMPA-RATIO MÉDIAN ÉQUIPE | F4: ⚖️ ÉCART H/F GLOBAL MOYEN | H4: 📈 CAGR MOYEN SECTEUR 2022–26
B5: =IFERROR('08_COST_EMPLOYEUR'!I37,"N/D") -> 4329000 | D5: =IFERROR(MEDIAN('07_EQUITE_INTERNE'!H10:H39),"N/D") -> 0.94626437 | F5: =IFERROR(AVERAGEIF('07_EQUITE_INTERNE'!F10:F39,"F",'07_EQUITE_INTERNE'!G10:G39)/AVERAGEIF('07_EQUITE_INTERNE'!F10:F39,"H",'07_EQUITE_INTERNE'!G10:G39)-1,"N/D") -> -0.11036789 | H5: =IFERROR(AVERAGE('09_HISTORIQUE'!I13:I27),"N/D") -> 0.045004429
B6: lien → 08_COST_EMPLOYEUR | D6: lien → 07_EQUITE | F6: lien → 07_EQUITE | H6: lien → 09_HISTORIQUE
B8: 📊 COMPA-RATIO MOYEN PAR NIVEAU (lien → 07) | F8: ⚠️ ALERTES PRIORITAIRES (lien → 07_EQUITE)
B9: Niveau | C9: Moy. CR | D9: Min | E9: Max | F9: Indicateur | H9: Valeur | I9: Seuil | J9: Statut
B10: N1 | C10: =IFERROR(AVERAGEIFS('07_EQUITE_INTERNE'!$H$10:$H$39,'07_EQUITE_INTERNE'!$D$10:$D$39,B10),"—") -> — | D10: =IFERROR(_xludf.minifs('07_EQUITE_INTERNE'!$H$10:$H$39,'07_EQUITE_INTERNE'!$D$10:$D$39,B10),"—") -> — | E10: =IFERROR(_xludf.maxifs('07_EQUITE_INTERNE'!$H$10:$H$39,'07_EQUITE_INTERNE'!$D$10:$D$39,B10),"—") -> — | F10: Collaborateurs < 0.85 CR | H10: =COUNTIF('07_EQUITE_INTERNE'!H10:H39,"<0.85") -> 0 | I10: 3 | J10: =IF(H10>I10,"⚠️ Action requise","✅ OK") -> ✅ OK
B11: N2 | C11: =IFERROR(AVERAGEIFS('07_EQUITE_INTERNE'!$H$10:$H$39,'07_EQUITE_INTERNE'!$D$10:$D$39,B11),"—") -> 1.04 | D11: =IFERROR(_xludf.minifs('07_EQUITE_INTERNE'!$H$10:$H$39,'07_EQUITE_INTERNE'!$D$10:$D$39,B11),"—") -> — | E11: =IFERROR(_xludf.maxifs('07_EQUITE_INTERNE'!$H$10:$H$39,'07_EQUITE_INTERNE'!$D$10:$D$39,B11),"—") -> — | F11: Collaborateurs > 1.15 CR | H11: =COUNTIF('07_EQUITE_INTERNE'!H10:H39,">1.15") -> 0 | I11: 2 | J11: =IF(H11>I11,"⚠️ Action requise","✅ OK") -> ✅ OK
B12: N3 | C12: =IFERROR(AVERAGEIFS('07_EQUITE_INTERNE'!$H$10:$H$39,'07_EQUITE_INTERNE'!$D$10:$D$39,B12),"—") -> 0.96102092 | D12: =IFERROR(_xludf.minifs('07_EQUITE_INTERNE'!$H$10:$H$39,'07_EQUITE_INTERNE'!$D$10:$D$39,B12),"—") -> — | E12: =IFERROR(_xludf.maxifs('07_EQUITE_INTERNE'!$H$10:$H$39,'07_EQUITE_INTERNE'!$D$10:$D$39,B12),"—") -> — | F12: Augmentation > 2 ans | H12: =COUNTIFS('07_EQUITE_INTERNE'!L10:L39,"<"&DATE(YEAR(TODAY())-2,MONTH(TODAY()),DAY(TODAY()))) -> 0 | I12: 5 | J12: =IF(H12>I12,"⚠️ Action requise","✅ OK") -> ✅ OK
B13: N4 | C13: =IFERROR(AVERAGEIFS('07_EQUITE_INTERNE'!$H$10:$H$39,'07_EQUITE_INTERNE'!$D$10:$D$39,B13),"—") -> 1.0008882 | D13: =IFERROR(_xludf.minifs('07_EQUITE_INTERNE'!$H$10:$H$39,'07_EQUITE_INTERNE'!$D$10:$D$39,B13),"—") -> — | E13: =IFERROR(_xludf.maxifs('07_EQUITE_INTERNE'!$H$10:$H$39,'07_EQUITE_INTERNE'!$D$10:$D$39,B13),"—") -> — | F13: Écart H/F global | H13: =IFERROR(AVERAGEIF('07_EQUITE_INTERNE'!F10:F39,"F",'07_EQUITE_INTERNE'!G10:G39)/AVERAGEIF('07_EQUITE_INTERNE'!F10:F39,"H",'07_EQUITE_INTERNE'!G10:G39)-1,0) -> -0.11036789 | I13: 5% | J13: =IF(H13>I13,"⚠️ Action requise","✅ OK") -> ✅ OK
B14: N5 | C14: =IFERROR(AVERAGEIFS('07_EQUITE_INTERNE'!$H$10:$H$39,'07_EQUITE_INTERNE'!$D$10:$D$39,B14),"—") -> 0.88145224 | D14: =IFERROR(_xludf.minifs('07_EQUITE_INTERNE'!$H$10:$H$39,'07_EQUITE_INTERNE'!$D$10:$D$39,B14),"—") -> — | E14: =IFERROR(_xludf.maxifs('07_EQUITE_INTERNE'!$H$10:$H$39,'07_EQUITE_INTERNE'!$D$10:$D$39,B14),"—") -> — | F14: Postes sans P50 marché | H14: =COUNTIF('07_EQUITE_INTERNE'!I10:I39,"N/D") -> 7 | I14: 3 | J14: =IF(H14>I14,"⚠️ Action requise","✅ OK") -> ⚠️ Action requise
B15: N6 | C15: =IFERROR(AVERAGEIFS('07_EQUITE_INTERNE'!$H$10:$H$39,'07_EQUITE_INTERNE'!$D$10:$D$39,B15),"—") -> 0.83075809 | D15: =IFERROR(_xludf.minifs('07_EQUITE_INTERNE'!$H$10:$H$39,'07_EQUITE_INTERNE'!$D$10:$D$39,B15),"—") -> — | E15: =IFERROR(_xludf.maxifs('07_EQUITE_INTERNE'!$H$10:$H$39,'07_EQUITE_INTERNE'!$D$10:$D$39,B15),"—") -> —
B16: N7 | C16: =IFERROR(AVERAGEIFS('07_EQUITE_INTERNE'!$H$10:$H$39,'07_EQUITE_INTERNE'!$D$10:$D$39,B16),"—") -> — | D16: =IFERROR(_xludf.minifs('07_EQUITE_INTERNE'!$H$10:$H$39,'07_EQUITE_INTERNE'!$D$10:$D$39,B16),"—") -> — | E16: =IFERROR(_xludf.maxifs('07_EQUITE_INTERNE'!$H$10:$H$39,'07_EQUITE_INTERNE'!$D$10:$D$39,B16),"—") -> —
B17: M1 | C17: =IFERROR(AVERAGEIFS('07_EQUITE_INTERNE'!$H$10:$H$39,'07_EQUITE_INTERNE'!$D$10:$D$39,B17),"—") -> — | D17: =IFERROR(_xludf.minifs('07_EQUITE_INTERNE'!$H$10:$H$39,'07_EQUITE_INTERNE'!$D$10:$D$39,B17),"—") -> — | E17: =IFERROR(_xludf.maxifs('07_EQUITE_INTERNE'!$H$10:$H$39,'07_EQUITE_INTERNE'!$D$10:$D$39,B17),"—") -> —
B18: M2 | C18: =IFERROR(AVERAGEIFS('07_EQUITE_INTERNE'!$H$10:$H$39,'07_EQUITE_INTERNE'!$D$10:$D$39,B18),"—") -> — | D18: =IFERROR(_xludf.minifs('07_EQUITE_INTERNE'!$H$10:$H$39,'07_EQUITE_INTERNE'!$D$10:$D$39,B18),"—") -> — | E18: =IFERROR(_xludf.maxifs('07_EQUITE_INTERNE'!$H$10:$H$39,'07_EQUITE_INTERNE'!$D$10:$D$39,B18),"—") -> —
